<?xml version="1.0" ?>
<!-- =================================================================================== -->
<!-- |    This document was autogenerated by xacro from tablebot_row.xacro             | -->
<!-- |    EDITING THIS FILE BY HAND IS NOT RECOMMENDED                                 | -->
<!-- =================================================================================== -->
<robot name="tablebot">
  <!-- <link name="footprint">
      <visual>
        <geometry>
          <sphere radius="0.0001" />
        </geometry>
      </visual>
    </link> -->
  <link name="table_base">
    <visual>
      <geometry>
        <!-- <box size="${tab_size} ${tab_size} ${tab_height}"/> -->
        <box size="0.0001 0.0001 0.0001"/>
      </geometry>
      <!-- <origin xyz="${tab_size / 2} ${tab_size / 2} ${-tab_height / 2}" rpy="0 0 0"/> -->
      <origin rpy="0 0 0" xyz="0 0 0"/>
      <material name="black">
        <color rgba="1 1 1 0.5"/>
      </material>
      <inertial>
        <origin rpy="0 0 0" xyz="0 0 0"/>
        <mass value="10"/>
        <inertia ixx="1.0" ixy="0.0" ixz="0.0" iyy="1.0" iyz="0.0" izz="1.0"/>
      </inertial>
    </visual>
  </link>
  <!-- <joint name="base2footprint" type="fixed">
      <parent link="footprint" />
      <child link="table_base" />
      <origin xyz="0 0 ${tab_height / 2 }" />
    </joint> -->
  <!-- <xacro:macro name="loop" params="links_qty">
        <xacro:if value="${links_qty}">
            <xacro:loop links_qty="${links_qty-1}" />
        </xacro:if>
    </xacro:macro> -->
  <link name="link_0_14">
    <visual>
      <geometry>
        <box size="0.016 0.016 0.055"/>
      </geometry>
      <origin rpy="0 0 0" xyz="0 0 -0.0275"/>
      <material name="blue0">
        <color rgba="0 0 1 0.9"/>
      </material>
    </visual>
    <collision>
      <geometry>
        <box size="0.016 0.016 0.055"/>
      </geometry>
      <origin rpy="0 0 0" xyz="0 0 -0.0275"/>
    </collision>
    <inertial>
      <origin rpy="0 0 0" xyz="0 0 0"/>
      <mass value="0.5"/>
      <inertia ixx="1.0" ixy="0.0" ixz="0.0" iyy="1.0" iyz="0.0" izz="1.0"/>
    </inertial>
  </link>
  <joint name="joint_0_14" type="prismatic">
    <parent link="table_base"/>
    <child link="link_0_14"/>
    <origin ryp="0 0 0" xyz="0.018000000000000002 0.29800000000000004 0"/>
    <axis xyz="0 0 1"/>
    <limit effort="4" lower="0" upper="0.045" velocity="0.01"/>
  </joint>
  <link name="cylinder_0_14">
    <visual>
      <geometry>
        <cylinder length="0.01" radius="0.009"/>
      </geometry>
      <origin rpy="0 0 0" xyz="0 0 -0.005"/>
      <material name="blue1">
        <color rgba="0 0 1 0.6"/>
      </material>
    </visual>
    <collision>
      <geometry>
        <cylinder length="0.01" radius="0.009"/>
      </geometry>
      <origin rpy="0 0 0" xyz="0 0 -0.005"/>
    </collision>
    <inertial>
      <origin rpy="0 0 0" xyz="0 0 0"/>
      <mass value="0.05"/>
      <inertia ixx="1.0" ixy="0.0" ixz="0.0" iyy="1.0" iyz="0.0" izz="1.0"/>
    </inertial>
  </link>
  <joint name="cylinder2base_0_14" type="fixed">
    <parent link="link_0_14"/>
    <child link="cylinder_0_14"/>
    <origin ryp="0 0 0" xyz="0 0 0.01"/>
  </joint>
  <link name="sphere_0_14">
    <visual>
      <geometry>
        <sphere radius="0.009"/>
      </geometry>
      <origin rpy="0 0 0" xyz="0 0 0"/>
      <material name="blue1">
        <color rgba="0 0 1 0.6"/>
      </material>
    </visual>
    <collision>
      <geometry>
        <sphere radius="0.009"/>
      </geometry>
      <origin rpy="0 0 0" xyz="0 0 0"/>
    </collision>
    <inertial>
      <origin rpy="0 0 0" xyz="0 0 0"/>
      <mass value="0.05"/>
      <inertia ixx="1.0" ixy="0.0" ixz="0.0" iyy="1.0" iyz="0.0" izz="1.0"/>
    </inertial>
  </link>
  <joint name="sphere2cylinder_0_14" type="fixed">
    <parent link="cylinder_0_14"/>
    <child link="sphere_0_14"/>
    <origin ryp="0 0 0" xyz="0 0 0"/>
  </joint>
  <link name="link_0_13">
    <visual>
      <geometry>
        <box size="0.016 0.016 0.055"/>
      </geometry>
      <origin rpy="0 0 0" xyz="0 0 -0.0275"/>
      <material name="blue0">
        <color rgba="0 0 1 0.9"/>
      </material>
    </visual>
    <collision>
      <geometry>
        <box size="0.016 0.016 0.055"/>
      </geometry>
      <origin rpy="0 0 0" xyz="0 0 -0.0275"/>
    </collision>
    <inertial>
      <origin rpy="0 0 0" xyz="0 0 0"/>
      <mass value="0.5"/>
      <inertia ixx="1.0" ixy="0.0" ixz="0.0" iyy="1.0" iyz="0.0" izz="1.0"/>
    </inertial>
  </link>
  <joint name="joint_0_13" type="prismatic">
    <parent link="table_base"/>
    <child link="link_0_13"/>
    <origin ryp="0 0 0" xyz="0.018000000000000002 0.278 0"/>
    <axis xyz="0 0 1"/>
    <limit effort="4" lower="0" upper="0.045" velocity="0.01"/>
  </joint>
  <link name="cylinder_0_13">
    <visual>
      <geometry>
        <cylinder length="0.01" radius="0.009"/>
      </geometry>
      <origin rpy="0 0 0" xyz="0 0 -0.005"/>
      <material name="blue1">
        <color rgba="0 0 1 0.6"/>
      </material>
    </visual>
    <collision>
      <geometry>
        <cylinder length="0.01" radius="0.009"/>
      </geometry>
      <origin rpy="0 0 0" xyz="0 0 -0.005"/>
    </collision>
    <inertial>
      <origin rpy="0 0 0" xyz="0 0 0"/>
      <mass value="0.05"/>
      <inertia ixx="1.0" ixy="0.0" ixz="0.0" iyy="1.0" iyz="0.0" izz="1.0"/>
    </inertial>
  </link>
  <joint name="cylinder2base_0_13" type="fixed">
    <parent link="link_0_13"/>
    <child link="cylinder_0_13"/>
    <origin ryp="0 0 0" xyz="0 0 0.01"/>
  </joint>
  <link name="sphere_0_13">
    <visual>
      <geometry>
        <sphere radius="0.009"/>
      </geometry>
      <origin rpy="0 0 0" xyz="0 0 0"/>
      <material name="blue1">
        <color rgba="0 0 1 0.6"/>
      </material>
    </visual>
    <collision>
      <geometry>
        <sphere radius="0.009"/>
      </geometry>
      <origin rpy="0 0 0" xyz="0 0 0"/>
    </collision>
    <inertial>
      <origin rpy="0 0 0" xyz="0 0 0"/>
      <mass value="0.05"/>
      <inertia ixx="1.0" ixy="0.0" ixz="0.0" iyy="1.0" iyz="0.0" izz="1.0"/>
    </inertial>
  </link>
  <joint name="sphere2cylinder_0_13" type="fixed">
    <parent link="cylinder_0_13"/>
    <child link="sphere_0_13"/>
    <origin ryp="0 0 0" xyz="0 0 0"/>
  </joint>
  <link name="link_0_12">
    <visual>
      <geometry>
        <box size="0.016 0.016 0.055"/>
      </geometry>
      <origin rpy="0 0 0" xyz="0 0 -0.0275"/>
      <material name="blue0">
        <color rgba="0 0 1 0.9"/>
      </material>
    </visual>
    <collision>
      <geometry>
        <box size="0.016 0.016 0.055"/>
      </geometry>
      <origin rpy="0 0 0" xyz="0 0 -0.0275"/>
    </collision>
    <inertial>
      <origin rpy="0 0 0" xyz="0 0 0"/>
      <mass value="0.5"/>
      <inertia ixx="1.0" ixy="0.0" ixz="0.0" iyy="1.0" iyz="0.0" izz="1.0"/>
    </inertial>
  </link>
  <joint name="joint_0_12" type="prismatic">
    <parent link="table_base"/>
    <child link="link_0_12"/>
    <origin ryp="0 0 0" xyz="0.018000000000000002 0.258 0"/>
    <axis xyz="0 0 1"/>
    <limit effort="4" lower="0" upper="0.045" velocity="0.01"/>
  </joint>
  <link name="cylinder_0_12">
    <visual>
      <geometry>
        <cylinder length="0.01" radius="0.009"/>
      </geometry>
      <origin rpy="0 0 0" xyz="0 0 -0.005"/>
      <material name="blue1">
        <color rgba="0 0 1 0.6"/>
      </material>
    </visual>
    <collision>
      <geometry>
        <cylinder length="0.01" radius="0.009"/>
      </geometry>
      <origin rpy="0 0 0" xyz="0 0 -0.005"/>
    </collision>
    <inertial>
      <origin rpy="0 0 0" xyz="0 0 0"/>
      <mass value="0.05"/>
      <inertia ixx="1.0" ixy="0.0" ixz="0.0" iyy="1.0" iyz="0.0" izz="1.0"/>
    </inertial>
  </link>
  <joint name="cylinder2base_0_12" type="fixed">
    <parent link="link_0_12"/>
    <child link="cylinder_0_12"/>
    <origin ryp="0 0 0" xyz="0 0 0.01"/>
  </joint>
  <link name="sphere_0_12">
    <visual>
      <geometry>
        <sphere radius="0.009"/>
      </geometry>
      <origin rpy="0 0 0" xyz="0 0 0"/>
      <material name="blue1">
        <color rgba="0 0 1 0.6"/>
      </material>
    </visual>
    <collision>
      <geometry>
        <sphere radius="0.009"/>
      </geometry>
      <origin rpy="0 0 0" xyz="0 0 0"/>
    </collision>
    <inertial>
      <origin rpy="0 0 0" xyz="0 0 0"/>
      <mass value="0.05"/>
      <inertia ixx="1.0" ixy="0.0" ixz="0.0" iyy="1.0" iyz="0.0" izz="1.0"/>
    </inertial>
  </link>
  <joint name="sphere2cylinder_0_12" type="fixed">
    <parent link="cylinder_0_12"/>
    <child link="sphere_0_12"/>
    <origin ryp="0 0 0" xyz="0 0 0"/>
  </joint>
  <link name="link_0_11">
    <visual>
      <geometry>
        <box size="0.016 0.016 0.055"/>
      </geometry>
      <origin rpy="0 0 0" xyz="0 0 -0.0275"/>
      <material name="blue0">
        <color rgba="0 0 1 0.9"/>
      </material>
    </visual>
    <collision>
      <geometry>
        <box size="0.016 0.016 0.055"/>
      </geometry>
      <origin rpy="0 0 0" xyz="0 0 -0.0275"/>
    </collision>
    <inertial>
      <origin rpy="0 0 0" xyz="0 0 0"/>
      <mass value="0.5"/>
      <inertia ixx="1.0" ixy="0.0" ixz="0.0" iyy="1.0" iyz="0.0" izz="1.0"/>
    </inertial>
  </link>
  <joint name="joint_0_11" type="prismatic">
    <parent link="table_base"/>
    <child link="link_0_11"/>
    <origin ryp="0 0 0" xyz="0.018000000000000002 0.238 0"/>
    <axis xyz="0 0 1"/>
    <limit effort="4" lower="0" upper="0.045" velocity="0.01"/>
  </joint>
  <link name="cylinder_0_11">
    <visual>
      <geometry>
        <cylinder length="0.01" radius="0.009"/>
      </geometry>
      <origin rpy="0 0 0" xyz="0 0 -0.005"/>
      <material name="blue1">
        <color rgba="0 0 1 0.6"/>
      </material>
    </visual>
    <collision>
      <geometry>
        <cylinder length="0.01" radius="0.009"/>
      </geometry>
      <origin rpy="0 0 0" xyz="0 0 -0.005"/>
    </collision>
    <inertial>
      <origin rpy="0 0 0" xyz="0 0 0"/>
      <mass value="0.05"/>
      <inertia ixx="1.0" ixy="0.0" ixz="0.0" iyy="1.0" iyz="0.0" izz="1.0"/>
    </inertial>
  </link>
  <joint name="cylinder2base_0_11" type="fixed">
    <parent link="link_0_11"/>
    <child link="cylinder_0_11"/>
    <origin ryp="0 0 0" xyz="0 0 0.01"/>
  </joint>
  <link name="sphere_0_11">
    <visual>
      <geometry>
        <sphere radius="0.009"/>
      </geometry>
      <origin rpy="0 0 0" xyz="0 0 0"/>
      <material name="blue1">
        <color rgba="0 0 1 0.6"/>
      </material>
    </visual>
    <collision>
      <geometry>
        <sphere radius="0.009"/>
      </geometry>
      <origin rpy="0 0 0" xyz="0 0 0"/>
    </collision>
    <inertial>
      <origin rpy="0 0 0" xyz="0 0 0"/>
      <mass value="0.05"/>
      <inertia ixx="1.0" ixy="0.0" ixz="0.0" iyy="1.0" iyz="0.0" izz="1.0"/>
    </inertial>
  </link>
  <joint name="sphere2cylinder_0_11" type="fixed">
    <parent link="cylinder_0_11"/>
    <child link="sphere_0_11"/>
    <origin ryp="0 0 0" xyz="0 0 0"/>
  </joint>
  <link name="link_0_10">
    <visual>
      <geometry>
        <box size="0.016 0.016 0.055"/>
      </geometry>
      <origin rpy="0 0 0" xyz="0 0 -0.0275"/>
      <material name="blue0">
        <color rgba="0 0 1 0.9"/>
      </material>
    </visual>
    <collision>
      <geometry>
        <box size="0.016 0.016 0.055"/>
      </geometry>
      <origin rpy="0 0 0" xyz="0 0 -0.0275"/>
    </collision>
    <inertial>
      <origin rpy="0 0 0" xyz="0 0 0"/>
      <mass value="0.5"/>
      <inertia ixx="1.0" ixy="0.0" ixz="0.0" iyy="1.0" iyz="0.0" izz="1.0"/>
    </inertial>
  </link>
  <joint name="joint_0_10" type="prismatic">
    <parent link="table_base"/>
    <child link="link_0_10"/>
    <origin ryp="0 0 0" xyz="0.018000000000000002 0.21800000000000003 0"/>
    <axis xyz="0 0 1"/>
    <limit effort="4" lower="0" upper="0.045" velocity="0.01"/>
  </joint>
  <link name="cylinder_0_10">
    <visual>
      <geometry>
        <cylinder length="0.01" radius="0.009"/>
      </geometry>
      <origin rpy="0 0 0" xyz="0 0 -0.005"/>
      <material name="blue1">
        <color rgba="0 0 1 0.6"/>
      </material>
    </visual>
    <collision>
      <geometry>
        <cylinder length="0.01" radius="0.009"/>
      </geometry>
      <origin rpy="0 0 0" xyz="0 0 -0.005"/>
    </collision>
    <inertial>
      <origin rpy="0 0 0" xyz="0 0 0"/>
      <mass value="0.05"/>
      <inertia ixx="1.0" ixy="0.0" ixz="0.0" iyy="1.0" iyz="0.0" izz="1.0"/>
    </inertial>
  </link>
  <joint name="cylinder2base_0_10" type="fixed">
    <parent link="link_0_10"/>
    <child link="cylinder_0_10"/>
    <origin ryp="0 0 0" xyz="0 0 0.01"/>
  </joint>
  <link name="sphere_0_10">
    <visual>
      <geometry>
        <sphere radius="0.009"/>
      </geometry>
      <origin rpy="0 0 0" xyz="0 0 0"/>
      <material name="blue1">
        <color rgba="0 0 1 0.6"/>
      </material>
    </visual>
    <collision>
      <geometry>
        <sphere radius="0.009"/>
      </geometry>
      <origin rpy="0 0 0" xyz="0 0 0"/>
    </collision>
    <inertial>
      <origin rpy="0 0 0" xyz="0 0 0"/>
      <mass value="0.05"/>
      <inertia ixx="1.0" ixy="0.0" ixz="0.0" iyy="1.0" iyz="0.0" izz="1.0"/>
    </inertial>
  </link>
  <joint name="sphere2cylinder_0_10" type="fixed">
    <parent link="cylinder_0_10"/>
    <child link="sphere_0_10"/>
    <origin ryp="0 0 0" xyz="0 0 0"/>
  </joint>
  <link name="link_0_9">
    <visual>
      <geometry>
        <box size="0.016 0.016 0.055"/>
      </geometry>
      <origin rpy="0 0 0" xyz="0 0 -0.0275"/>
      <material name="blue0">
        <color rgba="0 0 1 0.9"/>
      </material>
    </visual>
    <collision>
      <geometry>
        <box size="0.016 0.016 0.055"/>
      </geometry>
      <origin rpy="0 0 0" xyz="0 0 -0.0275"/>
    </collision>
    <inertial>
      <origin rpy="0 0 0" xyz="0 0 0"/>
      <mass value="0.5"/>
      <inertia ixx="1.0" ixy="0.0" ixz="0.0" iyy="1.0" iyz="0.0" izz="1.0"/>
    </inertial>
  </link>
  <joint name="joint_0_9" type="prismatic">
    <parent link="table_base"/>
    <child link="link_0_9"/>
    <origin ryp="0 0 0" xyz="0.018000000000000002 0.198 0"/>
    <axis xyz="0 0 1"/>
    <limit effort="4" lower="0" upper="0.045" velocity="0.01"/>
  </joint>
  <link name="cylinder_0_9">
    <visual>
      <geometry>
        <cylinder length="0.01" radius="0.009"/>
      </geometry>
      <origin rpy="0 0 0" xyz="0 0 -0.005"/>
      <material name="blue1">
        <color rgba="0 0 1 0.6"/>
      </material>
    </visual>
    <collision>
      <geometry>
        <cylinder length="0.01" radius="0.009"/>
      </geometry>
      <origin rpy="0 0 0" xyz="0 0 -0.005"/>
    </collision>
    <inertial>
      <origin rpy="0 0 0" xyz="0 0 0"/>
      <mass value="0.05"/>
      <inertia ixx="1.0" ixy="0.0" ixz="0.0" iyy="1.0" iyz="0.0" izz="1.0"/>
    </inertial>
  </link>
  <joint name="cylinder2base_0_9" type="fixed">
    <parent link="link_0_9"/>
    <child link="cylinder_0_9"/>
    <origin ryp="0 0 0" xyz="0 0 0.01"/>
  </joint>
  <link name="sphere_0_9">
    <visual>
      <geometry>
        <sphere radius="0.009"/>
      </geometry>
      <origin rpy="0 0 0" xyz="0 0 0"/>
      <material name="blue1">
        <color rgba="0 0 1 0.6"/>
      </material>
    </visual>
    <collision>
      <geometry>
        <sphere radius="0.009"/>
      </geometry>
      <origin rpy="0 0 0" xyz="0 0 0"/>
    </collision>
    <inertial>
      <origin rpy="0 0 0" xyz="0 0 0"/>
      <mass value="0.05"/>
      <inertia ixx="1.0" ixy="0.0" ixz="0.0" iyy="1.0" iyz="0.0" izz="1.0"/>
    </inertial>
  </link>
  <joint name="sphere2cylinder_0_9" type="fixed">
    <parent link="cylinder_0_9"/>
    <child link="sphere_0_9"/>
    <origin ryp="0 0 0" xyz="0 0 0"/>
  </joint>
  <link name="link_0_8">
    <visual>
      <geometry>
        <box size="0.016 0.016 0.055"/>
      </geometry>
      <origin rpy="0 0 0" xyz="0 0 -0.0275"/>
      <material name="blue0">
        <color rgba="0 0 1 0.9"/>
      </material>
    </visual>
    <collision>
      <geometry>
        <box size="0.016 0.016 0.055"/>
      </geometry>
      <origin rpy="0 0 0" xyz="0 0 -0.0275"/>
    </collision>
    <inertial>
      <origin rpy="0 0 0" xyz="0 0 0"/>
      <mass value="0.5"/>
      <inertia ixx="1.0" ixy="0.0" ixz="0.0" iyy="1.0" iyz="0.0" izz="1.0"/>
    </inertial>
  </link>
  <joint name="joint_0_8" type="prismatic">
    <parent link="table_base"/>
    <child link="link_0_8"/>
    <origin ryp="0 0 0" xyz="0.018000000000000002 0.17800000000000002 0"/>
    <axis xyz="0 0 1"/>
    <limit effort="4" lower="0" upper="0.045" velocity="0.01"/>
  </joint>
  <link name="cylinder_0_8">
    <visual>
      <geometry>
        <cylinder length="0.01" radius="0.009"/>
      </geometry>
      <origin rpy="0 0 0" xyz="0 0 -0.005"/>
      <material name="blue1">
        <color rgba="0 0 1 0.6"/>
      </material>
    </visual>
    <collision>
      <geometry>
        <cylinder length="0.01" radius="0.009"/>
      </geometry>
      <origin rpy="0 0 0" xyz="0 0 -0.005"/>
    </collision>
    <inertial>
      <origin rpy="0 0 0" xyz="0 0 0"/>
      <mass value="0.05"/>
      <inertia ixx="1.0" ixy="0.0" ixz="0.0" iyy="1.0" iyz="0.0" izz="1.0"/>
    </inertial>
  </link>
  <joint name="cylinder2base_0_8" type="fixed">
    <parent link="link_0_8"/>
    <child link="cylinder_0_8"/>
    <origin ryp="0 0 0" xyz="0 0 0.01"/>
  </joint>
  <link name="sphere_0_8">
    <visual>
      <geometry>
        <sphere radius="0.009"/>
      </geometry>
      <origin rpy="0 0 0" xyz="0 0 0"/>
      <material name="blue1">
        <color rgba="0 0 1 0.6"/>
      </material>
    </visual>
    <collision>
      <geometry>
        <sphere radius="0.009"/>
      </geometry>
      <origin rpy="0 0 0" xyz="0 0 0"/>
    </collision>
    <inertial>
      <origin rpy="0 0 0" xyz="0 0 0"/>
      <mass value="0.05"/>
      <inertia ixx="1.0" ixy="0.0" ixz="0.0" iyy="1.0" iyz="0.0" izz="1.0"/>
    </inertial>
  </link>
  <joint name="sphere2cylinder_0_8" type="fixed">
    <parent link="cylinder_0_8"/>
    <child link="sphere_0_8"/>
    <origin ryp="0 0 0" xyz="0 0 0"/>
  </joint>
  <link name="link_0_7">
    <visual>
      <geometry>
        <box size="0.016 0.016 0.055"/>
      </geometry>
      <origin rpy="0 0 0" xyz="0 0 -0.0275"/>
      <material name="blue0">
        <color rgba="0 0 1 0.9"/>
      </material>
    </visual>
    <collision>
      <geometry>
        <box size="0.016 0.016 0.055"/>
      </geometry>
      <origin rpy="0 0 0" xyz="0 0 -0.0275"/>
    </collision>
    <inertial>
      <origin rpy="0 0 0" xyz="0 0 0"/>
      <mass value="0.5"/>
      <inertia ixx="1.0" ixy="0.0" ixz="0.0" iyy="1.0" iyz="0.0" izz="1.0"/>
    </inertial>
  </link>
  <joint name="joint_0_7" type="prismatic">
    <parent link="table_base"/>
    <child link="link_0_7"/>
    <origin ryp="0 0 0" xyz="0.018000000000000002 0.158 0"/>
    <axis xyz="0 0 1"/>
    <limit effort="4" lower="0" upper="0.045" velocity="0.01"/>
  </joint>
  <link name="cylinder_0_7">
    <visual>
      <geometry>
        <cylinder length="0.01" radius="0.009"/>
      </geometry>
      <origin rpy="0 0 0" xyz="0 0 -0.005"/>
      <material name="blue1">
        <color rgba="0 0 1 0.6"/>
      </material>
    </visual>
    <collision>
      <geometry>
        <cylinder length="0.01" radius="0.009"/>
      </geometry>
      <origin rpy="0 0 0" xyz="0 0 -0.005"/>
    </collision>
    <inertial>
      <origin rpy="0 0 0" xyz="0 0 0"/>
      <mass value="0.05"/>
      <inertia ixx="1.0" ixy="0.0" ixz="0.0" iyy="1.0" iyz="0.0" izz="1.0"/>
    </inertial>
  </link>
  <joint name="cylinder2base_0_7" type="fixed">
    <parent link="link_0_7"/>
    <child link="cylinder_0_7"/>
    <origin ryp="0 0 0" xyz="0 0 0.01"/>
  </joint>
  <link name="sphere_0_7">
    <visual>
      <geometry>
        <sphere radius="0.009"/>
      </geometry>
      <origin rpy="0 0 0" xyz="0 0 0"/>
      <material name="blue1">
        <color rgba="0 0 1 0.6"/>
      </material>
    </visual>
    <collision>
      <geometry>
        <sphere radius="0.009"/>
      </geometry>
      <origin rpy="0 0 0" xyz="0 0 0"/>
    </collision>
    <inertial>
      <origin rpy="0 0 0" xyz="0 0 0"/>
      <mass value="0.05"/>
      <inertia ixx="1.0" ixy="0.0" ixz="0.0" iyy="1.0" iyz="0.0" izz="1.0"/>
    </inertial>
  </link>
  <joint name="sphere2cylinder_0_7" type="fixed">
    <parent link="cylinder_0_7"/>
    <child link="sphere_0_7"/>
    <origin ryp="0 0 0" xyz="0 0 0"/>
  </joint>
  <link name="link_0_6">
    <visual>
      <geometry>
        <box size="0.016 0.016 0.055"/>
      </geometry>
      <origin rpy="0 0 0" xyz="0 0 -0.0275"/>
      <material name="blue0">
        <color rgba="0 0 1 0.9"/>
      </material>
    </visual>
    <collision>
      <geometry>
        <box size="0.016 0.016 0.055"/>
      </geometry>
      <origin rpy="0 0 0" xyz="0 0 -0.0275"/>
    </collision>
    <inertial>
      <origin rpy="0 0 0" xyz="0 0 0"/>
      <mass value="0.5"/>
      <inertia ixx="1.0" ixy="0.0" ixz="0.0" iyy="1.0" iyz="0.0" izz="1.0"/>
    </inertial>
  </link>
  <joint name="joint_0_6" type="prismatic">
    <parent link="table_base"/>
    <child link="link_0_6"/>
    <origin ryp="0 0 0" xyz="0.018000000000000002 0.138 0"/>
    <axis xyz="0 0 1"/>
    <limit effort="4" lower="0" upper="0.045" velocity="0.01"/>
  </joint>
  <link name="cylinder_0_6">
    <visual>
      <geometry>
        <cylinder length="0.01" radius="0.009"/>
      </geometry>
      <origin rpy="0 0 0" xyz="0 0 -0.005"/>
      <material name="blue1">
        <color rgba="0 0 1 0.6"/>
      </material>
    </visual>
    <collision>
      <geometry>
        <cylinder length="0.01" radius="0.009"/>
      </geometry>
      <origin rpy="0 0 0" xyz="0 0 -0.005"/>
    </collision>
    <inertial>
      <origin rpy="0 0 0" xyz="0 0 0"/>
      <mass value="0.05"/>
      <inertia ixx="1.0" ixy="0.0" ixz="0.0" iyy="1.0" iyz="0.0" izz="1.0"/>
    </inertial>
  </link>
  <joint name="cylinder2base_0_6" type="fixed">
    <parent link="link_0_6"/>
    <child link="cylinder_0_6"/>
    <origin ryp="0 0 0" xyz="0 0 0.01"/>
  </joint>
  <link name="sphere_0_6">
    <visual>
      <geometry>
        <sphere radius="0.009"/>
      </geometry>
      <origin rpy="0 0 0" xyz="0 0 0"/>
      <material name="blue1">
        <color rgba="0 0 1 0.6"/>
      </material>
    </visual>
    <collision>
      <geometry>
        <sphere radius="0.009"/>
      </geometry>
      <origin rpy="0 0 0" xyz="0 0 0"/>
    </collision>
    <inertial>
      <origin rpy="0 0 0" xyz="0 0 0"/>
      <mass value="0.05"/>
      <inertia ixx="1.0" ixy="0.0" ixz="0.0" iyy="1.0" iyz="0.0" izz="1.0"/>
    </inertial>
  </link>
  <joint name="sphere2cylinder_0_6" type="fixed">
    <parent link="cylinder_0_6"/>
    <child link="sphere_0_6"/>
    <origin ryp="0 0 0" xyz="0 0 0"/>
  </joint>
  <link name="link_0_5">
    <visual>
      <geometry>
        <box size="0.016 0.016 0.055"/>
      </geometry>
      <origin rpy="0 0 0" xyz="0 0 -0.0275"/>
      <material name="blue0">
        <color rgba="0 0 1 0.9"/>
      </material>
    </visual>
    <collision>
      <geometry>
        <box size="0.016 0.016 0.055"/>
      </geometry>
      <origin rpy="0 0 0" xyz="0 0 -0.0275"/>
    </collision>
    <inertial>
      <origin rpy="0 0 0" xyz="0 0 0"/>
      <mass value="0.5"/>
      <inertia ixx="1.0" ixy="0.0" ixz="0.0" iyy="1.0" iyz="0.0" izz="1.0"/>
    </inertial>
  </link>
  <joint name="joint_0_5" type="prismatic">
    <parent link="table_base"/>
    <child link="link_0_5"/>
    <origin ryp="0 0 0" xyz="0.018000000000000002 0.118 0"/>
    <axis xyz="0 0 1"/>
    <limit effort="4" lower="0" upper="0.045" velocity="0.01"/>
  </joint>
  <link name="cylinder_0_5">
    <visual>
      <geometry>
        <cylinder length="0.01" radius="0.009"/>
      </geometry>
      <origin rpy="0 0 0" xyz="0 0 -0.005"/>
      <material name="blue1">
        <color rgba="0 0 1 0.6"/>
      </material>
    </visual>
    <collision>
      <geometry>
        <cylinder length="0.01" radius="0.009"/>
      </geometry>
      <origin rpy="0 0 0" xyz="0 0 -0.005"/>
    </collision>
    <inertial>
      <origin rpy="0 0 0" xyz="0 0 0"/>
      <mass value="0.05"/>
      <inertia ixx="1.0" ixy="0.0" ixz="0.0" iyy="1.0" iyz="0.0" izz="1.0"/>
    </inertial>
  </link>
  <joint name="cylinder2base_0_5" type="fixed">
    <parent link="link_0_5"/>
    <child link="cylinder_0_5"/>
    <origin ryp="0 0 0" xyz="0 0 0.01"/>
  </joint>
  <link name="sphere_0_5">
    <visual>
      <geometry>
        <sphere radius="0.009"/>
      </geometry>
      <origin rpy="0 0 0" xyz="0 0 0"/>
      <material name="blue1">
        <color rgba="0 0 1 0.6"/>
      </material>
    </visual>
    <collision>
      <geometry>
        <sphere radius="0.009"/>
      </geometry>
      <origin rpy="0 0 0" xyz="0 0 0"/>
    </collision>
    <inertial>
      <origin rpy="0 0 0" xyz="0 0 0"/>
      <mass value="0.05"/>
      <inertia ixx="1.0" ixy="0.0" ixz="0.0" iyy="1.0" iyz="0.0" izz="1.0"/>
    </inertial>
  </link>
  <joint name="sphere2cylinder_0_5" type="fixed">
    <parent link="cylinder_0_5"/>
    <child link="sphere_0_5"/>
    <origin ryp="0 0 0" xyz="0 0 0"/>
  </joint>
  <link name="link_0_4">
    <visual>
      <geometry>
        <box size="0.016 0.016 0.055"/>
      </geometry>
      <origin rpy="0 0 0" xyz="0 0 -0.0275"/>
      <material name="blue0">
        <color rgba="0 0 1 0.9"/>
      </material>
    </visual>
    <collision>
      <geometry>
        <box size="0.016 0.016 0.055"/>
      </geometry>
      <origin rpy="0 0 0" xyz="0 0 -0.0275"/>
    </collision>
    <inertial>
      <origin rpy="0 0 0" xyz="0 0 0"/>
      <mass value="0.5"/>
      <inertia ixx="1.0" ixy="0.0" ixz="0.0" iyy="1.0" iyz="0.0" izz="1.0"/>
    </inertial>
  </link>
  <joint name="joint_0_4" type="prismatic">
    <parent link="table_base"/>
    <child link="link_0_4"/>
    <origin ryp="0 0 0" xyz="0.018000000000000002 0.098 0"/>
    <axis xyz="0 0 1"/>
    <limit effort="4" lower="0" upper="0.045" velocity="0.01"/>
  </joint>
  <link name="cylinder_0_4">
    <visual>
      <geometry>
        <cylinder length="0.01" radius="0.009"/>
      </geometry>
      <origin rpy="0 0 0" xyz="0 0 -0.005"/>
      <material name="blue1">
        <color rgba="0 0 1 0.6"/>
      </material>
    </visual>
    <collision>
      <geometry>
        <cylinder length="0.01" radius="0.009"/>
      </geometry>
      <origin rpy="0 0 0" xyz="0 0 -0.005"/>
    </collision>
    <inertial>
      <origin rpy="0 0 0" xyz="0 0 0"/>
      <mass value="0.05"/>
      <inertia ixx="1.0" ixy="0.0" ixz="0.0" iyy="1.0" iyz="0.0" izz="1.0"/>
    </inertial>
  </link>
  <joint name="cylinder2base_0_4" type="fixed">
    <parent link="link_0_4"/>
    <child link="cylinder_0_4"/>
    <origin ryp="0 0 0" xyz="0 0 0.01"/>
  </joint>
  <link name="sphere_0_4">
    <visual>
      <geometry>
        <sphere radius="0.009"/>
      </geometry>
      <origin rpy="0 0 0" xyz="0 0 0"/>
      <material name="blue1">
        <color rgba="0 0 1 0.6"/>
      </material>
    </visual>
    <collision>
      <geometry>
        <sphere radius="0.009"/>
      </geometry>
      <origin rpy="0 0 0" xyz="0 0 0"/>
    </collision>
    <inertial>
      <origin rpy="0 0 0" xyz="0 0 0"/>
      <mass value="0.05"/>
      <inertia ixx="1.0" ixy="0.0" ixz="0.0" iyy="1.0" iyz="0.0" izz="1.0"/>
    </inertial>
  </link>
  <joint name="sphere2cylinder_0_4" type="fixed">
    <parent link="cylinder_0_4"/>
    <child link="sphere_0_4"/>
    <origin ryp="0 0 0" xyz="0 0 0"/>
  </joint>
  <link name="link_0_3">
    <visual>
      <geometry>
        <box size="0.016 0.016 0.055"/>
      </geometry>
      <origin rpy="0 0 0" xyz="0 0 -0.0275"/>
      <material name="blue0">
        <color rgba="0 0 1 0.9"/>
      </material>
    </visual>
    <collision>
      <geometry>
        <box size="0.016 0.016 0.055"/>
      </geometry>
      <origin rpy="0 0 0" xyz="0 0 -0.0275"/>
    </collision>
    <inertial>
      <origin rpy="0 0 0" xyz="0 0 0"/>
      <mass value="0.5"/>
      <inertia ixx="1.0" ixy="0.0" ixz="0.0" iyy="1.0" iyz="0.0" izz="1.0"/>
    </inertial>
  </link>
  <joint name="joint_0_3" type="prismatic">
    <parent link="table_base"/>
    <child link="link_0_3"/>
    <origin ryp="0 0 0" xyz="0.018000000000000002 0.078 0"/>
    <axis xyz="0 0 1"/>
    <limit effort="4" lower="0" upper="0.045" velocity="0.01"/>
  </joint>
  <link name="cylinder_0_3">
    <visual>
      <geometry>
        <cylinder length="0.01" radius="0.009"/>
      </geometry>
      <origin rpy="0 0 0" xyz="0 0 -0.005"/>
      <material name="blue1">
        <color rgba="0 0 1 0.6"/>
      </material>
    </visual>
    <collision>
      <geometry>
        <cylinder length="0.01" radius="0.009"/>
      </geometry>
      <origin rpy="0 0 0" xyz="0 0 -0.005"/>
    </collision>
    <inertial>
      <origin rpy="0 0 0" xyz="0 0 0"/>
      <mass value="0.05"/>
      <inertia ixx="1.0" ixy="0.0" ixz="0.0" iyy="1.0" iyz="0.0" izz="1.0"/>
    </inertial>
  </link>
  <joint name="cylinder2base_0_3" type="fixed">
    <parent link="link_0_3"/>
    <child link="cylinder_0_3"/>
    <origin ryp="0 0 0" xyz="0 0 0.01"/>
  </joint>
  <link name="sphere_0_3">
    <visual>
      <geometry>
        <sphere radius="0.009"/>
      </geometry>
      <origin rpy="0 0 0" xyz="0 0 0"/>
      <material name="blue1">
        <color rgba="0 0 1 0.6"/>
      </material>
    </visual>
    <collision>
      <geometry>
        <sphere radius="0.009"/>
      </geometry>
      <origin rpy="0 0 0" xyz="0 0 0"/>
    </collision>
    <inertial>
      <origin rpy="0 0 0" xyz="0 0 0"/>
      <mass value="0.05"/>
      <inertia ixx="1.0" ixy="0.0" ixz="0.0" iyy="1.0" iyz="0.0" izz="1.0"/>
    </inertial>
  </link>
  <joint name="sphere2cylinder_0_3" type="fixed">
    <parent link="cylinder_0_3"/>
    <child link="sphere_0_3"/>
    <origin ryp="0 0 0" xyz="0 0 0"/>
  </joint>
  <link name="link_0_2">
    <visual>
      <geometry>
        <box size="0.016 0.016 0.055"/>
      </geometry>
      <origin rpy="0 0 0" xyz="0 0 -0.0275"/>
      <material name="blue0">
        <color rgba="0 0 1 0.9"/>
      </material>
    </visual>
    <collision>
      <geometry>
        <box size="0.016 0.016 0.055"/>
      </geometry>
      <origin rpy="0 0 0" xyz="0 0 -0.0275"/>
    </collision>
    <inertial>
      <origin rpy="0 0 0" xyz="0 0 0"/>
      <mass value="0.5"/>
      <inertia ixx="1.0" ixy="0.0" ixz="0.0" iyy="1.0" iyz="0.0" izz="1.0"/>
    </inertial>
  </link>
  <joint name="joint_0_2" type="prismatic">
    <parent link="table_base"/>
    <child link="link_0_2"/>
    <origin ryp="0 0 0" xyz="0.018000000000000002 0.058 0"/>
    <axis xyz="0 0 1"/>
    <limit effort="4" lower="0" upper="0.045" velocity="0.01"/>
  </joint>
  <link name="cylinder_0_2">
    <visual>
      <geometry>
        <cylinder length="0.01" radius="0.009"/>
      </geometry>
      <origin rpy="0 0 0" xyz="0 0 -0.005"/>
      <material name="blue1">
        <color rgba="0 0 1 0.6"/>
      </material>
    </visual>
    <collision>
      <geometry>
        <cylinder length="0.01" radius="0.009"/>
      </geometry>
      <origin rpy="0 0 0" xyz="0 0 -0.005"/>
    </collision>
    <inertial>
      <origin rpy="0 0 0" xyz="0 0 0"/>
      <mass value="0.05"/>
      <inertia ixx="1.0" ixy="0.0" ixz="0.0" iyy="1.0" iyz="0.0" izz="1.0"/>
    </inertial>
  </link>
  <joint name="cylinder2base_0_2" type="fixed">
    <parent link="link_0_2"/>
    <child link="cylinder_0_2"/>
    <origin ryp="0 0 0" xyz="0 0 0.01"/>
  </joint>
  <link name="sphere_0_2">
    <visual>
      <geometry>
        <sphere radius="0.009"/>
      </geometry>
      <origin rpy="0 0 0" xyz="0 0 0"/>
      <material name="blue1">
        <color rgba="0 0 1 0.6"/>
      </material>
    </visual>
    <collision>
      <geometry>
        <sphere radius="0.009"/>
      </geometry>
      <origin rpy="0 0 0" xyz="0 0 0"/>
    </collision>
    <inertial>
      <origin rpy="0 0 0" xyz="0 0 0"/>
      <mass value="0.05"/>
      <inertia ixx="1.0" ixy="0.0" ixz="0.0" iyy="1.0" iyz="0.0" izz="1.0"/>
    </inertial>
  </link>
  <joint name="sphere2cylinder_0_2" type="fixed">
    <parent link="cylinder_0_2"/>
    <child link="sphere_0_2"/>
    <origin ryp="0 0 0" xyz="0 0 0"/>
  </joint>
  <link name="link_0_1">
    <visual>
      <geometry>
        <box size="0.016 0.016 0.055"/>
      </geometry>
      <origin rpy="0 0 0" xyz="0 0 -0.0275"/>
      <material name="blue0">
        <color rgba="0 0 1 0.9"/>
      </material>
    </visual>
    <collision>
      <geometry>
        <box size="0.016 0.016 0.055"/>
      </geometry>
      <origin rpy="0 0 0" xyz="0 0 -0.0275"/>
    </collision>
    <inertial>
      <origin rpy="0 0 0" xyz="0 0 0"/>
      <mass value="0.5"/>
      <inertia ixx="1.0" ixy="0.0" ixz="0.0" iyy="1.0" iyz="0.0" izz="1.0"/>
    </inertial>
  </link>
  <joint name="joint_0_1" type="prismatic">
    <parent link="table_base"/>
    <child link="link_0_1"/>
    <origin ryp="0 0 0" xyz="0.018000000000000002 0.038 0"/>
    <axis xyz="0 0 1"/>
    <limit effort="4" lower="0" upper="0.045" velocity="0.01"/>
  </joint>
  <link name="cylinder_0_1">
    <visual>
      <geometry>
        <cylinder length="0.01" radius="0.009"/>
      </geometry>
      <origin rpy="0 0 0" xyz="0 0 -0.005"/>
      <material name="blue1">
        <color rgba="0 0 1 0.6"/>
      </material>
    </visual>
    <collision>
      <geometry>
        <cylinder length="0.01" radius="0.009"/>
      </geometry>
      <origin rpy="0 0 0" xyz="0 0 -0.005"/>
    </collision>
    <inertial>
      <origin rpy="0 0 0" xyz="0 0 0"/>
      <mass value="0.05"/>
      <inertia ixx="1.0" ixy="0.0" ixz="0.0" iyy="1.0" iyz="0.0" izz="1.0"/>
    </inertial>
  </link>
  <joint name="cylinder2base_0_1" type="fixed">
    <parent link="link_0_1"/>
    <child link="cylinder_0_1"/>
    <origin ryp="0 0 0" xyz="0 0 0.01"/>
  </joint>
  <link name="sphere_0_1">
    <visual>
      <geometry>
        <sphere radius="0.009"/>
      </geometry>
      <origin rpy="0 0 0" xyz="0 0 0"/>
      <material name="blue1">
        <color rgba="0 0 1 0.6"/>
      </material>
    </visual>
    <collision>
      <geometry>
        <sphere radius="0.009"/>
      </geometry>
      <origin rpy="0 0 0" xyz="0 0 0"/>
    </collision>
    <inertial>
      <origin rpy="0 0 0" xyz="0 0 0"/>
      <mass value="0.05"/>
      <inertia ixx="1.0" ixy="0.0" ixz="0.0" iyy="1.0" iyz="0.0" izz="1.0"/>
    </inertial>
  </link>
  <joint name="sphere2cylinder_0_1" type="fixed">
    <parent link="cylinder_0_1"/>
    <child link="sphere_0_1"/>
    <origin ryp="0 0 0" xyz="0 0 0"/>
  </joint>
  <link name="link_0_0">
    <visual>
      <geometry>
        <box size="0.016 0.016 0.055"/>
      </geometry>
      <origin rpy="0 0 0" xyz="0 0 -0.0275"/>
      <material name="blue0">
        <color rgba="0 0 1 0.9"/>
      </material>
    </visual>
    <collision>
      <geometry>
        <box size="0.016 0.016 0.055"/>
      </geometry>
      <origin rpy="0 0 0" xyz="0 0 -0.0275"/>
    </collision>
    <inertial>
      <origin rpy="0 0 0" xyz="0 0 0"/>
      <mass value="0.5"/>
      <inertia ixx="1.0" ixy="0.0" ixz="0.0" iyy="1.0" iyz="0.0" izz="1.0"/>
    </inertial>
  </link>
  <joint name="joint_0_0" type="prismatic">
    <parent link="table_base"/>
    <child link="link_0_0"/>
    <origin ryp="0 0 0" xyz="0.018000000000000002 0.018000000000000002 0"/>
    <axis xyz="0 0 1"/>
    <limit effort="4" lower="0" upper="0.045" velocity="0.01"/>
  </joint>
  <link name="cylinder_0_0">
    <visual>
      <geometry>
        <cylinder length="0.01" radius="0.009"/>
      </geometry>
      <origin rpy="0 0 0" xyz="0 0 -0.005"/>
      <material name="blue1">
        <color rgba="0 0 1 0.6"/>
      </material>
    </visual>
    <collision>
      <geometry>
        <cylinder length="0.01" radius="0.009"/>
      </geometry>
      <origin rpy="0 0 0" xyz="0 0 -0.005"/>
    </collision>
    <inertial>
      <origin rpy="0 0 0" xyz="0 0 0"/>
      <mass value="0.05"/>
      <inertia ixx="1.0" ixy="0.0" ixz="0.0" iyy="1.0" iyz="0.0" izz="1.0"/>
    </inertial>
  </link>
  <joint name="cylinder2base_0_0" type="fixed">
    <parent link="link_0_0"/>
    <child link="cylinder_0_0"/>
    <origin ryp="0 0 0" xyz="0 0 0.01"/>
  </joint>
  <link name="sphere_0_0">
    <visual>
      <geometry>
        <sphere radius="0.009"/>
      </geometry>
      <origin rpy="0 0 0" xyz="0 0 0"/>
      <material name="blue1">
        <color rgba="0 0 1 0.6"/>
      </material>
    </visual>
    <collision>
      <geometry>
        <sphere radius="0.009"/>
      </geometry>
      <origin rpy="0 0 0" xyz="0 0 0"/>
    </collision>
    <inertial>
      <origin rpy="0 0 0" xyz="0 0 0"/>
      <mass value="0.05"/>
      <inertia ixx="1.0" ixy="0.0" ixz="0.0" iyy="1.0" iyz="0.0" izz="1.0"/>
    </inertial>
  </link>
  <joint name="sphere2cylinder_0_0" type="fixed">
    <parent link="cylinder_0_0"/>
    <child link="sphere_0_0"/>
    <origin ryp="0 0 0" xyz="0 0 0"/>
  </joint>
</robot>

