<?xml version="1.0" ?>
<!-- =================================================================================== -->
<!-- |    This document was autogenerated by xacro from tablebot.xacro                 | -->
<!-- |    EDITING THIS FILE BY HAND IS NOT RECOMMENDED                                 | -->
<!-- =================================================================================== -->
<robot name="tablebot">
  <!-- <link name="footprint">
      <visual>
        <geometry>
          <sphere radius="0.0001" />
        </geometry>
      </visual>
    </link> -->
  <link name="table_base">
    <visual>
      <geometry>
        <box size="0.223 0.223 0.12"/>
      </geometry>
      <origin rpy="0 0 0" xyz="0.1115 0.1115 -0.06"/>
      <material name="black">
        <color rgba="1 1 1 0.5"/>
      </material>
      <inertial>
        <origin rpy="0 0 0" xyz="0 0 0"/>
        <mass value="10"/>
        <inertia ixx="1.0" ixy="0.0" ixz="0.0" iyy="1.0" iyz="0.0" izz="1.0"/>
      </inertial>
    </visual>
  </link>
  <!-- <joint name="base2footprint" type="fixed">
      <parent link="footprint" />
      <child link="table_base" />
      <origin xyz="0 0 ${tab_height / 2 }" />
    </joint> -->
  <!-- <xacro:macro name="loop" params="links_qty">
        <xacro:if value="${links_qty}">
            <xacro:loop links_qty="${links_qty-1}" />
        </xacro:if>
    </xacro:macro> -->
  <link name="link_11_11">
    <visual>
      <geometry>
        <box size="0.016 0.016 0.055"/>
      </geometry>
      <origin rpy="0 0 0" xyz="0 0 -0.0275"/>
      <material name="blue">
        <color rgba="0 0 1 0.9"/>
      </material>
    </visual>
    <collision>
      <geometry>
        <box size="0.016 0.016 0.055"/>
      </geometry>
      <origin rpy="0 0 0" xyz="0 0 -0.0275"/>
    </collision>
    <inertial>
      <origin rpy="0 0 0" xyz="0 0 0"/>
      <mass value="0.5"/>
      <inertia ixx="1.0" ixy="0.0" ixz="0.0" iyy="1.0" iyz="0.0" izz="1.0"/>
    </inertial>
  </link>
  <joint name="joint_11_11" type="prismatic">
    <parent link="table_base"/>
    <child link="link_11_11"/>
    <origin ryp="0 0 0" xyz="0.205 0.205 0"/>
    <axis xyz="0 0 1"/>
    <limit effort="4" lower="0" upper="0.045" velocity="0.01"/>
  </joint>
  <link name="link_11_10">
    <visual>
      <geometry>
        <box size="0.016 0.016 0.055"/>
      </geometry>
      <origin rpy="0 0 0" xyz="0 0 -0.0275"/>
      <material name="blue">
        <color rgba="0 0 1 0.9"/>
      </material>
    </visual>
    <collision>
      <geometry>
        <box size="0.016 0.016 0.055"/>
      </geometry>
      <origin rpy="0 0 0" xyz="0 0 -0.0275"/>
    </collision>
    <inertial>
      <origin rpy="0 0 0" xyz="0 0 0"/>
      <mass value="0.5"/>
      <inertia ixx="1.0" ixy="0.0" ixz="0.0" iyy="1.0" iyz="0.0" izz="1.0"/>
    </inertial>
  </link>
  <joint name="joint_11_10" type="prismatic">
    <parent link="table_base"/>
    <child link="link_11_10"/>
    <origin ryp="0 0 0" xyz="0.205 0.188 0"/>
    <axis xyz="0 0 1"/>
    <limit effort="4" lower="0" upper="0.045" velocity="0.01"/>
  </joint>
  <link name="link_11_9">
    <visual>
      <geometry>
        <box size="0.016 0.016 0.055"/>
      </geometry>
      <origin rpy="0 0 0" xyz="0 0 -0.0275"/>
      <material name="blue">
        <color rgba="0 0 1 0.9"/>
      </material>
    </visual>
    <collision>
      <geometry>
        <box size="0.016 0.016 0.055"/>
      </geometry>
      <origin rpy="0 0 0" xyz="0 0 -0.0275"/>
    </collision>
    <inertial>
      <origin rpy="0 0 0" xyz="0 0 0"/>
      <mass value="0.5"/>
      <inertia ixx="1.0" ixy="0.0" ixz="0.0" iyy="1.0" iyz="0.0" izz="1.0"/>
    </inertial>
  </link>
  <joint name="joint_11_9" type="prismatic">
    <parent link="table_base"/>
    <child link="link_11_9"/>
    <origin ryp="0 0 0" xyz="0.205 0.17099999999999999 0"/>
    <axis xyz="0 0 1"/>
    <limit effort="4" lower="0" upper="0.045" velocity="0.01"/>
  </joint>
  <link name="link_11_8">
    <visual>
      <geometry>
        <box size="0.016 0.016 0.055"/>
      </geometry>
      <origin rpy="0 0 0" xyz="0 0 -0.0275"/>
      <material name="blue">
        <color rgba="0 0 1 0.9"/>
      </material>
    </visual>
    <collision>
      <geometry>
        <box size="0.016 0.016 0.055"/>
      </geometry>
      <origin rpy="0 0 0" xyz="0 0 -0.0275"/>
    </collision>
    <inertial>
      <origin rpy="0 0 0" xyz="0 0 0"/>
      <mass value="0.5"/>
      <inertia ixx="1.0" ixy="0.0" ixz="0.0" iyy="1.0" iyz="0.0" izz="1.0"/>
    </inertial>
  </link>
  <joint name="joint_11_8" type="prismatic">
    <parent link="table_base"/>
    <child link="link_11_8"/>
    <origin ryp="0 0 0" xyz="0.205 0.15400000000000003 0"/>
    <axis xyz="0 0 1"/>
    <limit effort="4" lower="0" upper="0.045" velocity="0.01"/>
  </joint>
  <link name="link_11_7">
    <visual>
      <geometry>
        <box size="0.016 0.016 0.055"/>
      </geometry>
      <origin rpy="0 0 0" xyz="0 0 -0.0275"/>
      <material name="blue">
        <color rgba="0 0 1 0.9"/>
      </material>
    </visual>
    <collision>
      <geometry>
        <box size="0.016 0.016 0.055"/>
      </geometry>
      <origin rpy="0 0 0" xyz="0 0 -0.0275"/>
    </collision>
    <inertial>
      <origin rpy="0 0 0" xyz="0 0 0"/>
      <mass value="0.5"/>
      <inertia ixx="1.0" ixy="0.0" ixz="0.0" iyy="1.0" iyz="0.0" izz="1.0"/>
    </inertial>
  </link>
  <joint name="joint_11_7" type="prismatic">
    <parent link="table_base"/>
    <child link="link_11_7"/>
    <origin ryp="0 0 0" xyz="0.205 0.137 0"/>
    <axis xyz="0 0 1"/>
    <limit effort="4" lower="0" upper="0.045" velocity="0.01"/>
  </joint>
  <link name="link_11_6">
    <visual>
      <geometry>
        <box size="0.016 0.016 0.055"/>
      </geometry>
      <origin rpy="0 0 0" xyz="0 0 -0.0275"/>
      <material name="blue">
        <color rgba="0 0 1 0.9"/>
      </material>
    </visual>
    <collision>
      <geometry>
        <box size="0.016 0.016 0.055"/>
      </geometry>
      <origin rpy="0 0 0" xyz="0 0 -0.0275"/>
    </collision>
    <inertial>
      <origin rpy="0 0 0" xyz="0 0 0"/>
      <mass value="0.5"/>
      <inertia ixx="1.0" ixy="0.0" ixz="0.0" iyy="1.0" iyz="0.0" izz="1.0"/>
    </inertial>
  </link>
  <joint name="joint_11_6" type="prismatic">
    <parent link="table_base"/>
    <child link="link_11_6"/>
    <origin ryp="0 0 0" xyz="0.205 0.12000000000000001 0"/>
    <axis xyz="0 0 1"/>
    <limit effort="4" lower="0" upper="0.045" velocity="0.01"/>
  </joint>
  <link name="link_11_5">
    <visual>
      <geometry>
        <box size="0.016 0.016 0.055"/>
      </geometry>
      <origin rpy="0 0 0" xyz="0 0 -0.0275"/>
      <material name="blue">
        <color rgba="0 0 1 0.9"/>
      </material>
    </visual>
    <collision>
      <geometry>
        <box size="0.016 0.016 0.055"/>
      </geometry>
      <origin rpy="0 0 0" xyz="0 0 -0.0275"/>
    </collision>
    <inertial>
      <origin rpy="0 0 0" xyz="0 0 0"/>
      <mass value="0.5"/>
      <inertia ixx="1.0" ixy="0.0" ixz="0.0" iyy="1.0" iyz="0.0" izz="1.0"/>
    </inertial>
  </link>
  <joint name="joint_11_5" type="prismatic">
    <parent link="table_base"/>
    <child link="link_11_5"/>
    <origin ryp="0 0 0" xyz="0.205 0.103 0"/>
    <axis xyz="0 0 1"/>
    <limit effort="4" lower="0" upper="0.045" velocity="0.01"/>
  </joint>
  <link name="link_11_4">
    <visual>
      <geometry>
        <box size="0.016 0.016 0.055"/>
      </geometry>
      <origin rpy="0 0 0" xyz="0 0 -0.0275"/>
      <material name="blue">
        <color rgba="0 0 1 0.9"/>
      </material>
    </visual>
    <collision>
      <geometry>
        <box size="0.016 0.016 0.055"/>
      </geometry>
      <origin rpy="0 0 0" xyz="0 0 -0.0275"/>
    </collision>
    <inertial>
      <origin rpy="0 0 0" xyz="0 0 0"/>
      <mass value="0.5"/>
      <inertia ixx="1.0" ixy="0.0" ixz="0.0" iyy="1.0" iyz="0.0" izz="1.0"/>
    </inertial>
  </link>
  <joint name="joint_11_4" type="prismatic">
    <parent link="table_base"/>
    <child link="link_11_4"/>
    <origin ryp="0 0 0" xyz="0.205 0.08600000000000001 0"/>
    <axis xyz="0 0 1"/>
    <limit effort="4" lower="0" upper="0.045" velocity="0.01"/>
  </joint>
  <link name="link_11_3">
    <visual>
      <geometry>
        <box size="0.016 0.016 0.055"/>
      </geometry>
      <origin rpy="0 0 0" xyz="0 0 -0.0275"/>
      <material name="blue">
        <color rgba="0 0 1 0.9"/>
      </material>
    </visual>
    <collision>
      <geometry>
        <box size="0.016 0.016 0.055"/>
      </geometry>
      <origin rpy="0 0 0" xyz="0 0 -0.0275"/>
    </collision>
    <inertial>
      <origin rpy="0 0 0" xyz="0 0 0"/>
      <mass value="0.5"/>
      <inertia ixx="1.0" ixy="0.0" ixz="0.0" iyy="1.0" iyz="0.0" izz="1.0"/>
    </inertial>
  </link>
  <joint name="joint_11_3" type="prismatic">
    <parent link="table_base"/>
    <child link="link_11_3"/>
    <origin ryp="0 0 0" xyz="0.205 0.069 0"/>
    <axis xyz="0 0 1"/>
    <limit effort="4" lower="0" upper="0.045" velocity="0.01"/>
  </joint>
  <link name="link_11_2">
    <visual>
      <geometry>
        <box size="0.016 0.016 0.055"/>
      </geometry>
      <origin rpy="0 0 0" xyz="0 0 -0.0275"/>
      <material name="blue">
        <color rgba="0 0 1 0.9"/>
      </material>
    </visual>
    <collision>
      <geometry>
        <box size="0.016 0.016 0.055"/>
      </geometry>
      <origin rpy="0 0 0" xyz="0 0 -0.0275"/>
    </collision>
    <inertial>
      <origin rpy="0 0 0" xyz="0 0 0"/>
      <mass value="0.5"/>
      <inertia ixx="1.0" ixy="0.0" ixz="0.0" iyy="1.0" iyz="0.0" izz="1.0"/>
    </inertial>
  </link>
  <joint name="joint_11_2" type="prismatic">
    <parent link="table_base"/>
    <child link="link_11_2"/>
    <origin ryp="0 0 0" xyz="0.205 0.052000000000000005 0"/>
    <axis xyz="0 0 1"/>
    <limit effort="4" lower="0" upper="0.045" velocity="0.01"/>
  </joint>
  <link name="link_11_1">
    <visual>
      <geometry>
        <box size="0.016 0.016 0.055"/>
      </geometry>
      <origin rpy="0 0 0" xyz="0 0 -0.0275"/>
      <material name="blue">
        <color rgba="0 0 1 0.9"/>
      </material>
    </visual>
    <collision>
      <geometry>
        <box size="0.016 0.016 0.055"/>
      </geometry>
      <origin rpy="0 0 0" xyz="0 0 -0.0275"/>
    </collision>
    <inertial>
      <origin rpy="0 0 0" xyz="0 0 0"/>
      <mass value="0.5"/>
      <inertia ixx="1.0" ixy="0.0" ixz="0.0" iyy="1.0" iyz="0.0" izz="1.0"/>
    </inertial>
  </link>
  <joint name="joint_11_1" type="prismatic">
    <parent link="table_base"/>
    <child link="link_11_1"/>
    <origin ryp="0 0 0" xyz="0.205 0.035 0"/>
    <axis xyz="0 0 1"/>
    <limit effort="4" lower="0" upper="0.045" velocity="0.01"/>
  </joint>
  <link name="link_11_0">
    <visual>
      <geometry>
        <box size="0.016 0.016 0.055"/>
      </geometry>
      <origin rpy="0 0 0" xyz="0 0 -0.0275"/>
      <material name="blue">
        <color rgba="0 0 1 0.9"/>
      </material>
    </visual>
    <collision>
      <geometry>
        <box size="0.016 0.016 0.055"/>
      </geometry>
      <origin rpy="0 0 0" xyz="0 0 -0.0275"/>
    </collision>
    <inertial>
      <origin rpy="0 0 0" xyz="0 0 0"/>
      <mass value="0.5"/>
      <inertia ixx="1.0" ixy="0.0" ixz="0.0" iyy="1.0" iyz="0.0" izz="1.0"/>
    </inertial>
  </link>
  <joint name="joint_11_0" type="prismatic">
    <parent link="table_base"/>
    <child link="link_11_0"/>
    <origin ryp="0 0 0" xyz="0.205 0.018000000000000002 0"/>
    <axis xyz="0 0 1"/>
    <limit effort="4" lower="0" upper="0.045" velocity="0.01"/>
  </joint>
  <link name="link_10_11">
    <visual>
      <geometry>
        <box size="0.016 0.016 0.055"/>
      </geometry>
      <origin rpy="0 0 0" xyz="0 0 -0.0275"/>
      <material name="blue">
        <color rgba="0 0 1 0.9"/>
      </material>
    </visual>
    <collision>
      <geometry>
        <box size="0.016 0.016 0.055"/>
      </geometry>
      <origin rpy="0 0 0" xyz="0 0 -0.0275"/>
    </collision>
    <inertial>
      <origin rpy="0 0 0" xyz="0 0 0"/>
      <mass value="0.5"/>
      <inertia ixx="1.0" ixy="0.0" ixz="0.0" iyy="1.0" iyz="0.0" izz="1.0"/>
    </inertial>
  </link>
  <joint name="joint_10_11" type="prismatic">
    <parent link="table_base"/>
    <child link="link_10_11"/>
    <origin ryp="0 0 0" xyz="0.188 0.205 0"/>
    <axis xyz="0 0 1"/>
    <limit effort="4" lower="0" upper="0.045" velocity="0.01"/>
  </joint>
  <link name="link_10_10">
    <visual>
      <geometry>
        <box size="0.016 0.016 0.055"/>
      </geometry>
      <origin rpy="0 0 0" xyz="0 0 -0.0275"/>
      <material name="blue">
        <color rgba="0 0 1 0.9"/>
      </material>
    </visual>
    <collision>
      <geometry>
        <box size="0.016 0.016 0.055"/>
      </geometry>
      <origin rpy="0 0 0" xyz="0 0 -0.0275"/>
    </collision>
    <inertial>
      <origin rpy="0 0 0" xyz="0 0 0"/>
      <mass value="0.5"/>
      <inertia ixx="1.0" ixy="0.0" ixz="0.0" iyy="1.0" iyz="0.0" izz="1.0"/>
    </inertial>
  </link>
  <joint name="joint_10_10" type="prismatic">
    <parent link="table_base"/>
    <child link="link_10_10"/>
    <origin ryp="0 0 0" xyz="0.188 0.188 0"/>
    <axis xyz="0 0 1"/>
    <limit effort="4" lower="0" upper="0.045" velocity="0.01"/>
  </joint>
  <link name="link_10_9">
    <visual>
      <geometry>
        <box size="0.016 0.016 0.055"/>
      </geometry>
      <origin rpy="0 0 0" xyz="0 0 -0.0275"/>
      <material name="blue">
        <color rgba="0 0 1 0.9"/>
      </material>
    </visual>
    <collision>
      <geometry>
        <box size="0.016 0.016 0.055"/>
      </geometry>
      <origin rpy="0 0 0" xyz="0 0 -0.0275"/>
    </collision>
    <inertial>
      <origin rpy="0 0 0" xyz="0 0 0"/>
      <mass value="0.5"/>
      <inertia ixx="1.0" ixy="0.0" ixz="0.0" iyy="1.0" iyz="0.0" izz="1.0"/>
    </inertial>
  </link>
  <joint name="joint_10_9" type="prismatic">
    <parent link="table_base"/>
    <child link="link_10_9"/>
    <origin ryp="0 0 0" xyz="0.188 0.17099999999999999 0"/>
    <axis xyz="0 0 1"/>
    <limit effort="4" lower="0" upper="0.045" velocity="0.01"/>
  </joint>
  <link name="link_10_8">
    <visual>
      <geometry>
        <box size="0.016 0.016 0.055"/>
      </geometry>
      <origin rpy="0 0 0" xyz="0 0 -0.0275"/>
      <material name="blue">
        <color rgba="0 0 1 0.9"/>
      </material>
    </visual>
    <collision>
      <geometry>
        <box size="0.016 0.016 0.055"/>
      </geometry>
      <origin rpy="0 0 0" xyz="0 0 -0.0275"/>
    </collision>
    <inertial>
      <origin rpy="0 0 0" xyz="0 0 0"/>
      <mass value="0.5"/>
      <inertia ixx="1.0" ixy="0.0" ixz="0.0" iyy="1.0" iyz="0.0" izz="1.0"/>
    </inertial>
  </link>
  <joint name="joint_10_8" type="prismatic">
    <parent link="table_base"/>
    <child link="link_10_8"/>
    <origin ryp="0 0 0" xyz="0.188 0.15400000000000003 0"/>
    <axis xyz="0 0 1"/>
    <limit effort="4" lower="0" upper="0.045" velocity="0.01"/>
  </joint>
  <link name="link_10_7">
    <visual>
      <geometry>
        <box size="0.016 0.016 0.055"/>
      </geometry>
      <origin rpy="0 0 0" xyz="0 0 -0.0275"/>
      <material name="blue">
        <color rgba="0 0 1 0.9"/>
      </material>
    </visual>
    <collision>
      <geometry>
        <box size="0.016 0.016 0.055"/>
      </geometry>
      <origin rpy="0 0 0" xyz="0 0 -0.0275"/>
    </collision>
    <inertial>
      <origin rpy="0 0 0" xyz="0 0 0"/>
      <mass value="0.5"/>
      <inertia ixx="1.0" ixy="0.0" ixz="0.0" iyy="1.0" iyz="0.0" izz="1.0"/>
    </inertial>
  </link>
  <joint name="joint_10_7" type="prismatic">
    <parent link="table_base"/>
    <child link="link_10_7"/>
    <origin ryp="0 0 0" xyz="0.188 0.137 0"/>
    <axis xyz="0 0 1"/>
    <limit effort="4" lower="0" upper="0.045" velocity="0.01"/>
  </joint>
  <link name="link_10_6">
    <visual>
      <geometry>
        <box size="0.016 0.016 0.055"/>
      </geometry>
      <origin rpy="0 0 0" xyz="0 0 -0.0275"/>
      <material name="blue">
        <color rgba="0 0 1 0.9"/>
      </material>
    </visual>
    <collision>
      <geometry>
        <box size="0.016 0.016 0.055"/>
      </geometry>
      <origin rpy="0 0 0" xyz="0 0 -0.0275"/>
    </collision>
    <inertial>
      <origin rpy="0 0 0" xyz="0 0 0"/>
      <mass value="0.5"/>
      <inertia ixx="1.0" ixy="0.0" ixz="0.0" iyy="1.0" iyz="0.0" izz="1.0"/>
    </inertial>
  </link>
  <joint name="joint_10_6" type="prismatic">
    <parent link="table_base"/>
    <child link="link_10_6"/>
    <origin ryp="0 0 0" xyz="0.188 0.12000000000000001 0"/>
    <axis xyz="0 0 1"/>
    <limit effort="4" lower="0" upper="0.045" velocity="0.01"/>
  </joint>
  <link name="link_10_5">
    <visual>
      <geometry>
        <box size="0.016 0.016 0.055"/>
      </geometry>
      <origin rpy="0 0 0" xyz="0 0 -0.0275"/>
      <material name="blue">
        <color rgba="0 0 1 0.9"/>
      </material>
    </visual>
    <collision>
      <geometry>
        <box size="0.016 0.016 0.055"/>
      </geometry>
      <origin rpy="0 0 0" xyz="0 0 -0.0275"/>
    </collision>
    <inertial>
      <origin rpy="0 0 0" xyz="0 0 0"/>
      <mass value="0.5"/>
      <inertia ixx="1.0" ixy="0.0" ixz="0.0" iyy="1.0" iyz="0.0" izz="1.0"/>
    </inertial>
  </link>
  <joint name="joint_10_5" type="prismatic">
    <parent link="table_base"/>
    <child link="link_10_5"/>
    <origin ryp="0 0 0" xyz="0.188 0.103 0"/>
    <axis xyz="0 0 1"/>
    <limit effort="4" lower="0" upper="0.045" velocity="0.01"/>
  </joint>
  <link name="link_10_4">
    <visual>
      <geometry>
        <box size="0.016 0.016 0.055"/>
      </geometry>
      <origin rpy="0 0 0" xyz="0 0 -0.0275"/>
      <material name="blue">
        <color rgba="0 0 1 0.9"/>
      </material>
    </visual>
    <collision>
      <geometry>
        <box size="0.016 0.016 0.055"/>
      </geometry>
      <origin rpy="0 0 0" xyz="0 0 -0.0275"/>
    </collision>
    <inertial>
      <origin rpy="0 0 0" xyz="0 0 0"/>
      <mass value="0.5"/>
      <inertia ixx="1.0" ixy="0.0" ixz="0.0" iyy="1.0" iyz="0.0" izz="1.0"/>
    </inertial>
  </link>
  <joint name="joint_10_4" type="prismatic">
    <parent link="table_base"/>
    <child link="link_10_4"/>
    <origin ryp="0 0 0" xyz="0.188 0.08600000000000001 0"/>
    <axis xyz="0 0 1"/>
    <limit effort="4" lower="0" upper="0.045" velocity="0.01"/>
  </joint>
  <link name="link_10_3">
    <visual>
      <geometry>
        <box size="0.016 0.016 0.055"/>
      </geometry>
      <origin rpy="0 0 0" xyz="0 0 -0.0275"/>
      <material name="blue">
        <color rgba="0 0 1 0.9"/>
      </material>
    </visual>
    <collision>
      <geometry>
        <box size="0.016 0.016 0.055"/>
      </geometry>
      <origin rpy="0 0 0" xyz="0 0 -0.0275"/>
    </collision>
    <inertial>
      <origin rpy="0 0 0" xyz="0 0 0"/>
      <mass value="0.5"/>
      <inertia ixx="1.0" ixy="0.0" ixz="0.0" iyy="1.0" iyz="0.0" izz="1.0"/>
    </inertial>
  </link>
  <joint name="joint_10_3" type="prismatic">
    <parent link="table_base"/>
    <child link="link_10_3"/>
    <origin ryp="0 0 0" xyz="0.188 0.069 0"/>
    <axis xyz="0 0 1"/>
    <limit effort="4" lower="0" upper="0.045" velocity="0.01"/>
  </joint>
  <link name="link_10_2">
    <visual>
      <geometry>
        <box size="0.016 0.016 0.055"/>
      </geometry>
      <origin rpy="0 0 0" xyz="0 0 -0.0275"/>
      <material name="blue">
        <color rgba="0 0 1 0.9"/>
      </material>
    </visual>
    <collision>
      <geometry>
        <box size="0.016 0.016 0.055"/>
      </geometry>
      <origin rpy="0 0 0" xyz="0 0 -0.0275"/>
    </collision>
    <inertial>
      <origin rpy="0 0 0" xyz="0 0 0"/>
      <mass value="0.5"/>
      <inertia ixx="1.0" ixy="0.0" ixz="0.0" iyy="1.0" iyz="0.0" izz="1.0"/>
    </inertial>
  </link>
  <joint name="joint_10_2" type="prismatic">
    <parent link="table_base"/>
    <child link="link_10_2"/>
    <origin ryp="0 0 0" xyz="0.188 0.052000000000000005 0"/>
    <axis xyz="0 0 1"/>
    <limit effort="4" lower="0" upper="0.045" velocity="0.01"/>
  </joint>
  <link name="link_10_1">
    <visual>
      <geometry>
        <box size="0.016 0.016 0.055"/>
      </geometry>
      <origin rpy="0 0 0" xyz="0 0 -0.0275"/>
      <material name="blue">
        <color rgba="0 0 1 0.9"/>
      </material>
    </visual>
    <collision>
      <geometry>
        <box size="0.016 0.016 0.055"/>
      </geometry>
      <origin rpy="0 0 0" xyz="0 0 -0.0275"/>
    </collision>
    <inertial>
      <origin rpy="0 0 0" xyz="0 0 0"/>
      <mass value="0.5"/>
      <inertia ixx="1.0" ixy="0.0" ixz="0.0" iyy="1.0" iyz="0.0" izz="1.0"/>
    </inertial>
  </link>
  <joint name="joint_10_1" type="prismatic">
    <parent link="table_base"/>
    <child link="link_10_1"/>
    <origin ryp="0 0 0" xyz="0.188 0.035 0"/>
    <axis xyz="0 0 1"/>
    <limit effort="4" lower="0" upper="0.045" velocity="0.01"/>
  </joint>
  <link name="link_10_0">
    <visual>
      <geometry>
        <box size="0.016 0.016 0.055"/>
      </geometry>
      <origin rpy="0 0 0" xyz="0 0 -0.0275"/>
      <material name="blue">
        <color rgba="0 0 1 0.9"/>
      </material>
    </visual>
    <collision>
      <geometry>
        <box size="0.016 0.016 0.055"/>
      </geometry>
      <origin rpy="0 0 0" xyz="0 0 -0.0275"/>
    </collision>
    <inertial>
      <origin rpy="0 0 0" xyz="0 0 0"/>
      <mass value="0.5"/>
      <inertia ixx="1.0" ixy="0.0" ixz="0.0" iyy="1.0" iyz="0.0" izz="1.0"/>
    </inertial>
  </link>
  <joint name="joint_10_0" type="prismatic">
    <parent link="table_base"/>
    <child link="link_10_0"/>
    <origin ryp="0 0 0" xyz="0.188 0.018000000000000002 0"/>
    <axis xyz="0 0 1"/>
    <limit effort="4" lower="0" upper="0.045" velocity="0.01"/>
  </joint>
  <link name="link_9_11">
    <visual>
      <geometry>
        <box size="0.016 0.016 0.055"/>
      </geometry>
      <origin rpy="0 0 0" xyz="0 0 -0.0275"/>
      <material name="blue">
        <color rgba="0 0 1 0.9"/>
      </material>
    </visual>
    <collision>
      <geometry>
        <box size="0.016 0.016 0.055"/>
      </geometry>
      <origin rpy="0 0 0" xyz="0 0 -0.0275"/>
    </collision>
    <inertial>
      <origin rpy="0 0 0" xyz="0 0 0"/>
      <mass value="0.5"/>
      <inertia ixx="1.0" ixy="0.0" ixz="0.0" iyy="1.0" iyz="0.0" izz="1.0"/>
    </inertial>
  </link>
  <joint name="joint_9_11" type="prismatic">
    <parent link="table_base"/>
    <child link="link_9_11"/>
    <origin ryp="0 0 0" xyz="0.17099999999999999 0.205 0"/>
    <axis xyz="0 0 1"/>
    <limit effort="4" lower="0" upper="0.045" velocity="0.01"/>
  </joint>
  <link name="link_9_10">
    <visual>
      <geometry>
        <box size="0.016 0.016 0.055"/>
      </geometry>
      <origin rpy="0 0 0" xyz="0 0 -0.0275"/>
      <material name="blue">
        <color rgba="0 0 1 0.9"/>
      </material>
    </visual>
    <collision>
      <geometry>
        <box size="0.016 0.016 0.055"/>
      </geometry>
      <origin rpy="0 0 0" xyz="0 0 -0.0275"/>
    </collision>
    <inertial>
      <origin rpy="0 0 0" xyz="0 0 0"/>
      <mass value="0.5"/>
      <inertia ixx="1.0" ixy="0.0" ixz="0.0" iyy="1.0" iyz="0.0" izz="1.0"/>
    </inertial>
  </link>
  <joint name="joint_9_10" type="prismatic">
    <parent link="table_base"/>
    <child link="link_9_10"/>
    <origin ryp="0 0 0" xyz="0.17099999999999999 0.188 0"/>
    <axis xyz="0 0 1"/>
    <limit effort="4" lower="0" upper="0.045" velocity="0.01"/>
  </joint>
  <link name="link_9_9">
    <visual>
      <geometry>
        <box size="0.016 0.016 0.055"/>
      </geometry>
      <origin rpy="0 0 0" xyz="0 0 -0.0275"/>
      <material name="blue">
        <color rgba="0 0 1 0.9"/>
      </material>
    </visual>
    <collision>
      <geometry>
        <box size="0.016 0.016 0.055"/>
      </geometry>
      <origin rpy="0 0 0" xyz="0 0 -0.0275"/>
    </collision>
    <inertial>
      <origin rpy="0 0 0" xyz="0 0 0"/>
      <mass value="0.5"/>
      <inertia ixx="1.0" ixy="0.0" ixz="0.0" iyy="1.0" iyz="0.0" izz="1.0"/>
    </inertial>
  </link>
  <joint name="joint_9_9" type="prismatic">
    <parent link="table_base"/>
    <child link="link_9_9"/>
    <origin ryp="0 0 0" xyz="0.17099999999999999 0.17099999999999999 0"/>
    <axis xyz="0 0 1"/>
    <limit effort="4" lower="0" upper="0.045" velocity="0.01"/>
  </joint>
  <link name="link_9_8">
    <visual>
      <geometry>
        <box size="0.016 0.016 0.055"/>
      </geometry>
      <origin rpy="0 0 0" xyz="0 0 -0.0275"/>
      <material name="blue">
        <color rgba="0 0 1 0.9"/>
      </material>
    </visual>
    <collision>
      <geometry>
        <box size="0.016 0.016 0.055"/>
      </geometry>
      <origin rpy="0 0 0" xyz="0 0 -0.0275"/>
    </collision>
    <inertial>
      <origin rpy="0 0 0" xyz="0 0 0"/>
      <mass value="0.5"/>
      <inertia ixx="1.0" ixy="0.0" ixz="0.0" iyy="1.0" iyz="0.0" izz="1.0"/>
    </inertial>
  </link>
  <joint name="joint_9_8" type="prismatic">
    <parent link="table_base"/>
    <child link="link_9_8"/>
    <origin ryp="0 0 0" xyz="0.17099999999999999 0.15400000000000003 0"/>
    <axis xyz="0 0 1"/>
    <limit effort="4" lower="0" upper="0.045" velocity="0.01"/>
  </joint>
  <link name="link_9_7">
    <visual>
      <geometry>
        <box size="0.016 0.016 0.055"/>
      </geometry>
      <origin rpy="0 0 0" xyz="0 0 -0.0275"/>
      <material name="blue">
        <color rgba="0 0 1 0.9"/>
      </material>
    </visual>
    <collision>
      <geometry>
        <box size="0.016 0.016 0.055"/>
      </geometry>
      <origin rpy="0 0 0" xyz="0 0 -0.0275"/>
    </collision>
    <inertial>
      <origin rpy="0 0 0" xyz="0 0 0"/>
      <mass value="0.5"/>
      <inertia ixx="1.0" ixy="0.0" ixz="0.0" iyy="1.0" iyz="0.0" izz="1.0"/>
    </inertial>
  </link>
  <joint name="joint_9_7" type="prismatic">
    <parent link="table_base"/>
    <child link="link_9_7"/>
    <origin ryp="0 0 0" xyz="0.17099999999999999 0.137 0"/>
    <axis xyz="0 0 1"/>
    <limit effort="4" lower="0" upper="0.045" velocity="0.01"/>
  </joint>
  <link name="link_9_6">
    <visual>
      <geometry>
        <box size="0.016 0.016 0.055"/>
      </geometry>
      <origin rpy="0 0 0" xyz="0 0 -0.0275"/>
      <material name="blue">
        <color rgba="0 0 1 0.9"/>
      </material>
    </visual>
    <collision>
      <geometry>
        <box size="0.016 0.016 0.055"/>
      </geometry>
      <origin rpy="0 0 0" xyz="0 0 -0.0275"/>
    </collision>
    <inertial>
      <origin rpy="0 0 0" xyz="0 0 0"/>
      <mass value="0.5"/>
      <inertia ixx="1.0" ixy="0.0" ixz="0.0" iyy="1.0" iyz="0.0" izz="1.0"/>
    </inertial>
  </link>
  <joint name="joint_9_6" type="prismatic">
    <parent link="table_base"/>
    <child link="link_9_6"/>
    <origin ryp="0 0 0" xyz="0.17099999999999999 0.12000000000000001 0"/>
    <axis xyz="0 0 1"/>
    <limit effort="4" lower="0" upper="0.045" velocity="0.01"/>
  </joint>
  <link name="link_9_5">
    <visual>
      <geometry>
        <box size="0.016 0.016 0.055"/>
      </geometry>
      <origin rpy="0 0 0" xyz="0 0 -0.0275"/>
      <material name="blue">
        <color rgba="0 0 1 0.9"/>
      </material>
    </visual>
    <collision>
      <geometry>
        <box size="0.016 0.016 0.055"/>
      </geometry>
      <origin rpy="0 0 0" xyz="0 0 -0.0275"/>
    </collision>
    <inertial>
      <origin rpy="0 0 0" xyz="0 0 0"/>
      <mass value="0.5"/>
      <inertia ixx="1.0" ixy="0.0" ixz="0.0" iyy="1.0" iyz="0.0" izz="1.0"/>
    </inertial>
  </link>
  <joint name="joint_9_5" type="prismatic">
    <parent link="table_base"/>
    <child link="link_9_5"/>
    <origin ryp="0 0 0" xyz="0.17099999999999999 0.103 0"/>
    <axis xyz="0 0 1"/>
    <limit effort="4" lower="0" upper="0.045" velocity="0.01"/>
  </joint>
  <link name="link_9_4">
    <visual>
      <geometry>
        <box size="0.016 0.016 0.055"/>
      </geometry>
      <origin rpy="0 0 0" xyz="0 0 -0.0275"/>
      <material name="blue">
        <color rgba="0 0 1 0.9"/>
      </material>
    </visual>
    <collision>
      <geometry>
        <box size="0.016 0.016 0.055"/>
      </geometry>
      <origin rpy="0 0 0" xyz="0 0 -0.0275"/>
    </collision>
    <inertial>
      <origin rpy="0 0 0" xyz="0 0 0"/>
      <mass value="0.5"/>
      <inertia ixx="1.0" ixy="0.0" ixz="0.0" iyy="1.0" iyz="0.0" izz="1.0"/>
    </inertial>
  </link>
  <joint name="joint_9_4" type="prismatic">
    <parent link="table_base"/>
    <child link="link_9_4"/>
    <origin ryp="0 0 0" xyz="0.17099999999999999 0.08600000000000001 0"/>
    <axis xyz="0 0 1"/>
    <limit effort="4" lower="0" upper="0.045" velocity="0.01"/>
  </joint>
  <link name="link_9_3">
    <visual>
      <geometry>
        <box size="0.016 0.016 0.055"/>
      </geometry>
      <origin rpy="0 0 0" xyz="0 0 -0.0275"/>
      <material name="blue">
        <color rgba="0 0 1 0.9"/>
      </material>
    </visual>
    <collision>
      <geometry>
        <box size="0.016 0.016 0.055"/>
      </geometry>
      <origin rpy="0 0 0" xyz="0 0 -0.0275"/>
    </collision>
    <inertial>
      <origin rpy="0 0 0" xyz="0 0 0"/>
      <mass value="0.5"/>
      <inertia ixx="1.0" ixy="0.0" ixz="0.0" iyy="1.0" iyz="0.0" izz="1.0"/>
    </inertial>
  </link>
  <joint name="joint_9_3" type="prismatic">
    <parent link="table_base"/>
    <child link="link_9_3"/>
    <origin ryp="0 0 0" xyz="0.17099999999999999 0.069 0"/>
    <axis xyz="0 0 1"/>
    <limit effort="4" lower="0" upper="0.045" velocity="0.01"/>
  </joint>
  <link name="link_9_2">
    <visual>
      <geometry>
        <box size="0.016 0.016 0.055"/>
      </geometry>
      <origin rpy="0 0 0" xyz="0 0 -0.0275"/>
      <material name="blue">
        <color rgba="0 0 1 0.9"/>
      </material>
    </visual>
    <collision>
      <geometry>
        <box size="0.016 0.016 0.055"/>
      </geometry>
      <origin rpy="0 0 0" xyz="0 0 -0.0275"/>
    </collision>
    <inertial>
      <origin rpy="0 0 0" xyz="0 0 0"/>
      <mass value="0.5"/>
      <inertia ixx="1.0" ixy="0.0" ixz="0.0" iyy="1.0" iyz="0.0" izz="1.0"/>
    </inertial>
  </link>
  <joint name="joint_9_2" type="prismatic">
    <parent link="table_base"/>
    <child link="link_9_2"/>
    <origin ryp="0 0 0" xyz="0.17099999999999999 0.052000000000000005 0"/>
    <axis xyz="0 0 1"/>
    <limit effort="4" lower="0" upper="0.045" velocity="0.01"/>
  </joint>
  <link name="link_9_1">
    <visual>
      <geometry>
        <box size="0.016 0.016 0.055"/>
      </geometry>
      <origin rpy="0 0 0" xyz="0 0 -0.0275"/>
      <material name="blue">
        <color rgba="0 0 1 0.9"/>
      </material>
    </visual>
    <collision>
      <geometry>
        <box size="0.016 0.016 0.055"/>
      </geometry>
      <origin rpy="0 0 0" xyz="0 0 -0.0275"/>
    </collision>
    <inertial>
      <origin rpy="0 0 0" xyz="0 0 0"/>
      <mass value="0.5"/>
      <inertia ixx="1.0" ixy="0.0" ixz="0.0" iyy="1.0" iyz="0.0" izz="1.0"/>
    </inertial>
  </link>
  <joint name="joint_9_1" type="prismatic">
    <parent link="table_base"/>
    <child link="link_9_1"/>
    <origin ryp="0 0 0" xyz="0.17099999999999999 0.035 0"/>
    <axis xyz="0 0 1"/>
    <limit effort="4" lower="0" upper="0.045" velocity="0.01"/>
  </joint>
  <link name="link_9_0">
    <visual>
      <geometry>
        <box size="0.016 0.016 0.055"/>
      </geometry>
      <origin rpy="0 0 0" xyz="0 0 -0.0275"/>
      <material name="blue">
        <color rgba="0 0 1 0.9"/>
      </material>
    </visual>
    <collision>
      <geometry>
        <box size="0.016 0.016 0.055"/>
      </geometry>
      <origin rpy="0 0 0" xyz="0 0 -0.0275"/>
    </collision>
    <inertial>
      <origin rpy="0 0 0" xyz="0 0 0"/>
      <mass value="0.5"/>
      <inertia ixx="1.0" ixy="0.0" ixz="0.0" iyy="1.0" iyz="0.0" izz="1.0"/>
    </inertial>
  </link>
  <joint name="joint_9_0" type="prismatic">
    <parent link="table_base"/>
    <child link="link_9_0"/>
    <origin ryp="0 0 0" xyz="0.17099999999999999 0.018000000000000002 0"/>
    <axis xyz="0 0 1"/>
    <limit effort="4" lower="0" upper="0.045" velocity="0.01"/>
  </joint>
  <link name="link_8_11">
    <visual>
      <geometry>
        <box size="0.016 0.016 0.055"/>
      </geometry>
      <origin rpy="0 0 0" xyz="0 0 -0.0275"/>
      <material name="blue">
        <color rgba="0 0 1 0.9"/>
      </material>
    </visual>
    <collision>
      <geometry>
        <box size="0.016 0.016 0.055"/>
      </geometry>
      <origin rpy="0 0 0" xyz="0 0 -0.0275"/>
    </collision>
    <inertial>
      <origin rpy="0 0 0" xyz="0 0 0"/>
      <mass value="0.5"/>
      <inertia ixx="1.0" ixy="0.0" ixz="0.0" iyy="1.0" iyz="0.0" izz="1.0"/>
    </inertial>
  </link>
  <joint name="joint_8_11" type="prismatic">
    <parent link="table_base"/>
    <child link="link_8_11"/>
    <origin ryp="0 0 0" xyz="0.15400000000000003 0.205 0"/>
    <axis xyz="0 0 1"/>
    <limit effort="4" lower="0" upper="0.045" velocity="0.01"/>
  </joint>
  <link name="link_8_10">
    <visual>
      <geometry>
        <box size="0.016 0.016 0.055"/>
      </geometry>
      <origin rpy="0 0 0" xyz="0 0 -0.0275"/>
      <material name="blue">
        <color rgba="0 0 1 0.9"/>
      </material>
    </visual>
    <collision>
      <geometry>
        <box size="0.016 0.016 0.055"/>
      </geometry>
      <origin rpy="0 0 0" xyz="0 0 -0.0275"/>
    </collision>
    <inertial>
      <origin rpy="0 0 0" xyz="0 0 0"/>
      <mass value="0.5"/>
      <inertia ixx="1.0" ixy="0.0" ixz="0.0" iyy="1.0" iyz="0.0" izz="1.0"/>
    </inertial>
  </link>
  <joint name="joint_8_10" type="prismatic">
    <parent link="table_base"/>
    <child link="link_8_10"/>
    <origin ryp="0 0 0" xyz="0.15400000000000003 0.188 0"/>
    <axis xyz="0 0 1"/>
    <limit effort="4" lower="0" upper="0.045" velocity="0.01"/>
  </joint>
  <link name="link_8_9">
    <visual>
      <geometry>
        <box size="0.016 0.016 0.055"/>
      </geometry>
      <origin rpy="0 0 0" xyz="0 0 -0.0275"/>
      <material name="blue">
        <color rgba="0 0 1 0.9"/>
      </material>
    </visual>
    <collision>
      <geometry>
        <box size="0.016 0.016 0.055"/>
      </geometry>
      <origin rpy="0 0 0" xyz="0 0 -0.0275"/>
    </collision>
    <inertial>
      <origin rpy="0 0 0" xyz="0 0 0"/>
      <mass value="0.5"/>
      <inertia ixx="1.0" ixy="0.0" ixz="0.0" iyy="1.0" iyz="0.0" izz="1.0"/>
    </inertial>
  </link>
  <joint name="joint_8_9" type="prismatic">
    <parent link="table_base"/>
    <child link="link_8_9"/>
    <origin ryp="0 0 0" xyz="0.15400000000000003 0.17099999999999999 0"/>
    <axis xyz="0 0 1"/>
    <limit effort="4" lower="0" upper="0.045" velocity="0.01"/>
  </joint>
  <link name="link_8_8">
    <visual>
      <geometry>
        <box size="0.016 0.016 0.055"/>
      </geometry>
      <origin rpy="0 0 0" xyz="0 0 -0.0275"/>
      <material name="blue">
        <color rgba="0 0 1 0.9"/>
      </material>
    </visual>
    <collision>
      <geometry>
        <box size="0.016 0.016 0.055"/>
      </geometry>
      <origin rpy="0 0 0" xyz="0 0 -0.0275"/>
    </collision>
    <inertial>
      <origin rpy="0 0 0" xyz="0 0 0"/>
      <mass value="0.5"/>
      <inertia ixx="1.0" ixy="0.0" ixz="0.0" iyy="1.0" iyz="0.0" izz="1.0"/>
    </inertial>
  </link>
  <joint name="joint_8_8" type="prismatic">
    <parent link="table_base"/>
    <child link="link_8_8"/>
    <origin ryp="0 0 0" xyz="0.15400000000000003 0.15400000000000003 0"/>
    <axis xyz="0 0 1"/>
    <limit effort="4" lower="0" upper="0.045" velocity="0.01"/>
  </joint>
  <link name="link_8_7">
    <visual>
      <geometry>
        <box size="0.016 0.016 0.055"/>
      </geometry>
      <origin rpy="0 0 0" xyz="0 0 -0.0275"/>
      <material name="blue">
        <color rgba="0 0 1 0.9"/>
      </material>
    </visual>
    <collision>
      <geometry>
        <box size="0.016 0.016 0.055"/>
      </geometry>
      <origin rpy="0 0 0" xyz="0 0 -0.0275"/>
    </collision>
    <inertial>
      <origin rpy="0 0 0" xyz="0 0 0"/>
      <mass value="0.5"/>
      <inertia ixx="1.0" ixy="0.0" ixz="0.0" iyy="1.0" iyz="0.0" izz="1.0"/>
    </inertial>
  </link>
  <joint name="joint_8_7" type="prismatic">
    <parent link="table_base"/>
    <child link="link_8_7"/>
    <origin ryp="0 0 0" xyz="0.15400000000000003 0.137 0"/>
    <axis xyz="0 0 1"/>
    <limit effort="4" lower="0" upper="0.045" velocity="0.01"/>
  </joint>
  <link name="link_8_6">
    <visual>
      <geometry>
        <box size="0.016 0.016 0.055"/>
      </geometry>
      <origin rpy="0 0 0" xyz="0 0 -0.0275"/>
      <material name="blue">
        <color rgba="0 0 1 0.9"/>
      </material>
    </visual>
    <collision>
      <geometry>
        <box size="0.016 0.016 0.055"/>
      </geometry>
      <origin rpy="0 0 0" xyz="0 0 -0.0275"/>
    </collision>
    <inertial>
      <origin rpy="0 0 0" xyz="0 0 0"/>
      <mass value="0.5"/>
      <inertia ixx="1.0" ixy="0.0" ixz="0.0" iyy="1.0" iyz="0.0" izz="1.0"/>
    </inertial>
  </link>
  <joint name="joint_8_6" type="prismatic">
    <parent link="table_base"/>
    <child link="link_8_6"/>
    <origin ryp="0 0 0" xyz="0.15400000000000003 0.12000000000000001 0"/>
    <axis xyz="0 0 1"/>
    <limit effort="4" lower="0" upper="0.045" velocity="0.01"/>
  </joint>
  <link name="link_8_5">
    <visual>
      <geometry>
        <box size="0.016 0.016 0.055"/>
      </geometry>
      <origin rpy="0 0 0" xyz="0 0 -0.0275"/>
      <material name="blue">
        <color rgba="0 0 1 0.9"/>
      </material>
    </visual>
    <collision>
      <geometry>
        <box size="0.016 0.016 0.055"/>
      </geometry>
      <origin rpy="0 0 0" xyz="0 0 -0.0275"/>
    </collision>
    <inertial>
      <origin rpy="0 0 0" xyz="0 0 0"/>
      <mass value="0.5"/>
      <inertia ixx="1.0" ixy="0.0" ixz="0.0" iyy="1.0" iyz="0.0" izz="1.0"/>
    </inertial>
  </link>
  <joint name="joint_8_5" type="prismatic">
    <parent link="table_base"/>
    <child link="link_8_5"/>
    <origin ryp="0 0 0" xyz="0.15400000000000003 0.103 0"/>
    <axis xyz="0 0 1"/>
    <limit effort="4" lower="0" upper="0.045" velocity="0.01"/>
  </joint>
  <link name="link_8_4">
    <visual>
      <geometry>
        <box size="0.016 0.016 0.055"/>
      </geometry>
      <origin rpy="0 0 0" xyz="0 0 -0.0275"/>
      <material name="blue">
        <color rgba="0 0 1 0.9"/>
      </material>
    </visual>
    <collision>
      <geometry>
        <box size="0.016 0.016 0.055"/>
      </geometry>
      <origin rpy="0 0 0" xyz="0 0 -0.0275"/>
    </collision>
    <inertial>
      <origin rpy="0 0 0" xyz="0 0 0"/>
      <mass value="0.5"/>
      <inertia ixx="1.0" ixy="0.0" ixz="0.0" iyy="1.0" iyz="0.0" izz="1.0"/>
    </inertial>
  </link>
  <joint name="joint_8_4" type="prismatic">
    <parent link="table_base"/>
    <child link="link_8_4"/>
    <origin ryp="0 0 0" xyz="0.15400000000000003 0.08600000000000001 0"/>
    <axis xyz="0 0 1"/>
    <limit effort="4" lower="0" upper="0.045" velocity="0.01"/>
  </joint>
  <link name="link_8_3">
    <visual>
      <geometry>
        <box size="0.016 0.016 0.055"/>
      </geometry>
      <origin rpy="0 0 0" xyz="0 0 -0.0275"/>
      <material name="blue">
        <color rgba="0 0 1 0.9"/>
      </material>
    </visual>
    <collision>
      <geometry>
        <box size="0.016 0.016 0.055"/>
      </geometry>
      <origin rpy="0 0 0" xyz="0 0 -0.0275"/>
    </collision>
    <inertial>
      <origin rpy="0 0 0" xyz="0 0 0"/>
      <mass value="0.5"/>
      <inertia ixx="1.0" ixy="0.0" ixz="0.0" iyy="1.0" iyz="0.0" izz="1.0"/>
    </inertial>
  </link>
  <joint name="joint_8_3" type="prismatic">
    <parent link="table_base"/>
    <child link="link_8_3"/>
    <origin ryp="0 0 0" xyz="0.15400000000000003 0.069 0"/>
    <axis xyz="0 0 1"/>
    <limit effort="4" lower="0" upper="0.045" velocity="0.01"/>
  </joint>
  <link name="link_8_2">
    <visual>
      <geometry>
        <box size="0.016 0.016 0.055"/>
      </geometry>
      <origin rpy="0 0 0" xyz="0 0 -0.0275"/>
      <material name="blue">
        <color rgba="0 0 1 0.9"/>
      </material>
    </visual>
    <collision>
      <geometry>
        <box size="0.016 0.016 0.055"/>
      </geometry>
      <origin rpy="0 0 0" xyz="0 0 -0.0275"/>
    </collision>
    <inertial>
      <origin rpy="0 0 0" xyz="0 0 0"/>
      <mass value="0.5"/>
      <inertia ixx="1.0" ixy="0.0" ixz="0.0" iyy="1.0" iyz="0.0" izz="1.0"/>
    </inertial>
  </link>
  <joint name="joint_8_2" type="prismatic">
    <parent link="table_base"/>
    <child link="link_8_2"/>
    <origin ryp="0 0 0" xyz="0.15400000000000003 0.052000000000000005 0"/>
    <axis xyz="0 0 1"/>
    <limit effort="4" lower="0" upper="0.045" velocity="0.01"/>
  </joint>
  <link name="link_8_1">
    <visual>
      <geometry>
        <box size="0.016 0.016 0.055"/>
      </geometry>
      <origin rpy="0 0 0" xyz="0 0 -0.0275"/>
      <material name="blue">
        <color rgba="0 0 1 0.9"/>
      </material>
    </visual>
    <collision>
      <geometry>
        <box size="0.016 0.016 0.055"/>
      </geometry>
      <origin rpy="0 0 0" xyz="0 0 -0.0275"/>
    </collision>
    <inertial>
      <origin rpy="0 0 0" xyz="0 0 0"/>
      <mass value="0.5"/>
      <inertia ixx="1.0" ixy="0.0" ixz="0.0" iyy="1.0" iyz="0.0" izz="1.0"/>
    </inertial>
  </link>
  <joint name="joint_8_1" type="prismatic">
    <parent link="table_base"/>
    <child link="link_8_1"/>
    <origin ryp="0 0 0" xyz="0.15400000000000003 0.035 0"/>
    <axis xyz="0 0 1"/>
    <limit effort="4" lower="0" upper="0.045" velocity="0.01"/>
  </joint>
  <link name="link_8_0">
    <visual>
      <geometry>
        <box size="0.016 0.016 0.055"/>
      </geometry>
      <origin rpy="0 0 0" xyz="0 0 -0.0275"/>
      <material name="blue">
        <color rgba="0 0 1 0.9"/>
      </material>
    </visual>
    <collision>
      <geometry>
        <box size="0.016 0.016 0.055"/>
      </geometry>
      <origin rpy="0 0 0" xyz="0 0 -0.0275"/>
    </collision>
    <inertial>
      <origin rpy="0 0 0" xyz="0 0 0"/>
      <mass value="0.5"/>
      <inertia ixx="1.0" ixy="0.0" ixz="0.0" iyy="1.0" iyz="0.0" izz="1.0"/>
    </inertial>
  </link>
  <joint name="joint_8_0" type="prismatic">
    <parent link="table_base"/>
    <child link="link_8_0"/>
    <origin ryp="0 0 0" xyz="0.15400000000000003 0.018000000000000002 0"/>
    <axis xyz="0 0 1"/>
    <limit effort="4" lower="0" upper="0.045" velocity="0.01"/>
  </joint>
  <link name="link_7_11">
    <visual>
      <geometry>
        <box size="0.016 0.016 0.055"/>
      </geometry>
      <origin rpy="0 0 0" xyz="0 0 -0.0275"/>
      <material name="blue">
        <color rgba="0 0 1 0.9"/>
      </material>
    </visual>
    <collision>
      <geometry>
        <box size="0.016 0.016 0.055"/>
      </geometry>
      <origin rpy="0 0 0" xyz="0 0 -0.0275"/>
    </collision>
    <inertial>
      <origin rpy="0 0 0" xyz="0 0 0"/>
      <mass value="0.5"/>
      <inertia ixx="1.0" ixy="0.0" ixz="0.0" iyy="1.0" iyz="0.0" izz="1.0"/>
    </inertial>
  </link>
  <joint name="joint_7_11" type="prismatic">
    <parent link="table_base"/>
    <child link="link_7_11"/>
    <origin ryp="0 0 0" xyz="0.137 0.205 0"/>
    <axis xyz="0 0 1"/>
    <limit effort="4" lower="0" upper="0.045" velocity="0.01"/>
  </joint>
  <link name="link_7_10">
    <visual>
      <geometry>
        <box size="0.016 0.016 0.055"/>
      </geometry>
      <origin rpy="0 0 0" xyz="0 0 -0.0275"/>
      <material name="blue">
        <color rgba="0 0 1 0.9"/>
      </material>
    </visual>
    <collision>
      <geometry>
        <box size="0.016 0.016 0.055"/>
      </geometry>
      <origin rpy="0 0 0" xyz="0 0 -0.0275"/>
    </collision>
    <inertial>
      <origin rpy="0 0 0" xyz="0 0 0"/>
      <mass value="0.5"/>
      <inertia ixx="1.0" ixy="0.0" ixz="0.0" iyy="1.0" iyz="0.0" izz="1.0"/>
    </inertial>
  </link>
  <joint name="joint_7_10" type="prismatic">
    <parent link="table_base"/>
    <child link="link_7_10"/>
    <origin ryp="0 0 0" xyz="0.137 0.188 0"/>
    <axis xyz="0 0 1"/>
    <limit effort="4" lower="0" upper="0.045" velocity="0.01"/>
  </joint>
  <link name="link_7_9">
    <visual>
      <geometry>
        <box size="0.016 0.016 0.055"/>
      </geometry>
      <origin rpy="0 0 0" xyz="0 0 -0.0275"/>
      <material name="blue">
        <color rgba="0 0 1 0.9"/>
      </material>
    </visual>
    <collision>
      <geometry>
        <box size="0.016 0.016 0.055"/>
      </geometry>
      <origin rpy="0 0 0" xyz="0 0 -0.0275"/>
    </collision>
    <inertial>
      <origin rpy="0 0 0" xyz="0 0 0"/>
      <mass value="0.5"/>
      <inertia ixx="1.0" ixy="0.0" ixz="0.0" iyy="1.0" iyz="0.0" izz="1.0"/>
    </inertial>
  </link>
  <joint name="joint_7_9" type="prismatic">
    <parent link="table_base"/>
    <child link="link_7_9"/>
    <origin ryp="0 0 0" xyz="0.137 0.17099999999999999 0"/>
    <axis xyz="0 0 1"/>
    <limit effort="4" lower="0" upper="0.045" velocity="0.01"/>
  </joint>
  <link name="link_7_8">
    <visual>
      <geometry>
        <box size="0.016 0.016 0.055"/>
      </geometry>
      <origin rpy="0 0 0" xyz="0 0 -0.0275"/>
      <material name="blue">
        <color rgba="0 0 1 0.9"/>
      </material>
    </visual>
    <collision>
      <geometry>
        <box size="0.016 0.016 0.055"/>
      </geometry>
      <origin rpy="0 0 0" xyz="0 0 -0.0275"/>
    </collision>
    <inertial>
      <origin rpy="0 0 0" xyz="0 0 0"/>
      <mass value="0.5"/>
      <inertia ixx="1.0" ixy="0.0" ixz="0.0" iyy="1.0" iyz="0.0" izz="1.0"/>
    </inertial>
  </link>
  <joint name="joint_7_8" type="prismatic">
    <parent link="table_base"/>
    <child link="link_7_8"/>
    <origin ryp="0 0 0" xyz="0.137 0.15400000000000003 0"/>
    <axis xyz="0 0 1"/>
    <limit effort="4" lower="0" upper="0.045" velocity="0.01"/>
  </joint>
  <link name="link_7_7">
    <visual>
      <geometry>
        <box size="0.016 0.016 0.055"/>
      </geometry>
      <origin rpy="0 0 0" xyz="0 0 -0.0275"/>
      <material name="blue">
        <color rgba="0 0 1 0.9"/>
      </material>
    </visual>
    <collision>
      <geometry>
        <box size="0.016 0.016 0.055"/>
      </geometry>
      <origin rpy="0 0 0" xyz="0 0 -0.0275"/>
    </collision>
    <inertial>
      <origin rpy="0 0 0" xyz="0 0 0"/>
      <mass value="0.5"/>
      <inertia ixx="1.0" ixy="0.0" ixz="0.0" iyy="1.0" iyz="0.0" izz="1.0"/>
    </inertial>
  </link>
  <joint name="joint_7_7" type="prismatic">
    <parent link="table_base"/>
    <child link="link_7_7"/>
    <origin ryp="0 0 0" xyz="0.137 0.137 0"/>
    <axis xyz="0 0 1"/>
    <limit effort="4" lower="0" upper="0.045" velocity="0.01"/>
  </joint>
  <link name="link_7_6">
    <visual>
      <geometry>
        <box size="0.016 0.016 0.055"/>
      </geometry>
      <origin rpy="0 0 0" xyz="0 0 -0.0275"/>
      <material name="blue">
        <color rgba="0 0 1 0.9"/>
      </material>
    </visual>
    <collision>
      <geometry>
        <box size="0.016 0.016 0.055"/>
      </geometry>
      <origin rpy="0 0 0" xyz="0 0 -0.0275"/>
    </collision>
    <inertial>
      <origin rpy="0 0 0" xyz="0 0 0"/>
      <mass value="0.5"/>
      <inertia ixx="1.0" ixy="0.0" ixz="0.0" iyy="1.0" iyz="0.0" izz="1.0"/>
    </inertial>
  </link>
  <joint name="joint_7_6" type="prismatic">
    <parent link="table_base"/>
    <child link="link_7_6"/>
    <origin ryp="0 0 0" xyz="0.137 0.12000000000000001 0"/>
    <axis xyz="0 0 1"/>
    <limit effort="4" lower="0" upper="0.045" velocity="0.01"/>
  </joint>
  <link name="link_7_5">
    <visual>
      <geometry>
        <box size="0.016 0.016 0.055"/>
      </geometry>
      <origin rpy="0 0 0" xyz="0 0 -0.0275"/>
      <material name="blue">
        <color rgba="0 0 1 0.9"/>
      </material>
    </visual>
    <collision>
      <geometry>
        <box size="0.016 0.016 0.055"/>
      </geometry>
      <origin rpy="0 0 0" xyz="0 0 -0.0275"/>
    </collision>
    <inertial>
      <origin rpy="0 0 0" xyz="0 0 0"/>
      <mass value="0.5"/>
      <inertia ixx="1.0" ixy="0.0" ixz="0.0" iyy="1.0" iyz="0.0" izz="1.0"/>
    </inertial>
  </link>
  <joint name="joint_7_5" type="prismatic">
    <parent link="table_base"/>
    <child link="link_7_5"/>
    <origin ryp="0 0 0" xyz="0.137 0.103 0"/>
    <axis xyz="0 0 1"/>
    <limit effort="4" lower="0" upper="0.045" velocity="0.01"/>
  </joint>
  <link name="link_7_4">
    <visual>
      <geometry>
        <box size="0.016 0.016 0.055"/>
      </geometry>
      <origin rpy="0 0 0" xyz="0 0 -0.0275"/>
      <material name="blue">
        <color rgba="0 0 1 0.9"/>
      </material>
    </visual>
    <collision>
      <geometry>
        <box size="0.016 0.016 0.055"/>
      </geometry>
      <origin rpy="0 0 0" xyz="0 0 -0.0275"/>
    </collision>
    <inertial>
      <origin rpy="0 0 0" xyz="0 0 0"/>
      <mass value="0.5"/>
      <inertia ixx="1.0" ixy="0.0" ixz="0.0" iyy="1.0" iyz="0.0" izz="1.0"/>
    </inertial>
  </link>
  <joint name="joint_7_4" type="prismatic">
    <parent link="table_base"/>
    <child link="link_7_4"/>
    <origin ryp="0 0 0" xyz="0.137 0.08600000000000001 0"/>
    <axis xyz="0 0 1"/>
    <limit effort="4" lower="0" upper="0.045" velocity="0.01"/>
  </joint>
  <link name="link_7_3">
    <visual>
      <geometry>
        <box size="0.016 0.016 0.055"/>
      </geometry>
      <origin rpy="0 0 0" xyz="0 0 -0.0275"/>
      <material name="blue">
        <color rgba="0 0 1 0.9"/>
      </material>
    </visual>
    <collision>
      <geometry>
        <box size="0.016 0.016 0.055"/>
      </geometry>
      <origin rpy="0 0 0" xyz="0 0 -0.0275"/>
    </collision>
    <inertial>
      <origin rpy="0 0 0" xyz="0 0 0"/>
      <mass value="0.5"/>
      <inertia ixx="1.0" ixy="0.0" ixz="0.0" iyy="1.0" iyz="0.0" izz="1.0"/>
    </inertial>
  </link>
  <joint name="joint_7_3" type="prismatic">
    <parent link="table_base"/>
    <child link="link_7_3"/>
    <origin ryp="0 0 0" xyz="0.137 0.069 0"/>
    <axis xyz="0 0 1"/>
    <limit effort="4" lower="0" upper="0.045" velocity="0.01"/>
  </joint>
  <link name="link_7_2">
    <visual>
      <geometry>
        <box size="0.016 0.016 0.055"/>
      </geometry>
      <origin rpy="0 0 0" xyz="0 0 -0.0275"/>
      <material name="blue">
        <color rgba="0 0 1 0.9"/>
      </material>
    </visual>
    <collision>
      <geometry>
        <box size="0.016 0.016 0.055"/>
      </geometry>
      <origin rpy="0 0 0" xyz="0 0 -0.0275"/>
    </collision>
    <inertial>
      <origin rpy="0 0 0" xyz="0 0 0"/>
      <mass value="0.5"/>
      <inertia ixx="1.0" ixy="0.0" ixz="0.0" iyy="1.0" iyz="0.0" izz="1.0"/>
    </inertial>
  </link>
  <joint name="joint_7_2" type="prismatic">
    <parent link="table_base"/>
    <child link="link_7_2"/>
    <origin ryp="0 0 0" xyz="0.137 0.052000000000000005 0"/>
    <axis xyz="0 0 1"/>
    <limit effort="4" lower="0" upper="0.045" velocity="0.01"/>
  </joint>
  <link name="link_7_1">
    <visual>
      <geometry>
        <box size="0.016 0.016 0.055"/>
      </geometry>
      <origin rpy="0 0 0" xyz="0 0 -0.0275"/>
      <material name="blue">
        <color rgba="0 0 1 0.9"/>
      </material>
    </visual>
    <collision>
      <geometry>
        <box size="0.016 0.016 0.055"/>
      </geometry>
      <origin rpy="0 0 0" xyz="0 0 -0.0275"/>
    </collision>
    <inertial>
      <origin rpy="0 0 0" xyz="0 0 0"/>
      <mass value="0.5"/>
      <inertia ixx="1.0" ixy="0.0" ixz="0.0" iyy="1.0" iyz="0.0" izz="1.0"/>
    </inertial>
  </link>
  <joint name="joint_7_1" type="prismatic">
    <parent link="table_base"/>
    <child link="link_7_1"/>
    <origin ryp="0 0 0" xyz="0.137 0.035 0"/>
    <axis xyz="0 0 1"/>
    <limit effort="4" lower="0" upper="0.045" velocity="0.01"/>
  </joint>
  <link name="link_7_0">
    <visual>
      <geometry>
        <box size="0.016 0.016 0.055"/>
      </geometry>
      <origin rpy="0 0 0" xyz="0 0 -0.0275"/>
      <material name="blue">
        <color rgba="0 0 1 0.9"/>
      </material>
    </visual>
    <collision>
      <geometry>
        <box size="0.016 0.016 0.055"/>
      </geometry>
      <origin rpy="0 0 0" xyz="0 0 -0.0275"/>
    </collision>
    <inertial>
      <origin rpy="0 0 0" xyz="0 0 0"/>
      <mass value="0.5"/>
      <inertia ixx="1.0" ixy="0.0" ixz="0.0" iyy="1.0" iyz="0.0" izz="1.0"/>
    </inertial>
  </link>
  <joint name="joint_7_0" type="prismatic">
    <parent link="table_base"/>
    <child link="link_7_0"/>
    <origin ryp="0 0 0" xyz="0.137 0.018000000000000002 0"/>
    <axis xyz="0 0 1"/>
    <limit effort="4" lower="0" upper="0.045" velocity="0.01"/>
  </joint>
  <link name="link_6_11">
    <visual>
      <geometry>
        <box size="0.016 0.016 0.055"/>
      </geometry>
      <origin rpy="0 0 0" xyz="0 0 -0.0275"/>
      <material name="blue">
        <color rgba="0 0 1 0.9"/>
      </material>
    </visual>
    <collision>
      <geometry>
        <box size="0.016 0.016 0.055"/>
      </geometry>
      <origin rpy="0 0 0" xyz="0 0 -0.0275"/>
    </collision>
    <inertial>
      <origin rpy="0 0 0" xyz="0 0 0"/>
      <mass value="0.5"/>
      <inertia ixx="1.0" ixy="0.0" ixz="0.0" iyy="1.0" iyz="0.0" izz="1.0"/>
    </inertial>
  </link>
  <joint name="joint_6_11" type="prismatic">
    <parent link="table_base"/>
    <child link="link_6_11"/>
    <origin ryp="0 0 0" xyz="0.12000000000000001 0.205 0"/>
    <axis xyz="0 0 1"/>
    <limit effort="4" lower="0" upper="0.045" velocity="0.01"/>
  </joint>
  <link name="link_6_10">
    <visual>
      <geometry>
        <box size="0.016 0.016 0.055"/>
      </geometry>
      <origin rpy="0 0 0" xyz="0 0 -0.0275"/>
      <material name="blue">
        <color rgba="0 0 1 0.9"/>
      </material>
    </visual>
    <collision>
      <geometry>
        <box size="0.016 0.016 0.055"/>
      </geometry>
      <origin rpy="0 0 0" xyz="0 0 -0.0275"/>
    </collision>
    <inertial>
      <origin rpy="0 0 0" xyz="0 0 0"/>
      <mass value="0.5"/>
      <inertia ixx="1.0" ixy="0.0" ixz="0.0" iyy="1.0" iyz="0.0" izz="1.0"/>
    </inertial>
  </link>
  <joint name="joint_6_10" type="prismatic">
    <parent link="table_base"/>
    <child link="link_6_10"/>
    <origin ryp="0 0 0" xyz="0.12000000000000001 0.188 0"/>
    <axis xyz="0 0 1"/>
    <limit effort="4" lower="0" upper="0.045" velocity="0.01"/>
  </joint>
  <link name="link_6_9">
    <visual>
      <geometry>
        <box size="0.016 0.016 0.055"/>
      </geometry>
      <origin rpy="0 0 0" xyz="0 0 -0.0275"/>
      <material name="blue">
        <color rgba="0 0 1 0.9"/>
      </material>
    </visual>
    <collision>
      <geometry>
        <box size="0.016 0.016 0.055"/>
      </geometry>
      <origin rpy="0 0 0" xyz="0 0 -0.0275"/>
    </collision>
    <inertial>
      <origin rpy="0 0 0" xyz="0 0 0"/>
      <mass value="0.5"/>
      <inertia ixx="1.0" ixy="0.0" ixz="0.0" iyy="1.0" iyz="0.0" izz="1.0"/>
    </inertial>
  </link>
  <joint name="joint_6_9" type="prismatic">
    <parent link="table_base"/>
    <child link="link_6_9"/>
    <origin ryp="0 0 0" xyz="0.12000000000000001 0.17099999999999999 0"/>
    <axis xyz="0 0 1"/>
    <limit effort="4" lower="0" upper="0.045" velocity="0.01"/>
  </joint>
  <link name="link_6_8">
    <visual>
      <geometry>
        <box size="0.016 0.016 0.055"/>
      </geometry>
      <origin rpy="0 0 0" xyz="0 0 -0.0275"/>
      <material name="blue">
        <color rgba="0 0 1 0.9"/>
      </material>
    </visual>
    <collision>
      <geometry>
        <box size="0.016 0.016 0.055"/>
      </geometry>
      <origin rpy="0 0 0" xyz="0 0 -0.0275"/>
    </collision>
    <inertial>
      <origin rpy="0 0 0" xyz="0 0 0"/>
      <mass value="0.5"/>
      <inertia ixx="1.0" ixy="0.0" ixz="0.0" iyy="1.0" iyz="0.0" izz="1.0"/>
    </inertial>
  </link>
  <joint name="joint_6_8" type="prismatic">
    <parent link="table_base"/>
    <child link="link_6_8"/>
    <origin ryp="0 0 0" xyz="0.12000000000000001 0.15400000000000003 0"/>
    <axis xyz="0 0 1"/>
    <limit effort="4" lower="0" upper="0.045" velocity="0.01"/>
  </joint>
  <link name="link_6_7">
    <visual>
      <geometry>
        <box size="0.016 0.016 0.055"/>
      </geometry>
      <origin rpy="0 0 0" xyz="0 0 -0.0275"/>
      <material name="blue">
        <color rgba="0 0 1 0.9"/>
      </material>
    </visual>
    <collision>
      <geometry>
        <box size="0.016 0.016 0.055"/>
      </geometry>
      <origin rpy="0 0 0" xyz="0 0 -0.0275"/>
    </collision>
    <inertial>
      <origin rpy="0 0 0" xyz="0 0 0"/>
      <mass value="0.5"/>
      <inertia ixx="1.0" ixy="0.0" ixz="0.0" iyy="1.0" iyz="0.0" izz="1.0"/>
    </inertial>
  </link>
  <joint name="joint_6_7" type="prismatic">
    <parent link="table_base"/>
    <child link="link_6_7"/>
    <origin ryp="0 0 0" xyz="0.12000000000000001 0.137 0"/>
    <axis xyz="0 0 1"/>
    <limit effort="4" lower="0" upper="0.045" velocity="0.01"/>
  </joint>
  <link name="link_6_6">
    <visual>
      <geometry>
        <box size="0.016 0.016 0.055"/>
      </geometry>
      <origin rpy="0 0 0" xyz="0 0 -0.0275"/>
      <material name="blue">
        <color rgba="0 0 1 0.9"/>
      </material>
    </visual>
    <collision>
      <geometry>
        <box size="0.016 0.016 0.055"/>
      </geometry>
      <origin rpy="0 0 0" xyz="0 0 -0.0275"/>
    </collision>
    <inertial>
      <origin rpy="0 0 0" xyz="0 0 0"/>
      <mass value="0.5"/>
      <inertia ixx="1.0" ixy="0.0" ixz="0.0" iyy="1.0" iyz="0.0" izz="1.0"/>
    </inertial>
  </link>
  <joint name="joint_6_6" type="prismatic">
    <parent link="table_base"/>
    <child link="link_6_6"/>
    <origin ryp="0 0 0" xyz="0.12000000000000001 0.12000000000000001 0"/>
    <axis xyz="0 0 1"/>
    <limit effort="4" lower="0" upper="0.045" velocity="0.01"/>
  </joint>
  <link name="link_6_5">
    <visual>
      <geometry>
        <box size="0.016 0.016 0.055"/>
      </geometry>
      <origin rpy="0 0 0" xyz="0 0 -0.0275"/>
      <material name="blue">
        <color rgba="0 0 1 0.9"/>
      </material>
    </visual>
    <collision>
      <geometry>
        <box size="0.016 0.016 0.055"/>
      </geometry>
      <origin rpy="0 0 0" xyz="0 0 -0.0275"/>
    </collision>
    <inertial>
      <origin rpy="0 0 0" xyz="0 0 0"/>
      <mass value="0.5"/>
      <inertia ixx="1.0" ixy="0.0" ixz="0.0" iyy="1.0" iyz="0.0" izz="1.0"/>
    </inertial>
  </link>
  <joint name="joint_6_5" type="prismatic">
    <parent link="table_base"/>
    <child link="link_6_5"/>
    <origin ryp="0 0 0" xyz="0.12000000000000001 0.103 0"/>
    <axis xyz="0 0 1"/>
    <limit effort="4" lower="0" upper="0.045" velocity="0.01"/>
  </joint>
  <link name="link_6_4">
    <visual>
      <geometry>
        <box size="0.016 0.016 0.055"/>
      </geometry>
      <origin rpy="0 0 0" xyz="0 0 -0.0275"/>
      <material name="blue">
        <color rgba="0 0 1 0.9"/>
      </material>
    </visual>
    <collision>
      <geometry>
        <box size="0.016 0.016 0.055"/>
      </geometry>
      <origin rpy="0 0 0" xyz="0 0 -0.0275"/>
    </collision>
    <inertial>
      <origin rpy="0 0 0" xyz="0 0 0"/>
      <mass value="0.5"/>
      <inertia ixx="1.0" ixy="0.0" ixz="0.0" iyy="1.0" iyz="0.0" izz="1.0"/>
    </inertial>
  </link>
  <joint name="joint_6_4" type="prismatic">
    <parent link="table_base"/>
    <child link="link_6_4"/>
    <origin ryp="0 0 0" xyz="0.12000000000000001 0.08600000000000001 0"/>
    <axis xyz="0 0 1"/>
    <limit effort="4" lower="0" upper="0.045" velocity="0.01"/>
  </joint>
  <link name="link_6_3">
    <visual>
      <geometry>
        <box size="0.016 0.016 0.055"/>
      </geometry>
      <origin rpy="0 0 0" xyz="0 0 -0.0275"/>
      <material name="blue">
        <color rgba="0 0 1 0.9"/>
      </material>
    </visual>
    <collision>
      <geometry>
        <box size="0.016 0.016 0.055"/>
      </geometry>
      <origin rpy="0 0 0" xyz="0 0 -0.0275"/>
    </collision>
    <inertial>
      <origin rpy="0 0 0" xyz="0 0 0"/>
      <mass value="0.5"/>
      <inertia ixx="1.0" ixy="0.0" ixz="0.0" iyy="1.0" iyz="0.0" izz="1.0"/>
    </inertial>
  </link>
  <joint name="joint_6_3" type="prismatic">
    <parent link="table_base"/>
    <child link="link_6_3"/>
    <origin ryp="0 0 0" xyz="0.12000000000000001 0.069 0"/>
    <axis xyz="0 0 1"/>
    <limit effort="4" lower="0" upper="0.045" velocity="0.01"/>
  </joint>
  <link name="link_6_2">
    <visual>
      <geometry>
        <box size="0.016 0.016 0.055"/>
      </geometry>
      <origin rpy="0 0 0" xyz="0 0 -0.0275"/>
      <material name="blue">
        <color rgba="0 0 1 0.9"/>
      </material>
    </visual>
    <collision>
      <geometry>
        <box size="0.016 0.016 0.055"/>
      </geometry>
      <origin rpy="0 0 0" xyz="0 0 -0.0275"/>
    </collision>
    <inertial>
      <origin rpy="0 0 0" xyz="0 0 0"/>
      <mass value="0.5"/>
      <inertia ixx="1.0" ixy="0.0" ixz="0.0" iyy="1.0" iyz="0.0" izz="1.0"/>
    </inertial>
  </link>
  <joint name="joint_6_2" type="prismatic">
    <parent link="table_base"/>
    <child link="link_6_2"/>
    <origin ryp="0 0 0" xyz="0.12000000000000001 0.052000000000000005 0"/>
    <axis xyz="0 0 1"/>
    <limit effort="4" lower="0" upper="0.045" velocity="0.01"/>
  </joint>
  <link name="link_6_1">
    <visual>
      <geometry>
        <box size="0.016 0.016 0.055"/>
      </geometry>
      <origin rpy="0 0 0" xyz="0 0 -0.0275"/>
      <material name="blue">
        <color rgba="0 0 1 0.9"/>
      </material>
    </visual>
    <collision>
      <geometry>
        <box size="0.016 0.016 0.055"/>
      </geometry>
      <origin rpy="0 0 0" xyz="0 0 -0.0275"/>
    </collision>
    <inertial>
      <origin rpy="0 0 0" xyz="0 0 0"/>
      <mass value="0.5"/>
      <inertia ixx="1.0" ixy="0.0" ixz="0.0" iyy="1.0" iyz="0.0" izz="1.0"/>
    </inertial>
  </link>
  <joint name="joint_6_1" type="prismatic">
    <parent link="table_base"/>
    <child link="link_6_1"/>
    <origin ryp="0 0 0" xyz="0.12000000000000001 0.035 0"/>
    <axis xyz="0 0 1"/>
    <limit effort="4" lower="0" upper="0.045" velocity="0.01"/>
  </joint>
  <link name="link_6_0">
    <visual>
      <geometry>
        <box size="0.016 0.016 0.055"/>
      </geometry>
      <origin rpy="0 0 0" xyz="0 0 -0.0275"/>
      <material name="blue">
        <color rgba="0 0 1 0.9"/>
      </material>
    </visual>
    <collision>
      <geometry>
        <box size="0.016 0.016 0.055"/>
      </geometry>
      <origin rpy="0 0 0" xyz="0 0 -0.0275"/>
    </collision>
    <inertial>
      <origin rpy="0 0 0" xyz="0 0 0"/>
      <mass value="0.5"/>
      <inertia ixx="1.0" ixy="0.0" ixz="0.0" iyy="1.0" iyz="0.0" izz="1.0"/>
    </inertial>
  </link>
  <joint name="joint_6_0" type="prismatic">
    <parent link="table_base"/>
    <child link="link_6_0"/>
    <origin ryp="0 0 0" xyz="0.12000000000000001 0.018000000000000002 0"/>
    <axis xyz="0 0 1"/>
    <limit effort="4" lower="0" upper="0.045" velocity="0.01"/>
  </joint>
  <link name="link_5_11">
    <visual>
      <geometry>
        <box size="0.016 0.016 0.055"/>
      </geometry>
      <origin rpy="0 0 0" xyz="0 0 -0.0275"/>
      <material name="blue">
        <color rgba="0 0 1 0.9"/>
      </material>
    </visual>
    <collision>
      <geometry>
        <box size="0.016 0.016 0.055"/>
      </geometry>
      <origin rpy="0 0 0" xyz="0 0 -0.0275"/>
    </collision>
    <inertial>
      <origin rpy="0 0 0" xyz="0 0 0"/>
      <mass value="0.5"/>
      <inertia ixx="1.0" ixy="0.0" ixz="0.0" iyy="1.0" iyz="0.0" izz="1.0"/>
    </inertial>
  </link>
  <joint name="joint_5_11" type="prismatic">
    <parent link="table_base"/>
    <child link="link_5_11"/>
    <origin ryp="0 0 0" xyz="0.103 0.205 0"/>
    <axis xyz="0 0 1"/>
    <limit effort="4" lower="0" upper="0.045" velocity="0.01"/>
  </joint>
  <link name="link_5_10">
    <visual>
      <geometry>
        <box size="0.016 0.016 0.055"/>
      </geometry>
      <origin rpy="0 0 0" xyz="0 0 -0.0275"/>
      <material name="blue">
        <color rgba="0 0 1 0.9"/>
      </material>
    </visual>
    <collision>
      <geometry>
        <box size="0.016 0.016 0.055"/>
      </geometry>
      <origin rpy="0 0 0" xyz="0 0 -0.0275"/>
    </collision>
    <inertial>
      <origin rpy="0 0 0" xyz="0 0 0"/>
      <mass value="0.5"/>
      <inertia ixx="1.0" ixy="0.0" ixz="0.0" iyy="1.0" iyz="0.0" izz="1.0"/>
    </inertial>
  </link>
  <joint name="joint_5_10" type="prismatic">
    <parent link="table_base"/>
    <child link="link_5_10"/>
    <origin ryp="0 0 0" xyz="0.103 0.188 0"/>
    <axis xyz="0 0 1"/>
    <limit effort="4" lower="0" upper="0.045" velocity="0.01"/>
  </joint>
  <link name="link_5_9">
    <visual>
      <geometry>
        <box size="0.016 0.016 0.055"/>
      </geometry>
      <origin rpy="0 0 0" xyz="0 0 -0.0275"/>
      <material name="blue">
        <color rgba="0 0 1 0.9"/>
      </material>
    </visual>
    <collision>
      <geometry>
        <box size="0.016 0.016 0.055"/>
      </geometry>
      <origin rpy="0 0 0" xyz="0 0 -0.0275"/>
    </collision>
    <inertial>
      <origin rpy="0 0 0" xyz="0 0 0"/>
      <mass value="0.5"/>
      <inertia ixx="1.0" ixy="0.0" ixz="0.0" iyy="1.0" iyz="0.0" izz="1.0"/>
    </inertial>
  </link>
  <joint name="joint_5_9" type="prismatic">
    <parent link="table_base"/>
    <child link="link_5_9"/>
    <origin ryp="0 0 0" xyz="0.103 0.17099999999999999 0"/>
    <axis xyz="0 0 1"/>
    <limit effort="4" lower="0" upper="0.045" velocity="0.01"/>
  </joint>
  <link name="link_5_8">
    <visual>
      <geometry>
        <box size="0.016 0.016 0.055"/>
      </geometry>
      <origin rpy="0 0 0" xyz="0 0 -0.0275"/>
      <material name="blue">
        <color rgba="0 0 1 0.9"/>
      </material>
    </visual>
    <collision>
      <geometry>
        <box size="0.016 0.016 0.055"/>
      </geometry>
      <origin rpy="0 0 0" xyz="0 0 -0.0275"/>
    </collision>
    <inertial>
      <origin rpy="0 0 0" xyz="0 0 0"/>
      <mass value="0.5"/>
      <inertia ixx="1.0" ixy="0.0" ixz="0.0" iyy="1.0" iyz="0.0" izz="1.0"/>
    </inertial>
  </link>
  <joint name="joint_5_8" type="prismatic">
    <parent link="table_base"/>
    <child link="link_5_8"/>
    <origin ryp="0 0 0" xyz="0.103 0.15400000000000003 0"/>
    <axis xyz="0 0 1"/>
    <limit effort="4" lower="0" upper="0.045" velocity="0.01"/>
  </joint>
  <link name="link_5_7">
    <visual>
      <geometry>
        <box size="0.016 0.016 0.055"/>
      </geometry>
      <origin rpy="0 0 0" xyz="0 0 -0.0275"/>
      <material name="blue">
        <color rgba="0 0 1 0.9"/>
      </material>
    </visual>
    <collision>
      <geometry>
        <box size="0.016 0.016 0.055"/>
      </geometry>
      <origin rpy="0 0 0" xyz="0 0 -0.0275"/>
    </collision>
    <inertial>
      <origin rpy="0 0 0" xyz="0 0 0"/>
      <mass value="0.5"/>
      <inertia ixx="1.0" ixy="0.0" ixz="0.0" iyy="1.0" iyz="0.0" izz="1.0"/>
    </inertial>
  </link>
  <joint name="joint_5_7" type="prismatic">
    <parent link="table_base"/>
    <child link="link_5_7"/>
    <origin ryp="0 0 0" xyz="0.103 0.137 0"/>
    <axis xyz="0 0 1"/>
    <limit effort="4" lower="0" upper="0.045" velocity="0.01"/>
  </joint>
  <link name="link_5_6">
    <visual>
      <geometry>
        <box size="0.016 0.016 0.055"/>
      </geometry>
      <origin rpy="0 0 0" xyz="0 0 -0.0275"/>
      <material name="blue">
        <color rgba="0 0 1 0.9"/>
      </material>
    </visual>
    <collision>
      <geometry>
        <box size="0.016 0.016 0.055"/>
      </geometry>
      <origin rpy="0 0 0" xyz="0 0 -0.0275"/>
    </collision>
    <inertial>
      <origin rpy="0 0 0" xyz="0 0 0"/>
      <mass value="0.5"/>
      <inertia ixx="1.0" ixy="0.0" ixz="0.0" iyy="1.0" iyz="0.0" izz="1.0"/>
    </inertial>
  </link>
  <joint name="joint_5_6" type="prismatic">
    <parent link="table_base"/>
    <child link="link_5_6"/>
    <origin ryp="0 0 0" xyz="0.103 0.12000000000000001 0"/>
    <axis xyz="0 0 1"/>
    <limit effort="4" lower="0" upper="0.045" velocity="0.01"/>
  </joint>
  <link name="link_5_5">
    <visual>
      <geometry>
        <box size="0.016 0.016 0.055"/>
      </geometry>
      <origin rpy="0 0 0" xyz="0 0 -0.0275"/>
      <material name="blue">
        <color rgba="0 0 1 0.9"/>
      </material>
    </visual>
    <collision>
      <geometry>
        <box size="0.016 0.016 0.055"/>
      </geometry>
      <origin rpy="0 0 0" xyz="0 0 -0.0275"/>
    </collision>
    <inertial>
      <origin rpy="0 0 0" xyz="0 0 0"/>
      <mass value="0.5"/>
      <inertia ixx="1.0" ixy="0.0" ixz="0.0" iyy="1.0" iyz="0.0" izz="1.0"/>
    </inertial>
  </link>
  <joint name="joint_5_5" type="prismatic">
    <parent link="table_base"/>
    <child link="link_5_5"/>
    <origin ryp="0 0 0" xyz="0.103 0.103 0"/>
    <axis xyz="0 0 1"/>
    <limit effort="4" lower="0" upper="0.045" velocity="0.01"/>
  </joint>
  <link name="link_5_4">
    <visual>
      <geometry>
        <box size="0.016 0.016 0.055"/>
      </geometry>
      <origin rpy="0 0 0" xyz="0 0 -0.0275"/>
      <material name="blue">
        <color rgba="0 0 1 0.9"/>
      </material>
    </visual>
    <collision>
      <geometry>
        <box size="0.016 0.016 0.055"/>
      </geometry>
      <origin rpy="0 0 0" xyz="0 0 -0.0275"/>
    </collision>
    <inertial>
      <origin rpy="0 0 0" xyz="0 0 0"/>
      <mass value="0.5"/>
      <inertia ixx="1.0" ixy="0.0" ixz="0.0" iyy="1.0" iyz="0.0" izz="1.0"/>
    </inertial>
  </link>
  <joint name="joint_5_4" type="prismatic">
    <parent link="table_base"/>
    <child link="link_5_4"/>
    <origin ryp="0 0 0" xyz="0.103 0.08600000000000001 0"/>
    <axis xyz="0 0 1"/>
    <limit effort="4" lower="0" upper="0.045" velocity="0.01"/>
  </joint>
  <link name="link_5_3">
    <visual>
      <geometry>
        <box size="0.016 0.016 0.055"/>
      </geometry>
      <origin rpy="0 0 0" xyz="0 0 -0.0275"/>
      <material name="blue">
        <color rgba="0 0 1 0.9"/>
      </material>
    </visual>
    <collision>
      <geometry>
        <box size="0.016 0.016 0.055"/>
      </geometry>
      <origin rpy="0 0 0" xyz="0 0 -0.0275"/>
    </collision>
    <inertial>
      <origin rpy="0 0 0" xyz="0 0 0"/>
      <mass value="0.5"/>
      <inertia ixx="1.0" ixy="0.0" ixz="0.0" iyy="1.0" iyz="0.0" izz="1.0"/>
    </inertial>
  </link>
  <joint name="joint_5_3" type="prismatic">
    <parent link="table_base"/>
    <child link="link_5_3"/>
    <origin ryp="0 0 0" xyz="0.103 0.069 0"/>
    <axis xyz="0 0 1"/>
    <limit effort="4" lower="0" upper="0.045" velocity="0.01"/>
  </joint>
  <link name="link_5_2">
    <visual>
      <geometry>
        <box size="0.016 0.016 0.055"/>
      </geometry>
      <origin rpy="0 0 0" xyz="0 0 -0.0275"/>
      <material name="blue">
        <color rgba="0 0 1 0.9"/>
      </material>
    </visual>
    <collision>
      <geometry>
        <box size="0.016 0.016 0.055"/>
      </geometry>
      <origin rpy="0 0 0" xyz="0 0 -0.0275"/>
    </collision>
    <inertial>
      <origin rpy="0 0 0" xyz="0 0 0"/>
      <mass value="0.5"/>
      <inertia ixx="1.0" ixy="0.0" ixz="0.0" iyy="1.0" iyz="0.0" izz="1.0"/>
    </inertial>
  </link>
  <joint name="joint_5_2" type="prismatic">
    <parent link="table_base"/>
    <child link="link_5_2"/>
    <origin ryp="0 0 0" xyz="0.103 0.052000000000000005 0"/>
    <axis xyz="0 0 1"/>
    <limit effort="4" lower="0" upper="0.045" velocity="0.01"/>
  </joint>
  <link name="link_5_1">
    <visual>
      <geometry>
        <box size="0.016 0.016 0.055"/>
      </geometry>
      <origin rpy="0 0 0" xyz="0 0 -0.0275"/>
      <material name="blue">
        <color rgba="0 0 1 0.9"/>
      </material>
    </visual>
    <collision>
      <geometry>
        <box size="0.016 0.016 0.055"/>
      </geometry>
      <origin rpy="0 0 0" xyz="0 0 -0.0275"/>
    </collision>
    <inertial>
      <origin rpy="0 0 0" xyz="0 0 0"/>
      <mass value="0.5"/>
      <inertia ixx="1.0" ixy="0.0" ixz="0.0" iyy="1.0" iyz="0.0" izz="1.0"/>
    </inertial>
  </link>
  <joint name="joint_5_1" type="prismatic">
    <parent link="table_base"/>
    <child link="link_5_1"/>
    <origin ryp="0 0 0" xyz="0.103 0.035 0"/>
    <axis xyz="0 0 1"/>
    <limit effort="4" lower="0" upper="0.045" velocity="0.01"/>
  </joint>
  <link name="link_5_0">
    <visual>
      <geometry>
        <box size="0.016 0.016 0.055"/>
      </geometry>
      <origin rpy="0 0 0" xyz="0 0 -0.0275"/>
      <material name="blue">
        <color rgba="0 0 1 0.9"/>
      </material>
    </visual>
    <collision>
      <geometry>
        <box size="0.016 0.016 0.055"/>
      </geometry>
      <origin rpy="0 0 0" xyz="0 0 -0.0275"/>
    </collision>
    <inertial>
      <origin rpy="0 0 0" xyz="0 0 0"/>
      <mass value="0.5"/>
      <inertia ixx="1.0" ixy="0.0" ixz="0.0" iyy="1.0" iyz="0.0" izz="1.0"/>
    </inertial>
  </link>
  <joint name="joint_5_0" type="prismatic">
    <parent link="table_base"/>
    <child link="link_5_0"/>
    <origin ryp="0 0 0" xyz="0.103 0.018000000000000002 0"/>
    <axis xyz="0 0 1"/>
    <limit effort="4" lower="0" upper="0.045" velocity="0.01"/>
  </joint>
  <link name="link_4_11">
    <visual>
      <geometry>
        <box size="0.016 0.016 0.055"/>
      </geometry>
      <origin rpy="0 0 0" xyz="0 0 -0.0275"/>
      <material name="blue">
        <color rgba="0 0 1 0.9"/>
      </material>
    </visual>
    <collision>
      <geometry>
        <box size="0.016 0.016 0.055"/>
      </geometry>
      <origin rpy="0 0 0" xyz="0 0 -0.0275"/>
    </collision>
    <inertial>
      <origin rpy="0 0 0" xyz="0 0 0"/>
      <mass value="0.5"/>
      <inertia ixx="1.0" ixy="0.0" ixz="0.0" iyy="1.0" iyz="0.0" izz="1.0"/>
    </inertial>
  </link>
  <joint name="joint_4_11" type="prismatic">
    <parent link="table_base"/>
    <child link="link_4_11"/>
    <origin ryp="0 0 0" xyz="0.08600000000000001 0.205 0"/>
    <axis xyz="0 0 1"/>
    <limit effort="4" lower="0" upper="0.045" velocity="0.01"/>
  </joint>
  <link name="link_4_10">
    <visual>
      <geometry>
        <box size="0.016 0.016 0.055"/>
      </geometry>
      <origin rpy="0 0 0" xyz="0 0 -0.0275"/>
      <material name="blue">
        <color rgba="0 0 1 0.9"/>
      </material>
    </visual>
    <collision>
      <geometry>
        <box size="0.016 0.016 0.055"/>
      </geometry>
      <origin rpy="0 0 0" xyz="0 0 -0.0275"/>
    </collision>
    <inertial>
      <origin rpy="0 0 0" xyz="0 0 0"/>
      <mass value="0.5"/>
      <inertia ixx="1.0" ixy="0.0" ixz="0.0" iyy="1.0" iyz="0.0" izz="1.0"/>
    </inertial>
  </link>
  <joint name="joint_4_10" type="prismatic">
    <parent link="table_base"/>
    <child link="link_4_10"/>
    <origin ryp="0 0 0" xyz="0.08600000000000001 0.188 0"/>
    <axis xyz="0 0 1"/>
    <limit effort="4" lower="0" upper="0.045" velocity="0.01"/>
  </joint>
  <link name="link_4_9">
    <visual>
      <geometry>
        <box size="0.016 0.016 0.055"/>
      </geometry>
      <origin rpy="0 0 0" xyz="0 0 -0.0275"/>
      <material name="blue">
        <color rgba="0 0 1 0.9"/>
      </material>
    </visual>
    <collision>
      <geometry>
        <box size="0.016 0.016 0.055"/>
      </geometry>
      <origin rpy="0 0 0" xyz="0 0 -0.0275"/>
    </collision>
    <inertial>
      <origin rpy="0 0 0" xyz="0 0 0"/>
      <mass value="0.5"/>
      <inertia ixx="1.0" ixy="0.0" ixz="0.0" iyy="1.0" iyz="0.0" izz="1.0"/>
    </inertial>
  </link>
  <joint name="joint_4_9" type="prismatic">
    <parent link="table_base"/>
    <child link="link_4_9"/>
    <origin ryp="0 0 0" xyz="0.08600000000000001 0.17099999999999999 0"/>
    <axis xyz="0 0 1"/>
    <limit effort="4" lower="0" upper="0.045" velocity="0.01"/>
  </joint>
  <link name="link_4_8">
    <visual>
      <geometry>
        <box size="0.016 0.016 0.055"/>
      </geometry>
      <origin rpy="0 0 0" xyz="0 0 -0.0275"/>
      <material name="blue">
        <color rgba="0 0 1 0.9"/>
      </material>
    </visual>
    <collision>
      <geometry>
        <box size="0.016 0.016 0.055"/>
      </geometry>
      <origin rpy="0 0 0" xyz="0 0 -0.0275"/>
    </collision>
    <inertial>
      <origin rpy="0 0 0" xyz="0 0 0"/>
      <mass value="0.5"/>
      <inertia ixx="1.0" ixy="0.0" ixz="0.0" iyy="1.0" iyz="0.0" izz="1.0"/>
    </inertial>
  </link>
  <joint name="joint_4_8" type="prismatic">
    <parent link="table_base"/>
    <child link="link_4_8"/>
    <origin ryp="0 0 0" xyz="0.08600000000000001 0.15400000000000003 0"/>
    <axis xyz="0 0 1"/>
    <limit effort="4" lower="0" upper="0.045" velocity="0.01"/>
  </joint>
  <link name="link_4_7">
    <visual>
      <geometry>
        <box size="0.016 0.016 0.055"/>
      </geometry>
      <origin rpy="0 0 0" xyz="0 0 -0.0275"/>
      <material name="blue">
        <color rgba="0 0 1 0.9"/>
      </material>
    </visual>
    <collision>
      <geometry>
        <box size="0.016 0.016 0.055"/>
      </geometry>
      <origin rpy="0 0 0" xyz="0 0 -0.0275"/>
    </collision>
    <inertial>
      <origin rpy="0 0 0" xyz="0 0 0"/>
      <mass value="0.5"/>
      <inertia ixx="1.0" ixy="0.0" ixz="0.0" iyy="1.0" iyz="0.0" izz="1.0"/>
    </inertial>
  </link>
  <joint name="joint_4_7" type="prismatic">
    <parent link="table_base"/>
    <child link="link_4_7"/>
    <origin ryp="0 0 0" xyz="0.08600000000000001 0.137 0"/>
    <axis xyz="0 0 1"/>
    <limit effort="4" lower="0" upper="0.045" velocity="0.01"/>
  </joint>
  <link name="link_4_6">
    <visual>
      <geometry>
        <box size="0.016 0.016 0.055"/>
      </geometry>
      <origin rpy="0 0 0" xyz="0 0 -0.0275"/>
      <material name="blue">
        <color rgba="0 0 1 0.9"/>
      </material>
    </visual>
    <collision>
      <geometry>
        <box size="0.016 0.016 0.055"/>
      </geometry>
      <origin rpy="0 0 0" xyz="0 0 -0.0275"/>
    </collision>
    <inertial>
      <origin rpy="0 0 0" xyz="0 0 0"/>
      <mass value="0.5"/>
      <inertia ixx="1.0" ixy="0.0" ixz="0.0" iyy="1.0" iyz="0.0" izz="1.0"/>
    </inertial>
  </link>
  <joint name="joint_4_6" type="prismatic">
    <parent link="table_base"/>
    <child link="link_4_6"/>
    <origin ryp="0 0 0" xyz="0.08600000000000001 0.12000000000000001 0"/>
    <axis xyz="0 0 1"/>
    <limit effort="4" lower="0" upper="0.045" velocity="0.01"/>
  </joint>
  <link name="link_4_5">
    <visual>
      <geometry>
        <box size="0.016 0.016 0.055"/>
      </geometry>
      <origin rpy="0 0 0" xyz="0 0 -0.0275"/>
      <material name="blue">
        <color rgba="0 0 1 0.9"/>
      </material>
    </visual>
    <collision>
      <geometry>
        <box size="0.016 0.016 0.055"/>
      </geometry>
      <origin rpy="0 0 0" xyz="0 0 -0.0275"/>
    </collision>
    <inertial>
      <origin rpy="0 0 0" xyz="0 0 0"/>
      <mass value="0.5"/>
      <inertia ixx="1.0" ixy="0.0" ixz="0.0" iyy="1.0" iyz="0.0" izz="1.0"/>
    </inertial>
  </link>
  <joint name="joint_4_5" type="prismatic">
    <parent link="table_base"/>
    <child link="link_4_5"/>
    <origin ryp="0 0 0" xyz="0.08600000000000001 0.103 0"/>
    <axis xyz="0 0 1"/>
    <limit effort="4" lower="0" upper="0.045" velocity="0.01"/>
  </joint>
  <link name="link_4_4">
    <visual>
      <geometry>
        <box size="0.016 0.016 0.055"/>
      </geometry>
      <origin rpy="0 0 0" xyz="0 0 -0.0275"/>
      <material name="blue">
        <color rgba="0 0 1 0.9"/>
      </material>
    </visual>
    <collision>
      <geometry>
        <box size="0.016 0.016 0.055"/>
      </geometry>
      <origin rpy="0 0 0" xyz="0 0 -0.0275"/>
    </collision>
    <inertial>
      <origin rpy="0 0 0" xyz="0 0 0"/>
      <mass value="0.5"/>
      <inertia ixx="1.0" ixy="0.0" ixz="0.0" iyy="1.0" iyz="0.0" izz="1.0"/>
    </inertial>
  </link>
  <joint name="joint_4_4" type="prismatic">
    <parent link="table_base"/>
    <child link="link_4_4"/>
    <origin ryp="0 0 0" xyz="0.08600000000000001 0.08600000000000001 0"/>
    <axis xyz="0 0 1"/>
    <limit effort="4" lower="0" upper="0.045" velocity="0.01"/>
  </joint>
  <link name="link_4_3">
    <visual>
      <geometry>
        <box size="0.016 0.016 0.055"/>
      </geometry>
      <origin rpy="0 0 0" xyz="0 0 -0.0275"/>
      <material name="blue">
        <color rgba="0 0 1 0.9"/>
      </material>
    </visual>
    <collision>
      <geometry>
        <box size="0.016 0.016 0.055"/>
      </geometry>
      <origin rpy="0 0 0" xyz="0 0 -0.0275"/>
    </collision>
    <inertial>
      <origin rpy="0 0 0" xyz="0 0 0"/>
      <mass value="0.5"/>
      <inertia ixx="1.0" ixy="0.0" ixz="0.0" iyy="1.0" iyz="0.0" izz="1.0"/>
    </inertial>
  </link>
  <joint name="joint_4_3" type="prismatic">
    <parent link="table_base"/>
    <child link="link_4_3"/>
    <origin ryp="0 0 0" xyz="0.08600000000000001 0.069 0"/>
    <axis xyz="0 0 1"/>
    <limit effort="4" lower="0" upper="0.045" velocity="0.01"/>
  </joint>
  <link name="link_4_2">
    <visual>
      <geometry>
        <box size="0.016 0.016 0.055"/>
      </geometry>
      <origin rpy="0 0 0" xyz="0 0 -0.0275"/>
      <material name="blue">
        <color rgba="0 0 1 0.9"/>
      </material>
    </visual>
    <collision>
      <geometry>
        <box size="0.016 0.016 0.055"/>
      </geometry>
      <origin rpy="0 0 0" xyz="0 0 -0.0275"/>
    </collision>
    <inertial>
      <origin rpy="0 0 0" xyz="0 0 0"/>
      <mass value="0.5"/>
      <inertia ixx="1.0" ixy="0.0" ixz="0.0" iyy="1.0" iyz="0.0" izz="1.0"/>
    </inertial>
  </link>
  <joint name="joint_4_2" type="prismatic">
    <parent link="table_base"/>
    <child link="link_4_2"/>
    <origin ryp="0 0 0" xyz="0.08600000000000001 0.052000000000000005 0"/>
    <axis xyz="0 0 1"/>
    <limit effort="4" lower="0" upper="0.045" velocity="0.01"/>
  </joint>
  <link name="link_4_1">
    <visual>
      <geometry>
        <box size="0.016 0.016 0.055"/>
      </geometry>
      <origin rpy="0 0 0" xyz="0 0 -0.0275"/>
      <material name="blue">
        <color rgba="0 0 1 0.9"/>
      </material>
    </visual>
    <collision>
      <geometry>
        <box size="0.016 0.016 0.055"/>
      </geometry>
      <origin rpy="0 0 0" xyz="0 0 -0.0275"/>
    </collision>
    <inertial>
      <origin rpy="0 0 0" xyz="0 0 0"/>
      <mass value="0.5"/>
      <inertia ixx="1.0" ixy="0.0" ixz="0.0" iyy="1.0" iyz="0.0" izz="1.0"/>
    </inertial>
  </link>
  <joint name="joint_4_1" type="prismatic">
    <parent link="table_base"/>
    <child link="link_4_1"/>
    <origin ryp="0 0 0" xyz="0.08600000000000001 0.035 0"/>
    <axis xyz="0 0 1"/>
    <limit effort="4" lower="0" upper="0.045" velocity="0.01"/>
  </joint>
  <link name="link_4_0">
    <visual>
      <geometry>
        <box size="0.016 0.016 0.055"/>
      </geometry>
      <origin rpy="0 0 0" xyz="0 0 -0.0275"/>
      <material name="blue">
        <color rgba="0 0 1 0.9"/>
      </material>
    </visual>
    <collision>
      <geometry>
        <box size="0.016 0.016 0.055"/>
      </geometry>
      <origin rpy="0 0 0" xyz="0 0 -0.0275"/>
    </collision>
    <inertial>
      <origin rpy="0 0 0" xyz="0 0 0"/>
      <mass value="0.5"/>
      <inertia ixx="1.0" ixy="0.0" ixz="0.0" iyy="1.0" iyz="0.0" izz="1.0"/>
    </inertial>
  </link>
  <joint name="joint_4_0" type="prismatic">
    <parent link="table_base"/>
    <child link="link_4_0"/>
    <origin ryp="0 0 0" xyz="0.08600000000000001 0.018000000000000002 0"/>
    <axis xyz="0 0 1"/>
    <limit effort="4" lower="0" upper="0.045" velocity="0.01"/>
  </joint>
  <link name="link_3_11">
    <visual>
      <geometry>
        <box size="0.016 0.016 0.055"/>
      </geometry>
      <origin rpy="0 0 0" xyz="0 0 -0.0275"/>
      <material name="blue">
        <color rgba="0 0 1 0.9"/>
      </material>
    </visual>
    <collision>
      <geometry>
        <box size="0.016 0.016 0.055"/>
      </geometry>
      <origin rpy="0 0 0" xyz="0 0 -0.0275"/>
    </collision>
    <inertial>
      <origin rpy="0 0 0" xyz="0 0 0"/>
      <mass value="0.5"/>
      <inertia ixx="1.0" ixy="0.0" ixz="0.0" iyy="1.0" iyz="0.0" izz="1.0"/>
    </inertial>
  </link>
  <joint name="joint_3_11" type="prismatic">
    <parent link="table_base"/>
    <child link="link_3_11"/>
    <origin ryp="0 0 0" xyz="0.069 0.205 0"/>
    <axis xyz="0 0 1"/>
    <limit effort="4" lower="0" upper="0.045" velocity="0.01"/>
  </joint>
  <link name="link_3_10">
    <visual>
      <geometry>
        <box size="0.016 0.016 0.055"/>
      </geometry>
      <origin rpy="0 0 0" xyz="0 0 -0.0275"/>
      <material name="blue">
        <color rgba="0 0 1 0.9"/>
      </material>
    </visual>
    <collision>
      <geometry>
        <box size="0.016 0.016 0.055"/>
      </geometry>
      <origin rpy="0 0 0" xyz="0 0 -0.0275"/>
    </collision>
    <inertial>
      <origin rpy="0 0 0" xyz="0 0 0"/>
      <mass value="0.5"/>
      <inertia ixx="1.0" ixy="0.0" ixz="0.0" iyy="1.0" iyz="0.0" izz="1.0"/>
    </inertial>
  </link>
  <joint name="joint_3_10" type="prismatic">
    <parent link="table_base"/>
    <child link="link_3_10"/>
    <origin ryp="0 0 0" xyz="0.069 0.188 0"/>
    <axis xyz="0 0 1"/>
    <limit effort="4" lower="0" upper="0.045" velocity="0.01"/>
  </joint>
  <link name="link_3_9">
    <visual>
      <geometry>
        <box size="0.016 0.016 0.055"/>
      </geometry>
      <origin rpy="0 0 0" xyz="0 0 -0.0275"/>
      <material name="blue">
        <color rgba="0 0 1 0.9"/>
      </material>
    </visual>
    <collision>
      <geometry>
        <box size="0.016 0.016 0.055"/>
      </geometry>
      <origin rpy="0 0 0" xyz="0 0 -0.0275"/>
    </collision>
    <inertial>
      <origin rpy="0 0 0" xyz="0 0 0"/>
      <mass value="0.5"/>
      <inertia ixx="1.0" ixy="0.0" ixz="0.0" iyy="1.0" iyz="0.0" izz="1.0"/>
    </inertial>
  </link>
  <joint name="joint_3_9" type="prismatic">
    <parent link="table_base"/>
    <child link="link_3_9"/>
    <origin ryp="0 0 0" xyz="0.069 0.17099999999999999 0"/>
    <axis xyz="0 0 1"/>
    <limit effort="4" lower="0" upper="0.045" velocity="0.01"/>
  </joint>
  <link name="link_3_8">
    <visual>
      <geometry>
        <box size="0.016 0.016 0.055"/>
      </geometry>
      <origin rpy="0 0 0" xyz="0 0 -0.0275"/>
      <material name="blue">
        <color rgba="0 0 1 0.9"/>
      </material>
    </visual>
    <collision>
      <geometry>
        <box size="0.016 0.016 0.055"/>
      </geometry>
      <origin rpy="0 0 0" xyz="0 0 -0.0275"/>
    </collision>
    <inertial>
      <origin rpy="0 0 0" xyz="0 0 0"/>
      <mass value="0.5"/>
      <inertia ixx="1.0" ixy="0.0" ixz="0.0" iyy="1.0" iyz="0.0" izz="1.0"/>
    </inertial>
  </link>
  <joint name="joint_3_8" type="prismatic">
    <parent link="table_base"/>
    <child link="link_3_8"/>
    <origin ryp="0 0 0" xyz="0.069 0.15400000000000003 0"/>
    <axis xyz="0 0 1"/>
    <limit effort="4" lower="0" upper="0.045" velocity="0.01"/>
  </joint>
  <link name="link_3_7">
    <visual>
      <geometry>
        <box size="0.016 0.016 0.055"/>
      </geometry>
      <origin rpy="0 0 0" xyz="0 0 -0.0275"/>
      <material name="blue">
        <color rgba="0 0 1 0.9"/>
      </material>
    </visual>
    <collision>
      <geometry>
        <box size="0.016 0.016 0.055"/>
      </geometry>
      <origin rpy="0 0 0" xyz="0 0 -0.0275"/>
    </collision>
    <inertial>
      <origin rpy="0 0 0" xyz="0 0 0"/>
      <mass value="0.5"/>
      <inertia ixx="1.0" ixy="0.0" ixz="0.0" iyy="1.0" iyz="0.0" izz="1.0"/>
    </inertial>
  </link>
  <joint name="joint_3_7" type="prismatic">
    <parent link="table_base"/>
    <child link="link_3_7"/>
    <origin ryp="0 0 0" xyz="0.069 0.137 0"/>
    <axis xyz="0 0 1"/>
    <limit effort="4" lower="0" upper="0.045" velocity="0.01"/>
  </joint>
  <link name="link_3_6">
    <visual>
      <geometry>
        <box size="0.016 0.016 0.055"/>
      </geometry>
      <origin rpy="0 0 0" xyz="0 0 -0.0275"/>
      <material name="blue">
        <color rgba="0 0 1 0.9"/>
      </material>
    </visual>
    <collision>
      <geometry>
        <box size="0.016 0.016 0.055"/>
      </geometry>
      <origin rpy="0 0 0" xyz="0 0 -0.0275"/>
    </collision>
    <inertial>
      <origin rpy="0 0 0" xyz="0 0 0"/>
      <mass value="0.5"/>
      <inertia ixx="1.0" ixy="0.0" ixz="0.0" iyy="1.0" iyz="0.0" izz="1.0"/>
    </inertial>
  </link>
  <joint name="joint_3_6" type="prismatic">
    <parent link="table_base"/>
    <child link="link_3_6"/>
    <origin ryp="0 0 0" xyz="0.069 0.12000000000000001 0"/>
    <axis xyz="0 0 1"/>
    <limit effort="4" lower="0" upper="0.045" velocity="0.01"/>
  </joint>
  <link name="link_3_5">
    <visual>
      <geometry>
        <box size="0.016 0.016 0.055"/>
      </geometry>
      <origin rpy="0 0 0" xyz="0 0 -0.0275"/>
      <material name="blue">
        <color rgba="0 0 1 0.9"/>
      </material>
    </visual>
    <collision>
      <geometry>
        <box size="0.016 0.016 0.055"/>
      </geometry>
      <origin rpy="0 0 0" xyz="0 0 -0.0275"/>
    </collision>
    <inertial>
      <origin rpy="0 0 0" xyz="0 0 0"/>
      <mass value="0.5"/>
      <inertia ixx="1.0" ixy="0.0" ixz="0.0" iyy="1.0" iyz="0.0" izz="1.0"/>
    </inertial>
  </link>
  <joint name="joint_3_5" type="prismatic">
    <parent link="table_base"/>
    <child link="link_3_5"/>
    <origin ryp="0 0 0" xyz="0.069 0.103 0"/>
    <axis xyz="0 0 1"/>
    <limit effort="4" lower="0" upper="0.045" velocity="0.01"/>
  </joint>
  <link name="link_3_4">
    <visual>
      <geometry>
        <box size="0.016 0.016 0.055"/>
      </geometry>
      <origin rpy="0 0 0" xyz="0 0 -0.0275"/>
      <material name="blue">
        <color rgba="0 0 1 0.9"/>
      </material>
    </visual>
    <collision>
      <geometry>
        <box size="0.016 0.016 0.055"/>
      </geometry>
      <origin rpy="0 0 0" xyz="0 0 -0.0275"/>
    </collision>
    <inertial>
      <origin rpy="0 0 0" xyz="0 0 0"/>
      <mass value="0.5"/>
      <inertia ixx="1.0" ixy="0.0" ixz="0.0" iyy="1.0" iyz="0.0" izz="1.0"/>
    </inertial>
  </link>
  <joint name="joint_3_4" type="prismatic">
    <parent link="table_base"/>
    <child link="link_3_4"/>
    <origin ryp="0 0 0" xyz="0.069 0.08600000000000001 0"/>
    <axis xyz="0 0 1"/>
    <limit effort="4" lower="0" upper="0.045" velocity="0.01"/>
  </joint>
  <link name="link_3_3">
    <visual>
      <geometry>
        <box size="0.016 0.016 0.055"/>
      </geometry>
      <origin rpy="0 0 0" xyz="0 0 -0.0275"/>
      <material name="blue">
        <color rgba="0 0 1 0.9"/>
      </material>
    </visual>
    <collision>
      <geometry>
        <box size="0.016 0.016 0.055"/>
      </geometry>
      <origin rpy="0 0 0" xyz="0 0 -0.0275"/>
    </collision>
    <inertial>
      <origin rpy="0 0 0" xyz="0 0 0"/>
      <mass value="0.5"/>
      <inertia ixx="1.0" ixy="0.0" ixz="0.0" iyy="1.0" iyz="0.0" izz="1.0"/>
    </inertial>
  </link>
  <joint name="joint_3_3" type="prismatic">
    <parent link="table_base"/>
    <child link="link_3_3"/>
    <origin ryp="0 0 0" xyz="0.069 0.069 0"/>
    <axis xyz="0 0 1"/>
    <limit effort="4" lower="0" upper="0.045" velocity="0.01"/>
  </joint>
  <link name="link_3_2">
    <visual>
      <geometry>
        <box size="0.016 0.016 0.055"/>
      </geometry>
      <origin rpy="0 0 0" xyz="0 0 -0.0275"/>
      <material name="blue">
        <color rgba="0 0 1 0.9"/>
      </material>
    </visual>
    <collision>
      <geometry>
        <box size="0.016 0.016 0.055"/>
      </geometry>
      <origin rpy="0 0 0" xyz="0 0 -0.0275"/>
    </collision>
    <inertial>
      <origin rpy="0 0 0" xyz="0 0 0"/>
      <mass value="0.5"/>
      <inertia ixx="1.0" ixy="0.0" ixz="0.0" iyy="1.0" iyz="0.0" izz="1.0"/>
    </inertial>
  </link>
  <joint name="joint_3_2" type="prismatic">
    <parent link="table_base"/>
    <child link="link_3_2"/>
    <origin ryp="0 0 0" xyz="0.069 0.052000000000000005 0"/>
    <axis xyz="0 0 1"/>
    <limit effort="4" lower="0" upper="0.045" velocity="0.01"/>
  </joint>
  <link name="link_3_1">
    <visual>
      <geometry>
        <box size="0.016 0.016 0.055"/>
      </geometry>
      <origin rpy="0 0 0" xyz="0 0 -0.0275"/>
      <material name="blue">
        <color rgba="0 0 1 0.9"/>
      </material>
    </visual>
    <collision>
      <geometry>
        <box size="0.016 0.016 0.055"/>
      </geometry>
      <origin rpy="0 0 0" xyz="0 0 -0.0275"/>
    </collision>
    <inertial>
      <origin rpy="0 0 0" xyz="0 0 0"/>
      <mass value="0.5"/>
      <inertia ixx="1.0" ixy="0.0" ixz="0.0" iyy="1.0" iyz="0.0" izz="1.0"/>
    </inertial>
  </link>
  <joint name="joint_3_1" type="prismatic">
    <parent link="table_base"/>
    <child link="link_3_1"/>
    <origin ryp="0 0 0" xyz="0.069 0.035 0"/>
    <axis xyz="0 0 1"/>
    <limit effort="4" lower="0" upper="0.045" velocity="0.01"/>
  </joint>
  <link name="link_3_0">
    <visual>
      <geometry>
        <box size="0.016 0.016 0.055"/>
      </geometry>
      <origin rpy="0 0 0" xyz="0 0 -0.0275"/>
      <material name="blue">
        <color rgba="0 0 1 0.9"/>
      </material>
    </visual>
    <collision>
      <geometry>
        <box size="0.016 0.016 0.055"/>
      </geometry>
      <origin rpy="0 0 0" xyz="0 0 -0.0275"/>
    </collision>
    <inertial>
      <origin rpy="0 0 0" xyz="0 0 0"/>
      <mass value="0.5"/>
      <inertia ixx="1.0" ixy="0.0" ixz="0.0" iyy="1.0" iyz="0.0" izz="1.0"/>
    </inertial>
  </link>
  <joint name="joint_3_0" type="prismatic">
    <parent link="table_base"/>
    <child link="link_3_0"/>
    <origin ryp="0 0 0" xyz="0.069 0.018000000000000002 0"/>
    <axis xyz="0 0 1"/>
    <limit effort="4" lower="0" upper="0.045" velocity="0.01"/>
  </joint>
  <link name="link_2_11">
    <visual>
      <geometry>
        <box size="0.016 0.016 0.055"/>
      </geometry>
      <origin rpy="0 0 0" xyz="0 0 -0.0275"/>
      <material name="blue">
        <color rgba="0 0 1 0.9"/>
      </material>
    </visual>
    <collision>
      <geometry>
        <box size="0.016 0.016 0.055"/>
      </geometry>
      <origin rpy="0 0 0" xyz="0 0 -0.0275"/>
    </collision>
    <inertial>
      <origin rpy="0 0 0" xyz="0 0 0"/>
      <mass value="0.5"/>
      <inertia ixx="1.0" ixy="0.0" ixz="0.0" iyy="1.0" iyz="0.0" izz="1.0"/>
    </inertial>
  </link>
  <joint name="joint_2_11" type="prismatic">
    <parent link="table_base"/>
    <child link="link_2_11"/>
    <origin ryp="0 0 0" xyz="0.052000000000000005 0.205 0"/>
    <axis xyz="0 0 1"/>
    <limit effort="4" lower="0" upper="0.045" velocity="0.01"/>
  </joint>
  <link name="link_2_10">
    <visual>
      <geometry>
        <box size="0.016 0.016 0.055"/>
      </geometry>
      <origin rpy="0 0 0" xyz="0 0 -0.0275"/>
      <material name="blue">
        <color rgba="0 0 1 0.9"/>
      </material>
    </visual>
    <collision>
      <geometry>
        <box size="0.016 0.016 0.055"/>
      </geometry>
      <origin rpy="0 0 0" xyz="0 0 -0.0275"/>
    </collision>
    <inertial>
      <origin rpy="0 0 0" xyz="0 0 0"/>
      <mass value="0.5"/>
      <inertia ixx="1.0" ixy="0.0" ixz="0.0" iyy="1.0" iyz="0.0" izz="1.0"/>
    </inertial>
  </link>
  <joint name="joint_2_10" type="prismatic">
    <parent link="table_base"/>
    <child link="link_2_10"/>
    <origin ryp="0 0 0" xyz="0.052000000000000005 0.188 0"/>
    <axis xyz="0 0 1"/>
    <limit effort="4" lower="0" upper="0.045" velocity="0.01"/>
  </joint>
  <link name="link_2_9">
    <visual>
      <geometry>
        <box size="0.016 0.016 0.055"/>
      </geometry>
      <origin rpy="0 0 0" xyz="0 0 -0.0275"/>
      <material name="blue">
        <color rgba="0 0 1 0.9"/>
      </material>
    </visual>
    <collision>
      <geometry>
        <box size="0.016 0.016 0.055"/>
      </geometry>
      <origin rpy="0 0 0" xyz="0 0 -0.0275"/>
    </collision>
    <inertial>
      <origin rpy="0 0 0" xyz="0 0 0"/>
      <mass value="0.5"/>
      <inertia ixx="1.0" ixy="0.0" ixz="0.0" iyy="1.0" iyz="0.0" izz="1.0"/>
    </inertial>
  </link>
  <joint name="joint_2_9" type="prismatic">
    <parent link="table_base"/>
    <child link="link_2_9"/>
    <origin ryp="0 0 0" xyz="0.052000000000000005 0.17099999999999999 0"/>
    <axis xyz="0 0 1"/>
    <limit effort="4" lower="0" upper="0.045" velocity="0.01"/>
  </joint>
  <link name="link_2_8">
    <visual>
      <geometry>
        <box size="0.016 0.016 0.055"/>
      </geometry>
      <origin rpy="0 0 0" xyz="0 0 -0.0275"/>
      <material name="blue">
        <color rgba="0 0 1 0.9"/>
      </material>
    </visual>
    <collision>
      <geometry>
        <box size="0.016 0.016 0.055"/>
      </geometry>
      <origin rpy="0 0 0" xyz="0 0 -0.0275"/>
    </collision>
    <inertial>
      <origin rpy="0 0 0" xyz="0 0 0"/>
      <mass value="0.5"/>
      <inertia ixx="1.0" ixy="0.0" ixz="0.0" iyy="1.0" iyz="0.0" izz="1.0"/>
    </inertial>
  </link>
  <joint name="joint_2_8" type="prismatic">
    <parent link="table_base"/>
    <child link="link_2_8"/>
    <origin ryp="0 0 0" xyz="0.052000000000000005 0.15400000000000003 0"/>
    <axis xyz="0 0 1"/>
    <limit effort="4" lower="0" upper="0.045" velocity="0.01"/>
  </joint>
  <link name="link_2_7">
    <visual>
      <geometry>
        <box size="0.016 0.016 0.055"/>
      </geometry>
      <origin rpy="0 0 0" xyz="0 0 -0.0275"/>
      <material name="blue">
        <color rgba="0 0 1 0.9"/>
      </material>
    </visual>
    <collision>
      <geometry>
        <box size="0.016 0.016 0.055"/>
      </geometry>
      <origin rpy="0 0 0" xyz="0 0 -0.0275"/>
    </collision>
    <inertial>
      <origin rpy="0 0 0" xyz="0 0 0"/>
      <mass value="0.5"/>
      <inertia ixx="1.0" ixy="0.0" ixz="0.0" iyy="1.0" iyz="0.0" izz="1.0"/>
    </inertial>
  </link>
  <joint name="joint_2_7" type="prismatic">
    <parent link="table_base"/>
    <child link="link_2_7"/>
    <origin ryp="0 0 0" xyz="0.052000000000000005 0.137 0"/>
    <axis xyz="0 0 1"/>
    <limit effort="4" lower="0" upper="0.045" velocity="0.01"/>
  </joint>
  <link name="link_2_6">
    <visual>
      <geometry>
        <box size="0.016 0.016 0.055"/>
      </geometry>
      <origin rpy="0 0 0" xyz="0 0 -0.0275"/>
      <material name="blue">
        <color rgba="0 0 1 0.9"/>
      </material>
    </visual>
    <collision>
      <geometry>
        <box size="0.016 0.016 0.055"/>
      </geometry>
      <origin rpy="0 0 0" xyz="0 0 -0.0275"/>
    </collision>
    <inertial>
      <origin rpy="0 0 0" xyz="0 0 0"/>
      <mass value="0.5"/>
      <inertia ixx="1.0" ixy="0.0" ixz="0.0" iyy="1.0" iyz="0.0" izz="1.0"/>
    </inertial>
  </link>
  <joint name="joint_2_6" type="prismatic">
    <parent link="table_base"/>
    <child link="link_2_6"/>
    <origin ryp="0 0 0" xyz="0.052000000000000005 0.12000000000000001 0"/>
    <axis xyz="0 0 1"/>
    <limit effort="4" lower="0" upper="0.045" velocity="0.01"/>
  </joint>
  <link name="link_2_5">
    <visual>
      <geometry>
        <box size="0.016 0.016 0.055"/>
      </geometry>
      <origin rpy="0 0 0" xyz="0 0 -0.0275"/>
      <material name="blue">
        <color rgba="0 0 1 0.9"/>
      </material>
    </visual>
    <collision>
      <geometry>
        <box size="0.016 0.016 0.055"/>
      </geometry>
      <origin rpy="0 0 0" xyz="0 0 -0.0275"/>
    </collision>
    <inertial>
      <origin rpy="0 0 0" xyz="0 0 0"/>
      <mass value="0.5"/>
      <inertia ixx="1.0" ixy="0.0" ixz="0.0" iyy="1.0" iyz="0.0" izz="1.0"/>
    </inertial>
  </link>
  <joint name="joint_2_5" type="prismatic">
    <parent link="table_base"/>
    <child link="link_2_5"/>
    <origin ryp="0 0 0" xyz="0.052000000000000005 0.103 0"/>
    <axis xyz="0 0 1"/>
    <limit effort="4" lower="0" upper="0.045" velocity="0.01"/>
  </joint>
  <link name="link_2_4">
    <visual>
      <geometry>
        <box size="0.016 0.016 0.055"/>
      </geometry>
      <origin rpy="0 0 0" xyz="0 0 -0.0275"/>
      <material name="blue">
        <color rgba="0 0 1 0.9"/>
      </material>
    </visual>
    <collision>
      <geometry>
        <box size="0.016 0.016 0.055"/>
      </geometry>
      <origin rpy="0 0 0" xyz="0 0 -0.0275"/>
    </collision>
    <inertial>
      <origin rpy="0 0 0" xyz="0 0 0"/>
      <mass value="0.5"/>
      <inertia ixx="1.0" ixy="0.0" ixz="0.0" iyy="1.0" iyz="0.0" izz="1.0"/>
    </inertial>
  </link>
  <joint name="joint_2_4" type="prismatic">
    <parent link="table_base"/>
    <child link="link_2_4"/>
    <origin ryp="0 0 0" xyz="0.052000000000000005 0.08600000000000001 0"/>
    <axis xyz="0 0 1"/>
    <limit effort="4" lower="0" upper="0.045" velocity="0.01"/>
  </joint>
  <link name="link_2_3">
    <visual>
      <geometry>
        <box size="0.016 0.016 0.055"/>
      </geometry>
      <origin rpy="0 0 0" xyz="0 0 -0.0275"/>
      <material name="blue">
        <color rgba="0 0 1 0.9"/>
      </material>
    </visual>
    <collision>
      <geometry>
        <box size="0.016 0.016 0.055"/>
      </geometry>
      <origin rpy="0 0 0" xyz="0 0 -0.0275"/>
    </collision>
    <inertial>
      <origin rpy="0 0 0" xyz="0 0 0"/>
      <mass value="0.5"/>
      <inertia ixx="1.0" ixy="0.0" ixz="0.0" iyy="1.0" iyz="0.0" izz="1.0"/>
    </inertial>
  </link>
  <joint name="joint_2_3" type="prismatic">
    <parent link="table_base"/>
    <child link="link_2_3"/>
    <origin ryp="0 0 0" xyz="0.052000000000000005 0.069 0"/>
    <axis xyz="0 0 1"/>
    <limit effort="4" lower="0" upper="0.045" velocity="0.01"/>
  </joint>
  <link name="link_2_2">
    <visual>
      <geometry>
        <box size="0.016 0.016 0.055"/>
      </geometry>
      <origin rpy="0 0 0" xyz="0 0 -0.0275"/>
      <material name="blue">
        <color rgba="0 0 1 0.9"/>
      </material>
    </visual>
    <collision>
      <geometry>
        <box size="0.016 0.016 0.055"/>
      </geometry>
      <origin rpy="0 0 0" xyz="0 0 -0.0275"/>
    </collision>
    <inertial>
      <origin rpy="0 0 0" xyz="0 0 0"/>
      <mass value="0.5"/>
      <inertia ixx="1.0" ixy="0.0" ixz="0.0" iyy="1.0" iyz="0.0" izz="1.0"/>
    </inertial>
  </link>
  <joint name="joint_2_2" type="prismatic">
    <parent link="table_base"/>
    <child link="link_2_2"/>
    <origin ryp="0 0 0" xyz="0.052000000000000005 0.052000000000000005 0"/>
    <axis xyz="0 0 1"/>
    <limit effort="4" lower="0" upper="0.045" velocity="0.01"/>
  </joint>
  <link name="link_2_1">
    <visual>
      <geometry>
        <box size="0.016 0.016 0.055"/>
      </geometry>
      <origin rpy="0 0 0" xyz="0 0 -0.0275"/>
      <material name="blue">
        <color rgba="0 0 1 0.9"/>
      </material>
    </visual>
    <collision>
      <geometry>
        <box size="0.016 0.016 0.055"/>
      </geometry>
      <origin rpy="0 0 0" xyz="0 0 -0.0275"/>
    </collision>
    <inertial>
      <origin rpy="0 0 0" xyz="0 0 0"/>
      <mass value="0.5"/>
      <inertia ixx="1.0" ixy="0.0" ixz="0.0" iyy="1.0" iyz="0.0" izz="1.0"/>
    </inertial>
  </link>
  <joint name="joint_2_1" type="prismatic">
    <parent link="table_base"/>
    <child link="link_2_1"/>
    <origin ryp="0 0 0" xyz="0.052000000000000005 0.035 0"/>
    <axis xyz="0 0 1"/>
    <limit effort="4" lower="0" upper="0.045" velocity="0.01"/>
  </joint>
  <link name="link_2_0">
    <visual>
      <geometry>
        <box size="0.016 0.016 0.055"/>
      </geometry>
      <origin rpy="0 0 0" xyz="0 0 -0.0275"/>
      <material name="blue">
        <color rgba="0 0 1 0.9"/>
      </material>
    </visual>
    <collision>
      <geometry>
        <box size="0.016 0.016 0.055"/>
      </geometry>
      <origin rpy="0 0 0" xyz="0 0 -0.0275"/>
    </collision>
    <inertial>
      <origin rpy="0 0 0" xyz="0 0 0"/>
      <mass value="0.5"/>
      <inertia ixx="1.0" ixy="0.0" ixz="0.0" iyy="1.0" iyz="0.0" izz="1.0"/>
    </inertial>
  </link>
  <joint name="joint_2_0" type="prismatic">
    <parent link="table_base"/>
    <child link="link_2_0"/>
    <origin ryp="0 0 0" xyz="0.052000000000000005 0.018000000000000002 0"/>
    <axis xyz="0 0 1"/>
    <limit effort="4" lower="0" upper="0.045" velocity="0.01"/>
  </joint>
  <link name="link_1_11">
    <visual>
      <geometry>
        <box size="0.016 0.016 0.055"/>
      </geometry>
      <origin rpy="0 0 0" xyz="0 0 -0.0275"/>
      <material name="blue">
        <color rgba="0 0 1 0.9"/>
      </material>
    </visual>
    <collision>
      <geometry>
        <box size="0.016 0.016 0.055"/>
      </geometry>
      <origin rpy="0 0 0" xyz="0 0 -0.0275"/>
    </collision>
    <inertial>
      <origin rpy="0 0 0" xyz="0 0 0"/>
      <mass value="0.5"/>
      <inertia ixx="1.0" ixy="0.0" ixz="0.0" iyy="1.0" iyz="0.0" izz="1.0"/>
    </inertial>
  </link>
  <joint name="joint_1_11" type="prismatic">
    <parent link="table_base"/>
    <child link="link_1_11"/>
    <origin ryp="0 0 0" xyz="0.035 0.205 0"/>
    <axis xyz="0 0 1"/>
    <limit effort="4" lower="0" upper="0.045" velocity="0.01"/>
  </joint>
  <link name="link_1_10">
    <visual>
      <geometry>
        <box size="0.016 0.016 0.055"/>
      </geometry>
      <origin rpy="0 0 0" xyz="0 0 -0.0275"/>
      <material name="blue">
        <color rgba="0 0 1 0.9"/>
      </material>
    </visual>
    <collision>
      <geometry>
        <box size="0.016 0.016 0.055"/>
      </geometry>
      <origin rpy="0 0 0" xyz="0 0 -0.0275"/>
    </collision>
    <inertial>
      <origin rpy="0 0 0" xyz="0 0 0"/>
      <mass value="0.5"/>
      <inertia ixx="1.0" ixy="0.0" ixz="0.0" iyy="1.0" iyz="0.0" izz="1.0"/>
    </inertial>
  </link>
  <joint name="joint_1_10" type="prismatic">
    <parent link="table_base"/>
    <child link="link_1_10"/>
    <origin ryp="0 0 0" xyz="0.035 0.188 0"/>
    <axis xyz="0 0 1"/>
    <limit effort="4" lower="0" upper="0.045" velocity="0.01"/>
  </joint>
  <link name="link_1_9">
    <visual>
      <geometry>
        <box size="0.016 0.016 0.055"/>
      </geometry>
      <origin rpy="0 0 0" xyz="0 0 -0.0275"/>
      <material name="blue">
        <color rgba="0 0 1 0.9"/>
      </material>
    </visual>
    <collision>
      <geometry>
        <box size="0.016 0.016 0.055"/>
      </geometry>
      <origin rpy="0 0 0" xyz="0 0 -0.0275"/>
    </collision>
    <inertial>
      <origin rpy="0 0 0" xyz="0 0 0"/>
      <mass value="0.5"/>
      <inertia ixx="1.0" ixy="0.0" ixz="0.0" iyy="1.0" iyz="0.0" izz="1.0"/>
    </inertial>
  </link>
  <joint name="joint_1_9" type="prismatic">
    <parent link="table_base"/>
    <child link="link_1_9"/>
    <origin ryp="0 0 0" xyz="0.035 0.17099999999999999 0"/>
    <axis xyz="0 0 1"/>
    <limit effort="4" lower="0" upper="0.045" velocity="0.01"/>
  </joint>
  <link name="link_1_8">
    <visual>
      <geometry>
        <box size="0.016 0.016 0.055"/>
      </geometry>
      <origin rpy="0 0 0" xyz="0 0 -0.0275"/>
      <material name="blue">
        <color rgba="0 0 1 0.9"/>
      </material>
    </visual>
    <collision>
      <geometry>
        <box size="0.016 0.016 0.055"/>
      </geometry>
      <origin rpy="0 0 0" xyz="0 0 -0.0275"/>
    </collision>
    <inertial>
      <origin rpy="0 0 0" xyz="0 0 0"/>
      <mass value="0.5"/>
      <inertia ixx="1.0" ixy="0.0" ixz="0.0" iyy="1.0" iyz="0.0" izz="1.0"/>
    </inertial>
  </link>
  <joint name="joint_1_8" type="prismatic">
    <parent link="table_base"/>
    <child link="link_1_8"/>
    <origin ryp="0 0 0" xyz="0.035 0.15400000000000003 0"/>
    <axis xyz="0 0 1"/>
    <limit effort="4" lower="0" upper="0.045" velocity="0.01"/>
  </joint>
  <link name="link_1_7">
    <visual>
      <geometry>
        <box size="0.016 0.016 0.055"/>
      </geometry>
      <origin rpy="0 0 0" xyz="0 0 -0.0275"/>
      <material name="blue">
        <color rgba="0 0 1 0.9"/>
      </material>
    </visual>
    <collision>
      <geometry>
        <box size="0.016 0.016 0.055"/>
      </geometry>
      <origin rpy="0 0 0" xyz="0 0 -0.0275"/>
    </collision>
    <inertial>
      <origin rpy="0 0 0" xyz="0 0 0"/>
      <mass value="0.5"/>
      <inertia ixx="1.0" ixy="0.0" ixz="0.0" iyy="1.0" iyz="0.0" izz="1.0"/>
    </inertial>
  </link>
  <joint name="joint_1_7" type="prismatic">
    <parent link="table_base"/>
    <child link="link_1_7"/>
    <origin ryp="0 0 0" xyz="0.035 0.137 0"/>
    <axis xyz="0 0 1"/>
    <limit effort="4" lower="0" upper="0.045" velocity="0.01"/>
  </joint>
  <link name="link_1_6">
    <visual>
      <geometry>
        <box size="0.016 0.016 0.055"/>
      </geometry>
      <origin rpy="0 0 0" xyz="0 0 -0.0275"/>
      <material name="blue">
        <color rgba="0 0 1 0.9"/>
      </material>
    </visual>
    <collision>
      <geometry>
        <box size="0.016 0.016 0.055"/>
      </geometry>
      <origin rpy="0 0 0" xyz="0 0 -0.0275"/>
    </collision>
    <inertial>
      <origin rpy="0 0 0" xyz="0 0 0"/>
      <mass value="0.5"/>
      <inertia ixx="1.0" ixy="0.0" ixz="0.0" iyy="1.0" iyz="0.0" izz="1.0"/>
    </inertial>
  </link>
  <joint name="joint_1_6" type="prismatic">
    <parent link="table_base"/>
    <child link="link_1_6"/>
    <origin ryp="0 0 0" xyz="0.035 0.12000000000000001 0"/>
    <axis xyz="0 0 1"/>
    <limit effort="4" lower="0" upper="0.045" velocity="0.01"/>
  </joint>
  <link name="link_1_5">
    <visual>
      <geometry>
        <box size="0.016 0.016 0.055"/>
      </geometry>
      <origin rpy="0 0 0" xyz="0 0 -0.0275"/>
      <material name="blue">
        <color rgba="0 0 1 0.9"/>
      </material>
    </visual>
    <collision>
      <geometry>
        <box size="0.016 0.016 0.055"/>
      </geometry>
      <origin rpy="0 0 0" xyz="0 0 -0.0275"/>
    </collision>
    <inertial>
      <origin rpy="0 0 0" xyz="0 0 0"/>
      <mass value="0.5"/>
      <inertia ixx="1.0" ixy="0.0" ixz="0.0" iyy="1.0" iyz="0.0" izz="1.0"/>
    </inertial>
  </link>
  <joint name="joint_1_5" type="prismatic">
    <parent link="table_base"/>
    <child link="link_1_5"/>
    <origin ryp="0 0 0" xyz="0.035 0.103 0"/>
    <axis xyz="0 0 1"/>
    <limit effort="4" lower="0" upper="0.045" velocity="0.01"/>
  </joint>
  <link name="link_1_4">
    <visual>
      <geometry>
        <box size="0.016 0.016 0.055"/>
      </geometry>
      <origin rpy="0 0 0" xyz="0 0 -0.0275"/>
      <material name="blue">
        <color rgba="0 0 1 0.9"/>
      </material>
    </visual>
    <collision>
      <geometry>
        <box size="0.016 0.016 0.055"/>
      </geometry>
      <origin rpy="0 0 0" xyz="0 0 -0.0275"/>
    </collision>
    <inertial>
      <origin rpy="0 0 0" xyz="0 0 0"/>
      <mass value="0.5"/>
      <inertia ixx="1.0" ixy="0.0" ixz="0.0" iyy="1.0" iyz="0.0" izz="1.0"/>
    </inertial>
  </link>
  <joint name="joint_1_4" type="prismatic">
    <parent link="table_base"/>
    <child link="link_1_4"/>
    <origin ryp="0 0 0" xyz="0.035 0.08600000000000001 0"/>
    <axis xyz="0 0 1"/>
    <limit effort="4" lower="0" upper="0.045" velocity="0.01"/>
  </joint>
  <link name="link_1_3">
    <visual>
      <geometry>
        <box size="0.016 0.016 0.055"/>
      </geometry>
      <origin rpy="0 0 0" xyz="0 0 -0.0275"/>
      <material name="blue">
        <color rgba="0 0 1 0.9"/>
      </material>
    </visual>
    <collision>
      <geometry>
        <box size="0.016 0.016 0.055"/>
      </geometry>
      <origin rpy="0 0 0" xyz="0 0 -0.0275"/>
    </collision>
    <inertial>
      <origin rpy="0 0 0" xyz="0 0 0"/>
      <mass value="0.5"/>
      <inertia ixx="1.0" ixy="0.0" ixz="0.0" iyy="1.0" iyz="0.0" izz="1.0"/>
    </inertial>
  </link>
  <joint name="joint_1_3" type="prismatic">
    <parent link="table_base"/>
    <child link="link_1_3"/>
    <origin ryp="0 0 0" xyz="0.035 0.069 0"/>
    <axis xyz="0 0 1"/>
    <limit effort="4" lower="0" upper="0.045" velocity="0.01"/>
  </joint>
  <link name="link_1_2">
    <visual>
      <geometry>
        <box size="0.016 0.016 0.055"/>
      </geometry>
      <origin rpy="0 0 0" xyz="0 0 -0.0275"/>
      <material name="blue">
        <color rgba="0 0 1 0.9"/>
      </material>
    </visual>
    <collision>
      <geometry>
        <box size="0.016 0.016 0.055"/>
      </geometry>
      <origin rpy="0 0 0" xyz="0 0 -0.0275"/>
    </collision>
    <inertial>
      <origin rpy="0 0 0" xyz="0 0 0"/>
      <mass value="0.5"/>
      <inertia ixx="1.0" ixy="0.0" ixz="0.0" iyy="1.0" iyz="0.0" izz="1.0"/>
    </inertial>
  </link>
  <joint name="joint_1_2" type="prismatic">
    <parent link="table_base"/>
    <child link="link_1_2"/>
    <origin ryp="0 0 0" xyz="0.035 0.052000000000000005 0"/>
    <axis xyz="0 0 1"/>
    <limit effort="4" lower="0" upper="0.045" velocity="0.01"/>
  </joint>
  <link name="link_1_1">
    <visual>
      <geometry>
        <box size="0.016 0.016 0.055"/>
      </geometry>
      <origin rpy="0 0 0" xyz="0 0 -0.0275"/>
      <material name="blue">
        <color rgba="0 0 1 0.9"/>
      </material>
    </visual>
    <collision>
      <geometry>
        <box size="0.016 0.016 0.055"/>
      </geometry>
      <origin rpy="0 0 0" xyz="0 0 -0.0275"/>
    </collision>
    <inertial>
      <origin rpy="0 0 0" xyz="0 0 0"/>
      <mass value="0.5"/>
      <inertia ixx="1.0" ixy="0.0" ixz="0.0" iyy="1.0" iyz="0.0" izz="1.0"/>
    </inertial>
  </link>
  <joint name="joint_1_1" type="prismatic">
    <parent link="table_base"/>
    <child link="link_1_1"/>
    <origin ryp="0 0 0" xyz="0.035 0.035 0"/>
    <axis xyz="0 0 1"/>
    <limit effort="4" lower="0" upper="0.045" velocity="0.01"/>
  </joint>
  <link name="link_1_0">
    <visual>
      <geometry>
        <box size="0.016 0.016 0.055"/>
      </geometry>
      <origin rpy="0 0 0" xyz="0 0 -0.0275"/>
      <material name="blue">
        <color rgba="0 0 1 0.9"/>
      </material>
    </visual>
    <collision>
      <geometry>
        <box size="0.016 0.016 0.055"/>
      </geometry>
      <origin rpy="0 0 0" xyz="0 0 -0.0275"/>
    </collision>
    <inertial>
      <origin rpy="0 0 0" xyz="0 0 0"/>
      <mass value="0.5"/>
      <inertia ixx="1.0" ixy="0.0" ixz="0.0" iyy="1.0" iyz="0.0" izz="1.0"/>
    </inertial>
  </link>
  <joint name="joint_1_0" type="prismatic">
    <parent link="table_base"/>
    <child link="link_1_0"/>
    <origin ryp="0 0 0" xyz="0.035 0.018000000000000002 0"/>
    <axis xyz="0 0 1"/>
    <limit effort="4" lower="0" upper="0.045" velocity="0.01"/>
  </joint>
  <link name="link_0_11">
    <visual>
      <geometry>
        <box size="0.016 0.016 0.055"/>
      </geometry>
      <origin rpy="0 0 0" xyz="0 0 -0.0275"/>
      <material name="blue">
        <color rgba="0 0 1 0.9"/>
      </material>
    </visual>
    <collision>
      <geometry>
        <box size="0.016 0.016 0.055"/>
      </geometry>
      <origin rpy="0 0 0" xyz="0 0 -0.0275"/>
    </collision>
    <inertial>
      <origin rpy="0 0 0" xyz="0 0 0"/>
      <mass value="0.5"/>
      <inertia ixx="1.0" ixy="0.0" ixz="0.0" iyy="1.0" iyz="0.0" izz="1.0"/>
    </inertial>
  </link>
  <joint name="joint_0_11" type="prismatic">
    <parent link="table_base"/>
    <child link="link_0_11"/>
    <origin ryp="0 0 0" xyz="0.018000000000000002 0.205 0"/>
    <axis xyz="0 0 1"/>
    <limit effort="4" lower="0" upper="0.045" velocity="0.01"/>
  </joint>
  <link name="link_0_10">
    <visual>
      <geometry>
        <box size="0.016 0.016 0.055"/>
      </geometry>
      <origin rpy="0 0 0" xyz="0 0 -0.0275"/>
      <material name="blue">
        <color rgba="0 0 1 0.9"/>
      </material>
    </visual>
    <collision>
      <geometry>
        <box size="0.016 0.016 0.055"/>
      </geometry>
      <origin rpy="0 0 0" xyz="0 0 -0.0275"/>
    </collision>
    <inertial>
      <origin rpy="0 0 0" xyz="0 0 0"/>
      <mass value="0.5"/>
      <inertia ixx="1.0" ixy="0.0" ixz="0.0" iyy="1.0" iyz="0.0" izz="1.0"/>
    </inertial>
  </link>
  <joint name="joint_0_10" type="prismatic">
    <parent link="table_base"/>
    <child link="link_0_10"/>
    <origin ryp="0 0 0" xyz="0.018000000000000002 0.188 0"/>
    <axis xyz="0 0 1"/>
    <limit effort="4" lower="0" upper="0.045" velocity="0.01"/>
  </joint>
  <link name="link_0_9">
    <visual>
      <geometry>
        <box size="0.016 0.016 0.055"/>
      </geometry>
      <origin rpy="0 0 0" xyz="0 0 -0.0275"/>
      <material name="blue">
        <color rgba="0 0 1 0.9"/>
      </material>
    </visual>
    <collision>
      <geometry>
        <box size="0.016 0.016 0.055"/>
      </geometry>
      <origin rpy="0 0 0" xyz="0 0 -0.0275"/>
    </collision>
    <inertial>
      <origin rpy="0 0 0" xyz="0 0 0"/>
      <mass value="0.5"/>
      <inertia ixx="1.0" ixy="0.0" ixz="0.0" iyy="1.0" iyz="0.0" izz="1.0"/>
    </inertial>
  </link>
  <joint name="joint_0_9" type="prismatic">
    <parent link="table_base"/>
    <child link="link_0_9"/>
    <origin ryp="0 0 0" xyz="0.018000000000000002 0.17099999999999999 0"/>
    <axis xyz="0 0 1"/>
    <limit effort="4" lower="0" upper="0.045" velocity="0.01"/>
  </joint>
  <link name="link_0_8">
    <visual>
      <geometry>
        <box size="0.016 0.016 0.055"/>
      </geometry>
      <origin rpy="0 0 0" xyz="0 0 -0.0275"/>
      <material name="blue">
        <color rgba="0 0 1 0.9"/>
      </material>
    </visual>
    <collision>
      <geometry>
        <box size="0.016 0.016 0.055"/>
      </geometry>
      <origin rpy="0 0 0" xyz="0 0 -0.0275"/>
    </collision>
    <inertial>
      <origin rpy="0 0 0" xyz="0 0 0"/>
      <mass value="0.5"/>
      <inertia ixx="1.0" ixy="0.0" ixz="0.0" iyy="1.0" iyz="0.0" izz="1.0"/>
    </inertial>
  </link>
  <joint name="joint_0_8" type="prismatic">
    <parent link="table_base"/>
    <child link="link_0_8"/>
    <origin ryp="0 0 0" xyz="0.018000000000000002 0.15400000000000003 0"/>
    <axis xyz="0 0 1"/>
    <limit effort="4" lower="0" upper="0.045" velocity="0.01"/>
  </joint>
  <link name="link_0_7">
    <visual>
      <geometry>
        <box size="0.016 0.016 0.055"/>
      </geometry>
      <origin rpy="0 0 0" xyz="0 0 -0.0275"/>
      <material name="blue">
        <color rgba="0 0 1 0.9"/>
      </material>
    </visual>
    <collision>
      <geometry>
        <box size="0.016 0.016 0.055"/>
      </geometry>
      <origin rpy="0 0 0" xyz="0 0 -0.0275"/>
    </collision>
    <inertial>
      <origin rpy="0 0 0" xyz="0 0 0"/>
      <mass value="0.5"/>
      <inertia ixx="1.0" ixy="0.0" ixz="0.0" iyy="1.0" iyz="0.0" izz="1.0"/>
    </inertial>
  </link>
  <joint name="joint_0_7" type="prismatic">
    <parent link="table_base"/>
    <child link="link_0_7"/>
    <origin ryp="0 0 0" xyz="0.018000000000000002 0.137 0"/>
    <axis xyz="0 0 1"/>
    <limit effort="4" lower="0" upper="0.045" velocity="0.01"/>
  </joint>
  <link name="link_0_6">
    <visual>
      <geometry>
        <box size="0.016 0.016 0.055"/>
      </geometry>
      <origin rpy="0 0 0" xyz="0 0 -0.0275"/>
      <material name="blue">
        <color rgba="0 0 1 0.9"/>
      </material>
    </visual>
    <collision>
      <geometry>
        <box size="0.016 0.016 0.055"/>
      </geometry>
      <origin rpy="0 0 0" xyz="0 0 -0.0275"/>
    </collision>
    <inertial>
      <origin rpy="0 0 0" xyz="0 0 0"/>
      <mass value="0.5"/>
      <inertia ixx="1.0" ixy="0.0" ixz="0.0" iyy="1.0" iyz="0.0" izz="1.0"/>
    </inertial>
  </link>
  <joint name="joint_0_6" type="prismatic">
    <parent link="table_base"/>
    <child link="link_0_6"/>
    <origin ryp="0 0 0" xyz="0.018000000000000002 0.12000000000000001 0"/>
    <axis xyz="0 0 1"/>
    <limit effort="4" lower="0" upper="0.045" velocity="0.01"/>
  </joint>
  <link name="link_0_5">
    <visual>
      <geometry>
        <box size="0.016 0.016 0.055"/>
      </geometry>
      <origin rpy="0 0 0" xyz="0 0 -0.0275"/>
      <material name="blue">
        <color rgba="0 0 1 0.9"/>
      </material>
    </visual>
    <collision>
      <geometry>
        <box size="0.016 0.016 0.055"/>
      </geometry>
      <origin rpy="0 0 0" xyz="0 0 -0.0275"/>
    </collision>
    <inertial>
      <origin rpy="0 0 0" xyz="0 0 0"/>
      <mass value="0.5"/>
      <inertia ixx="1.0" ixy="0.0" ixz="0.0" iyy="1.0" iyz="0.0" izz="1.0"/>
    </inertial>
  </link>
  <joint name="joint_0_5" type="prismatic">
    <parent link="table_base"/>
    <child link="link_0_5"/>
    <origin ryp="0 0 0" xyz="0.018000000000000002 0.103 0"/>
    <axis xyz="0 0 1"/>
    <limit effort="4" lower="0" upper="0.045" velocity="0.01"/>
  </joint>
  <link name="link_0_4">
    <visual>
      <geometry>
        <box size="0.016 0.016 0.055"/>
      </geometry>
      <origin rpy="0 0 0" xyz="0 0 -0.0275"/>
      <material name="blue">
        <color rgba="0 0 1 0.9"/>
      </material>
    </visual>
    <collision>
      <geometry>
        <box size="0.016 0.016 0.055"/>
      </geometry>
      <origin rpy="0 0 0" xyz="0 0 -0.0275"/>
    </collision>
    <inertial>
      <origin rpy="0 0 0" xyz="0 0 0"/>
      <mass value="0.5"/>
      <inertia ixx="1.0" ixy="0.0" ixz="0.0" iyy="1.0" iyz="0.0" izz="1.0"/>
    </inertial>
  </link>
  <joint name="joint_0_4" type="prismatic">
    <parent link="table_base"/>
    <child link="link_0_4"/>
    <origin ryp="0 0 0" xyz="0.018000000000000002 0.08600000000000001 0"/>
    <axis xyz="0 0 1"/>
    <limit effort="4" lower="0" upper="0.045" velocity="0.01"/>
  </joint>
  <link name="link_0_3">
    <visual>
      <geometry>
        <box size="0.016 0.016 0.055"/>
      </geometry>
      <origin rpy="0 0 0" xyz="0 0 -0.0275"/>
      <material name="blue">
        <color rgba="0 0 1 0.9"/>
      </material>
    </visual>
    <collision>
      <geometry>
        <box size="0.016 0.016 0.055"/>
      </geometry>
      <origin rpy="0 0 0" xyz="0 0 -0.0275"/>
    </collision>
    <inertial>
      <origin rpy="0 0 0" xyz="0 0 0"/>
      <mass value="0.5"/>
      <inertia ixx="1.0" ixy="0.0" ixz="0.0" iyy="1.0" iyz="0.0" izz="1.0"/>
    </inertial>
  </link>
  <joint name="joint_0_3" type="prismatic">
    <parent link="table_base"/>
    <child link="link_0_3"/>
    <origin ryp="0 0 0" xyz="0.018000000000000002 0.069 0"/>
    <axis xyz="0 0 1"/>
    <limit effort="4" lower="0" upper="0.045" velocity="0.01"/>
  </joint>
  <link name="link_0_2">
    <visual>
      <geometry>
        <box size="0.016 0.016 0.055"/>
      </geometry>
      <origin rpy="0 0 0" xyz="0 0 -0.0275"/>
      <material name="blue">
        <color rgba="0 0 1 0.9"/>
      </material>
    </visual>
    <collision>
      <geometry>
        <box size="0.016 0.016 0.055"/>
      </geometry>
      <origin rpy="0 0 0" xyz="0 0 -0.0275"/>
    </collision>
    <inertial>
      <origin rpy="0 0 0" xyz="0 0 0"/>
      <mass value="0.5"/>
      <inertia ixx="1.0" ixy="0.0" ixz="0.0" iyy="1.0" iyz="0.0" izz="1.0"/>
    </inertial>
  </link>
  <joint name="joint_0_2" type="prismatic">
    <parent link="table_base"/>
    <child link="link_0_2"/>
    <origin ryp="0 0 0" xyz="0.018000000000000002 0.052000000000000005 0"/>
    <axis xyz="0 0 1"/>
    <limit effort="4" lower="0" upper="0.045" velocity="0.01"/>
  </joint>
  <link name="link_0_1">
    <visual>
      <geometry>
        <box size="0.016 0.016 0.055"/>
      </geometry>
      <origin rpy="0 0 0" xyz="0 0 -0.0275"/>
      <material name="blue">
        <color rgba="0 0 1 0.9"/>
      </material>
    </visual>
    <collision>
      <geometry>
        <box size="0.016 0.016 0.055"/>
      </geometry>
      <origin rpy="0 0 0" xyz="0 0 -0.0275"/>
    </collision>
    <inertial>
      <origin rpy="0 0 0" xyz="0 0 0"/>
      <mass value="0.5"/>
      <inertia ixx="1.0" ixy="0.0" ixz="0.0" iyy="1.0" iyz="0.0" izz="1.0"/>
    </inertial>
  </link>
  <joint name="joint_0_1" type="prismatic">
    <parent link="table_base"/>
    <child link="link_0_1"/>
    <origin ryp="0 0 0" xyz="0.018000000000000002 0.035 0"/>
    <axis xyz="0 0 1"/>
    <limit effort="4" lower="0" upper="0.045" velocity="0.01"/>
  </joint>
  <link name="link_0_0">
    <visual>
      <geometry>
        <box size="0.016 0.016 0.055"/>
      </geometry>
      <origin rpy="0 0 0" xyz="0 0 -0.0275"/>
      <material name="blue">
        <color rgba="0 0 1 0.9"/>
      </material>
    </visual>
    <collision>
      <geometry>
        <box size="0.016 0.016 0.055"/>
      </geometry>
      <origin rpy="0 0 0" xyz="0 0 -0.0275"/>
    </collision>
    <inertial>
      <origin rpy="0 0 0" xyz="0 0 0"/>
      <mass value="0.5"/>
      <inertia ixx="1.0" ixy="0.0" ixz="0.0" iyy="1.0" iyz="0.0" izz="1.0"/>
    </inertial>
  </link>
  <joint name="joint_0_0" type="prismatic">
    <parent link="table_base"/>
    <child link="link_0_0"/>
    <origin ryp="0 0 0" xyz="0.018000000000000002 0.018000000000000002 0"/>
    <axis xyz="0 0 1"/>
    <limit effort="4" lower="0" upper="0.045" velocity="0.01"/>
  </joint>
</robot>

