<?xml version="1.0" ?>
<!-- =================================================================================== -->
<!-- |    This document was autogenerated by xacro from tablebot_row.xacro             | -->
<!-- |    EDITING THIS FILE BY HAND IS NOT RECOMMENDED                                 | -->
<!-- =================================================================================== -->
<robot name="tablebot">
  <!-- <link name="footprint">
      <visual>
        <geometry>
          <sphere radius="0.0001" />
        </geometry>
      </visual>
    </link> -->
  <link name="table_base">
    <visual>
      <geometry>
        <!-- <box size="${tab_size} ${tab_size} ${tab_height}"/> -->
        <box size="0.0001 0.0001 0.0001"/>
      </geometry>
      <!-- <origin xyz="${tab_size / 2} ${tab_size / 2} ${-tab_height / 2}" rpy="0 0 0"/> -->
      <origin rpy="0 0 0" xyz="0 0 0"/>
      <material name="black">
        <color rgba="1 1 1 0.5"/>
      </material>
      <inertial>
        <origin rpy="0 0 0" xyz="0 0 0"/>
        <mass value="10"/>
        <inertia ixx="1.0" ixy="0.0" ixz="0.0" iyy="1.0" iyz="0.0" izz="1.0"/>
      </inertial>
    </visual>
  </link>
  <!-- <joint name="base2footprint" type="fixed">
      <parent link="footprint" />
      <child link="table_base" />
      <origin xyz="0 0 ${tab_height / 2 }" />
    </joint> -->
  <!-- <xacro:macro name="loop" params="links_qty">
        <xacro:if value="${links_qty}">
            <xacro:loop links_qty="${links_qty-1}" />
        </xacro:if>
    </xacro:macro> -->
  <link name="link_10_25">
    <visual>
      <geometry>
        <box size="0.016 0.016 0.055"/>
      </geometry>
      <origin rpy="0 0 0" xyz="0 0 -0.0275"/>
      <material name="blue0">
        <color rgba="0 0 1 0.9"/>
      </material>
    </visual>
    <collision>
      <geometry>
        <box size="0.016 0.016 0.055"/>
      </geometry>
      <origin rpy="0 0 0" xyz="0 0 -0.0275"/>
    </collision>
    <inertial>
      <origin rpy="0 0 0" xyz="0 0 0"/>
      <mass value="0.5"/>
      <inertia ixx="1.0" ixy="0.0" ixz="0.0" iyy="1.0" iyz="0.0" izz="1.0"/>
    </inertial>
  </link>
  <joint name="joint_10_25" type="prismatic">
    <parent link="table_base"/>
    <child link="link_10_25"/>
    <origin ryp="0 0 0" xyz="0.018000000000000002 0.318 0"/>
    <axis xyz="0 0 1"/>
    <limit effort="4" lower="0" upper="0.045" velocity="0.05"/>
  </joint>
  <link name="cylinder_10_25">
    <visual>
      <geometry>
        <cylinder length="0.01" radius="0.009"/>
      </geometry>
      <origin rpy="0 0 0" xyz="0 0 -0.005"/>
      <material name="blue1">
        <color rgba="0 0 1 0.6"/>
      </material>
    </visual>
    <collision>
      <geometry>
        <cylinder length="0.01" radius="0.009"/>
      </geometry>
      <origin rpy="0 0 0" xyz="0 0 -0.005"/>
    </collision>
    <inertial>
      <origin rpy="0 0 0" xyz="0 0 0"/>
      <mass value="0.05"/>
      <inertia ixx="1.0" ixy="0.0" ixz="0.0" iyy="1.0" iyz="0.0" izz="1.0"/>
    </inertial>
  </link>
  <joint name="cylinder2base_10_25" type="fixed">
    <parent link="link_10_25"/>
    <child link="cylinder_10_25"/>
    <origin ryp="0 0 0" xyz="0 0 0.01"/>
  </joint>
  <link name="sphere_10_25">
    <visual>
      <geometry>
        <sphere radius="0.009"/>
      </geometry>
      <origin rpy="0 0 0" xyz="0 0 0"/>
      <material name="blue1">
        <color rgba="0 0 1 0.6"/>
      </material>
    </visual>
    <collision>
      <geometry>
        <sphere radius="0.009"/>
      </geometry>
      <origin rpy="0 0 0" xyz="0 0 0"/>
    </collision>
    <inertial>
      <origin rpy="0 0 0" xyz="0 0 0"/>
      <mass value="0.05"/>
      <inertia ixx="1.0" ixy="0.0" ixz="0.0" iyy="1.0" iyz="0.0" izz="1.0"/>
    </inertial>
  </link>
  <joint name="sphere2cylinder_10_25" type="fixed">
    <parent link="cylinder_10_25"/>
    <child link="sphere_10_25"/>
    <origin ryp="0 0 0" xyz="0 0 0"/>
  </joint>
  <link name="link_10_24">
    <visual>
      <geometry>
        <box size="0.016 0.016 0.055"/>
      </geometry>
      <origin rpy="0 0 0" xyz="0 0 -0.0275"/>
      <material name="blue0">
        <color rgba="0 0 1 0.9"/>
      </material>
    </visual>
    <collision>
      <geometry>
        <box size="0.016 0.016 0.055"/>
      </geometry>
      <origin rpy="0 0 0" xyz="0 0 -0.0275"/>
    </collision>
    <inertial>
      <origin rpy="0 0 0" xyz="0 0 0"/>
      <mass value="0.5"/>
      <inertia ixx="1.0" ixy="0.0" ixz="0.0" iyy="1.0" iyz="0.0" izz="1.0"/>
    </inertial>
  </link>
  <joint name="joint_10_24" type="prismatic">
    <parent link="table_base"/>
    <child link="link_10_24"/>
    <origin ryp="0 0 0" xyz="0.018000000000000002 0.29800000000000004 0"/>
    <axis xyz="0 0 1"/>
    <limit effort="4" lower="0" upper="0.045" velocity="0.05"/>
  </joint>
  <link name="cylinder_10_24">
    <visual>
      <geometry>
        <cylinder length="0.01" radius="0.009"/>
      </geometry>
      <origin rpy="0 0 0" xyz="0 0 -0.005"/>
      <material name="blue1">
        <color rgba="0 0 1 0.6"/>
      </material>
    </visual>
    <collision>
      <geometry>
        <cylinder length="0.01" radius="0.009"/>
      </geometry>
      <origin rpy="0 0 0" xyz="0 0 -0.005"/>
    </collision>
    <inertial>
      <origin rpy="0 0 0" xyz="0 0 0"/>
      <mass value="0.05"/>
      <inertia ixx="1.0" ixy="0.0" ixz="0.0" iyy="1.0" iyz="0.0" izz="1.0"/>
    </inertial>
  </link>
  <joint name="cylinder2base_10_24" type="fixed">
    <parent link="link_10_24"/>
    <child link="cylinder_10_24"/>
    <origin ryp="0 0 0" xyz="0 0 0.01"/>
  </joint>
  <link name="sphere_10_24">
    <visual>
      <geometry>
        <sphere radius="0.009"/>
      </geometry>
      <origin rpy="0 0 0" xyz="0 0 0"/>
      <material name="blue1">
        <color rgba="0 0 1 0.6"/>
      </material>
    </visual>
    <collision>
      <geometry>
        <sphere radius="0.009"/>
      </geometry>
      <origin rpy="0 0 0" xyz="0 0 0"/>
    </collision>
    <inertial>
      <origin rpy="0 0 0" xyz="0 0 0"/>
      <mass value="0.05"/>
      <inertia ixx="1.0" ixy="0.0" ixz="0.0" iyy="1.0" iyz="0.0" izz="1.0"/>
    </inertial>
  </link>
  <joint name="sphere2cylinder_10_24" type="fixed">
    <parent link="cylinder_10_24"/>
    <child link="sphere_10_24"/>
    <origin ryp="0 0 0" xyz="0 0 0"/>
  </joint>
  <link name="link_10_23">
    <visual>
      <geometry>
        <box size="0.016 0.016 0.055"/>
      </geometry>
      <origin rpy="0 0 0" xyz="0 0 -0.0275"/>
      <material name="blue0">
        <color rgba="0 0 1 0.9"/>
      </material>
    </visual>
    <collision>
      <geometry>
        <box size="0.016 0.016 0.055"/>
      </geometry>
      <origin rpy="0 0 0" xyz="0 0 -0.0275"/>
    </collision>
    <inertial>
      <origin rpy="0 0 0" xyz="0 0 0"/>
      <mass value="0.5"/>
      <inertia ixx="1.0" ixy="0.0" ixz="0.0" iyy="1.0" iyz="0.0" izz="1.0"/>
    </inertial>
  </link>
  <joint name="joint_10_23" type="prismatic">
    <parent link="table_base"/>
    <child link="link_10_23"/>
    <origin ryp="0 0 0" xyz="0.018000000000000002 0.278 0"/>
    <axis xyz="0 0 1"/>
    <limit effort="4" lower="0" upper="0.045" velocity="0.05"/>
  </joint>
  <link name="cylinder_10_23">
    <visual>
      <geometry>
        <cylinder length="0.01" radius="0.009"/>
      </geometry>
      <origin rpy="0 0 0" xyz="0 0 -0.005"/>
      <material name="blue1">
        <color rgba="0 0 1 0.6"/>
      </material>
    </visual>
    <collision>
      <geometry>
        <cylinder length="0.01" radius="0.009"/>
      </geometry>
      <origin rpy="0 0 0" xyz="0 0 -0.005"/>
    </collision>
    <inertial>
      <origin rpy="0 0 0" xyz="0 0 0"/>
      <mass value="0.05"/>
      <inertia ixx="1.0" ixy="0.0" ixz="0.0" iyy="1.0" iyz="0.0" izz="1.0"/>
    </inertial>
  </link>
  <joint name="cylinder2base_10_23" type="fixed">
    <parent link="link_10_23"/>
    <child link="cylinder_10_23"/>
    <origin ryp="0 0 0" xyz="0 0 0.01"/>
  </joint>
  <link name="sphere_10_23">
    <visual>
      <geometry>
        <sphere radius="0.009"/>
      </geometry>
      <origin rpy="0 0 0" xyz="0 0 0"/>
      <material name="blue1">
        <color rgba="0 0 1 0.6"/>
      </material>
    </visual>
    <collision>
      <geometry>
        <sphere radius="0.009"/>
      </geometry>
      <origin rpy="0 0 0" xyz="0 0 0"/>
    </collision>
    <inertial>
      <origin rpy="0 0 0" xyz="0 0 0"/>
      <mass value="0.05"/>
      <inertia ixx="1.0" ixy="0.0" ixz="0.0" iyy="1.0" iyz="0.0" izz="1.0"/>
    </inertial>
  </link>
  <joint name="sphere2cylinder_10_23" type="fixed">
    <parent link="cylinder_10_23"/>
    <child link="sphere_10_23"/>
    <origin ryp="0 0 0" xyz="0 0 0"/>
  </joint>
  <link name="link_10_22">
    <visual>
      <geometry>
        <box size="0.016 0.016 0.055"/>
      </geometry>
      <origin rpy="0 0 0" xyz="0 0 -0.0275"/>
      <material name="blue0">
        <color rgba="0 0 1 0.9"/>
      </material>
    </visual>
    <collision>
      <geometry>
        <box size="0.016 0.016 0.055"/>
      </geometry>
      <origin rpy="0 0 0" xyz="0 0 -0.0275"/>
    </collision>
    <inertial>
      <origin rpy="0 0 0" xyz="0 0 0"/>
      <mass value="0.5"/>
      <inertia ixx="1.0" ixy="0.0" ixz="0.0" iyy="1.0" iyz="0.0" izz="1.0"/>
    </inertial>
  </link>
  <joint name="joint_10_22" type="prismatic">
    <parent link="table_base"/>
    <child link="link_10_22"/>
    <origin ryp="0 0 0" xyz="0.018000000000000002 0.258 0"/>
    <axis xyz="0 0 1"/>
    <limit effort="4" lower="0" upper="0.045" velocity="0.05"/>
  </joint>
  <link name="cylinder_10_22">
    <visual>
      <geometry>
        <cylinder length="0.01" radius="0.009"/>
      </geometry>
      <origin rpy="0 0 0" xyz="0 0 -0.005"/>
      <material name="blue1">
        <color rgba="0 0 1 0.6"/>
      </material>
    </visual>
    <collision>
      <geometry>
        <cylinder length="0.01" radius="0.009"/>
      </geometry>
      <origin rpy="0 0 0" xyz="0 0 -0.005"/>
    </collision>
    <inertial>
      <origin rpy="0 0 0" xyz="0 0 0"/>
      <mass value="0.05"/>
      <inertia ixx="1.0" ixy="0.0" ixz="0.0" iyy="1.0" iyz="0.0" izz="1.0"/>
    </inertial>
  </link>
  <joint name="cylinder2base_10_22" type="fixed">
    <parent link="link_10_22"/>
    <child link="cylinder_10_22"/>
    <origin ryp="0 0 0" xyz="0 0 0.01"/>
  </joint>
  <link name="sphere_10_22">
    <visual>
      <geometry>
        <sphere radius="0.009"/>
      </geometry>
      <origin rpy="0 0 0" xyz="0 0 0"/>
      <material name="blue1">
        <color rgba="0 0 1 0.6"/>
      </material>
    </visual>
    <collision>
      <geometry>
        <sphere radius="0.009"/>
      </geometry>
      <origin rpy="0 0 0" xyz="0 0 0"/>
    </collision>
    <inertial>
      <origin rpy="0 0 0" xyz="0 0 0"/>
      <mass value="0.05"/>
      <inertia ixx="1.0" ixy="0.0" ixz="0.0" iyy="1.0" iyz="0.0" izz="1.0"/>
    </inertial>
  </link>
  <joint name="sphere2cylinder_10_22" type="fixed">
    <parent link="cylinder_10_22"/>
    <child link="sphere_10_22"/>
    <origin ryp="0 0 0" xyz="0 0 0"/>
  </joint>
  <link name="link_10_21">
    <visual>
      <geometry>
        <box size="0.016 0.016 0.055"/>
      </geometry>
      <origin rpy="0 0 0" xyz="0 0 -0.0275"/>
      <material name="blue0">
        <color rgba="0 0 1 0.9"/>
      </material>
    </visual>
    <collision>
      <geometry>
        <box size="0.016 0.016 0.055"/>
      </geometry>
      <origin rpy="0 0 0" xyz="0 0 -0.0275"/>
    </collision>
    <inertial>
      <origin rpy="0 0 0" xyz="0 0 0"/>
      <mass value="0.5"/>
      <inertia ixx="1.0" ixy="0.0" ixz="0.0" iyy="1.0" iyz="0.0" izz="1.0"/>
    </inertial>
  </link>
  <joint name="joint_10_21" type="prismatic">
    <parent link="table_base"/>
    <child link="link_10_21"/>
    <origin ryp="0 0 0" xyz="0.018000000000000002 0.238 0"/>
    <axis xyz="0 0 1"/>
    <limit effort="4" lower="0" upper="0.045" velocity="0.05"/>
  </joint>
  <link name="cylinder_10_21">
    <visual>
      <geometry>
        <cylinder length="0.01" radius="0.009"/>
      </geometry>
      <origin rpy="0 0 0" xyz="0 0 -0.005"/>
      <material name="blue1">
        <color rgba="0 0 1 0.6"/>
      </material>
    </visual>
    <collision>
      <geometry>
        <cylinder length="0.01" radius="0.009"/>
      </geometry>
      <origin rpy="0 0 0" xyz="0 0 -0.005"/>
    </collision>
    <inertial>
      <origin rpy="0 0 0" xyz="0 0 0"/>
      <mass value="0.05"/>
      <inertia ixx="1.0" ixy="0.0" ixz="0.0" iyy="1.0" iyz="0.0" izz="1.0"/>
    </inertial>
  </link>
  <joint name="cylinder2base_10_21" type="fixed">
    <parent link="link_10_21"/>
    <child link="cylinder_10_21"/>
    <origin ryp="0 0 0" xyz="0 0 0.01"/>
  </joint>
  <link name="sphere_10_21">
    <visual>
      <geometry>
        <sphere radius="0.009"/>
      </geometry>
      <origin rpy="0 0 0" xyz="0 0 0"/>
      <material name="blue1">
        <color rgba="0 0 1 0.6"/>
      </material>
    </visual>
    <collision>
      <geometry>
        <sphere radius="0.009"/>
      </geometry>
      <origin rpy="0 0 0" xyz="0 0 0"/>
    </collision>
    <inertial>
      <origin rpy="0 0 0" xyz="0 0 0"/>
      <mass value="0.05"/>
      <inertia ixx="1.0" ixy="0.0" ixz="0.0" iyy="1.0" iyz="0.0" izz="1.0"/>
    </inertial>
  </link>
  <joint name="sphere2cylinder_10_21" type="fixed">
    <parent link="cylinder_10_21"/>
    <child link="sphere_10_21"/>
    <origin ryp="0 0 0" xyz="0 0 0"/>
  </joint>
  <link name="link_10_20">
    <visual>
      <geometry>
        <box size="0.016 0.016 0.055"/>
      </geometry>
      <origin rpy="0 0 0" xyz="0 0 -0.0275"/>
      <material name="blue0">
        <color rgba="0 0 1 0.9"/>
      </material>
    </visual>
    <collision>
      <geometry>
        <box size="0.016 0.016 0.055"/>
      </geometry>
      <origin rpy="0 0 0" xyz="0 0 -0.0275"/>
    </collision>
    <inertial>
      <origin rpy="0 0 0" xyz="0 0 0"/>
      <mass value="0.5"/>
      <inertia ixx="1.0" ixy="0.0" ixz="0.0" iyy="1.0" iyz="0.0" izz="1.0"/>
    </inertial>
  </link>
  <joint name="joint_10_20" type="prismatic">
    <parent link="table_base"/>
    <child link="link_10_20"/>
    <origin ryp="0 0 0" xyz="0.018000000000000002 0.21800000000000003 0"/>
    <axis xyz="0 0 1"/>
    <limit effort="4" lower="0" upper="0.045" velocity="0.05"/>
  </joint>
  <link name="cylinder_10_20">
    <visual>
      <geometry>
        <cylinder length="0.01" radius="0.009"/>
      </geometry>
      <origin rpy="0 0 0" xyz="0 0 -0.005"/>
      <material name="blue1">
        <color rgba="0 0 1 0.6"/>
      </material>
    </visual>
    <collision>
      <geometry>
        <cylinder length="0.01" radius="0.009"/>
      </geometry>
      <origin rpy="0 0 0" xyz="0 0 -0.005"/>
    </collision>
    <inertial>
      <origin rpy="0 0 0" xyz="0 0 0"/>
      <mass value="0.05"/>
      <inertia ixx="1.0" ixy="0.0" ixz="0.0" iyy="1.0" iyz="0.0" izz="1.0"/>
    </inertial>
  </link>
  <joint name="cylinder2base_10_20" type="fixed">
    <parent link="link_10_20"/>
    <child link="cylinder_10_20"/>
    <origin ryp="0 0 0" xyz="0 0 0.01"/>
  </joint>
  <link name="sphere_10_20">
    <visual>
      <geometry>
        <sphere radius="0.009"/>
      </geometry>
      <origin rpy="0 0 0" xyz="0 0 0"/>
      <material name="blue1">
        <color rgba="0 0 1 0.6"/>
      </material>
    </visual>
    <collision>
      <geometry>
        <sphere radius="0.009"/>
      </geometry>
      <origin rpy="0 0 0" xyz="0 0 0"/>
    </collision>
    <inertial>
      <origin rpy="0 0 0" xyz="0 0 0"/>
      <mass value="0.05"/>
      <inertia ixx="1.0" ixy="0.0" ixz="0.0" iyy="1.0" iyz="0.0" izz="1.0"/>
    </inertial>
  </link>
  <joint name="sphere2cylinder_10_20" type="fixed">
    <parent link="cylinder_10_20"/>
    <child link="sphere_10_20"/>
    <origin ryp="0 0 0" xyz="0 0 0"/>
  </joint>
  <link name="link_10_19">
    <visual>
      <geometry>
        <box size="0.016 0.016 0.055"/>
      </geometry>
      <origin rpy="0 0 0" xyz="0 0 -0.0275"/>
      <material name="blue0">
        <color rgba="0 0 1 0.9"/>
      </material>
    </visual>
    <collision>
      <geometry>
        <box size="0.016 0.016 0.055"/>
      </geometry>
      <origin rpy="0 0 0" xyz="0 0 -0.0275"/>
    </collision>
    <inertial>
      <origin rpy="0 0 0" xyz="0 0 0"/>
      <mass value="0.5"/>
      <inertia ixx="1.0" ixy="0.0" ixz="0.0" iyy="1.0" iyz="0.0" izz="1.0"/>
    </inertial>
  </link>
  <joint name="joint_10_19" type="prismatic">
    <parent link="table_base"/>
    <child link="link_10_19"/>
    <origin ryp="0 0 0" xyz="0.018000000000000002 0.198 0"/>
    <axis xyz="0 0 1"/>
    <limit effort="4" lower="0" upper="0.045" velocity="0.05"/>
  </joint>
  <link name="cylinder_10_19">
    <visual>
      <geometry>
        <cylinder length="0.01" radius="0.009"/>
      </geometry>
      <origin rpy="0 0 0" xyz="0 0 -0.005"/>
      <material name="blue1">
        <color rgba="0 0 1 0.6"/>
      </material>
    </visual>
    <collision>
      <geometry>
        <cylinder length="0.01" radius="0.009"/>
      </geometry>
      <origin rpy="0 0 0" xyz="0 0 -0.005"/>
    </collision>
    <inertial>
      <origin rpy="0 0 0" xyz="0 0 0"/>
      <mass value="0.05"/>
      <inertia ixx="1.0" ixy="0.0" ixz="0.0" iyy="1.0" iyz="0.0" izz="1.0"/>
    </inertial>
  </link>
  <joint name="cylinder2base_10_19" type="fixed">
    <parent link="link_10_19"/>
    <child link="cylinder_10_19"/>
    <origin ryp="0 0 0" xyz="0 0 0.01"/>
  </joint>
  <link name="sphere_10_19">
    <visual>
      <geometry>
        <sphere radius="0.009"/>
      </geometry>
      <origin rpy="0 0 0" xyz="0 0 0"/>
      <material name="blue1">
        <color rgba="0 0 1 0.6"/>
      </material>
    </visual>
    <collision>
      <geometry>
        <sphere radius="0.009"/>
      </geometry>
      <origin rpy="0 0 0" xyz="0 0 0"/>
    </collision>
    <inertial>
      <origin rpy="0 0 0" xyz="0 0 0"/>
      <mass value="0.05"/>
      <inertia ixx="1.0" ixy="0.0" ixz="0.0" iyy="1.0" iyz="0.0" izz="1.0"/>
    </inertial>
  </link>
  <joint name="sphere2cylinder_10_19" type="fixed">
    <parent link="cylinder_10_19"/>
    <child link="sphere_10_19"/>
    <origin ryp="0 0 0" xyz="0 0 0"/>
  </joint>
  <link name="link_10_18">
    <visual>
      <geometry>
        <box size="0.016 0.016 0.055"/>
      </geometry>
      <origin rpy="0 0 0" xyz="0 0 -0.0275"/>
      <material name="blue0">
        <color rgba="0 0 1 0.9"/>
      </material>
    </visual>
    <collision>
      <geometry>
        <box size="0.016 0.016 0.055"/>
      </geometry>
      <origin rpy="0 0 0" xyz="0 0 -0.0275"/>
    </collision>
    <inertial>
      <origin rpy="0 0 0" xyz="0 0 0"/>
      <mass value="0.5"/>
      <inertia ixx="1.0" ixy="0.0" ixz="0.0" iyy="1.0" iyz="0.0" izz="1.0"/>
    </inertial>
  </link>
  <joint name="joint_10_18" type="prismatic">
    <parent link="table_base"/>
    <child link="link_10_18"/>
    <origin ryp="0 0 0" xyz="0.018000000000000002 0.17800000000000002 0"/>
    <axis xyz="0 0 1"/>
    <limit effort="4" lower="0" upper="0.045" velocity="0.05"/>
  </joint>
  <link name="cylinder_10_18">
    <visual>
      <geometry>
        <cylinder length="0.01" radius="0.009"/>
      </geometry>
      <origin rpy="0 0 0" xyz="0 0 -0.005"/>
      <material name="blue1">
        <color rgba="0 0 1 0.6"/>
      </material>
    </visual>
    <collision>
      <geometry>
        <cylinder length="0.01" radius="0.009"/>
      </geometry>
      <origin rpy="0 0 0" xyz="0 0 -0.005"/>
    </collision>
    <inertial>
      <origin rpy="0 0 0" xyz="0 0 0"/>
      <mass value="0.05"/>
      <inertia ixx="1.0" ixy="0.0" ixz="0.0" iyy="1.0" iyz="0.0" izz="1.0"/>
    </inertial>
  </link>
  <joint name="cylinder2base_10_18" type="fixed">
    <parent link="link_10_18"/>
    <child link="cylinder_10_18"/>
    <origin ryp="0 0 0" xyz="0 0 0.01"/>
  </joint>
  <link name="sphere_10_18">
    <visual>
      <geometry>
        <sphere radius="0.009"/>
      </geometry>
      <origin rpy="0 0 0" xyz="0 0 0"/>
      <material name="blue1">
        <color rgba="0 0 1 0.6"/>
      </material>
    </visual>
    <collision>
      <geometry>
        <sphere radius="0.009"/>
      </geometry>
      <origin rpy="0 0 0" xyz="0 0 0"/>
    </collision>
    <inertial>
      <origin rpy="0 0 0" xyz="0 0 0"/>
      <mass value="0.05"/>
      <inertia ixx="1.0" ixy="0.0" ixz="0.0" iyy="1.0" iyz="0.0" izz="1.0"/>
    </inertial>
  </link>
  <joint name="sphere2cylinder_10_18" type="fixed">
    <parent link="cylinder_10_18"/>
    <child link="sphere_10_18"/>
    <origin ryp="0 0 0" xyz="0 0 0"/>
  </joint>
  <link name="link_10_17">
    <visual>
      <geometry>
        <box size="0.016 0.016 0.055"/>
      </geometry>
      <origin rpy="0 0 0" xyz="0 0 -0.0275"/>
      <material name="blue0">
        <color rgba="0 0 1 0.9"/>
      </material>
    </visual>
    <collision>
      <geometry>
        <box size="0.016 0.016 0.055"/>
      </geometry>
      <origin rpy="0 0 0" xyz="0 0 -0.0275"/>
    </collision>
    <inertial>
      <origin rpy="0 0 0" xyz="0 0 0"/>
      <mass value="0.5"/>
      <inertia ixx="1.0" ixy="0.0" ixz="0.0" iyy="1.0" iyz="0.0" izz="1.0"/>
    </inertial>
  </link>
  <joint name="joint_10_17" type="prismatic">
    <parent link="table_base"/>
    <child link="link_10_17"/>
    <origin ryp="0 0 0" xyz="0.018000000000000002 0.158 0"/>
    <axis xyz="0 0 1"/>
    <limit effort="4" lower="0" upper="0.045" velocity="0.05"/>
  </joint>
  <link name="cylinder_10_17">
    <visual>
      <geometry>
        <cylinder length="0.01" radius="0.009"/>
      </geometry>
      <origin rpy="0 0 0" xyz="0 0 -0.005"/>
      <material name="blue1">
        <color rgba="0 0 1 0.6"/>
      </material>
    </visual>
    <collision>
      <geometry>
        <cylinder length="0.01" radius="0.009"/>
      </geometry>
      <origin rpy="0 0 0" xyz="0 0 -0.005"/>
    </collision>
    <inertial>
      <origin rpy="0 0 0" xyz="0 0 0"/>
      <mass value="0.05"/>
      <inertia ixx="1.0" ixy="0.0" ixz="0.0" iyy="1.0" iyz="0.0" izz="1.0"/>
    </inertial>
  </link>
  <joint name="cylinder2base_10_17" type="fixed">
    <parent link="link_10_17"/>
    <child link="cylinder_10_17"/>
    <origin ryp="0 0 0" xyz="0 0 0.01"/>
  </joint>
  <link name="sphere_10_17">
    <visual>
      <geometry>
        <sphere radius="0.009"/>
      </geometry>
      <origin rpy="0 0 0" xyz="0 0 0"/>
      <material name="blue1">
        <color rgba="0 0 1 0.6"/>
      </material>
    </visual>
    <collision>
      <geometry>
        <sphere radius="0.009"/>
      </geometry>
      <origin rpy="0 0 0" xyz="0 0 0"/>
    </collision>
    <inertial>
      <origin rpy="0 0 0" xyz="0 0 0"/>
      <mass value="0.05"/>
      <inertia ixx="1.0" ixy="0.0" ixz="0.0" iyy="1.0" iyz="0.0" izz="1.0"/>
    </inertial>
  </link>
  <joint name="sphere2cylinder_10_17" type="fixed">
    <parent link="cylinder_10_17"/>
    <child link="sphere_10_17"/>
    <origin ryp="0 0 0" xyz="0 0 0"/>
  </joint>
  <link name="link_10_16">
    <visual>
      <geometry>
        <box size="0.016 0.016 0.055"/>
      </geometry>
      <origin rpy="0 0 0" xyz="0 0 -0.0275"/>
      <material name="blue0">
        <color rgba="0 0 1 0.9"/>
      </material>
    </visual>
    <collision>
      <geometry>
        <box size="0.016 0.016 0.055"/>
      </geometry>
      <origin rpy="0 0 0" xyz="0 0 -0.0275"/>
    </collision>
    <inertial>
      <origin rpy="0 0 0" xyz="0 0 0"/>
      <mass value="0.5"/>
      <inertia ixx="1.0" ixy="0.0" ixz="0.0" iyy="1.0" iyz="0.0" izz="1.0"/>
    </inertial>
  </link>
  <joint name="joint_10_16" type="prismatic">
    <parent link="table_base"/>
    <child link="link_10_16"/>
    <origin ryp="0 0 0" xyz="0.018000000000000002 0.138 0"/>
    <axis xyz="0 0 1"/>
    <limit effort="4" lower="0" upper="0.045" velocity="0.05"/>
  </joint>
  <link name="cylinder_10_16">
    <visual>
      <geometry>
        <cylinder length="0.01" radius="0.009"/>
      </geometry>
      <origin rpy="0 0 0" xyz="0 0 -0.005"/>
      <material name="blue1">
        <color rgba="0 0 1 0.6"/>
      </material>
    </visual>
    <collision>
      <geometry>
        <cylinder length="0.01" radius="0.009"/>
      </geometry>
      <origin rpy="0 0 0" xyz="0 0 -0.005"/>
    </collision>
    <inertial>
      <origin rpy="0 0 0" xyz="0 0 0"/>
      <mass value="0.05"/>
      <inertia ixx="1.0" ixy="0.0" ixz="0.0" iyy="1.0" iyz="0.0" izz="1.0"/>
    </inertial>
  </link>
  <joint name="cylinder2base_10_16" type="fixed">
    <parent link="link_10_16"/>
    <child link="cylinder_10_16"/>
    <origin ryp="0 0 0" xyz="0 0 0.01"/>
  </joint>
  <link name="sphere_10_16">
    <visual>
      <geometry>
        <sphere radius="0.009"/>
      </geometry>
      <origin rpy="0 0 0" xyz="0 0 0"/>
      <material name="blue1">
        <color rgba="0 0 1 0.6"/>
      </material>
    </visual>
    <collision>
      <geometry>
        <sphere radius="0.009"/>
      </geometry>
      <origin rpy="0 0 0" xyz="0 0 0"/>
    </collision>
    <inertial>
      <origin rpy="0 0 0" xyz="0 0 0"/>
      <mass value="0.05"/>
      <inertia ixx="1.0" ixy="0.0" ixz="0.0" iyy="1.0" iyz="0.0" izz="1.0"/>
    </inertial>
  </link>
  <joint name="sphere2cylinder_10_16" type="fixed">
    <parent link="cylinder_10_16"/>
    <child link="sphere_10_16"/>
    <origin ryp="0 0 0" xyz="0 0 0"/>
  </joint>
  <link name="link_10_15">
    <visual>
      <geometry>
        <box size="0.016 0.016 0.055"/>
      </geometry>
      <origin rpy="0 0 0" xyz="0 0 -0.0275"/>
      <material name="blue0">
        <color rgba="0 0 1 0.9"/>
      </material>
    </visual>
    <collision>
      <geometry>
        <box size="0.016 0.016 0.055"/>
      </geometry>
      <origin rpy="0 0 0" xyz="0 0 -0.0275"/>
    </collision>
    <inertial>
      <origin rpy="0 0 0" xyz="0 0 0"/>
      <mass value="0.5"/>
      <inertia ixx="1.0" ixy="0.0" ixz="0.0" iyy="1.0" iyz="0.0" izz="1.0"/>
    </inertial>
  </link>
  <joint name="joint_10_15" type="prismatic">
    <parent link="table_base"/>
    <child link="link_10_15"/>
    <origin ryp="0 0 0" xyz="0.018000000000000002 0.118 0"/>
    <axis xyz="0 0 1"/>
    <limit effort="4" lower="0" upper="0.045" velocity="0.05"/>
  </joint>
  <link name="cylinder_10_15">
    <visual>
      <geometry>
        <cylinder length="0.01" radius="0.009"/>
      </geometry>
      <origin rpy="0 0 0" xyz="0 0 -0.005"/>
      <material name="blue1">
        <color rgba="0 0 1 0.6"/>
      </material>
    </visual>
    <collision>
      <geometry>
        <cylinder length="0.01" radius="0.009"/>
      </geometry>
      <origin rpy="0 0 0" xyz="0 0 -0.005"/>
    </collision>
    <inertial>
      <origin rpy="0 0 0" xyz="0 0 0"/>
      <mass value="0.05"/>
      <inertia ixx="1.0" ixy="0.0" ixz="0.0" iyy="1.0" iyz="0.0" izz="1.0"/>
    </inertial>
  </link>
  <joint name="cylinder2base_10_15" type="fixed">
    <parent link="link_10_15"/>
    <child link="cylinder_10_15"/>
    <origin ryp="0 0 0" xyz="0 0 0.01"/>
  </joint>
  <link name="sphere_10_15">
    <visual>
      <geometry>
        <sphere radius="0.009"/>
      </geometry>
      <origin rpy="0 0 0" xyz="0 0 0"/>
      <material name="blue1">
        <color rgba="0 0 1 0.6"/>
      </material>
    </visual>
    <collision>
      <geometry>
        <sphere radius="0.009"/>
      </geometry>
      <origin rpy="0 0 0" xyz="0 0 0"/>
    </collision>
    <inertial>
      <origin rpy="0 0 0" xyz="0 0 0"/>
      <mass value="0.05"/>
      <inertia ixx="1.0" ixy="0.0" ixz="0.0" iyy="1.0" iyz="0.0" izz="1.0"/>
    </inertial>
  </link>
  <joint name="sphere2cylinder_10_15" type="fixed">
    <parent link="cylinder_10_15"/>
    <child link="sphere_10_15"/>
    <origin ryp="0 0 0" xyz="0 0 0"/>
  </joint>
  <link name="link_10_14">
    <visual>
      <geometry>
        <box size="0.016 0.016 0.055"/>
      </geometry>
      <origin rpy="0 0 0" xyz="0 0 -0.0275"/>
      <material name="blue0">
        <color rgba="0 0 1 0.9"/>
      </material>
    </visual>
    <collision>
      <geometry>
        <box size="0.016 0.016 0.055"/>
      </geometry>
      <origin rpy="0 0 0" xyz="0 0 -0.0275"/>
    </collision>
    <inertial>
      <origin rpy="0 0 0" xyz="0 0 0"/>
      <mass value="0.5"/>
      <inertia ixx="1.0" ixy="0.0" ixz="0.0" iyy="1.0" iyz="0.0" izz="1.0"/>
    </inertial>
  </link>
  <joint name="joint_10_14" type="prismatic">
    <parent link="table_base"/>
    <child link="link_10_14"/>
    <origin ryp="0 0 0" xyz="0.018000000000000002 0.098 0"/>
    <axis xyz="0 0 1"/>
    <limit effort="4" lower="0" upper="0.045" velocity="0.05"/>
  </joint>
  <link name="cylinder_10_14">
    <visual>
      <geometry>
        <cylinder length="0.01" radius="0.009"/>
      </geometry>
      <origin rpy="0 0 0" xyz="0 0 -0.005"/>
      <material name="blue1">
        <color rgba="0 0 1 0.6"/>
      </material>
    </visual>
    <collision>
      <geometry>
        <cylinder length="0.01" radius="0.009"/>
      </geometry>
      <origin rpy="0 0 0" xyz="0 0 -0.005"/>
    </collision>
    <inertial>
      <origin rpy="0 0 0" xyz="0 0 0"/>
      <mass value="0.05"/>
      <inertia ixx="1.0" ixy="0.0" ixz="0.0" iyy="1.0" iyz="0.0" izz="1.0"/>
    </inertial>
  </link>
  <joint name="cylinder2base_10_14" type="fixed">
    <parent link="link_10_14"/>
    <child link="cylinder_10_14"/>
    <origin ryp="0 0 0" xyz="0 0 0.01"/>
  </joint>
  <link name="sphere_10_14">
    <visual>
      <geometry>
        <sphere radius="0.009"/>
      </geometry>
      <origin rpy="0 0 0" xyz="0 0 0"/>
      <material name="blue1">
        <color rgba="0 0 1 0.6"/>
      </material>
    </visual>
    <collision>
      <geometry>
        <sphere radius="0.009"/>
      </geometry>
      <origin rpy="0 0 0" xyz="0 0 0"/>
    </collision>
    <inertial>
      <origin rpy="0 0 0" xyz="0 0 0"/>
      <mass value="0.05"/>
      <inertia ixx="1.0" ixy="0.0" ixz="0.0" iyy="1.0" iyz="0.0" izz="1.0"/>
    </inertial>
  </link>
  <joint name="sphere2cylinder_10_14" type="fixed">
    <parent link="cylinder_10_14"/>
    <child link="sphere_10_14"/>
    <origin ryp="0 0 0" xyz="0 0 0"/>
  </joint>
  <link name="link_10_13">
    <visual>
      <geometry>
        <box size="0.016 0.016 0.055"/>
      </geometry>
      <origin rpy="0 0 0" xyz="0 0 -0.0275"/>
      <material name="blue0">
        <color rgba="0 0 1 0.9"/>
      </material>
    </visual>
    <collision>
      <geometry>
        <box size="0.016 0.016 0.055"/>
      </geometry>
      <origin rpy="0 0 0" xyz="0 0 -0.0275"/>
    </collision>
    <inertial>
      <origin rpy="0 0 0" xyz="0 0 0"/>
      <mass value="0.5"/>
      <inertia ixx="1.0" ixy="0.0" ixz="0.0" iyy="1.0" iyz="0.0" izz="1.0"/>
    </inertial>
  </link>
  <joint name="joint_10_13" type="prismatic">
    <parent link="table_base"/>
    <child link="link_10_13"/>
    <origin ryp="0 0 0" xyz="0.018000000000000002 0.078 0"/>
    <axis xyz="0 0 1"/>
    <limit effort="4" lower="0" upper="0.045" velocity="0.05"/>
  </joint>
  <link name="cylinder_10_13">
    <visual>
      <geometry>
        <cylinder length="0.01" radius="0.009"/>
      </geometry>
      <origin rpy="0 0 0" xyz="0 0 -0.005"/>
      <material name="blue1">
        <color rgba="0 0 1 0.6"/>
      </material>
    </visual>
    <collision>
      <geometry>
        <cylinder length="0.01" radius="0.009"/>
      </geometry>
      <origin rpy="0 0 0" xyz="0 0 -0.005"/>
    </collision>
    <inertial>
      <origin rpy="0 0 0" xyz="0 0 0"/>
      <mass value="0.05"/>
      <inertia ixx="1.0" ixy="0.0" ixz="0.0" iyy="1.0" iyz="0.0" izz="1.0"/>
    </inertial>
  </link>
  <joint name="cylinder2base_10_13" type="fixed">
    <parent link="link_10_13"/>
    <child link="cylinder_10_13"/>
    <origin ryp="0 0 0" xyz="0 0 0.01"/>
  </joint>
  <link name="sphere_10_13">
    <visual>
      <geometry>
        <sphere radius="0.009"/>
      </geometry>
      <origin rpy="0 0 0" xyz="0 0 0"/>
      <material name="blue1">
        <color rgba="0 0 1 0.6"/>
      </material>
    </visual>
    <collision>
      <geometry>
        <sphere radius="0.009"/>
      </geometry>
      <origin rpy="0 0 0" xyz="0 0 0"/>
    </collision>
    <inertial>
      <origin rpy="0 0 0" xyz="0 0 0"/>
      <mass value="0.05"/>
      <inertia ixx="1.0" ixy="0.0" ixz="0.0" iyy="1.0" iyz="0.0" izz="1.0"/>
    </inertial>
  </link>
  <joint name="sphere2cylinder_10_13" type="fixed">
    <parent link="cylinder_10_13"/>
    <child link="sphere_10_13"/>
    <origin ryp="0 0 0" xyz="0 0 0"/>
  </joint>
  <link name="link_10_12">
    <visual>
      <geometry>
        <box size="0.016 0.016 0.055"/>
      </geometry>
      <origin rpy="0 0 0" xyz="0 0 -0.0275"/>
      <material name="blue0">
        <color rgba="0 0 1 0.9"/>
      </material>
    </visual>
    <collision>
      <geometry>
        <box size="0.016 0.016 0.055"/>
      </geometry>
      <origin rpy="0 0 0" xyz="0 0 -0.0275"/>
    </collision>
    <inertial>
      <origin rpy="0 0 0" xyz="0 0 0"/>
      <mass value="0.5"/>
      <inertia ixx="1.0" ixy="0.0" ixz="0.0" iyy="1.0" iyz="0.0" izz="1.0"/>
    </inertial>
  </link>
  <joint name="joint_10_12" type="prismatic">
    <parent link="table_base"/>
    <child link="link_10_12"/>
    <origin ryp="0 0 0" xyz="0.018000000000000002 0.058 0"/>
    <axis xyz="0 0 1"/>
    <limit effort="4" lower="0" upper="0.045" velocity="0.05"/>
  </joint>
  <link name="cylinder_10_12">
    <visual>
      <geometry>
        <cylinder length="0.01" radius="0.009"/>
      </geometry>
      <origin rpy="0 0 0" xyz="0 0 -0.005"/>
      <material name="blue1">
        <color rgba="0 0 1 0.6"/>
      </material>
    </visual>
    <collision>
      <geometry>
        <cylinder length="0.01" radius="0.009"/>
      </geometry>
      <origin rpy="0 0 0" xyz="0 0 -0.005"/>
    </collision>
    <inertial>
      <origin rpy="0 0 0" xyz="0 0 0"/>
      <mass value="0.05"/>
      <inertia ixx="1.0" ixy="0.0" ixz="0.0" iyy="1.0" iyz="0.0" izz="1.0"/>
    </inertial>
  </link>
  <joint name="cylinder2base_10_12" type="fixed">
    <parent link="link_10_12"/>
    <child link="cylinder_10_12"/>
    <origin ryp="0 0 0" xyz="0 0 0.01"/>
  </joint>
  <link name="sphere_10_12">
    <visual>
      <geometry>
        <sphere radius="0.009"/>
      </geometry>
      <origin rpy="0 0 0" xyz="0 0 0"/>
      <material name="blue1">
        <color rgba="0 0 1 0.6"/>
      </material>
    </visual>
    <collision>
      <geometry>
        <sphere radius="0.009"/>
      </geometry>
      <origin rpy="0 0 0" xyz="0 0 0"/>
    </collision>
    <inertial>
      <origin rpy="0 0 0" xyz="0 0 0"/>
      <mass value="0.05"/>
      <inertia ixx="1.0" ixy="0.0" ixz="0.0" iyy="1.0" iyz="0.0" izz="1.0"/>
    </inertial>
  </link>
  <joint name="sphere2cylinder_10_12" type="fixed">
    <parent link="cylinder_10_12"/>
    <child link="sphere_10_12"/>
    <origin ryp="0 0 0" xyz="0 0 0"/>
  </joint>
  <link name="link_10_11">
    <visual>
      <geometry>
        <box size="0.016 0.016 0.055"/>
      </geometry>
      <origin rpy="0 0 0" xyz="0 0 -0.0275"/>
      <material name="blue0">
        <color rgba="0 0 1 0.9"/>
      </material>
    </visual>
    <collision>
      <geometry>
        <box size="0.016 0.016 0.055"/>
      </geometry>
      <origin rpy="0 0 0" xyz="0 0 -0.0275"/>
    </collision>
    <inertial>
      <origin rpy="0 0 0" xyz="0 0 0"/>
      <mass value="0.5"/>
      <inertia ixx="1.0" ixy="0.0" ixz="0.0" iyy="1.0" iyz="0.0" izz="1.0"/>
    </inertial>
  </link>
  <joint name="joint_10_11" type="prismatic">
    <parent link="table_base"/>
    <child link="link_10_11"/>
    <origin ryp="0 0 0" xyz="0.018000000000000002 0.038 0"/>
    <axis xyz="0 0 1"/>
    <limit effort="4" lower="0" upper="0.045" velocity="0.05"/>
  </joint>
  <link name="cylinder_10_11">
    <visual>
      <geometry>
        <cylinder length="0.01" radius="0.009"/>
      </geometry>
      <origin rpy="0 0 0" xyz="0 0 -0.005"/>
      <material name="blue1">
        <color rgba="0 0 1 0.6"/>
      </material>
    </visual>
    <collision>
      <geometry>
        <cylinder length="0.01" radius="0.009"/>
      </geometry>
      <origin rpy="0 0 0" xyz="0 0 -0.005"/>
    </collision>
    <inertial>
      <origin rpy="0 0 0" xyz="0 0 0"/>
      <mass value="0.05"/>
      <inertia ixx="1.0" ixy="0.0" ixz="0.0" iyy="1.0" iyz="0.0" izz="1.0"/>
    </inertial>
  </link>
  <joint name="cylinder2base_10_11" type="fixed">
    <parent link="link_10_11"/>
    <child link="cylinder_10_11"/>
    <origin ryp="0 0 0" xyz="0 0 0.01"/>
  </joint>
  <link name="sphere_10_11">
    <visual>
      <geometry>
        <sphere radius="0.009"/>
      </geometry>
      <origin rpy="0 0 0" xyz="0 0 0"/>
      <material name="blue1">
        <color rgba="0 0 1 0.6"/>
      </material>
    </visual>
    <collision>
      <geometry>
        <sphere radius="0.009"/>
      </geometry>
      <origin rpy="0 0 0" xyz="0 0 0"/>
    </collision>
    <inertial>
      <origin rpy="0 0 0" xyz="0 0 0"/>
      <mass value="0.05"/>
      <inertia ixx="1.0" ixy="0.0" ixz="0.0" iyy="1.0" iyz="0.0" izz="1.0"/>
    </inertial>
  </link>
  <joint name="sphere2cylinder_10_11" type="fixed">
    <parent link="cylinder_10_11"/>
    <child link="sphere_10_11"/>
    <origin ryp="0 0 0" xyz="0 0 0"/>
  </joint>
  <link name="link_10_10">
    <visual>
      <geometry>
        <box size="0.016 0.016 0.055"/>
      </geometry>
      <origin rpy="0 0 0" xyz="0 0 -0.0275"/>
      <material name="blue0">
        <color rgba="0 0 1 0.9"/>
      </material>
    </visual>
    <collision>
      <geometry>
        <box size="0.016 0.016 0.055"/>
      </geometry>
      <origin rpy="0 0 0" xyz="0 0 -0.0275"/>
    </collision>
    <inertial>
      <origin rpy="0 0 0" xyz="0 0 0"/>
      <mass value="0.5"/>
      <inertia ixx="1.0" ixy="0.0" ixz="0.0" iyy="1.0" iyz="0.0" izz="1.0"/>
    </inertial>
  </link>
  <joint name="joint_10_10" type="prismatic">
    <parent link="table_base"/>
    <child link="link_10_10"/>
    <origin ryp="0 0 0" xyz="0.018000000000000002 0.018000000000000002 0"/>
    <axis xyz="0 0 1"/>
    <limit effort="4" lower="0" upper="0.045" velocity="0.05"/>
  </joint>
  <link name="cylinder_10_10">
    <visual>
      <geometry>
        <cylinder length="0.01" radius="0.009"/>
      </geometry>
      <origin rpy="0 0 0" xyz="0 0 -0.005"/>
      <material name="blue1">
        <color rgba="0 0 1 0.6"/>
      </material>
    </visual>
    <collision>
      <geometry>
        <cylinder length="0.01" radius="0.009"/>
      </geometry>
      <origin rpy="0 0 0" xyz="0 0 -0.005"/>
    </collision>
    <inertial>
      <origin rpy="0 0 0" xyz="0 0 0"/>
      <mass value="0.05"/>
      <inertia ixx="1.0" ixy="0.0" ixz="0.0" iyy="1.0" iyz="0.0" izz="1.0"/>
    </inertial>
  </link>
  <joint name="cylinder2base_10_10" type="fixed">
    <parent link="link_10_10"/>
    <child link="cylinder_10_10"/>
    <origin ryp="0 0 0" xyz="0 0 0.01"/>
  </joint>
  <link name="sphere_10_10">
    <visual>
      <geometry>
        <sphere radius="0.009"/>
      </geometry>
      <origin rpy="0 0 0" xyz="0 0 0"/>
      <material name="blue1">
        <color rgba="0 0 1 0.6"/>
      </material>
    </visual>
    <collision>
      <geometry>
        <sphere radius="0.009"/>
      </geometry>
      <origin rpy="0 0 0" xyz="0 0 0"/>
    </collision>
    <inertial>
      <origin rpy="0 0 0" xyz="0 0 0"/>
      <mass value="0.05"/>
      <inertia ixx="1.0" ixy="0.0" ixz="0.0" iyy="1.0" iyz="0.0" izz="1.0"/>
    </inertial>
  </link>
  <joint name="sphere2cylinder_10_10" type="fixed">
    <parent link="cylinder_10_10"/>
    <child link="sphere_10_10"/>
    <origin ryp="0 0 0" xyz="0 0 0"/>
  </joint>
</robot>

