<?xml version="1.0" ?>
<!-- =================================================================================== -->
<!-- |    This document was autogenerated by xacro from learn-ros/src/my_urdf/urdf/xacro/tablebot.xacro | -->
<!-- |    EDITING THIS FILE BY HAND IS NOT RECOMMENDED                                 | -->
<!-- =================================================================================== -->
<robot name="tablebot">
  <!-- <link name="footprint">
      <visual>
        <geometry>
          <sphere radius="0.0001" />
        </geometry>
      </visual>
    </link> -->
  <link name="table_base">
    <visual>
      <geometry>
        <box size="0.178 0.178 0.12"/>
      </geometry>
      <origin rpy="0 0 0" xyz="0.089 0.089 -0.06"/>
      <material name="black">
        <color rgba="1 1 1 0.5"/>
      </material>
      <inertial>
        <origin rpy="0 0 0" xyz="0 0 0"/>
        <mass value="10"/>
        <inertia ixx="1.0" ixy="0.0" ixz="0.0" iyy="1.0" iyz="0.0" izz="1.0"/>
      </inertial>
    </visual>
  </link>
  <!-- <joint name="base2footprint" type="fixed">
      <parent link="footprint" />
      <child link="table_base" />
      <origin xyz="0 0 ${tab_height / 2 }" />
    </joint> -->
  <!-- <xacro:macro name="loop" params="links_qty">
        <xacro:if value="${links_qty}">
            <xacro:loop links_qty="${links_qty-1}" />
        </xacro:if>
    </xacro:macro> -->
  <link name="link_9_9">
    <visual>
      <geometry>
        <box size="0.005 0.005 0.055"/>
      </geometry>
      <origin rpy="0 0 0" xyz="0 0 -0.0275"/>
      <material name="blue">
        <color rgba="0 0 1 0.9"/>
      </material>
    </visual>
    <collision>
      <geometry>
        <box size="0.005 0.005 0.055"/>
      </geometry>
      <origin rpy="0 0 0" xyz="0 0 -0.0275"/>
    </collision>
    <inertial>
      <origin rpy="0 0 0" xyz="0 0 0"/>
      <mass value="0.5"/>
      <inertia ixx="1.0" ixy="0.0" ixz="0.0" iyy="1.0" iyz="0.0" izz="1.0"/>
    </inertial>
  </link>
  <joint name="joint_9_9" type="prismatic">
    <parent link="table_base"/>
    <child link="link_9_9"/>
    <origin ryp="0 0 0" xyz="0.16549999999999998 0.16549999999999998 0"/>
    <axis xyz="0 0 1"/>
    <limit effort="4" lower="0" upper="0.045" velocity="0.01"/>
  </joint>
  <link name="link_9_8">
    <visual>
      <geometry>
        <box size="0.005 0.005 0.055"/>
      </geometry>
      <origin rpy="0 0 0" xyz="0 0 -0.0275"/>
      <material name="blue">
        <color rgba="0 0 1 0.9"/>
      </material>
    </visual>
    <collision>
      <geometry>
        <box size="0.005 0.005 0.055"/>
      </geometry>
      <origin rpy="0 0 0" xyz="0 0 -0.0275"/>
    </collision>
    <inertial>
      <origin rpy="0 0 0" xyz="0 0 0"/>
      <mass value="0.5"/>
      <inertia ixx="1.0" ixy="0.0" ixz="0.0" iyy="1.0" iyz="0.0" izz="1.0"/>
    </inertial>
  </link>
  <joint name="joint_9_8" type="prismatic">
    <parent link="table_base"/>
    <child link="link_9_8"/>
    <origin ryp="0 0 0" xyz="0.16549999999999998 0.1485 0"/>
    <axis xyz="0 0 1"/>
    <limit effort="4" lower="0" upper="0.045" velocity="0.01"/>
  </joint>
  <link name="link_9_7">
    <visual>
      <geometry>
        <box size="0.005 0.005 0.055"/>
      </geometry>
      <origin rpy="0 0 0" xyz="0 0 -0.0275"/>
      <material name="blue">
        <color rgba="0 0 1 0.9"/>
      </material>
    </visual>
    <collision>
      <geometry>
        <box size="0.005 0.005 0.055"/>
      </geometry>
      <origin rpy="0 0 0" xyz="0 0 -0.0275"/>
    </collision>
    <inertial>
      <origin rpy="0 0 0" xyz="0 0 0"/>
      <mass value="0.5"/>
      <inertia ixx="1.0" ixy="0.0" ixz="0.0" iyy="1.0" iyz="0.0" izz="1.0"/>
    </inertial>
  </link>
  <joint name="joint_9_7" type="prismatic">
    <parent link="table_base"/>
    <child link="link_9_7"/>
    <origin ryp="0 0 0" xyz="0.16549999999999998 0.1315 0"/>
    <axis xyz="0 0 1"/>
    <limit effort="4" lower="0" upper="0.045" velocity="0.01"/>
  </joint>
  <link name="link_9_6">
    <visual>
      <geometry>
        <box size="0.005 0.005 0.055"/>
      </geometry>
      <origin rpy="0 0 0" xyz="0 0 -0.0275"/>
      <material name="blue">
        <color rgba="0 0 1 0.9"/>
      </material>
    </visual>
    <collision>
      <geometry>
        <box size="0.005 0.005 0.055"/>
      </geometry>
      <origin rpy="0 0 0" xyz="0 0 -0.0275"/>
    </collision>
    <inertial>
      <origin rpy="0 0 0" xyz="0 0 0"/>
      <mass value="0.5"/>
      <inertia ixx="1.0" ixy="0.0" ixz="0.0" iyy="1.0" iyz="0.0" izz="1.0"/>
    </inertial>
  </link>
  <joint name="joint_9_6" type="prismatic">
    <parent link="table_base"/>
    <child link="link_9_6"/>
    <origin ryp="0 0 0" xyz="0.16549999999999998 0.1145 0"/>
    <axis xyz="0 0 1"/>
    <limit effort="4" lower="0" upper="0.045" velocity="0.01"/>
  </joint>
  <link name="link_9_5">
    <visual>
      <geometry>
        <box size="0.005 0.005 0.055"/>
      </geometry>
      <origin rpy="0 0 0" xyz="0 0 -0.0275"/>
      <material name="blue">
        <color rgba="0 0 1 0.9"/>
      </material>
    </visual>
    <collision>
      <geometry>
        <box size="0.005 0.005 0.055"/>
      </geometry>
      <origin rpy="0 0 0" xyz="0 0 -0.0275"/>
    </collision>
    <inertial>
      <origin rpy="0 0 0" xyz="0 0 0"/>
      <mass value="0.5"/>
      <inertia ixx="1.0" ixy="0.0" ixz="0.0" iyy="1.0" iyz="0.0" izz="1.0"/>
    </inertial>
  </link>
  <joint name="joint_9_5" type="prismatic">
    <parent link="table_base"/>
    <child link="link_9_5"/>
    <origin ryp="0 0 0" xyz="0.16549999999999998 0.09749999999999999 0"/>
    <axis xyz="0 0 1"/>
    <limit effort="4" lower="0" upper="0.045" velocity="0.01"/>
  </joint>
  <link name="link_9_4">
    <visual>
      <geometry>
        <box size="0.005 0.005 0.055"/>
      </geometry>
      <origin rpy="0 0 0" xyz="0 0 -0.0275"/>
      <material name="blue">
        <color rgba="0 0 1 0.9"/>
      </material>
    </visual>
    <collision>
      <geometry>
        <box size="0.005 0.005 0.055"/>
      </geometry>
      <origin rpy="0 0 0" xyz="0 0 -0.0275"/>
    </collision>
    <inertial>
      <origin rpy="0 0 0" xyz="0 0 0"/>
      <mass value="0.5"/>
      <inertia ixx="1.0" ixy="0.0" ixz="0.0" iyy="1.0" iyz="0.0" izz="1.0"/>
    </inertial>
  </link>
  <joint name="joint_9_4" type="prismatic">
    <parent link="table_base"/>
    <child link="link_9_4"/>
    <origin ryp="0 0 0" xyz="0.16549999999999998 0.0805 0"/>
    <axis xyz="0 0 1"/>
    <limit effort="4" lower="0" upper="0.045" velocity="0.01"/>
  </joint>
  <link name="link_9_3">
    <visual>
      <geometry>
        <box size="0.005 0.005 0.055"/>
      </geometry>
      <origin rpy="0 0 0" xyz="0 0 -0.0275"/>
      <material name="blue">
        <color rgba="0 0 1 0.9"/>
      </material>
    </visual>
    <collision>
      <geometry>
        <box size="0.005 0.005 0.055"/>
      </geometry>
      <origin rpy="0 0 0" xyz="0 0 -0.0275"/>
    </collision>
    <inertial>
      <origin rpy="0 0 0" xyz="0 0 0"/>
      <mass value="0.5"/>
      <inertia ixx="1.0" ixy="0.0" ixz="0.0" iyy="1.0" iyz="0.0" izz="1.0"/>
    </inertial>
  </link>
  <joint name="joint_9_3" type="prismatic">
    <parent link="table_base"/>
    <child link="link_9_3"/>
    <origin ryp="0 0 0" xyz="0.16549999999999998 0.0635 0"/>
    <axis xyz="0 0 1"/>
    <limit effort="4" lower="0" upper="0.045" velocity="0.01"/>
  </joint>
  <link name="link_9_2">
    <visual>
      <geometry>
        <box size="0.005 0.005 0.055"/>
      </geometry>
      <origin rpy="0 0 0" xyz="0 0 -0.0275"/>
      <material name="blue">
        <color rgba="0 0 1 0.9"/>
      </material>
    </visual>
    <collision>
      <geometry>
        <box size="0.005 0.005 0.055"/>
      </geometry>
      <origin rpy="0 0 0" xyz="0 0 -0.0275"/>
    </collision>
    <inertial>
      <origin rpy="0 0 0" xyz="0 0 0"/>
      <mass value="0.5"/>
      <inertia ixx="1.0" ixy="0.0" ixz="0.0" iyy="1.0" iyz="0.0" izz="1.0"/>
    </inertial>
  </link>
  <joint name="joint_9_2" type="prismatic">
    <parent link="table_base"/>
    <child link="link_9_2"/>
    <origin ryp="0 0 0" xyz="0.16549999999999998 0.0465 0"/>
    <axis xyz="0 0 1"/>
    <limit effort="4" lower="0" upper="0.045" velocity="0.01"/>
  </joint>
  <link name="link_9_1">
    <visual>
      <geometry>
        <box size="0.005 0.005 0.055"/>
      </geometry>
      <origin rpy="0 0 0" xyz="0 0 -0.0275"/>
      <material name="blue">
        <color rgba="0 0 1 0.9"/>
      </material>
    </visual>
    <collision>
      <geometry>
        <box size="0.005 0.005 0.055"/>
      </geometry>
      <origin rpy="0 0 0" xyz="0 0 -0.0275"/>
    </collision>
    <inertial>
      <origin rpy="0 0 0" xyz="0 0 0"/>
      <mass value="0.5"/>
      <inertia ixx="1.0" ixy="0.0" ixz="0.0" iyy="1.0" iyz="0.0" izz="1.0"/>
    </inertial>
  </link>
  <joint name="joint_9_1" type="prismatic">
    <parent link="table_base"/>
    <child link="link_9_1"/>
    <origin ryp="0 0 0" xyz="0.16549999999999998 0.0295 0"/>
    <axis xyz="0 0 1"/>
    <limit effort="4" lower="0" upper="0.045" velocity="0.01"/>
  </joint>
  <link name="link_9_0">
    <visual>
      <geometry>
        <box size="0.005 0.005 0.055"/>
      </geometry>
      <origin rpy="0 0 0" xyz="0 0 -0.0275"/>
      <material name="blue">
        <color rgba="0 0 1 0.9"/>
      </material>
    </visual>
    <collision>
      <geometry>
        <box size="0.005 0.005 0.055"/>
      </geometry>
      <origin rpy="0 0 0" xyz="0 0 -0.0275"/>
    </collision>
    <inertial>
      <origin rpy="0 0 0" xyz="0 0 0"/>
      <mass value="0.5"/>
      <inertia ixx="1.0" ixy="0.0" ixz="0.0" iyy="1.0" iyz="0.0" izz="1.0"/>
    </inertial>
  </link>
  <joint name="joint_9_0" type="prismatic">
    <parent link="table_base"/>
    <child link="link_9_0"/>
    <origin ryp="0 0 0" xyz="0.16549999999999998 0.0125 0"/>
    <axis xyz="0 0 1"/>
    <limit effort="4" lower="0" upper="0.045" velocity="0.01"/>
  </joint>
  <link name="link_8_9">
    <visual>
      <geometry>
        <box size="0.005 0.005 0.055"/>
      </geometry>
      <origin rpy="0 0 0" xyz="0 0 -0.0275"/>
      <material name="blue">
        <color rgba="0 0 1 0.9"/>
      </material>
    </visual>
    <collision>
      <geometry>
        <box size="0.005 0.005 0.055"/>
      </geometry>
      <origin rpy="0 0 0" xyz="0 0 -0.0275"/>
    </collision>
    <inertial>
      <origin rpy="0 0 0" xyz="0 0 0"/>
      <mass value="0.5"/>
      <inertia ixx="1.0" ixy="0.0" ixz="0.0" iyy="1.0" iyz="0.0" izz="1.0"/>
    </inertial>
  </link>
  <joint name="joint_8_9" type="prismatic">
    <parent link="table_base"/>
    <child link="link_8_9"/>
    <origin ryp="0 0 0" xyz="0.1485 0.16549999999999998 0"/>
    <axis xyz="0 0 1"/>
    <limit effort="4" lower="0" upper="0.045" velocity="0.01"/>
  </joint>
  <link name="link_8_8">
    <visual>
      <geometry>
        <box size="0.005 0.005 0.055"/>
      </geometry>
      <origin rpy="0 0 0" xyz="0 0 -0.0275"/>
      <material name="blue">
        <color rgba="0 0 1 0.9"/>
      </material>
    </visual>
    <collision>
      <geometry>
        <box size="0.005 0.005 0.055"/>
      </geometry>
      <origin rpy="0 0 0" xyz="0 0 -0.0275"/>
    </collision>
    <inertial>
      <origin rpy="0 0 0" xyz="0 0 0"/>
      <mass value="0.5"/>
      <inertia ixx="1.0" ixy="0.0" ixz="0.0" iyy="1.0" iyz="0.0" izz="1.0"/>
    </inertial>
  </link>
  <joint name="joint_8_8" type="prismatic">
    <parent link="table_base"/>
    <child link="link_8_8"/>
    <origin ryp="0 0 0" xyz="0.1485 0.1485 0"/>
    <axis xyz="0 0 1"/>
    <limit effort="4" lower="0" upper="0.045" velocity="0.01"/>
  </joint>
  <link name="link_8_7">
    <visual>
      <geometry>
        <box size="0.005 0.005 0.055"/>
      </geometry>
      <origin rpy="0 0 0" xyz="0 0 -0.0275"/>
      <material name="blue">
        <color rgba="0 0 1 0.9"/>
      </material>
    </visual>
    <collision>
      <geometry>
        <box size="0.005 0.005 0.055"/>
      </geometry>
      <origin rpy="0 0 0" xyz="0 0 -0.0275"/>
    </collision>
    <inertial>
      <origin rpy="0 0 0" xyz="0 0 0"/>
      <mass value="0.5"/>
      <inertia ixx="1.0" ixy="0.0" ixz="0.0" iyy="1.0" iyz="0.0" izz="1.0"/>
    </inertial>
  </link>
  <joint name="joint_8_7" type="prismatic">
    <parent link="table_base"/>
    <child link="link_8_7"/>
    <origin ryp="0 0 0" xyz="0.1485 0.1315 0"/>
    <axis xyz="0 0 1"/>
    <limit effort="4" lower="0" upper="0.045" velocity="0.01"/>
  </joint>
  <link name="link_8_6">
    <visual>
      <geometry>
        <box size="0.005 0.005 0.055"/>
      </geometry>
      <origin rpy="0 0 0" xyz="0 0 -0.0275"/>
      <material name="blue">
        <color rgba="0 0 1 0.9"/>
      </material>
    </visual>
    <collision>
      <geometry>
        <box size="0.005 0.005 0.055"/>
      </geometry>
      <origin rpy="0 0 0" xyz="0 0 -0.0275"/>
    </collision>
    <inertial>
      <origin rpy="0 0 0" xyz="0 0 0"/>
      <mass value="0.5"/>
      <inertia ixx="1.0" ixy="0.0" ixz="0.0" iyy="1.0" iyz="0.0" izz="1.0"/>
    </inertial>
  </link>
  <joint name="joint_8_6" type="prismatic">
    <parent link="table_base"/>
    <child link="link_8_6"/>
    <origin ryp="0 0 0" xyz="0.1485 0.1145 0"/>
    <axis xyz="0 0 1"/>
    <limit effort="4" lower="0" upper="0.045" velocity="0.01"/>
  </joint>
  <link name="link_8_5">
    <visual>
      <geometry>
        <box size="0.005 0.005 0.055"/>
      </geometry>
      <origin rpy="0 0 0" xyz="0 0 -0.0275"/>
      <material name="blue">
        <color rgba="0 0 1 0.9"/>
      </material>
    </visual>
    <collision>
      <geometry>
        <box size="0.005 0.005 0.055"/>
      </geometry>
      <origin rpy="0 0 0" xyz="0 0 -0.0275"/>
    </collision>
    <inertial>
      <origin rpy="0 0 0" xyz="0 0 0"/>
      <mass value="0.5"/>
      <inertia ixx="1.0" ixy="0.0" ixz="0.0" iyy="1.0" iyz="0.0" izz="1.0"/>
    </inertial>
  </link>
  <joint name="joint_8_5" type="prismatic">
    <parent link="table_base"/>
    <child link="link_8_5"/>
    <origin ryp="0 0 0" xyz="0.1485 0.09749999999999999 0"/>
    <axis xyz="0 0 1"/>
    <limit effort="4" lower="0" upper="0.045" velocity="0.01"/>
  </joint>
  <link name="link_8_4">
    <visual>
      <geometry>
        <box size="0.005 0.005 0.055"/>
      </geometry>
      <origin rpy="0 0 0" xyz="0 0 -0.0275"/>
      <material name="blue">
        <color rgba="0 0 1 0.9"/>
      </material>
    </visual>
    <collision>
      <geometry>
        <box size="0.005 0.005 0.055"/>
      </geometry>
      <origin rpy="0 0 0" xyz="0 0 -0.0275"/>
    </collision>
    <inertial>
      <origin rpy="0 0 0" xyz="0 0 0"/>
      <mass value="0.5"/>
      <inertia ixx="1.0" ixy="0.0" ixz="0.0" iyy="1.0" iyz="0.0" izz="1.0"/>
    </inertial>
  </link>
  <joint name="joint_8_4" type="prismatic">
    <parent link="table_base"/>
    <child link="link_8_4"/>
    <origin ryp="0 0 0" xyz="0.1485 0.0805 0"/>
    <axis xyz="0 0 1"/>
    <limit effort="4" lower="0" upper="0.045" velocity="0.01"/>
  </joint>
  <link name="link_8_3">
    <visual>
      <geometry>
        <box size="0.005 0.005 0.055"/>
      </geometry>
      <origin rpy="0 0 0" xyz="0 0 -0.0275"/>
      <material name="blue">
        <color rgba="0 0 1 0.9"/>
      </material>
    </visual>
    <collision>
      <geometry>
        <box size="0.005 0.005 0.055"/>
      </geometry>
      <origin rpy="0 0 0" xyz="0 0 -0.0275"/>
    </collision>
    <inertial>
      <origin rpy="0 0 0" xyz="0 0 0"/>
      <mass value="0.5"/>
      <inertia ixx="1.0" ixy="0.0" ixz="0.0" iyy="1.0" iyz="0.0" izz="1.0"/>
    </inertial>
  </link>
  <joint name="joint_8_3" type="prismatic">
    <parent link="table_base"/>
    <child link="link_8_3"/>
    <origin ryp="0 0 0" xyz="0.1485 0.0635 0"/>
    <axis xyz="0 0 1"/>
    <limit effort="4" lower="0" upper="0.045" velocity="0.01"/>
  </joint>
  <link name="link_8_2">
    <visual>
      <geometry>
        <box size="0.005 0.005 0.055"/>
      </geometry>
      <origin rpy="0 0 0" xyz="0 0 -0.0275"/>
      <material name="blue">
        <color rgba="0 0 1 0.9"/>
      </material>
    </visual>
    <collision>
      <geometry>
        <box size="0.005 0.005 0.055"/>
      </geometry>
      <origin rpy="0 0 0" xyz="0 0 -0.0275"/>
    </collision>
    <inertial>
      <origin rpy="0 0 0" xyz="0 0 0"/>
      <mass value="0.5"/>
      <inertia ixx="1.0" ixy="0.0" ixz="0.0" iyy="1.0" iyz="0.0" izz="1.0"/>
    </inertial>
  </link>
  <joint name="joint_8_2" type="prismatic">
    <parent link="table_base"/>
    <child link="link_8_2"/>
    <origin ryp="0 0 0" xyz="0.1485 0.0465 0"/>
    <axis xyz="0 0 1"/>
    <limit effort="4" lower="0" upper="0.045" velocity="0.01"/>
  </joint>
  <link name="link_8_1">
    <visual>
      <geometry>
        <box size="0.005 0.005 0.055"/>
      </geometry>
      <origin rpy="0 0 0" xyz="0 0 -0.0275"/>
      <material name="blue">
        <color rgba="0 0 1 0.9"/>
      </material>
    </visual>
    <collision>
      <geometry>
        <box size="0.005 0.005 0.055"/>
      </geometry>
      <origin rpy="0 0 0" xyz="0 0 -0.0275"/>
    </collision>
    <inertial>
      <origin rpy="0 0 0" xyz="0 0 0"/>
      <mass value="0.5"/>
      <inertia ixx="1.0" ixy="0.0" ixz="0.0" iyy="1.0" iyz="0.0" izz="1.0"/>
    </inertial>
  </link>
  <joint name="joint_8_1" type="prismatic">
    <parent link="table_base"/>
    <child link="link_8_1"/>
    <origin ryp="0 0 0" xyz="0.1485 0.0295 0"/>
    <axis xyz="0 0 1"/>
    <limit effort="4" lower="0" upper="0.045" velocity="0.01"/>
  </joint>
  <link name="link_8_0">
    <visual>
      <geometry>
        <box size="0.005 0.005 0.055"/>
      </geometry>
      <origin rpy="0 0 0" xyz="0 0 -0.0275"/>
      <material name="blue">
        <color rgba="0 0 1 0.9"/>
      </material>
    </visual>
    <collision>
      <geometry>
        <box size="0.005 0.005 0.055"/>
      </geometry>
      <origin rpy="0 0 0" xyz="0 0 -0.0275"/>
    </collision>
    <inertial>
      <origin rpy="0 0 0" xyz="0 0 0"/>
      <mass value="0.5"/>
      <inertia ixx="1.0" ixy="0.0" ixz="0.0" iyy="1.0" iyz="0.0" izz="1.0"/>
    </inertial>
  </link>
  <joint name="joint_8_0" type="prismatic">
    <parent link="table_base"/>
    <child link="link_8_0"/>
    <origin ryp="0 0 0" xyz="0.1485 0.0125 0"/>
    <axis xyz="0 0 1"/>
    <limit effort="4" lower="0" upper="0.045" velocity="0.01"/>
  </joint>
  <link name="link_7_9">
    <visual>
      <geometry>
        <box size="0.005 0.005 0.055"/>
      </geometry>
      <origin rpy="0 0 0" xyz="0 0 -0.0275"/>
      <material name="blue">
        <color rgba="0 0 1 0.9"/>
      </material>
    </visual>
    <collision>
      <geometry>
        <box size="0.005 0.005 0.055"/>
      </geometry>
      <origin rpy="0 0 0" xyz="0 0 -0.0275"/>
    </collision>
    <inertial>
      <origin rpy="0 0 0" xyz="0 0 0"/>
      <mass value="0.5"/>
      <inertia ixx="1.0" ixy="0.0" ixz="0.0" iyy="1.0" iyz="0.0" izz="1.0"/>
    </inertial>
  </link>
  <joint name="joint_7_9" type="prismatic">
    <parent link="table_base"/>
    <child link="link_7_9"/>
    <origin ryp="0 0 0" xyz="0.1315 0.16549999999999998 0"/>
    <axis xyz="0 0 1"/>
    <limit effort="4" lower="0" upper="0.045" velocity="0.01"/>
  </joint>
  <link name="link_7_8">
    <visual>
      <geometry>
        <box size="0.005 0.005 0.055"/>
      </geometry>
      <origin rpy="0 0 0" xyz="0 0 -0.0275"/>
      <material name="blue">
        <color rgba="0 0 1 0.9"/>
      </material>
    </visual>
    <collision>
      <geometry>
        <box size="0.005 0.005 0.055"/>
      </geometry>
      <origin rpy="0 0 0" xyz="0 0 -0.0275"/>
    </collision>
    <inertial>
      <origin rpy="0 0 0" xyz="0 0 0"/>
      <mass value="0.5"/>
      <inertia ixx="1.0" ixy="0.0" ixz="0.0" iyy="1.0" iyz="0.0" izz="1.0"/>
    </inertial>
  </link>
  <joint name="joint_7_8" type="prismatic">
    <parent link="table_base"/>
    <child link="link_7_8"/>
    <origin ryp="0 0 0" xyz="0.1315 0.1485 0"/>
    <axis xyz="0 0 1"/>
    <limit effort="4" lower="0" upper="0.045" velocity="0.01"/>
  </joint>
  <link name="link_7_7">
    <visual>
      <geometry>
        <box size="0.005 0.005 0.055"/>
      </geometry>
      <origin rpy="0 0 0" xyz="0 0 -0.0275"/>
      <material name="blue">
        <color rgba="0 0 1 0.9"/>
      </material>
    </visual>
    <collision>
      <geometry>
        <box size="0.005 0.005 0.055"/>
      </geometry>
      <origin rpy="0 0 0" xyz="0 0 -0.0275"/>
    </collision>
    <inertial>
      <origin rpy="0 0 0" xyz="0 0 0"/>
      <mass value="0.5"/>
      <inertia ixx="1.0" ixy="0.0" ixz="0.0" iyy="1.0" iyz="0.0" izz="1.0"/>
    </inertial>
  </link>
  <joint name="joint_7_7" type="prismatic">
    <parent link="table_base"/>
    <child link="link_7_7"/>
    <origin ryp="0 0 0" xyz="0.1315 0.1315 0"/>
    <axis xyz="0 0 1"/>
    <limit effort="4" lower="0" upper="0.045" velocity="0.01"/>
  </joint>
  <link name="link_7_6">
    <visual>
      <geometry>
        <box size="0.005 0.005 0.055"/>
      </geometry>
      <origin rpy="0 0 0" xyz="0 0 -0.0275"/>
      <material name="blue">
        <color rgba="0 0 1 0.9"/>
      </material>
    </visual>
    <collision>
      <geometry>
        <box size="0.005 0.005 0.055"/>
      </geometry>
      <origin rpy="0 0 0" xyz="0 0 -0.0275"/>
    </collision>
    <inertial>
      <origin rpy="0 0 0" xyz="0 0 0"/>
      <mass value="0.5"/>
      <inertia ixx="1.0" ixy="0.0" ixz="0.0" iyy="1.0" iyz="0.0" izz="1.0"/>
    </inertial>
  </link>
  <joint name="joint_7_6" type="prismatic">
    <parent link="table_base"/>
    <child link="link_7_6"/>
    <origin ryp="0 0 0" xyz="0.1315 0.1145 0"/>
    <axis xyz="0 0 1"/>
    <limit effort="4" lower="0" upper="0.045" velocity="0.01"/>
  </joint>
  <link name="link_7_5">
    <visual>
      <geometry>
        <box size="0.005 0.005 0.055"/>
      </geometry>
      <origin rpy="0 0 0" xyz="0 0 -0.0275"/>
      <material name="blue">
        <color rgba="0 0 1 0.9"/>
      </material>
    </visual>
    <collision>
      <geometry>
        <box size="0.005 0.005 0.055"/>
      </geometry>
      <origin rpy="0 0 0" xyz="0 0 -0.0275"/>
    </collision>
    <inertial>
      <origin rpy="0 0 0" xyz="0 0 0"/>
      <mass value="0.5"/>
      <inertia ixx="1.0" ixy="0.0" ixz="0.0" iyy="1.0" iyz="0.0" izz="1.0"/>
    </inertial>
  </link>
  <joint name="joint_7_5" type="prismatic">
    <parent link="table_base"/>
    <child link="link_7_5"/>
    <origin ryp="0 0 0" xyz="0.1315 0.09749999999999999 0"/>
    <axis xyz="0 0 1"/>
    <limit effort="4" lower="0" upper="0.045" velocity="0.01"/>
  </joint>
  <link name="link_7_4">
    <visual>
      <geometry>
        <box size="0.005 0.005 0.055"/>
      </geometry>
      <origin rpy="0 0 0" xyz="0 0 -0.0275"/>
      <material name="blue">
        <color rgba="0 0 1 0.9"/>
      </material>
    </visual>
    <collision>
      <geometry>
        <box size="0.005 0.005 0.055"/>
      </geometry>
      <origin rpy="0 0 0" xyz="0 0 -0.0275"/>
    </collision>
    <inertial>
      <origin rpy="0 0 0" xyz="0 0 0"/>
      <mass value="0.5"/>
      <inertia ixx="1.0" ixy="0.0" ixz="0.0" iyy="1.0" iyz="0.0" izz="1.0"/>
    </inertial>
  </link>
  <joint name="joint_7_4" type="prismatic">
    <parent link="table_base"/>
    <child link="link_7_4"/>
    <origin ryp="0 0 0" xyz="0.1315 0.0805 0"/>
    <axis xyz="0 0 1"/>
    <limit effort="4" lower="0" upper="0.045" velocity="0.01"/>
  </joint>
  <link name="link_7_3">
    <visual>
      <geometry>
        <box size="0.005 0.005 0.055"/>
      </geometry>
      <origin rpy="0 0 0" xyz="0 0 -0.0275"/>
      <material name="blue">
        <color rgba="0 0 1 0.9"/>
      </material>
    </visual>
    <collision>
      <geometry>
        <box size="0.005 0.005 0.055"/>
      </geometry>
      <origin rpy="0 0 0" xyz="0 0 -0.0275"/>
    </collision>
    <inertial>
      <origin rpy="0 0 0" xyz="0 0 0"/>
      <mass value="0.5"/>
      <inertia ixx="1.0" ixy="0.0" ixz="0.0" iyy="1.0" iyz="0.0" izz="1.0"/>
    </inertial>
  </link>
  <joint name="joint_7_3" type="prismatic">
    <parent link="table_base"/>
    <child link="link_7_3"/>
    <origin ryp="0 0 0" xyz="0.1315 0.0635 0"/>
    <axis xyz="0 0 1"/>
    <limit effort="4" lower="0" upper="0.045" velocity="0.01"/>
  </joint>
  <link name="link_7_2">
    <visual>
      <geometry>
        <box size="0.005 0.005 0.055"/>
      </geometry>
      <origin rpy="0 0 0" xyz="0 0 -0.0275"/>
      <material name="blue">
        <color rgba="0 0 1 0.9"/>
      </material>
    </visual>
    <collision>
      <geometry>
        <box size="0.005 0.005 0.055"/>
      </geometry>
      <origin rpy="0 0 0" xyz="0 0 -0.0275"/>
    </collision>
    <inertial>
      <origin rpy="0 0 0" xyz="0 0 0"/>
      <mass value="0.5"/>
      <inertia ixx="1.0" ixy="0.0" ixz="0.0" iyy="1.0" iyz="0.0" izz="1.0"/>
    </inertial>
  </link>
  <joint name="joint_7_2" type="prismatic">
    <parent link="table_base"/>
    <child link="link_7_2"/>
    <origin ryp="0 0 0" xyz="0.1315 0.0465 0"/>
    <axis xyz="0 0 1"/>
    <limit effort="4" lower="0" upper="0.045" velocity="0.01"/>
  </joint>
  <link name="link_7_1">
    <visual>
      <geometry>
        <box size="0.005 0.005 0.055"/>
      </geometry>
      <origin rpy="0 0 0" xyz="0 0 -0.0275"/>
      <material name="blue">
        <color rgba="0 0 1 0.9"/>
      </material>
    </visual>
    <collision>
      <geometry>
        <box size="0.005 0.005 0.055"/>
      </geometry>
      <origin rpy="0 0 0" xyz="0 0 -0.0275"/>
    </collision>
    <inertial>
      <origin rpy="0 0 0" xyz="0 0 0"/>
      <mass value="0.5"/>
      <inertia ixx="1.0" ixy="0.0" ixz="0.0" iyy="1.0" iyz="0.0" izz="1.0"/>
    </inertial>
  </link>
  <joint name="joint_7_1" type="prismatic">
    <parent link="table_base"/>
    <child link="link_7_1"/>
    <origin ryp="0 0 0" xyz="0.1315 0.0295 0"/>
    <axis xyz="0 0 1"/>
    <limit effort="4" lower="0" upper="0.045" velocity="0.01"/>
  </joint>
  <link name="link_7_0">
    <visual>
      <geometry>
        <box size="0.005 0.005 0.055"/>
      </geometry>
      <origin rpy="0 0 0" xyz="0 0 -0.0275"/>
      <material name="blue">
        <color rgba="0 0 1 0.9"/>
      </material>
    </visual>
    <collision>
      <geometry>
        <box size="0.005 0.005 0.055"/>
      </geometry>
      <origin rpy="0 0 0" xyz="0 0 -0.0275"/>
    </collision>
    <inertial>
      <origin rpy="0 0 0" xyz="0 0 0"/>
      <mass value="0.5"/>
      <inertia ixx="1.0" ixy="0.0" ixz="0.0" iyy="1.0" iyz="0.0" izz="1.0"/>
    </inertial>
  </link>
  <joint name="joint_7_0" type="prismatic">
    <parent link="table_base"/>
    <child link="link_7_0"/>
    <origin ryp="0 0 0" xyz="0.1315 0.0125 0"/>
    <axis xyz="0 0 1"/>
    <limit effort="4" lower="0" upper="0.045" velocity="0.01"/>
  </joint>
  <link name="link_6_9">
    <visual>
      <geometry>
        <box size="0.005 0.005 0.055"/>
      </geometry>
      <origin rpy="0 0 0" xyz="0 0 -0.0275"/>
      <material name="blue">
        <color rgba="0 0 1 0.9"/>
      </material>
    </visual>
    <collision>
      <geometry>
        <box size="0.005 0.005 0.055"/>
      </geometry>
      <origin rpy="0 0 0" xyz="0 0 -0.0275"/>
    </collision>
    <inertial>
      <origin rpy="0 0 0" xyz="0 0 0"/>
      <mass value="0.5"/>
      <inertia ixx="1.0" ixy="0.0" ixz="0.0" iyy="1.0" iyz="0.0" izz="1.0"/>
    </inertial>
  </link>
  <joint name="joint_6_9" type="prismatic">
    <parent link="table_base"/>
    <child link="link_6_9"/>
    <origin ryp="0 0 0" xyz="0.1145 0.16549999999999998 0"/>
    <axis xyz="0 0 1"/>
    <limit effort="4" lower="0" upper="0.045" velocity="0.01"/>
  </joint>
  <link name="link_6_8">
    <visual>
      <geometry>
        <box size="0.005 0.005 0.055"/>
      </geometry>
      <origin rpy="0 0 0" xyz="0 0 -0.0275"/>
      <material name="blue">
        <color rgba="0 0 1 0.9"/>
      </material>
    </visual>
    <collision>
      <geometry>
        <box size="0.005 0.005 0.055"/>
      </geometry>
      <origin rpy="0 0 0" xyz="0 0 -0.0275"/>
    </collision>
    <inertial>
      <origin rpy="0 0 0" xyz="0 0 0"/>
      <mass value="0.5"/>
      <inertia ixx="1.0" ixy="0.0" ixz="0.0" iyy="1.0" iyz="0.0" izz="1.0"/>
    </inertial>
  </link>
  <joint name="joint_6_8" type="prismatic">
    <parent link="table_base"/>
    <child link="link_6_8"/>
    <origin ryp="0 0 0" xyz="0.1145 0.1485 0"/>
    <axis xyz="0 0 1"/>
    <limit effort="4" lower="0" upper="0.045" velocity="0.01"/>
  </joint>
  <link name="link_6_7">
    <visual>
      <geometry>
        <box size="0.005 0.005 0.055"/>
      </geometry>
      <origin rpy="0 0 0" xyz="0 0 -0.0275"/>
      <material name="blue">
        <color rgba="0 0 1 0.9"/>
      </material>
    </visual>
    <collision>
      <geometry>
        <box size="0.005 0.005 0.055"/>
      </geometry>
      <origin rpy="0 0 0" xyz="0 0 -0.0275"/>
    </collision>
    <inertial>
      <origin rpy="0 0 0" xyz="0 0 0"/>
      <mass value="0.5"/>
      <inertia ixx="1.0" ixy="0.0" ixz="0.0" iyy="1.0" iyz="0.0" izz="1.0"/>
    </inertial>
  </link>
  <joint name="joint_6_7" type="prismatic">
    <parent link="table_base"/>
    <child link="link_6_7"/>
    <origin ryp="0 0 0" xyz="0.1145 0.1315 0"/>
    <axis xyz="0 0 1"/>
    <limit effort="4" lower="0" upper="0.045" velocity="0.01"/>
  </joint>
  <link name="link_6_6">
    <visual>
      <geometry>
        <box size="0.005 0.005 0.055"/>
      </geometry>
      <origin rpy="0 0 0" xyz="0 0 -0.0275"/>
      <material name="blue">
        <color rgba="0 0 1 0.9"/>
      </material>
    </visual>
    <collision>
      <geometry>
        <box size="0.005 0.005 0.055"/>
      </geometry>
      <origin rpy="0 0 0" xyz="0 0 -0.0275"/>
    </collision>
    <inertial>
      <origin rpy="0 0 0" xyz="0 0 0"/>
      <mass value="0.5"/>
      <inertia ixx="1.0" ixy="0.0" ixz="0.0" iyy="1.0" iyz="0.0" izz="1.0"/>
    </inertial>
  </link>
  <joint name="joint_6_6" type="prismatic">
    <parent link="table_base"/>
    <child link="link_6_6"/>
    <origin ryp="0 0 0" xyz="0.1145 0.1145 0"/>
    <axis xyz="0 0 1"/>
    <limit effort="4" lower="0" upper="0.045" velocity="0.01"/>
  </joint>
  <link name="link_6_5">
    <visual>
      <geometry>
        <box size="0.005 0.005 0.055"/>
      </geometry>
      <origin rpy="0 0 0" xyz="0 0 -0.0275"/>
      <material name="blue">
        <color rgba="0 0 1 0.9"/>
      </material>
    </visual>
    <collision>
      <geometry>
        <box size="0.005 0.005 0.055"/>
      </geometry>
      <origin rpy="0 0 0" xyz="0 0 -0.0275"/>
    </collision>
    <inertial>
      <origin rpy="0 0 0" xyz="0 0 0"/>
      <mass value="0.5"/>
      <inertia ixx="1.0" ixy="0.0" ixz="0.0" iyy="1.0" iyz="0.0" izz="1.0"/>
    </inertial>
  </link>
  <joint name="joint_6_5" type="prismatic">
    <parent link="table_base"/>
    <child link="link_6_5"/>
    <origin ryp="0 0 0" xyz="0.1145 0.09749999999999999 0"/>
    <axis xyz="0 0 1"/>
    <limit effort="4" lower="0" upper="0.045" velocity="0.01"/>
  </joint>
  <link name="link_6_4">
    <visual>
      <geometry>
        <box size="0.005 0.005 0.055"/>
      </geometry>
      <origin rpy="0 0 0" xyz="0 0 -0.0275"/>
      <material name="blue">
        <color rgba="0 0 1 0.9"/>
      </material>
    </visual>
    <collision>
      <geometry>
        <box size="0.005 0.005 0.055"/>
      </geometry>
      <origin rpy="0 0 0" xyz="0 0 -0.0275"/>
    </collision>
    <inertial>
      <origin rpy="0 0 0" xyz="0 0 0"/>
      <mass value="0.5"/>
      <inertia ixx="1.0" ixy="0.0" ixz="0.0" iyy="1.0" iyz="0.0" izz="1.0"/>
    </inertial>
  </link>
  <joint name="joint_6_4" type="prismatic">
    <parent link="table_base"/>
    <child link="link_6_4"/>
    <origin ryp="0 0 0" xyz="0.1145 0.0805 0"/>
    <axis xyz="0 0 1"/>
    <limit effort="4" lower="0" upper="0.045" velocity="0.01"/>
  </joint>
  <link name="link_6_3">
    <visual>
      <geometry>
        <box size="0.005 0.005 0.055"/>
      </geometry>
      <origin rpy="0 0 0" xyz="0 0 -0.0275"/>
      <material name="blue">
        <color rgba="0 0 1 0.9"/>
      </material>
    </visual>
    <collision>
      <geometry>
        <box size="0.005 0.005 0.055"/>
      </geometry>
      <origin rpy="0 0 0" xyz="0 0 -0.0275"/>
    </collision>
    <inertial>
      <origin rpy="0 0 0" xyz="0 0 0"/>
      <mass value="0.5"/>
      <inertia ixx="1.0" ixy="0.0" ixz="0.0" iyy="1.0" iyz="0.0" izz="1.0"/>
    </inertial>
  </link>
  <joint name="joint_6_3" type="prismatic">
    <parent link="table_base"/>
    <child link="link_6_3"/>
    <origin ryp="0 0 0" xyz="0.1145 0.0635 0"/>
    <axis xyz="0 0 1"/>
    <limit effort="4" lower="0" upper="0.045" velocity="0.01"/>
  </joint>
  <link name="link_6_2">
    <visual>
      <geometry>
        <box size="0.005 0.005 0.055"/>
      </geometry>
      <origin rpy="0 0 0" xyz="0 0 -0.0275"/>
      <material name="blue">
        <color rgba="0 0 1 0.9"/>
      </material>
    </visual>
    <collision>
      <geometry>
        <box size="0.005 0.005 0.055"/>
      </geometry>
      <origin rpy="0 0 0" xyz="0 0 -0.0275"/>
    </collision>
    <inertial>
      <origin rpy="0 0 0" xyz="0 0 0"/>
      <mass value="0.5"/>
      <inertia ixx="1.0" ixy="0.0" ixz="0.0" iyy="1.0" iyz="0.0" izz="1.0"/>
    </inertial>
  </link>
  <joint name="joint_6_2" type="prismatic">
    <parent link="table_base"/>
    <child link="link_6_2"/>
    <origin ryp="0 0 0" xyz="0.1145 0.0465 0"/>
    <axis xyz="0 0 1"/>
    <limit effort="4" lower="0" upper="0.045" velocity="0.01"/>
  </joint>
  <link name="link_6_1">
    <visual>
      <geometry>
        <box size="0.005 0.005 0.055"/>
      </geometry>
      <origin rpy="0 0 0" xyz="0 0 -0.0275"/>
      <material name="blue">
        <color rgba="0 0 1 0.9"/>
      </material>
    </visual>
    <collision>
      <geometry>
        <box size="0.005 0.005 0.055"/>
      </geometry>
      <origin rpy="0 0 0" xyz="0 0 -0.0275"/>
    </collision>
    <inertial>
      <origin rpy="0 0 0" xyz="0 0 0"/>
      <mass value="0.5"/>
      <inertia ixx="1.0" ixy="0.0" ixz="0.0" iyy="1.0" iyz="0.0" izz="1.0"/>
    </inertial>
  </link>
  <joint name="joint_6_1" type="prismatic">
    <parent link="table_base"/>
    <child link="link_6_1"/>
    <origin ryp="0 0 0" xyz="0.1145 0.0295 0"/>
    <axis xyz="0 0 1"/>
    <limit effort="4" lower="0" upper="0.045" velocity="0.01"/>
  </joint>
  <link name="link_6_0">
    <visual>
      <geometry>
        <box size="0.005 0.005 0.055"/>
      </geometry>
      <origin rpy="0 0 0" xyz="0 0 -0.0275"/>
      <material name="blue">
        <color rgba="0 0 1 0.9"/>
      </material>
    </visual>
    <collision>
      <geometry>
        <box size="0.005 0.005 0.055"/>
      </geometry>
      <origin rpy="0 0 0" xyz="0 0 -0.0275"/>
    </collision>
    <inertial>
      <origin rpy="0 0 0" xyz="0 0 0"/>
      <mass value="0.5"/>
      <inertia ixx="1.0" ixy="0.0" ixz="0.0" iyy="1.0" iyz="0.0" izz="1.0"/>
    </inertial>
  </link>
  <joint name="joint_6_0" type="prismatic">
    <parent link="table_base"/>
    <child link="link_6_0"/>
    <origin ryp="0 0 0" xyz="0.1145 0.0125 0"/>
    <axis xyz="0 0 1"/>
    <limit effort="4" lower="0" upper="0.045" velocity="0.01"/>
  </joint>
  <link name="link_5_9">
    <visual>
      <geometry>
        <box size="0.005 0.005 0.055"/>
      </geometry>
      <origin rpy="0 0 0" xyz="0 0 -0.0275"/>
      <material name="blue">
        <color rgba="0 0 1 0.9"/>
      </material>
    </visual>
    <collision>
      <geometry>
        <box size="0.005 0.005 0.055"/>
      </geometry>
      <origin rpy="0 0 0" xyz="0 0 -0.0275"/>
    </collision>
    <inertial>
      <origin rpy="0 0 0" xyz="0 0 0"/>
      <mass value="0.5"/>
      <inertia ixx="1.0" ixy="0.0" ixz="0.0" iyy="1.0" iyz="0.0" izz="1.0"/>
    </inertial>
  </link>
  <joint name="joint_5_9" type="prismatic">
    <parent link="table_base"/>
    <child link="link_5_9"/>
    <origin ryp="0 0 0" xyz="0.09749999999999999 0.16549999999999998 0"/>
    <axis xyz="0 0 1"/>
    <limit effort="4" lower="0" upper="0.045" velocity="0.01"/>
  </joint>
  <link name="link_5_8">
    <visual>
      <geometry>
        <box size="0.005 0.005 0.055"/>
      </geometry>
      <origin rpy="0 0 0" xyz="0 0 -0.0275"/>
      <material name="blue">
        <color rgba="0 0 1 0.9"/>
      </material>
    </visual>
    <collision>
      <geometry>
        <box size="0.005 0.005 0.055"/>
      </geometry>
      <origin rpy="0 0 0" xyz="0 0 -0.0275"/>
    </collision>
    <inertial>
      <origin rpy="0 0 0" xyz="0 0 0"/>
      <mass value="0.5"/>
      <inertia ixx="1.0" ixy="0.0" ixz="0.0" iyy="1.0" iyz="0.0" izz="1.0"/>
    </inertial>
  </link>
  <joint name="joint_5_8" type="prismatic">
    <parent link="table_base"/>
    <child link="link_5_8"/>
    <origin ryp="0 0 0" xyz="0.09749999999999999 0.1485 0"/>
    <axis xyz="0 0 1"/>
    <limit effort="4" lower="0" upper="0.045" velocity="0.01"/>
  </joint>
  <link name="link_5_7">
    <visual>
      <geometry>
        <box size="0.005 0.005 0.055"/>
      </geometry>
      <origin rpy="0 0 0" xyz="0 0 -0.0275"/>
      <material name="blue">
        <color rgba="0 0 1 0.9"/>
      </material>
    </visual>
    <collision>
      <geometry>
        <box size="0.005 0.005 0.055"/>
      </geometry>
      <origin rpy="0 0 0" xyz="0 0 -0.0275"/>
    </collision>
    <inertial>
      <origin rpy="0 0 0" xyz="0 0 0"/>
      <mass value="0.5"/>
      <inertia ixx="1.0" ixy="0.0" ixz="0.0" iyy="1.0" iyz="0.0" izz="1.0"/>
    </inertial>
  </link>
  <joint name="joint_5_7" type="prismatic">
    <parent link="table_base"/>
    <child link="link_5_7"/>
    <origin ryp="0 0 0" xyz="0.09749999999999999 0.1315 0"/>
    <axis xyz="0 0 1"/>
    <limit effort="4" lower="0" upper="0.045" velocity="0.01"/>
  </joint>
  <link name="link_5_6">
    <visual>
      <geometry>
        <box size="0.005 0.005 0.055"/>
      </geometry>
      <origin rpy="0 0 0" xyz="0 0 -0.0275"/>
      <material name="blue">
        <color rgba="0 0 1 0.9"/>
      </material>
    </visual>
    <collision>
      <geometry>
        <box size="0.005 0.005 0.055"/>
      </geometry>
      <origin rpy="0 0 0" xyz="0 0 -0.0275"/>
    </collision>
    <inertial>
      <origin rpy="0 0 0" xyz="0 0 0"/>
      <mass value="0.5"/>
      <inertia ixx="1.0" ixy="0.0" ixz="0.0" iyy="1.0" iyz="0.0" izz="1.0"/>
    </inertial>
  </link>
  <joint name="joint_5_6" type="prismatic">
    <parent link="table_base"/>
    <child link="link_5_6"/>
    <origin ryp="0 0 0" xyz="0.09749999999999999 0.1145 0"/>
    <axis xyz="0 0 1"/>
    <limit effort="4" lower="0" upper="0.045" velocity="0.01"/>
  </joint>
  <link name="link_5_5">
    <visual>
      <geometry>
        <box size="0.005 0.005 0.055"/>
      </geometry>
      <origin rpy="0 0 0" xyz="0 0 -0.0275"/>
      <material name="blue">
        <color rgba="0 0 1 0.9"/>
      </material>
    </visual>
    <collision>
      <geometry>
        <box size="0.005 0.005 0.055"/>
      </geometry>
      <origin rpy="0 0 0" xyz="0 0 -0.0275"/>
    </collision>
    <inertial>
      <origin rpy="0 0 0" xyz="0 0 0"/>
      <mass value="0.5"/>
      <inertia ixx="1.0" ixy="0.0" ixz="0.0" iyy="1.0" iyz="0.0" izz="1.0"/>
    </inertial>
  </link>
  <joint name="joint_5_5" type="prismatic">
    <parent link="table_base"/>
    <child link="link_5_5"/>
    <origin ryp="0 0 0" xyz="0.09749999999999999 0.09749999999999999 0"/>
    <axis xyz="0 0 1"/>
    <limit effort="4" lower="0" upper="0.045" velocity="0.01"/>
  </joint>
  <link name="link_5_4">
    <visual>
      <geometry>
        <box size="0.005 0.005 0.055"/>
      </geometry>
      <origin rpy="0 0 0" xyz="0 0 -0.0275"/>
      <material name="blue">
        <color rgba="0 0 1 0.9"/>
      </material>
    </visual>
    <collision>
      <geometry>
        <box size="0.005 0.005 0.055"/>
      </geometry>
      <origin rpy="0 0 0" xyz="0 0 -0.0275"/>
    </collision>
    <inertial>
      <origin rpy="0 0 0" xyz="0 0 0"/>
      <mass value="0.5"/>
      <inertia ixx="1.0" ixy="0.0" ixz="0.0" iyy="1.0" iyz="0.0" izz="1.0"/>
    </inertial>
  </link>
  <joint name="joint_5_4" type="prismatic">
    <parent link="table_base"/>
    <child link="link_5_4"/>
    <origin ryp="0 0 0" xyz="0.09749999999999999 0.0805 0"/>
    <axis xyz="0 0 1"/>
    <limit effort="4" lower="0" upper="0.045" velocity="0.01"/>
  </joint>
  <link name="link_5_3">
    <visual>
      <geometry>
        <box size="0.005 0.005 0.055"/>
      </geometry>
      <origin rpy="0 0 0" xyz="0 0 -0.0275"/>
      <material name="blue">
        <color rgba="0 0 1 0.9"/>
      </material>
    </visual>
    <collision>
      <geometry>
        <box size="0.005 0.005 0.055"/>
      </geometry>
      <origin rpy="0 0 0" xyz="0 0 -0.0275"/>
    </collision>
    <inertial>
      <origin rpy="0 0 0" xyz="0 0 0"/>
      <mass value="0.5"/>
      <inertia ixx="1.0" ixy="0.0" ixz="0.0" iyy="1.0" iyz="0.0" izz="1.0"/>
    </inertial>
  </link>
  <joint name="joint_5_3" type="prismatic">
    <parent link="table_base"/>
    <child link="link_5_3"/>
    <origin ryp="0 0 0" xyz="0.09749999999999999 0.0635 0"/>
    <axis xyz="0 0 1"/>
    <limit effort="4" lower="0" upper="0.045" velocity="0.01"/>
  </joint>
  <link name="link_5_2">
    <visual>
      <geometry>
        <box size="0.005 0.005 0.055"/>
      </geometry>
      <origin rpy="0 0 0" xyz="0 0 -0.0275"/>
      <material name="blue">
        <color rgba="0 0 1 0.9"/>
      </material>
    </visual>
    <collision>
      <geometry>
        <box size="0.005 0.005 0.055"/>
      </geometry>
      <origin rpy="0 0 0" xyz="0 0 -0.0275"/>
    </collision>
    <inertial>
      <origin rpy="0 0 0" xyz="0 0 0"/>
      <mass value="0.5"/>
      <inertia ixx="1.0" ixy="0.0" ixz="0.0" iyy="1.0" iyz="0.0" izz="1.0"/>
    </inertial>
  </link>
  <joint name="joint_5_2" type="prismatic">
    <parent link="table_base"/>
    <child link="link_5_2"/>
    <origin ryp="0 0 0" xyz="0.09749999999999999 0.0465 0"/>
    <axis xyz="0 0 1"/>
    <limit effort="4" lower="0" upper="0.045" velocity="0.01"/>
  </joint>
  <link name="link_5_1">
    <visual>
      <geometry>
        <box size="0.005 0.005 0.055"/>
      </geometry>
      <origin rpy="0 0 0" xyz="0 0 -0.0275"/>
      <material name="blue">
        <color rgba="0 0 1 0.9"/>
      </material>
    </visual>
    <collision>
      <geometry>
        <box size="0.005 0.005 0.055"/>
      </geometry>
      <origin rpy="0 0 0" xyz="0 0 -0.0275"/>
    </collision>
    <inertial>
      <origin rpy="0 0 0" xyz="0 0 0"/>
      <mass value="0.5"/>
      <inertia ixx="1.0" ixy="0.0" ixz="0.0" iyy="1.0" iyz="0.0" izz="1.0"/>
    </inertial>
  </link>
  <joint name="joint_5_1" type="prismatic">
    <parent link="table_base"/>
    <child link="link_5_1"/>
    <origin ryp="0 0 0" xyz="0.09749999999999999 0.0295 0"/>
    <axis xyz="0 0 1"/>
    <limit effort="4" lower="0" upper="0.045" velocity="0.01"/>
  </joint>
  <link name="link_5_0">
    <visual>
      <geometry>
        <box size="0.005 0.005 0.055"/>
      </geometry>
      <origin rpy="0 0 0" xyz="0 0 -0.0275"/>
      <material name="blue">
        <color rgba="0 0 1 0.9"/>
      </material>
    </visual>
    <collision>
      <geometry>
        <box size="0.005 0.005 0.055"/>
      </geometry>
      <origin rpy="0 0 0" xyz="0 0 -0.0275"/>
    </collision>
    <inertial>
      <origin rpy="0 0 0" xyz="0 0 0"/>
      <mass value="0.5"/>
      <inertia ixx="1.0" ixy="0.0" ixz="0.0" iyy="1.0" iyz="0.0" izz="1.0"/>
    </inertial>
  </link>
  <joint name="joint_5_0" type="prismatic">
    <parent link="table_base"/>
    <child link="link_5_0"/>
    <origin ryp="0 0 0" xyz="0.09749999999999999 0.0125 0"/>
    <axis xyz="0 0 1"/>
    <limit effort="4" lower="0" upper="0.045" velocity="0.01"/>
  </joint>
  <link name="link_4_9">
    <visual>
      <geometry>
        <box size="0.005 0.005 0.055"/>
      </geometry>
      <origin rpy="0 0 0" xyz="0 0 -0.0275"/>
      <material name="blue">
        <color rgba="0 0 1 0.9"/>
      </material>
    </visual>
    <collision>
      <geometry>
        <box size="0.005 0.005 0.055"/>
      </geometry>
      <origin rpy="0 0 0" xyz="0 0 -0.0275"/>
    </collision>
    <inertial>
      <origin rpy="0 0 0" xyz="0 0 0"/>
      <mass value="0.5"/>
      <inertia ixx="1.0" ixy="0.0" ixz="0.0" iyy="1.0" iyz="0.0" izz="1.0"/>
    </inertial>
  </link>
  <joint name="joint_4_9" type="prismatic">
    <parent link="table_base"/>
    <child link="link_4_9"/>
    <origin ryp="0 0 0" xyz="0.0805 0.16549999999999998 0"/>
    <axis xyz="0 0 1"/>
    <limit effort="4" lower="0" upper="0.045" velocity="0.01"/>
  </joint>
  <link name="link_4_8">
    <visual>
      <geometry>
        <box size="0.005 0.005 0.055"/>
      </geometry>
      <origin rpy="0 0 0" xyz="0 0 -0.0275"/>
      <material name="blue">
        <color rgba="0 0 1 0.9"/>
      </material>
    </visual>
    <collision>
      <geometry>
        <box size="0.005 0.005 0.055"/>
      </geometry>
      <origin rpy="0 0 0" xyz="0 0 -0.0275"/>
    </collision>
    <inertial>
      <origin rpy="0 0 0" xyz="0 0 0"/>
      <mass value="0.5"/>
      <inertia ixx="1.0" ixy="0.0" ixz="0.0" iyy="1.0" iyz="0.0" izz="1.0"/>
    </inertial>
  </link>
  <joint name="joint_4_8" type="prismatic">
    <parent link="table_base"/>
    <child link="link_4_8"/>
    <origin ryp="0 0 0" xyz="0.0805 0.1485 0"/>
    <axis xyz="0 0 1"/>
    <limit effort="4" lower="0" upper="0.045" velocity="0.01"/>
  </joint>
  <link name="link_4_7">
    <visual>
      <geometry>
        <box size="0.005 0.005 0.055"/>
      </geometry>
      <origin rpy="0 0 0" xyz="0 0 -0.0275"/>
      <material name="blue">
        <color rgba="0 0 1 0.9"/>
      </material>
    </visual>
    <collision>
      <geometry>
        <box size="0.005 0.005 0.055"/>
      </geometry>
      <origin rpy="0 0 0" xyz="0 0 -0.0275"/>
    </collision>
    <inertial>
      <origin rpy="0 0 0" xyz="0 0 0"/>
      <mass value="0.5"/>
      <inertia ixx="1.0" ixy="0.0" ixz="0.0" iyy="1.0" iyz="0.0" izz="1.0"/>
    </inertial>
  </link>
  <joint name="joint_4_7" type="prismatic">
    <parent link="table_base"/>
    <child link="link_4_7"/>
    <origin ryp="0 0 0" xyz="0.0805 0.1315 0"/>
    <axis xyz="0 0 1"/>
    <limit effort="4" lower="0" upper="0.045" velocity="0.01"/>
  </joint>
  <link name="link_4_6">
    <visual>
      <geometry>
        <box size="0.005 0.005 0.055"/>
      </geometry>
      <origin rpy="0 0 0" xyz="0 0 -0.0275"/>
      <material name="blue">
        <color rgba="0 0 1 0.9"/>
      </material>
    </visual>
    <collision>
      <geometry>
        <box size="0.005 0.005 0.055"/>
      </geometry>
      <origin rpy="0 0 0" xyz="0 0 -0.0275"/>
    </collision>
    <inertial>
      <origin rpy="0 0 0" xyz="0 0 0"/>
      <mass value="0.5"/>
      <inertia ixx="1.0" ixy="0.0" ixz="0.0" iyy="1.0" iyz="0.0" izz="1.0"/>
    </inertial>
  </link>
  <joint name="joint_4_6" type="prismatic">
    <parent link="table_base"/>
    <child link="link_4_6"/>
    <origin ryp="0 0 0" xyz="0.0805 0.1145 0"/>
    <axis xyz="0 0 1"/>
    <limit effort="4" lower="0" upper="0.045" velocity="0.01"/>
  </joint>
  <link name="link_4_5">
    <visual>
      <geometry>
        <box size="0.005 0.005 0.055"/>
      </geometry>
      <origin rpy="0 0 0" xyz="0 0 -0.0275"/>
      <material name="blue">
        <color rgba="0 0 1 0.9"/>
      </material>
    </visual>
    <collision>
      <geometry>
        <box size="0.005 0.005 0.055"/>
      </geometry>
      <origin rpy="0 0 0" xyz="0 0 -0.0275"/>
    </collision>
    <inertial>
      <origin rpy="0 0 0" xyz="0 0 0"/>
      <mass value="0.5"/>
      <inertia ixx="1.0" ixy="0.0" ixz="0.0" iyy="1.0" iyz="0.0" izz="1.0"/>
    </inertial>
  </link>
  <joint name="joint_4_5" type="prismatic">
    <parent link="table_base"/>
    <child link="link_4_5"/>
    <origin ryp="0 0 0" xyz="0.0805 0.09749999999999999 0"/>
    <axis xyz="0 0 1"/>
    <limit effort="4" lower="0" upper="0.045" velocity="0.01"/>
  </joint>
  <link name="link_4_4">
    <visual>
      <geometry>
        <box size="0.005 0.005 0.055"/>
      </geometry>
      <origin rpy="0 0 0" xyz="0 0 -0.0275"/>
      <material name="blue">
        <color rgba="0 0 1 0.9"/>
      </material>
    </visual>
    <collision>
      <geometry>
        <box size="0.005 0.005 0.055"/>
      </geometry>
      <origin rpy="0 0 0" xyz="0 0 -0.0275"/>
    </collision>
    <inertial>
      <origin rpy="0 0 0" xyz="0 0 0"/>
      <mass value="0.5"/>
      <inertia ixx="1.0" ixy="0.0" ixz="0.0" iyy="1.0" iyz="0.0" izz="1.0"/>
    </inertial>
  </link>
  <joint name="joint_4_4" type="prismatic">
    <parent link="table_base"/>
    <child link="link_4_4"/>
    <origin ryp="0 0 0" xyz="0.0805 0.0805 0"/>
    <axis xyz="0 0 1"/>
    <limit effort="4" lower="0" upper="0.045" velocity="0.01"/>
  </joint>
  <link name="link_4_3">
    <visual>
      <geometry>
        <box size="0.005 0.005 0.055"/>
      </geometry>
      <origin rpy="0 0 0" xyz="0 0 -0.0275"/>
      <material name="blue">
        <color rgba="0 0 1 0.9"/>
      </material>
    </visual>
    <collision>
      <geometry>
        <box size="0.005 0.005 0.055"/>
      </geometry>
      <origin rpy="0 0 0" xyz="0 0 -0.0275"/>
    </collision>
    <inertial>
      <origin rpy="0 0 0" xyz="0 0 0"/>
      <mass value="0.5"/>
      <inertia ixx="1.0" ixy="0.0" ixz="0.0" iyy="1.0" iyz="0.0" izz="1.0"/>
    </inertial>
  </link>
  <joint name="joint_4_3" type="prismatic">
    <parent link="table_base"/>
    <child link="link_4_3"/>
    <origin ryp="0 0 0" xyz="0.0805 0.0635 0"/>
    <axis xyz="0 0 1"/>
    <limit effort="4" lower="0" upper="0.045" velocity="0.01"/>
  </joint>
  <link name="link_4_2">
    <visual>
      <geometry>
        <box size="0.005 0.005 0.055"/>
      </geometry>
      <origin rpy="0 0 0" xyz="0 0 -0.0275"/>
      <material name="blue">
        <color rgba="0 0 1 0.9"/>
      </material>
    </visual>
    <collision>
      <geometry>
        <box size="0.005 0.005 0.055"/>
      </geometry>
      <origin rpy="0 0 0" xyz="0 0 -0.0275"/>
    </collision>
    <inertial>
      <origin rpy="0 0 0" xyz="0 0 0"/>
      <mass value="0.5"/>
      <inertia ixx="1.0" ixy="0.0" ixz="0.0" iyy="1.0" iyz="0.0" izz="1.0"/>
    </inertial>
  </link>
  <joint name="joint_4_2" type="prismatic">
    <parent link="table_base"/>
    <child link="link_4_2"/>
    <origin ryp="0 0 0" xyz="0.0805 0.0465 0"/>
    <axis xyz="0 0 1"/>
    <limit effort="4" lower="0" upper="0.045" velocity="0.01"/>
  </joint>
  <link name="link_4_1">
    <visual>
      <geometry>
        <box size="0.005 0.005 0.055"/>
      </geometry>
      <origin rpy="0 0 0" xyz="0 0 -0.0275"/>
      <material name="blue">
        <color rgba="0 0 1 0.9"/>
      </material>
    </visual>
    <collision>
      <geometry>
        <box size="0.005 0.005 0.055"/>
      </geometry>
      <origin rpy="0 0 0" xyz="0 0 -0.0275"/>
    </collision>
    <inertial>
      <origin rpy="0 0 0" xyz="0 0 0"/>
      <mass value="0.5"/>
      <inertia ixx="1.0" ixy="0.0" ixz="0.0" iyy="1.0" iyz="0.0" izz="1.0"/>
    </inertial>
  </link>
  <joint name="joint_4_1" type="prismatic">
    <parent link="table_base"/>
    <child link="link_4_1"/>
    <origin ryp="0 0 0" xyz="0.0805 0.0295 0"/>
    <axis xyz="0 0 1"/>
    <limit effort="4" lower="0" upper="0.045" velocity="0.01"/>
  </joint>
  <link name="link_4_0">
    <visual>
      <geometry>
        <box size="0.005 0.005 0.055"/>
      </geometry>
      <origin rpy="0 0 0" xyz="0 0 -0.0275"/>
      <material name="blue">
        <color rgba="0 0 1 0.9"/>
      </material>
    </visual>
    <collision>
      <geometry>
        <box size="0.005 0.005 0.055"/>
      </geometry>
      <origin rpy="0 0 0" xyz="0 0 -0.0275"/>
    </collision>
    <inertial>
      <origin rpy="0 0 0" xyz="0 0 0"/>
      <mass value="0.5"/>
      <inertia ixx="1.0" ixy="0.0" ixz="0.0" iyy="1.0" iyz="0.0" izz="1.0"/>
    </inertial>
  </link>
  <joint name="joint_4_0" type="prismatic">
    <parent link="table_base"/>
    <child link="link_4_0"/>
    <origin ryp="0 0 0" xyz="0.0805 0.0125 0"/>
    <axis xyz="0 0 1"/>
    <limit effort="4" lower="0" upper="0.045" velocity="0.01"/>
  </joint>
  <link name="link_3_9">
    <visual>
      <geometry>
        <box size="0.005 0.005 0.055"/>
      </geometry>
      <origin rpy="0 0 0" xyz="0 0 -0.0275"/>
      <material name="blue">
        <color rgba="0 0 1 0.9"/>
      </material>
    </visual>
    <collision>
      <geometry>
        <box size="0.005 0.005 0.055"/>
      </geometry>
      <origin rpy="0 0 0" xyz="0 0 -0.0275"/>
    </collision>
    <inertial>
      <origin rpy="0 0 0" xyz="0 0 0"/>
      <mass value="0.5"/>
      <inertia ixx="1.0" ixy="0.0" ixz="0.0" iyy="1.0" iyz="0.0" izz="1.0"/>
    </inertial>
  </link>
  <joint name="joint_3_9" type="prismatic">
    <parent link="table_base"/>
    <child link="link_3_9"/>
    <origin ryp="0 0 0" xyz="0.0635 0.16549999999999998 0"/>
    <axis xyz="0 0 1"/>
    <limit effort="4" lower="0" upper="0.045" velocity="0.01"/>
  </joint>
  <link name="link_3_8">
    <visual>
      <geometry>
        <box size="0.005 0.005 0.055"/>
      </geometry>
      <origin rpy="0 0 0" xyz="0 0 -0.0275"/>
      <material name="blue">
        <color rgba="0 0 1 0.9"/>
      </material>
    </visual>
    <collision>
      <geometry>
        <box size="0.005 0.005 0.055"/>
      </geometry>
      <origin rpy="0 0 0" xyz="0 0 -0.0275"/>
    </collision>
    <inertial>
      <origin rpy="0 0 0" xyz="0 0 0"/>
      <mass value="0.5"/>
      <inertia ixx="1.0" ixy="0.0" ixz="0.0" iyy="1.0" iyz="0.0" izz="1.0"/>
    </inertial>
  </link>
  <joint name="joint_3_8" type="prismatic">
    <parent link="table_base"/>
    <child link="link_3_8"/>
    <origin ryp="0 0 0" xyz="0.0635 0.1485 0"/>
    <axis xyz="0 0 1"/>
    <limit effort="4" lower="0" upper="0.045" velocity="0.01"/>
  </joint>
  <link name="link_3_7">
    <visual>
      <geometry>
        <box size="0.005 0.005 0.055"/>
      </geometry>
      <origin rpy="0 0 0" xyz="0 0 -0.0275"/>
      <material name="blue">
        <color rgba="0 0 1 0.9"/>
      </material>
    </visual>
    <collision>
      <geometry>
        <box size="0.005 0.005 0.055"/>
      </geometry>
      <origin rpy="0 0 0" xyz="0 0 -0.0275"/>
    </collision>
    <inertial>
      <origin rpy="0 0 0" xyz="0 0 0"/>
      <mass value="0.5"/>
      <inertia ixx="1.0" ixy="0.0" ixz="0.0" iyy="1.0" iyz="0.0" izz="1.0"/>
    </inertial>
  </link>
  <joint name="joint_3_7" type="prismatic">
    <parent link="table_base"/>
    <child link="link_3_7"/>
    <origin ryp="0 0 0" xyz="0.0635 0.1315 0"/>
    <axis xyz="0 0 1"/>
    <limit effort="4" lower="0" upper="0.045" velocity="0.01"/>
  </joint>
  <link name="link_3_6">
    <visual>
      <geometry>
        <box size="0.005 0.005 0.055"/>
      </geometry>
      <origin rpy="0 0 0" xyz="0 0 -0.0275"/>
      <material name="blue">
        <color rgba="0 0 1 0.9"/>
      </material>
    </visual>
    <collision>
      <geometry>
        <box size="0.005 0.005 0.055"/>
      </geometry>
      <origin rpy="0 0 0" xyz="0 0 -0.0275"/>
    </collision>
    <inertial>
      <origin rpy="0 0 0" xyz="0 0 0"/>
      <mass value="0.5"/>
      <inertia ixx="1.0" ixy="0.0" ixz="0.0" iyy="1.0" iyz="0.0" izz="1.0"/>
    </inertial>
  </link>
  <joint name="joint_3_6" type="prismatic">
    <parent link="table_base"/>
    <child link="link_3_6"/>
    <origin ryp="0 0 0" xyz="0.0635 0.1145 0"/>
    <axis xyz="0 0 1"/>
    <limit effort="4" lower="0" upper="0.045" velocity="0.01"/>
  </joint>
  <link name="link_3_5">
    <visual>
      <geometry>
        <box size="0.005 0.005 0.055"/>
      </geometry>
      <origin rpy="0 0 0" xyz="0 0 -0.0275"/>
      <material name="blue">
        <color rgba="0 0 1 0.9"/>
      </material>
    </visual>
    <collision>
      <geometry>
        <box size="0.005 0.005 0.055"/>
      </geometry>
      <origin rpy="0 0 0" xyz="0 0 -0.0275"/>
    </collision>
    <inertial>
      <origin rpy="0 0 0" xyz="0 0 0"/>
      <mass value="0.5"/>
      <inertia ixx="1.0" ixy="0.0" ixz="0.0" iyy="1.0" iyz="0.0" izz="1.0"/>
    </inertial>
  </link>
  <joint name="joint_3_5" type="prismatic">
    <parent link="table_base"/>
    <child link="link_3_5"/>
    <origin ryp="0 0 0" xyz="0.0635 0.09749999999999999 0"/>
    <axis xyz="0 0 1"/>
    <limit effort="4" lower="0" upper="0.045" velocity="0.01"/>
  </joint>
  <link name="link_3_4">
    <visual>
      <geometry>
        <box size="0.005 0.005 0.055"/>
      </geometry>
      <origin rpy="0 0 0" xyz="0 0 -0.0275"/>
      <material name="blue">
        <color rgba="0 0 1 0.9"/>
      </material>
    </visual>
    <collision>
      <geometry>
        <box size="0.005 0.005 0.055"/>
      </geometry>
      <origin rpy="0 0 0" xyz="0 0 -0.0275"/>
    </collision>
    <inertial>
      <origin rpy="0 0 0" xyz="0 0 0"/>
      <mass value="0.5"/>
      <inertia ixx="1.0" ixy="0.0" ixz="0.0" iyy="1.0" iyz="0.0" izz="1.0"/>
    </inertial>
  </link>
  <joint name="joint_3_4" type="prismatic">
    <parent link="table_base"/>
    <child link="link_3_4"/>
    <origin ryp="0 0 0" xyz="0.0635 0.0805 0"/>
    <axis xyz="0 0 1"/>
    <limit effort="4" lower="0" upper="0.045" velocity="0.01"/>
  </joint>
  <link name="link_3_3">
    <visual>
      <geometry>
        <box size="0.005 0.005 0.055"/>
      </geometry>
      <origin rpy="0 0 0" xyz="0 0 -0.0275"/>
      <material name="blue">
        <color rgba="0 0 1 0.9"/>
      </material>
    </visual>
    <collision>
      <geometry>
        <box size="0.005 0.005 0.055"/>
      </geometry>
      <origin rpy="0 0 0" xyz="0 0 -0.0275"/>
    </collision>
    <inertial>
      <origin rpy="0 0 0" xyz="0 0 0"/>
      <mass value="0.5"/>
      <inertia ixx="1.0" ixy="0.0" ixz="0.0" iyy="1.0" iyz="0.0" izz="1.0"/>
    </inertial>
  </link>
  <joint name="joint_3_3" type="prismatic">
    <parent link="table_base"/>
    <child link="link_3_3"/>
    <origin ryp="0 0 0" xyz="0.0635 0.0635 0"/>
    <axis xyz="0 0 1"/>
    <limit effort="4" lower="0" upper="0.045" velocity="0.01"/>
  </joint>
  <link name="link_3_2">
    <visual>
      <geometry>
        <box size="0.005 0.005 0.055"/>
      </geometry>
      <origin rpy="0 0 0" xyz="0 0 -0.0275"/>
      <material name="blue">
        <color rgba="0 0 1 0.9"/>
      </material>
    </visual>
    <collision>
      <geometry>
        <box size="0.005 0.005 0.055"/>
      </geometry>
      <origin rpy="0 0 0" xyz="0 0 -0.0275"/>
    </collision>
    <inertial>
      <origin rpy="0 0 0" xyz="0 0 0"/>
      <mass value="0.5"/>
      <inertia ixx="1.0" ixy="0.0" ixz="0.0" iyy="1.0" iyz="0.0" izz="1.0"/>
    </inertial>
  </link>
  <joint name="joint_3_2" type="prismatic">
    <parent link="table_base"/>
    <child link="link_3_2"/>
    <origin ryp="0 0 0" xyz="0.0635 0.0465 0"/>
    <axis xyz="0 0 1"/>
    <limit effort="4" lower="0" upper="0.045" velocity="0.01"/>
  </joint>
  <link name="link_3_1">
    <visual>
      <geometry>
        <box size="0.005 0.005 0.055"/>
      </geometry>
      <origin rpy="0 0 0" xyz="0 0 -0.0275"/>
      <material name="blue">
        <color rgba="0 0 1 0.9"/>
      </material>
    </visual>
    <collision>
      <geometry>
        <box size="0.005 0.005 0.055"/>
      </geometry>
      <origin rpy="0 0 0" xyz="0 0 -0.0275"/>
    </collision>
    <inertial>
      <origin rpy="0 0 0" xyz="0 0 0"/>
      <mass value="0.5"/>
      <inertia ixx="1.0" ixy="0.0" ixz="0.0" iyy="1.0" iyz="0.0" izz="1.0"/>
    </inertial>
  </link>
  <joint name="joint_3_1" type="prismatic">
    <parent link="table_base"/>
    <child link="link_3_1"/>
    <origin ryp="0 0 0" xyz="0.0635 0.0295 0"/>
    <axis xyz="0 0 1"/>
    <limit effort="4" lower="0" upper="0.045" velocity="0.01"/>
  </joint>
  <link name="link_3_0">
    <visual>
      <geometry>
        <box size="0.005 0.005 0.055"/>
      </geometry>
      <origin rpy="0 0 0" xyz="0 0 -0.0275"/>
      <material name="blue">
        <color rgba="0 0 1 0.9"/>
      </material>
    </visual>
    <collision>
      <geometry>
        <box size="0.005 0.005 0.055"/>
      </geometry>
      <origin rpy="0 0 0" xyz="0 0 -0.0275"/>
    </collision>
    <inertial>
      <origin rpy="0 0 0" xyz="0 0 0"/>
      <mass value="0.5"/>
      <inertia ixx="1.0" ixy="0.0" ixz="0.0" iyy="1.0" iyz="0.0" izz="1.0"/>
    </inertial>
  </link>
  <joint name="joint_3_0" type="prismatic">
    <parent link="table_base"/>
    <child link="link_3_0"/>
    <origin ryp="0 0 0" xyz="0.0635 0.0125 0"/>
    <axis xyz="0 0 1"/>
    <limit effort="4" lower="0" upper="0.045" velocity="0.01"/>
  </joint>
  <link name="link_2_9">
    <visual>
      <geometry>
        <box size="0.005 0.005 0.055"/>
      </geometry>
      <origin rpy="0 0 0" xyz="0 0 -0.0275"/>
      <material name="blue">
        <color rgba="0 0 1 0.9"/>
      </material>
    </visual>
    <collision>
      <geometry>
        <box size="0.005 0.005 0.055"/>
      </geometry>
      <origin rpy="0 0 0" xyz="0 0 -0.0275"/>
    </collision>
    <inertial>
      <origin rpy="0 0 0" xyz="0 0 0"/>
      <mass value="0.5"/>
      <inertia ixx="1.0" ixy="0.0" ixz="0.0" iyy="1.0" iyz="0.0" izz="1.0"/>
    </inertial>
  </link>
  <joint name="joint_2_9" type="prismatic">
    <parent link="table_base"/>
    <child link="link_2_9"/>
    <origin ryp="0 0 0" xyz="0.0465 0.16549999999999998 0"/>
    <axis xyz="0 0 1"/>
    <limit effort="4" lower="0" upper="0.045" velocity="0.01"/>
  </joint>
  <link name="link_2_8">
    <visual>
      <geometry>
        <box size="0.005 0.005 0.055"/>
      </geometry>
      <origin rpy="0 0 0" xyz="0 0 -0.0275"/>
      <material name="blue">
        <color rgba="0 0 1 0.9"/>
      </material>
    </visual>
    <collision>
      <geometry>
        <box size="0.005 0.005 0.055"/>
      </geometry>
      <origin rpy="0 0 0" xyz="0 0 -0.0275"/>
    </collision>
    <inertial>
      <origin rpy="0 0 0" xyz="0 0 0"/>
      <mass value="0.5"/>
      <inertia ixx="1.0" ixy="0.0" ixz="0.0" iyy="1.0" iyz="0.0" izz="1.0"/>
    </inertial>
  </link>
  <joint name="joint_2_8" type="prismatic">
    <parent link="table_base"/>
    <child link="link_2_8"/>
    <origin ryp="0 0 0" xyz="0.0465 0.1485 0"/>
    <axis xyz="0 0 1"/>
    <limit effort="4" lower="0" upper="0.045" velocity="0.01"/>
  </joint>
  <link name="link_2_7">
    <visual>
      <geometry>
        <box size="0.005 0.005 0.055"/>
      </geometry>
      <origin rpy="0 0 0" xyz="0 0 -0.0275"/>
      <material name="blue">
        <color rgba="0 0 1 0.9"/>
      </material>
    </visual>
    <collision>
      <geometry>
        <box size="0.005 0.005 0.055"/>
      </geometry>
      <origin rpy="0 0 0" xyz="0 0 -0.0275"/>
    </collision>
    <inertial>
      <origin rpy="0 0 0" xyz="0 0 0"/>
      <mass value="0.5"/>
      <inertia ixx="1.0" ixy="0.0" ixz="0.0" iyy="1.0" iyz="0.0" izz="1.0"/>
    </inertial>
  </link>
  <joint name="joint_2_7" type="prismatic">
    <parent link="table_base"/>
    <child link="link_2_7"/>
    <origin ryp="0 0 0" xyz="0.0465 0.1315 0"/>
    <axis xyz="0 0 1"/>
    <limit effort="4" lower="0" upper="0.045" velocity="0.01"/>
  </joint>
  <link name="link_2_6">
    <visual>
      <geometry>
        <box size="0.005 0.005 0.055"/>
      </geometry>
      <origin rpy="0 0 0" xyz="0 0 -0.0275"/>
      <material name="blue">
        <color rgba="0 0 1 0.9"/>
      </material>
    </visual>
    <collision>
      <geometry>
        <box size="0.005 0.005 0.055"/>
      </geometry>
      <origin rpy="0 0 0" xyz="0 0 -0.0275"/>
    </collision>
    <inertial>
      <origin rpy="0 0 0" xyz="0 0 0"/>
      <mass value="0.5"/>
      <inertia ixx="1.0" ixy="0.0" ixz="0.0" iyy="1.0" iyz="0.0" izz="1.0"/>
    </inertial>
  </link>
  <joint name="joint_2_6" type="prismatic">
    <parent link="table_base"/>
    <child link="link_2_6"/>
    <origin ryp="0 0 0" xyz="0.0465 0.1145 0"/>
    <axis xyz="0 0 1"/>
    <limit effort="4" lower="0" upper="0.045" velocity="0.01"/>
  </joint>
  <link name="link_2_5">
    <visual>
      <geometry>
        <box size="0.005 0.005 0.055"/>
      </geometry>
      <origin rpy="0 0 0" xyz="0 0 -0.0275"/>
      <material name="blue">
        <color rgba="0 0 1 0.9"/>
      </material>
    </visual>
    <collision>
      <geometry>
        <box size="0.005 0.005 0.055"/>
      </geometry>
      <origin rpy="0 0 0" xyz="0 0 -0.0275"/>
    </collision>
    <inertial>
      <origin rpy="0 0 0" xyz="0 0 0"/>
      <mass value="0.5"/>
      <inertia ixx="1.0" ixy="0.0" ixz="0.0" iyy="1.0" iyz="0.0" izz="1.0"/>
    </inertial>
  </link>
  <joint name="joint_2_5" type="prismatic">
    <parent link="table_base"/>
    <child link="link_2_5"/>
    <origin ryp="0 0 0" xyz="0.0465 0.09749999999999999 0"/>
    <axis xyz="0 0 1"/>
    <limit effort="4" lower="0" upper="0.045" velocity="0.01"/>
  </joint>
  <link name="link_2_4">
    <visual>
      <geometry>
        <box size="0.005 0.005 0.055"/>
      </geometry>
      <origin rpy="0 0 0" xyz="0 0 -0.0275"/>
      <material name="blue">
        <color rgba="0 0 1 0.9"/>
      </material>
    </visual>
    <collision>
      <geometry>
        <box size="0.005 0.005 0.055"/>
      </geometry>
      <origin rpy="0 0 0" xyz="0 0 -0.0275"/>
    </collision>
    <inertial>
      <origin rpy="0 0 0" xyz="0 0 0"/>
      <mass value="0.5"/>
      <inertia ixx="1.0" ixy="0.0" ixz="0.0" iyy="1.0" iyz="0.0" izz="1.0"/>
    </inertial>
  </link>
  <joint name="joint_2_4" type="prismatic">
    <parent link="table_base"/>
    <child link="link_2_4"/>
    <origin ryp="0 0 0" xyz="0.0465 0.0805 0"/>
    <axis xyz="0 0 1"/>
    <limit effort="4" lower="0" upper="0.045" velocity="0.01"/>
  </joint>
  <link name="link_2_3">
    <visual>
      <geometry>
        <box size="0.005 0.005 0.055"/>
      </geometry>
      <origin rpy="0 0 0" xyz="0 0 -0.0275"/>
      <material name="blue">
        <color rgba="0 0 1 0.9"/>
      </material>
    </visual>
    <collision>
      <geometry>
        <box size="0.005 0.005 0.055"/>
      </geometry>
      <origin rpy="0 0 0" xyz="0 0 -0.0275"/>
    </collision>
    <inertial>
      <origin rpy="0 0 0" xyz="0 0 0"/>
      <mass value="0.5"/>
      <inertia ixx="1.0" ixy="0.0" ixz="0.0" iyy="1.0" iyz="0.0" izz="1.0"/>
    </inertial>
  </link>
  <joint name="joint_2_3" type="prismatic">
    <parent link="table_base"/>
    <child link="link_2_3"/>
    <origin ryp="0 0 0" xyz="0.0465 0.0635 0"/>
    <axis xyz="0 0 1"/>
    <limit effort="4" lower="0" upper="0.045" velocity="0.01"/>
  </joint>
  <link name="link_2_2">
    <visual>
      <geometry>
        <box size="0.005 0.005 0.055"/>
      </geometry>
      <origin rpy="0 0 0" xyz="0 0 -0.0275"/>
      <material name="blue">
        <color rgba="0 0 1 0.9"/>
      </material>
    </visual>
    <collision>
      <geometry>
        <box size="0.005 0.005 0.055"/>
      </geometry>
      <origin rpy="0 0 0" xyz="0 0 -0.0275"/>
    </collision>
    <inertial>
      <origin rpy="0 0 0" xyz="0 0 0"/>
      <mass value="0.5"/>
      <inertia ixx="1.0" ixy="0.0" ixz="0.0" iyy="1.0" iyz="0.0" izz="1.0"/>
    </inertial>
  </link>
  <joint name="joint_2_2" type="prismatic">
    <parent link="table_base"/>
    <child link="link_2_2"/>
    <origin ryp="0 0 0" xyz="0.0465 0.0465 0"/>
    <axis xyz="0 0 1"/>
    <limit effort="4" lower="0" upper="0.045" velocity="0.01"/>
  </joint>
  <link name="link_2_1">
    <visual>
      <geometry>
        <box size="0.005 0.005 0.055"/>
      </geometry>
      <origin rpy="0 0 0" xyz="0 0 -0.0275"/>
      <material name="blue">
        <color rgba="0 0 1 0.9"/>
      </material>
    </visual>
    <collision>
      <geometry>
        <box size="0.005 0.005 0.055"/>
      </geometry>
      <origin rpy="0 0 0" xyz="0 0 -0.0275"/>
    </collision>
    <inertial>
      <origin rpy="0 0 0" xyz="0 0 0"/>
      <mass value="0.5"/>
      <inertia ixx="1.0" ixy="0.0" ixz="0.0" iyy="1.0" iyz="0.0" izz="1.0"/>
    </inertial>
  </link>
  <joint name="joint_2_1" type="prismatic">
    <parent link="table_base"/>
    <child link="link_2_1"/>
    <origin ryp="0 0 0" xyz="0.0465 0.0295 0"/>
    <axis xyz="0 0 1"/>
    <limit effort="4" lower="0" upper="0.045" velocity="0.01"/>
  </joint>
  <link name="link_2_0">
    <visual>
      <geometry>
        <box size="0.005 0.005 0.055"/>
      </geometry>
      <origin rpy="0 0 0" xyz="0 0 -0.0275"/>
      <material name="blue">
        <color rgba="0 0 1 0.9"/>
      </material>
    </visual>
    <collision>
      <geometry>
        <box size="0.005 0.005 0.055"/>
      </geometry>
      <origin rpy="0 0 0" xyz="0 0 -0.0275"/>
    </collision>
    <inertial>
      <origin rpy="0 0 0" xyz="0 0 0"/>
      <mass value="0.5"/>
      <inertia ixx="1.0" ixy="0.0" ixz="0.0" iyy="1.0" iyz="0.0" izz="1.0"/>
    </inertial>
  </link>
  <joint name="joint_2_0" type="prismatic">
    <parent link="table_base"/>
    <child link="link_2_0"/>
    <origin ryp="0 0 0" xyz="0.0465 0.0125 0"/>
    <axis xyz="0 0 1"/>
    <limit effort="4" lower="0" upper="0.045" velocity="0.01"/>
  </joint>
  <link name="link_1_9">
    <visual>
      <geometry>
        <box size="0.005 0.005 0.055"/>
      </geometry>
      <origin rpy="0 0 0" xyz="0 0 -0.0275"/>
      <material name="blue">
        <color rgba="0 0 1 0.9"/>
      </material>
    </visual>
    <collision>
      <geometry>
        <box size="0.005 0.005 0.055"/>
      </geometry>
      <origin rpy="0 0 0" xyz="0 0 -0.0275"/>
    </collision>
    <inertial>
      <origin rpy="0 0 0" xyz="0 0 0"/>
      <mass value="0.5"/>
      <inertia ixx="1.0" ixy="0.0" ixz="0.0" iyy="1.0" iyz="0.0" izz="1.0"/>
    </inertial>
  </link>
  <joint name="joint_1_9" type="prismatic">
    <parent link="table_base"/>
    <child link="link_1_9"/>
    <origin ryp="0 0 0" xyz="0.0295 0.16549999999999998 0"/>
    <axis xyz="0 0 1"/>
    <limit effort="4" lower="0" upper="0.045" velocity="0.01"/>
  </joint>
  <link name="link_1_8">
    <visual>
      <geometry>
        <box size="0.005 0.005 0.055"/>
      </geometry>
      <origin rpy="0 0 0" xyz="0 0 -0.0275"/>
      <material name="blue">
        <color rgba="0 0 1 0.9"/>
      </material>
    </visual>
    <collision>
      <geometry>
        <box size="0.005 0.005 0.055"/>
      </geometry>
      <origin rpy="0 0 0" xyz="0 0 -0.0275"/>
    </collision>
    <inertial>
      <origin rpy="0 0 0" xyz="0 0 0"/>
      <mass value="0.5"/>
      <inertia ixx="1.0" ixy="0.0" ixz="0.0" iyy="1.0" iyz="0.0" izz="1.0"/>
    </inertial>
  </link>
  <joint name="joint_1_8" type="prismatic">
    <parent link="table_base"/>
    <child link="link_1_8"/>
    <origin ryp="0 0 0" xyz="0.0295 0.1485 0"/>
    <axis xyz="0 0 1"/>
    <limit effort="4" lower="0" upper="0.045" velocity="0.01"/>
  </joint>
  <link name="link_1_7">
    <visual>
      <geometry>
        <box size="0.005 0.005 0.055"/>
      </geometry>
      <origin rpy="0 0 0" xyz="0 0 -0.0275"/>
      <material name="blue">
        <color rgba="0 0 1 0.9"/>
      </material>
    </visual>
    <collision>
      <geometry>
        <box size="0.005 0.005 0.055"/>
      </geometry>
      <origin rpy="0 0 0" xyz="0 0 -0.0275"/>
    </collision>
    <inertial>
      <origin rpy="0 0 0" xyz="0 0 0"/>
      <mass value="0.5"/>
      <inertia ixx="1.0" ixy="0.0" ixz="0.0" iyy="1.0" iyz="0.0" izz="1.0"/>
    </inertial>
  </link>
  <joint name="joint_1_7" type="prismatic">
    <parent link="table_base"/>
    <child link="link_1_7"/>
    <origin ryp="0 0 0" xyz="0.0295 0.1315 0"/>
    <axis xyz="0 0 1"/>
    <limit effort="4" lower="0" upper="0.045" velocity="0.01"/>
  </joint>
  <link name="link_1_6">
    <visual>
      <geometry>
        <box size="0.005 0.005 0.055"/>
      </geometry>
      <origin rpy="0 0 0" xyz="0 0 -0.0275"/>
      <material name="blue">
        <color rgba="0 0 1 0.9"/>
      </material>
    </visual>
    <collision>
      <geometry>
        <box size="0.005 0.005 0.055"/>
      </geometry>
      <origin rpy="0 0 0" xyz="0 0 -0.0275"/>
    </collision>
    <inertial>
      <origin rpy="0 0 0" xyz="0 0 0"/>
      <mass value="0.5"/>
      <inertia ixx="1.0" ixy="0.0" ixz="0.0" iyy="1.0" iyz="0.0" izz="1.0"/>
    </inertial>
  </link>
  <joint name="joint_1_6" type="prismatic">
    <parent link="table_base"/>
    <child link="link_1_6"/>
    <origin ryp="0 0 0" xyz="0.0295 0.1145 0"/>
    <axis xyz="0 0 1"/>
    <limit effort="4" lower="0" upper="0.045" velocity="0.01"/>
  </joint>
  <link name="link_1_5">
    <visual>
      <geometry>
        <box size="0.005 0.005 0.055"/>
      </geometry>
      <origin rpy="0 0 0" xyz="0 0 -0.0275"/>
      <material name="blue">
        <color rgba="0 0 1 0.9"/>
      </material>
    </visual>
    <collision>
      <geometry>
        <box size="0.005 0.005 0.055"/>
      </geometry>
      <origin rpy="0 0 0" xyz="0 0 -0.0275"/>
    </collision>
    <inertial>
      <origin rpy="0 0 0" xyz="0 0 0"/>
      <mass value="0.5"/>
      <inertia ixx="1.0" ixy="0.0" ixz="0.0" iyy="1.0" iyz="0.0" izz="1.0"/>
    </inertial>
  </link>
  <joint name="joint_1_5" type="prismatic">
    <parent link="table_base"/>
    <child link="link_1_5"/>
    <origin ryp="0 0 0" xyz="0.0295 0.09749999999999999 0"/>
    <axis xyz="0 0 1"/>
    <limit effort="4" lower="0" upper="0.045" velocity="0.01"/>
  </joint>
  <link name="link_1_4">
    <visual>
      <geometry>
        <box size="0.005 0.005 0.055"/>
      </geometry>
      <origin rpy="0 0 0" xyz="0 0 -0.0275"/>
      <material name="blue">
        <color rgba="0 0 1 0.9"/>
      </material>
    </visual>
    <collision>
      <geometry>
        <box size="0.005 0.005 0.055"/>
      </geometry>
      <origin rpy="0 0 0" xyz="0 0 -0.0275"/>
    </collision>
    <inertial>
      <origin rpy="0 0 0" xyz="0 0 0"/>
      <mass value="0.5"/>
      <inertia ixx="1.0" ixy="0.0" ixz="0.0" iyy="1.0" iyz="0.0" izz="1.0"/>
    </inertial>
  </link>
  <joint name="joint_1_4" type="prismatic">
    <parent link="table_base"/>
    <child link="link_1_4"/>
    <origin ryp="0 0 0" xyz="0.0295 0.0805 0"/>
    <axis xyz="0 0 1"/>
    <limit effort="4" lower="0" upper="0.045" velocity="0.01"/>
  </joint>
  <link name="link_1_3">
    <visual>
      <geometry>
        <box size="0.005 0.005 0.055"/>
      </geometry>
      <origin rpy="0 0 0" xyz="0 0 -0.0275"/>
      <material name="blue">
        <color rgba="0 0 1 0.9"/>
      </material>
    </visual>
    <collision>
      <geometry>
        <box size="0.005 0.005 0.055"/>
      </geometry>
      <origin rpy="0 0 0" xyz="0 0 -0.0275"/>
    </collision>
    <inertial>
      <origin rpy="0 0 0" xyz="0 0 0"/>
      <mass value="0.5"/>
      <inertia ixx="1.0" ixy="0.0" ixz="0.0" iyy="1.0" iyz="0.0" izz="1.0"/>
    </inertial>
  </link>
  <joint name="joint_1_3" type="prismatic">
    <parent link="table_base"/>
    <child link="link_1_3"/>
    <origin ryp="0 0 0" xyz="0.0295 0.0635 0"/>
    <axis xyz="0 0 1"/>
    <limit effort="4" lower="0" upper="0.045" velocity="0.01"/>
  </joint>
  <link name="link_1_2">
    <visual>
      <geometry>
        <box size="0.005 0.005 0.055"/>
      </geometry>
      <origin rpy="0 0 0" xyz="0 0 -0.0275"/>
      <material name="blue">
        <color rgba="0 0 1 0.9"/>
      </material>
    </visual>
    <collision>
      <geometry>
        <box size="0.005 0.005 0.055"/>
      </geometry>
      <origin rpy="0 0 0" xyz="0 0 -0.0275"/>
    </collision>
    <inertial>
      <origin rpy="0 0 0" xyz="0 0 0"/>
      <mass value="0.5"/>
      <inertia ixx="1.0" ixy="0.0" ixz="0.0" iyy="1.0" iyz="0.0" izz="1.0"/>
    </inertial>
  </link>
  <joint name="joint_1_2" type="prismatic">
    <parent link="table_base"/>
    <child link="link_1_2"/>
    <origin ryp="0 0 0" xyz="0.0295 0.0465 0"/>
    <axis xyz="0 0 1"/>
    <limit effort="4" lower="0" upper="0.045" velocity="0.01"/>
  </joint>
  <link name="link_1_1">
    <visual>
      <geometry>
        <box size="0.005 0.005 0.055"/>
      </geometry>
      <origin rpy="0 0 0" xyz="0 0 -0.0275"/>
      <material name="blue">
        <color rgba="0 0 1 0.9"/>
      </material>
    </visual>
    <collision>
      <geometry>
        <box size="0.005 0.005 0.055"/>
      </geometry>
      <origin rpy="0 0 0" xyz="0 0 -0.0275"/>
    </collision>
    <inertial>
      <origin rpy="0 0 0" xyz="0 0 0"/>
      <mass value="0.5"/>
      <inertia ixx="1.0" ixy="0.0" ixz="0.0" iyy="1.0" iyz="0.0" izz="1.0"/>
    </inertial>
  </link>
  <joint name="joint_1_1" type="prismatic">
    <parent link="table_base"/>
    <child link="link_1_1"/>
    <origin ryp="0 0 0" xyz="0.0295 0.0295 0"/>
    <axis xyz="0 0 1"/>
    <limit effort="4" lower="0" upper="0.045" velocity="0.01"/>
  </joint>
  <link name="link_1_0">
    <visual>
      <geometry>
        <box size="0.005 0.005 0.055"/>
      </geometry>
      <origin rpy="0 0 0" xyz="0 0 -0.0275"/>
      <material name="blue">
        <color rgba="0 0 1 0.9"/>
      </material>
    </visual>
    <collision>
      <geometry>
        <box size="0.005 0.005 0.055"/>
      </geometry>
      <origin rpy="0 0 0" xyz="0 0 -0.0275"/>
    </collision>
    <inertial>
      <origin rpy="0 0 0" xyz="0 0 0"/>
      <mass value="0.5"/>
      <inertia ixx="1.0" ixy="0.0" ixz="0.0" iyy="1.0" iyz="0.0" izz="1.0"/>
    </inertial>
  </link>
  <joint name="joint_1_0" type="prismatic">
    <parent link="table_base"/>
    <child link="link_1_0"/>
    <origin ryp="0 0 0" xyz="0.0295 0.0125 0"/>
    <axis xyz="0 0 1"/>
    <limit effort="4" lower="0" upper="0.045" velocity="0.01"/>
  </joint>
  <link name="link_0_9">
    <visual>
      <geometry>
        <box size="0.005 0.005 0.055"/>
      </geometry>
      <origin rpy="0 0 0" xyz="0 0 -0.0275"/>
      <material name="blue">
        <color rgba="0 0 1 0.9"/>
      </material>
    </visual>
    <collision>
      <geometry>
        <box size="0.005 0.005 0.055"/>
      </geometry>
      <origin rpy="0 0 0" xyz="0 0 -0.0275"/>
    </collision>
    <inertial>
      <origin rpy="0 0 0" xyz="0 0 0"/>
      <mass value="0.5"/>
      <inertia ixx="1.0" ixy="0.0" ixz="0.0" iyy="1.0" iyz="0.0" izz="1.0"/>
    </inertial>
  </link>
  <joint name="joint_0_9" type="prismatic">
    <parent link="table_base"/>
    <child link="link_0_9"/>
    <origin ryp="0 0 0" xyz="0.0125 0.16549999999999998 0"/>
    <axis xyz="0 0 1"/>
    <limit effort="4" lower="0" upper="0.045" velocity="0.01"/>
  </joint>
  <link name="link_0_8">
    <visual>
      <geometry>
        <box size="0.005 0.005 0.055"/>
      </geometry>
      <origin rpy="0 0 0" xyz="0 0 -0.0275"/>
      <material name="blue">
        <color rgba="0 0 1 0.9"/>
      </material>
    </visual>
    <collision>
      <geometry>
        <box size="0.005 0.005 0.055"/>
      </geometry>
      <origin rpy="0 0 0" xyz="0 0 -0.0275"/>
    </collision>
    <inertial>
      <origin rpy="0 0 0" xyz="0 0 0"/>
      <mass value="0.5"/>
      <inertia ixx="1.0" ixy="0.0" ixz="0.0" iyy="1.0" iyz="0.0" izz="1.0"/>
    </inertial>
  </link>
  <joint name="joint_0_8" type="prismatic">
    <parent link="table_base"/>
    <child link="link_0_8"/>
    <origin ryp="0 0 0" xyz="0.0125 0.1485 0"/>
    <axis xyz="0 0 1"/>
    <limit effort="4" lower="0" upper="0.045" velocity="0.01"/>
  </joint>
  <link name="link_0_7">
    <visual>
      <geometry>
        <box size="0.005 0.005 0.055"/>
      </geometry>
      <origin rpy="0 0 0" xyz="0 0 -0.0275"/>
      <material name="blue">
        <color rgba="0 0 1 0.9"/>
      </material>
    </visual>
    <collision>
      <geometry>
        <box size="0.005 0.005 0.055"/>
      </geometry>
      <origin rpy="0 0 0" xyz="0 0 -0.0275"/>
    </collision>
    <inertial>
      <origin rpy="0 0 0" xyz="0 0 0"/>
      <mass value="0.5"/>
      <inertia ixx="1.0" ixy="0.0" ixz="0.0" iyy="1.0" iyz="0.0" izz="1.0"/>
    </inertial>
  </link>
  <joint name="joint_0_7" type="prismatic">
    <parent link="table_base"/>
    <child link="link_0_7"/>
    <origin ryp="0 0 0" xyz="0.0125 0.1315 0"/>
    <axis xyz="0 0 1"/>
    <limit effort="4" lower="0" upper="0.045" velocity="0.01"/>
  </joint>
  <link name="link_0_6">
    <visual>
      <geometry>
        <box size="0.005 0.005 0.055"/>
      </geometry>
      <origin rpy="0 0 0" xyz="0 0 -0.0275"/>
      <material name="blue">
        <color rgba="0 0 1 0.9"/>
      </material>
    </visual>
    <collision>
      <geometry>
        <box size="0.005 0.005 0.055"/>
      </geometry>
      <origin rpy="0 0 0" xyz="0 0 -0.0275"/>
    </collision>
    <inertial>
      <origin rpy="0 0 0" xyz="0 0 0"/>
      <mass value="0.5"/>
      <inertia ixx="1.0" ixy="0.0" ixz="0.0" iyy="1.0" iyz="0.0" izz="1.0"/>
    </inertial>
  </link>
  <joint name="joint_0_6" type="prismatic">
    <parent link="table_base"/>
    <child link="link_0_6"/>
    <origin ryp="0 0 0" xyz="0.0125 0.1145 0"/>
    <axis xyz="0 0 1"/>
    <limit effort="4" lower="0" upper="0.045" velocity="0.01"/>
  </joint>
  <link name="link_0_5">
    <visual>
      <geometry>
        <box size="0.005 0.005 0.055"/>
      </geometry>
      <origin rpy="0 0 0" xyz="0 0 -0.0275"/>
      <material name="blue">
        <color rgba="0 0 1 0.9"/>
      </material>
    </visual>
    <collision>
      <geometry>
        <box size="0.005 0.005 0.055"/>
      </geometry>
      <origin rpy="0 0 0" xyz="0 0 -0.0275"/>
    </collision>
    <inertial>
      <origin rpy="0 0 0" xyz="0 0 0"/>
      <mass value="0.5"/>
      <inertia ixx="1.0" ixy="0.0" ixz="0.0" iyy="1.0" iyz="0.0" izz="1.0"/>
    </inertial>
  </link>
  <joint name="joint_0_5" type="prismatic">
    <parent link="table_base"/>
    <child link="link_0_5"/>
    <origin ryp="0 0 0" xyz="0.0125 0.09749999999999999 0"/>
    <axis xyz="0 0 1"/>
    <limit effort="4" lower="0" upper="0.045" velocity="0.01"/>
  </joint>
  <link name="link_0_4">
    <visual>
      <geometry>
        <box size="0.005 0.005 0.055"/>
      </geometry>
      <origin rpy="0 0 0" xyz="0 0 -0.0275"/>
      <material name="blue">
        <color rgba="0 0 1 0.9"/>
      </material>
    </visual>
    <collision>
      <geometry>
        <box size="0.005 0.005 0.055"/>
      </geometry>
      <origin rpy="0 0 0" xyz="0 0 -0.0275"/>
    </collision>
    <inertial>
      <origin rpy="0 0 0" xyz="0 0 0"/>
      <mass value="0.5"/>
      <inertia ixx="1.0" ixy="0.0" ixz="0.0" iyy="1.0" iyz="0.0" izz="1.0"/>
    </inertial>
  </link>
  <joint name="joint_0_4" type="prismatic">
    <parent link="table_base"/>
    <child link="link_0_4"/>
    <origin ryp="0 0 0" xyz="0.0125 0.0805 0"/>
    <axis xyz="0 0 1"/>
    <limit effort="4" lower="0" upper="0.045" velocity="0.01"/>
  </joint>
  <link name="link_0_3">
    <visual>
      <geometry>
        <box size="0.005 0.005 0.055"/>
      </geometry>
      <origin rpy="0 0 0" xyz="0 0 -0.0275"/>
      <material name="blue">
        <color rgba="0 0 1 0.9"/>
      </material>
    </visual>
    <collision>
      <geometry>
        <box size="0.005 0.005 0.055"/>
      </geometry>
      <origin rpy="0 0 0" xyz="0 0 -0.0275"/>
    </collision>
    <inertial>
      <origin rpy="0 0 0" xyz="0 0 0"/>
      <mass value="0.5"/>
      <inertia ixx="1.0" ixy="0.0" ixz="0.0" iyy="1.0" iyz="0.0" izz="1.0"/>
    </inertial>
  </link>
  <joint name="joint_0_3" type="prismatic">
    <parent link="table_base"/>
    <child link="link_0_3"/>
    <origin ryp="0 0 0" xyz="0.0125 0.0635 0"/>
    <axis xyz="0 0 1"/>
    <limit effort="4" lower="0" upper="0.045" velocity="0.01"/>
  </joint>
  <link name="link_0_2">
    <visual>
      <geometry>
        <box size="0.005 0.005 0.055"/>
      </geometry>
      <origin rpy="0 0 0" xyz="0 0 -0.0275"/>
      <material name="blue">
        <color rgba="0 0 1 0.9"/>
      </material>
    </visual>
    <collision>
      <geometry>
        <box size="0.005 0.005 0.055"/>
      </geometry>
      <origin rpy="0 0 0" xyz="0 0 -0.0275"/>
    </collision>
    <inertial>
      <origin rpy="0 0 0" xyz="0 0 0"/>
      <mass value="0.5"/>
      <inertia ixx="1.0" ixy="0.0" ixz="0.0" iyy="1.0" iyz="0.0" izz="1.0"/>
    </inertial>
  </link>
  <joint name="joint_0_2" type="prismatic">
    <parent link="table_base"/>
    <child link="link_0_2"/>
    <origin ryp="0 0 0" xyz="0.0125 0.0465 0"/>
    <axis xyz="0 0 1"/>
    <limit effort="4" lower="0" upper="0.045" velocity="0.01"/>
  </joint>
  <link name="link_0_1">
    <visual>
      <geometry>
        <box size="0.005 0.005 0.055"/>
      </geometry>
      <origin rpy="0 0 0" xyz="0 0 -0.0275"/>
      <material name="blue">
        <color rgba="0 0 1 0.9"/>
      </material>
    </visual>
    <collision>
      <geometry>
        <box size="0.005 0.005 0.055"/>
      </geometry>
      <origin rpy="0 0 0" xyz="0 0 -0.0275"/>
    </collision>
    <inertial>
      <origin rpy="0 0 0" xyz="0 0 0"/>
      <mass value="0.5"/>
      <inertia ixx="1.0" ixy="0.0" ixz="0.0" iyy="1.0" iyz="0.0" izz="1.0"/>
    </inertial>
  </link>
  <joint name="joint_0_1" type="prismatic">
    <parent link="table_base"/>
    <child link="link_0_1"/>
    <origin ryp="0 0 0" xyz="0.0125 0.0295 0"/>
    <axis xyz="0 0 1"/>
    <limit effort="4" lower="0" upper="0.045" velocity="0.01"/>
  </joint>
  <link name="link_0_0">
    <visual>
      <geometry>
        <box size="0.005 0.005 0.055"/>
      </geometry>
      <origin rpy="0 0 0" xyz="0 0 -0.0275"/>
      <material name="blue">
        <color rgba="0 0 1 0.9"/>
      </material>
    </visual>
    <collision>
      <geometry>
        <box size="0.005 0.005 0.055"/>
      </geometry>
      <origin rpy="0 0 0" xyz="0 0 -0.0275"/>
    </collision>
    <inertial>
      <origin rpy="0 0 0" xyz="0 0 0"/>
      <mass value="0.5"/>
      <inertia ixx="1.0" ixy="0.0" ixz="0.0" iyy="1.0" iyz="0.0" izz="1.0"/>
    </inertial>
  </link>
  <joint name="joint_0_0" type="prismatic">
    <parent link="table_base"/>
    <child link="link_0_0"/>
    <origin ryp="0 0 0" xyz="0.0125 0.0125 0"/>
    <axis xyz="0 0 1"/>
    <limit effort="4" lower="0" upper="0.045" velocity="0.01"/>
  </joint>
</robot>

