<?xml version="1.0" ?>
<!-- =================================================================================== -->
<!-- |    This document was autogenerated by xacro from tablebot.xacro                 | -->
<!-- |    EDITING THIS FILE BY HAND IS NOT RECOMMENDED                                 | -->
<!-- =================================================================================== -->
<robot name="tablebot">
  <!-- <link name="footprint">
      <visual>
        <geometry>
          <sphere radius="0.0001" />
        </geometry>
      </visual>
    </link> -->
  <link name="table_base">
    <visual>
      <geometry>
        <box size="0.155 0.155 0.12"/>
      </geometry>
      <origin rpy="0 0 0" xyz="0.0775 0.0775 -0.06"/>
      <material name="black">
        <color rgba="1 1 1 0.5"/>
      </material>
      <inertial>
        <origin rpy="0 0 0" xyz="0 0 0"/>
        <mass value="10"/>
        <inertia ixx="1.0" ixy="0.0" ixz="0.0" iyy="1.0" iyz="0.0" izz="1.0"/>
      </inertial>
    </visual>
  </link>
  <!-- <joint name="base2footprint" type="fixed">
      <parent link="footprint" />
      <child link="table_base" />
      <origin xyz="0 0 ${tab_height / 2 }" />
    </joint> -->
  <!-- <xacro:macro name="loop" params="links_qty">
        <xacro:if value="${links_qty}">
            <xacro:loop links_qty="${links_qty-1}" />
        </xacro:if>
    </xacro:macro> -->
  <link name="link_7_7">
    <visual>
      <geometry>
        <box size="0.016 0.016 0.055"/>
      </geometry>
      <origin rpy="0 0 0" xyz="0 0 -0.0275"/>
      <material name="blue">
        <color rgba="0 0 1 0.9"/>
      </material>
    </visual>
    <collision>
      <geometry>
        <box size="0.016 0.016 0.055"/>
      </geometry>
      <origin rpy="0 0 0" xyz="0 0 -0.0275"/>
    </collision>
    <inertial>
      <origin rpy="0 0 0" xyz="0 0 0"/>
      <mass value="0.5"/>
      <inertia ixx="1.0" ixy="0.0" ixz="0.0" iyy="1.0" iyz="0.0" izz="1.0"/>
    </inertial>
  </link>
  <joint name="joint_7_7" type="prismatic">
    <parent link="table_base"/>
    <child link="link_7_7"/>
    <origin ryp="0 0 0" xyz="0.137 0.137 0"/>
    <axis xyz="0 0 1"/>
    <limit effort="4" lower="0" upper="0.045" velocity="0.01"/>
  </joint>
  <link name="link_7_6">
    <visual>
      <geometry>
        <box size="0.016 0.016 0.055"/>
      </geometry>
      <origin rpy="0 0 0" xyz="0 0 -0.0275"/>
      <material name="blue">
        <color rgba="0 0 1 0.9"/>
      </material>
    </visual>
    <collision>
      <geometry>
        <box size="0.016 0.016 0.055"/>
      </geometry>
      <origin rpy="0 0 0" xyz="0 0 -0.0275"/>
    </collision>
    <inertial>
      <origin rpy="0 0 0" xyz="0 0 0"/>
      <mass value="0.5"/>
      <inertia ixx="1.0" ixy="0.0" ixz="0.0" iyy="1.0" iyz="0.0" izz="1.0"/>
    </inertial>
  </link>
  <joint name="joint_7_6" type="prismatic">
    <parent link="table_base"/>
    <child link="link_7_6"/>
    <origin ryp="0 0 0" xyz="0.137 0.12000000000000001 0"/>
    <axis xyz="0 0 1"/>
    <limit effort="4" lower="0" upper="0.045" velocity="0.01"/>
  </joint>
  <link name="link_7_5">
    <visual>
      <geometry>
        <box size="0.016 0.016 0.055"/>
      </geometry>
      <origin rpy="0 0 0" xyz="0 0 -0.0275"/>
      <material name="blue">
        <color rgba="0 0 1 0.9"/>
      </material>
    </visual>
    <collision>
      <geometry>
        <box size="0.016 0.016 0.055"/>
      </geometry>
      <origin rpy="0 0 0" xyz="0 0 -0.0275"/>
    </collision>
    <inertial>
      <origin rpy="0 0 0" xyz="0 0 0"/>
      <mass value="0.5"/>
      <inertia ixx="1.0" ixy="0.0" ixz="0.0" iyy="1.0" iyz="0.0" izz="1.0"/>
    </inertial>
  </link>
  <joint name="joint_7_5" type="prismatic">
    <parent link="table_base"/>
    <child link="link_7_5"/>
    <origin ryp="0 0 0" xyz="0.137 0.103 0"/>
    <axis xyz="0 0 1"/>
    <limit effort="4" lower="0" upper="0.045" velocity="0.01"/>
  </joint>
  <link name="link_7_4">
    <visual>
      <geometry>
        <box size="0.016 0.016 0.055"/>
      </geometry>
      <origin rpy="0 0 0" xyz="0 0 -0.0275"/>
      <material name="blue">
        <color rgba="0 0 1 0.9"/>
      </material>
    </visual>
    <collision>
      <geometry>
        <box size="0.016 0.016 0.055"/>
      </geometry>
      <origin rpy="0 0 0" xyz="0 0 -0.0275"/>
    </collision>
    <inertial>
      <origin rpy="0 0 0" xyz="0 0 0"/>
      <mass value="0.5"/>
      <inertia ixx="1.0" ixy="0.0" ixz="0.0" iyy="1.0" iyz="0.0" izz="1.0"/>
    </inertial>
  </link>
  <joint name="joint_7_4" type="prismatic">
    <parent link="table_base"/>
    <child link="link_7_4"/>
    <origin ryp="0 0 0" xyz="0.137 0.08600000000000001 0"/>
    <axis xyz="0 0 1"/>
    <limit effort="4" lower="0" upper="0.045" velocity="0.01"/>
  </joint>
  <link name="link_7_3">
    <visual>
      <geometry>
        <box size="0.016 0.016 0.055"/>
      </geometry>
      <origin rpy="0 0 0" xyz="0 0 -0.0275"/>
      <material name="blue">
        <color rgba="0 0 1 0.9"/>
      </material>
    </visual>
    <collision>
      <geometry>
        <box size="0.016 0.016 0.055"/>
      </geometry>
      <origin rpy="0 0 0" xyz="0 0 -0.0275"/>
    </collision>
    <inertial>
      <origin rpy="0 0 0" xyz="0 0 0"/>
      <mass value="0.5"/>
      <inertia ixx="1.0" ixy="0.0" ixz="0.0" iyy="1.0" iyz="0.0" izz="1.0"/>
    </inertial>
  </link>
  <joint name="joint_7_3" type="prismatic">
    <parent link="table_base"/>
    <child link="link_7_3"/>
    <origin ryp="0 0 0" xyz="0.137 0.069 0"/>
    <axis xyz="0 0 1"/>
    <limit effort="4" lower="0" upper="0.045" velocity="0.01"/>
  </joint>
  <link name="link_7_2">
    <visual>
      <geometry>
        <box size="0.016 0.016 0.055"/>
      </geometry>
      <origin rpy="0 0 0" xyz="0 0 -0.0275"/>
      <material name="blue">
        <color rgba="0 0 1 0.9"/>
      </material>
    </visual>
    <collision>
      <geometry>
        <box size="0.016 0.016 0.055"/>
      </geometry>
      <origin rpy="0 0 0" xyz="0 0 -0.0275"/>
    </collision>
    <inertial>
      <origin rpy="0 0 0" xyz="0 0 0"/>
      <mass value="0.5"/>
      <inertia ixx="1.0" ixy="0.0" ixz="0.0" iyy="1.0" iyz="0.0" izz="1.0"/>
    </inertial>
  </link>
  <joint name="joint_7_2" type="prismatic">
    <parent link="table_base"/>
    <child link="link_7_2"/>
    <origin ryp="0 0 0" xyz="0.137 0.052000000000000005 0"/>
    <axis xyz="0 0 1"/>
    <limit effort="4" lower="0" upper="0.045" velocity="0.01"/>
  </joint>
  <link name="link_7_1">
    <visual>
      <geometry>
        <box size="0.016 0.016 0.055"/>
      </geometry>
      <origin rpy="0 0 0" xyz="0 0 -0.0275"/>
      <material name="blue">
        <color rgba="0 0 1 0.9"/>
      </material>
    </visual>
    <collision>
      <geometry>
        <box size="0.016 0.016 0.055"/>
      </geometry>
      <origin rpy="0 0 0" xyz="0 0 -0.0275"/>
    </collision>
    <inertial>
      <origin rpy="0 0 0" xyz="0 0 0"/>
      <mass value="0.5"/>
      <inertia ixx="1.0" ixy="0.0" ixz="0.0" iyy="1.0" iyz="0.0" izz="1.0"/>
    </inertial>
  </link>
  <joint name="joint_7_1" type="prismatic">
    <parent link="table_base"/>
    <child link="link_7_1"/>
    <origin ryp="0 0 0" xyz="0.137 0.035 0"/>
    <axis xyz="0 0 1"/>
    <limit effort="4" lower="0" upper="0.045" velocity="0.01"/>
  </joint>
  <link name="link_7_0">
    <visual>
      <geometry>
        <box size="0.016 0.016 0.055"/>
      </geometry>
      <origin rpy="0 0 0" xyz="0 0 -0.0275"/>
      <material name="blue">
        <color rgba="0 0 1 0.9"/>
      </material>
    </visual>
    <collision>
      <geometry>
        <box size="0.016 0.016 0.055"/>
      </geometry>
      <origin rpy="0 0 0" xyz="0 0 -0.0275"/>
    </collision>
    <inertial>
      <origin rpy="0 0 0" xyz="0 0 0"/>
      <mass value="0.5"/>
      <inertia ixx="1.0" ixy="0.0" ixz="0.0" iyy="1.0" iyz="0.0" izz="1.0"/>
    </inertial>
  </link>
  <joint name="joint_7_0" type="prismatic">
    <parent link="table_base"/>
    <child link="link_7_0"/>
    <origin ryp="0 0 0" xyz="0.137 0.018000000000000002 0"/>
    <axis xyz="0 0 1"/>
    <limit effort="4" lower="0" upper="0.045" velocity="0.01"/>
  </joint>
  <link name="link_6_7">
    <visual>
      <geometry>
        <box size="0.016 0.016 0.055"/>
      </geometry>
      <origin rpy="0 0 0" xyz="0 0 -0.0275"/>
      <material name="blue">
        <color rgba="0 0 1 0.9"/>
      </material>
    </visual>
    <collision>
      <geometry>
        <box size="0.016 0.016 0.055"/>
      </geometry>
      <origin rpy="0 0 0" xyz="0 0 -0.0275"/>
    </collision>
    <inertial>
      <origin rpy="0 0 0" xyz="0 0 0"/>
      <mass value="0.5"/>
      <inertia ixx="1.0" ixy="0.0" ixz="0.0" iyy="1.0" iyz="0.0" izz="1.0"/>
    </inertial>
  </link>
  <joint name="joint_6_7" type="prismatic">
    <parent link="table_base"/>
    <child link="link_6_7"/>
    <origin ryp="0 0 0" xyz="0.12000000000000001 0.137 0"/>
    <axis xyz="0 0 1"/>
    <limit effort="4" lower="0" upper="0.045" velocity="0.01"/>
  </joint>
  <link name="link_6_6">
    <visual>
      <geometry>
        <box size="0.016 0.016 0.055"/>
      </geometry>
      <origin rpy="0 0 0" xyz="0 0 -0.0275"/>
      <material name="blue">
        <color rgba="0 0 1 0.9"/>
      </material>
    </visual>
    <collision>
      <geometry>
        <box size="0.016 0.016 0.055"/>
      </geometry>
      <origin rpy="0 0 0" xyz="0 0 -0.0275"/>
    </collision>
    <inertial>
      <origin rpy="0 0 0" xyz="0 0 0"/>
      <mass value="0.5"/>
      <inertia ixx="1.0" ixy="0.0" ixz="0.0" iyy="1.0" iyz="0.0" izz="1.0"/>
    </inertial>
  </link>
  <joint name="joint_6_6" type="prismatic">
    <parent link="table_base"/>
    <child link="link_6_6"/>
    <origin ryp="0 0 0" xyz="0.12000000000000001 0.12000000000000001 0"/>
    <axis xyz="0 0 1"/>
    <limit effort="4" lower="0" upper="0.045" velocity="0.01"/>
  </joint>
  <link name="link_6_5">
    <visual>
      <geometry>
        <box size="0.016 0.016 0.055"/>
      </geometry>
      <origin rpy="0 0 0" xyz="0 0 -0.0275"/>
      <material name="blue">
        <color rgba="0 0 1 0.9"/>
      </material>
    </visual>
    <collision>
      <geometry>
        <box size="0.016 0.016 0.055"/>
      </geometry>
      <origin rpy="0 0 0" xyz="0 0 -0.0275"/>
    </collision>
    <inertial>
      <origin rpy="0 0 0" xyz="0 0 0"/>
      <mass value="0.5"/>
      <inertia ixx="1.0" ixy="0.0" ixz="0.0" iyy="1.0" iyz="0.0" izz="1.0"/>
    </inertial>
  </link>
  <joint name="joint_6_5" type="prismatic">
    <parent link="table_base"/>
    <child link="link_6_5"/>
    <origin ryp="0 0 0" xyz="0.12000000000000001 0.103 0"/>
    <axis xyz="0 0 1"/>
    <limit effort="4" lower="0" upper="0.045" velocity="0.01"/>
  </joint>
  <link name="link_6_4">
    <visual>
      <geometry>
        <box size="0.016 0.016 0.055"/>
      </geometry>
      <origin rpy="0 0 0" xyz="0 0 -0.0275"/>
      <material name="blue">
        <color rgba="0 0 1 0.9"/>
      </material>
    </visual>
    <collision>
      <geometry>
        <box size="0.016 0.016 0.055"/>
      </geometry>
      <origin rpy="0 0 0" xyz="0 0 -0.0275"/>
    </collision>
    <inertial>
      <origin rpy="0 0 0" xyz="0 0 0"/>
      <mass value="0.5"/>
      <inertia ixx="1.0" ixy="0.0" ixz="0.0" iyy="1.0" iyz="0.0" izz="1.0"/>
    </inertial>
  </link>
  <joint name="joint_6_4" type="prismatic">
    <parent link="table_base"/>
    <child link="link_6_4"/>
    <origin ryp="0 0 0" xyz="0.12000000000000001 0.08600000000000001 0"/>
    <axis xyz="0 0 1"/>
    <limit effort="4" lower="0" upper="0.045" velocity="0.01"/>
  </joint>
  <link name="link_6_3">
    <visual>
      <geometry>
        <box size="0.016 0.016 0.055"/>
      </geometry>
      <origin rpy="0 0 0" xyz="0 0 -0.0275"/>
      <material name="blue">
        <color rgba="0 0 1 0.9"/>
      </material>
    </visual>
    <collision>
      <geometry>
        <box size="0.016 0.016 0.055"/>
      </geometry>
      <origin rpy="0 0 0" xyz="0 0 -0.0275"/>
    </collision>
    <inertial>
      <origin rpy="0 0 0" xyz="0 0 0"/>
      <mass value="0.5"/>
      <inertia ixx="1.0" ixy="0.0" ixz="0.0" iyy="1.0" iyz="0.0" izz="1.0"/>
    </inertial>
  </link>
  <joint name="joint_6_3" type="prismatic">
    <parent link="table_base"/>
    <child link="link_6_3"/>
    <origin ryp="0 0 0" xyz="0.12000000000000001 0.069 0"/>
    <axis xyz="0 0 1"/>
    <limit effort="4" lower="0" upper="0.045" velocity="0.01"/>
  </joint>
  <link name="link_6_2">
    <visual>
      <geometry>
        <box size="0.016 0.016 0.055"/>
      </geometry>
      <origin rpy="0 0 0" xyz="0 0 -0.0275"/>
      <material name="blue">
        <color rgba="0 0 1 0.9"/>
      </material>
    </visual>
    <collision>
      <geometry>
        <box size="0.016 0.016 0.055"/>
      </geometry>
      <origin rpy="0 0 0" xyz="0 0 -0.0275"/>
    </collision>
    <inertial>
      <origin rpy="0 0 0" xyz="0 0 0"/>
      <mass value="0.5"/>
      <inertia ixx="1.0" ixy="0.0" ixz="0.0" iyy="1.0" iyz="0.0" izz="1.0"/>
    </inertial>
  </link>
  <joint name="joint_6_2" type="prismatic">
    <parent link="table_base"/>
    <child link="link_6_2"/>
    <origin ryp="0 0 0" xyz="0.12000000000000001 0.052000000000000005 0"/>
    <axis xyz="0 0 1"/>
    <limit effort="4" lower="0" upper="0.045" velocity="0.01"/>
  </joint>
  <link name="link_6_1">
    <visual>
      <geometry>
        <box size="0.016 0.016 0.055"/>
      </geometry>
      <origin rpy="0 0 0" xyz="0 0 -0.0275"/>
      <material name="blue">
        <color rgba="0 0 1 0.9"/>
      </material>
    </visual>
    <collision>
      <geometry>
        <box size="0.016 0.016 0.055"/>
      </geometry>
      <origin rpy="0 0 0" xyz="0 0 -0.0275"/>
    </collision>
    <inertial>
      <origin rpy="0 0 0" xyz="0 0 0"/>
      <mass value="0.5"/>
      <inertia ixx="1.0" ixy="0.0" ixz="0.0" iyy="1.0" iyz="0.0" izz="1.0"/>
    </inertial>
  </link>
  <joint name="joint_6_1" type="prismatic">
    <parent link="table_base"/>
    <child link="link_6_1"/>
    <origin ryp="0 0 0" xyz="0.12000000000000001 0.035 0"/>
    <axis xyz="0 0 1"/>
    <limit effort="4" lower="0" upper="0.045" velocity="0.01"/>
  </joint>
  <link name="link_6_0">
    <visual>
      <geometry>
        <box size="0.016 0.016 0.055"/>
      </geometry>
      <origin rpy="0 0 0" xyz="0 0 -0.0275"/>
      <material name="blue">
        <color rgba="0 0 1 0.9"/>
      </material>
    </visual>
    <collision>
      <geometry>
        <box size="0.016 0.016 0.055"/>
      </geometry>
      <origin rpy="0 0 0" xyz="0 0 -0.0275"/>
    </collision>
    <inertial>
      <origin rpy="0 0 0" xyz="0 0 0"/>
      <mass value="0.5"/>
      <inertia ixx="1.0" ixy="0.0" ixz="0.0" iyy="1.0" iyz="0.0" izz="1.0"/>
    </inertial>
  </link>
  <joint name="joint_6_0" type="prismatic">
    <parent link="table_base"/>
    <child link="link_6_0"/>
    <origin ryp="0 0 0" xyz="0.12000000000000001 0.018000000000000002 0"/>
    <axis xyz="0 0 1"/>
    <limit effort="4" lower="0" upper="0.045" velocity="0.01"/>
  </joint>
  <link name="link_5_7">
    <visual>
      <geometry>
        <box size="0.016 0.016 0.055"/>
      </geometry>
      <origin rpy="0 0 0" xyz="0 0 -0.0275"/>
      <material name="blue">
        <color rgba="0 0 1 0.9"/>
      </material>
    </visual>
    <collision>
      <geometry>
        <box size="0.016 0.016 0.055"/>
      </geometry>
      <origin rpy="0 0 0" xyz="0 0 -0.0275"/>
    </collision>
    <inertial>
      <origin rpy="0 0 0" xyz="0 0 0"/>
      <mass value="0.5"/>
      <inertia ixx="1.0" ixy="0.0" ixz="0.0" iyy="1.0" iyz="0.0" izz="1.0"/>
    </inertial>
  </link>
  <joint name="joint_5_7" type="prismatic">
    <parent link="table_base"/>
    <child link="link_5_7"/>
    <origin ryp="0 0 0" xyz="0.103 0.137 0"/>
    <axis xyz="0 0 1"/>
    <limit effort="4" lower="0" upper="0.045" velocity="0.01"/>
  </joint>
  <link name="link_5_6">
    <visual>
      <geometry>
        <box size="0.016 0.016 0.055"/>
      </geometry>
      <origin rpy="0 0 0" xyz="0 0 -0.0275"/>
      <material name="blue">
        <color rgba="0 0 1 0.9"/>
      </material>
    </visual>
    <collision>
      <geometry>
        <box size="0.016 0.016 0.055"/>
      </geometry>
      <origin rpy="0 0 0" xyz="0 0 -0.0275"/>
    </collision>
    <inertial>
      <origin rpy="0 0 0" xyz="0 0 0"/>
      <mass value="0.5"/>
      <inertia ixx="1.0" ixy="0.0" ixz="0.0" iyy="1.0" iyz="0.0" izz="1.0"/>
    </inertial>
  </link>
  <joint name="joint_5_6" type="prismatic">
    <parent link="table_base"/>
    <child link="link_5_6"/>
    <origin ryp="0 0 0" xyz="0.103 0.12000000000000001 0"/>
    <axis xyz="0 0 1"/>
    <limit effort="4" lower="0" upper="0.045" velocity="0.01"/>
  </joint>
  <link name="link_5_5">
    <visual>
      <geometry>
        <box size="0.016 0.016 0.055"/>
      </geometry>
      <origin rpy="0 0 0" xyz="0 0 -0.0275"/>
      <material name="blue">
        <color rgba="0 0 1 0.9"/>
      </material>
    </visual>
    <collision>
      <geometry>
        <box size="0.016 0.016 0.055"/>
      </geometry>
      <origin rpy="0 0 0" xyz="0 0 -0.0275"/>
    </collision>
    <inertial>
      <origin rpy="0 0 0" xyz="0 0 0"/>
      <mass value="0.5"/>
      <inertia ixx="1.0" ixy="0.0" ixz="0.0" iyy="1.0" iyz="0.0" izz="1.0"/>
    </inertial>
  </link>
  <joint name="joint_5_5" type="prismatic">
    <parent link="table_base"/>
    <child link="link_5_5"/>
    <origin ryp="0 0 0" xyz="0.103 0.103 0"/>
    <axis xyz="0 0 1"/>
    <limit effort="4" lower="0" upper="0.045" velocity="0.01"/>
  </joint>
  <link name="link_5_4">
    <visual>
      <geometry>
        <box size="0.016 0.016 0.055"/>
      </geometry>
      <origin rpy="0 0 0" xyz="0 0 -0.0275"/>
      <material name="blue">
        <color rgba="0 0 1 0.9"/>
      </material>
    </visual>
    <collision>
      <geometry>
        <box size="0.016 0.016 0.055"/>
      </geometry>
      <origin rpy="0 0 0" xyz="0 0 -0.0275"/>
    </collision>
    <inertial>
      <origin rpy="0 0 0" xyz="0 0 0"/>
      <mass value="0.5"/>
      <inertia ixx="1.0" ixy="0.0" ixz="0.0" iyy="1.0" iyz="0.0" izz="1.0"/>
    </inertial>
  </link>
  <joint name="joint_5_4" type="prismatic">
    <parent link="table_base"/>
    <child link="link_5_4"/>
    <origin ryp="0 0 0" xyz="0.103 0.08600000000000001 0"/>
    <axis xyz="0 0 1"/>
    <limit effort="4" lower="0" upper="0.045" velocity="0.01"/>
  </joint>
  <link name="link_5_3">
    <visual>
      <geometry>
        <box size="0.016 0.016 0.055"/>
      </geometry>
      <origin rpy="0 0 0" xyz="0 0 -0.0275"/>
      <material name="blue">
        <color rgba="0 0 1 0.9"/>
      </material>
    </visual>
    <collision>
      <geometry>
        <box size="0.016 0.016 0.055"/>
      </geometry>
      <origin rpy="0 0 0" xyz="0 0 -0.0275"/>
    </collision>
    <inertial>
      <origin rpy="0 0 0" xyz="0 0 0"/>
      <mass value="0.5"/>
      <inertia ixx="1.0" ixy="0.0" ixz="0.0" iyy="1.0" iyz="0.0" izz="1.0"/>
    </inertial>
  </link>
  <joint name="joint_5_3" type="prismatic">
    <parent link="table_base"/>
    <child link="link_5_3"/>
    <origin ryp="0 0 0" xyz="0.103 0.069 0"/>
    <axis xyz="0 0 1"/>
    <limit effort="4" lower="0" upper="0.045" velocity="0.01"/>
  </joint>
  <link name="link_5_2">
    <visual>
      <geometry>
        <box size="0.016 0.016 0.055"/>
      </geometry>
      <origin rpy="0 0 0" xyz="0 0 -0.0275"/>
      <material name="blue">
        <color rgba="0 0 1 0.9"/>
      </material>
    </visual>
    <collision>
      <geometry>
        <box size="0.016 0.016 0.055"/>
      </geometry>
      <origin rpy="0 0 0" xyz="0 0 -0.0275"/>
    </collision>
    <inertial>
      <origin rpy="0 0 0" xyz="0 0 0"/>
      <mass value="0.5"/>
      <inertia ixx="1.0" ixy="0.0" ixz="0.0" iyy="1.0" iyz="0.0" izz="1.0"/>
    </inertial>
  </link>
  <joint name="joint_5_2" type="prismatic">
    <parent link="table_base"/>
    <child link="link_5_2"/>
    <origin ryp="0 0 0" xyz="0.103 0.052000000000000005 0"/>
    <axis xyz="0 0 1"/>
    <limit effort="4" lower="0" upper="0.045" velocity="0.01"/>
  </joint>
  <link name="link_5_1">
    <visual>
      <geometry>
        <box size="0.016 0.016 0.055"/>
      </geometry>
      <origin rpy="0 0 0" xyz="0 0 -0.0275"/>
      <material name="blue">
        <color rgba="0 0 1 0.9"/>
      </material>
    </visual>
    <collision>
      <geometry>
        <box size="0.016 0.016 0.055"/>
      </geometry>
      <origin rpy="0 0 0" xyz="0 0 -0.0275"/>
    </collision>
    <inertial>
      <origin rpy="0 0 0" xyz="0 0 0"/>
      <mass value="0.5"/>
      <inertia ixx="1.0" ixy="0.0" ixz="0.0" iyy="1.0" iyz="0.0" izz="1.0"/>
    </inertial>
  </link>
  <joint name="joint_5_1" type="prismatic">
    <parent link="table_base"/>
    <child link="link_5_1"/>
    <origin ryp="0 0 0" xyz="0.103 0.035 0"/>
    <axis xyz="0 0 1"/>
    <limit effort="4" lower="0" upper="0.045" velocity="0.01"/>
  </joint>
  <link name="link_5_0">
    <visual>
      <geometry>
        <box size="0.016 0.016 0.055"/>
      </geometry>
      <origin rpy="0 0 0" xyz="0 0 -0.0275"/>
      <material name="blue">
        <color rgba="0 0 1 0.9"/>
      </material>
    </visual>
    <collision>
      <geometry>
        <box size="0.016 0.016 0.055"/>
      </geometry>
      <origin rpy="0 0 0" xyz="0 0 -0.0275"/>
    </collision>
    <inertial>
      <origin rpy="0 0 0" xyz="0 0 0"/>
      <mass value="0.5"/>
      <inertia ixx="1.0" ixy="0.0" ixz="0.0" iyy="1.0" iyz="0.0" izz="1.0"/>
    </inertial>
  </link>
  <joint name="joint_5_0" type="prismatic">
    <parent link="table_base"/>
    <child link="link_5_0"/>
    <origin ryp="0 0 0" xyz="0.103 0.018000000000000002 0"/>
    <axis xyz="0 0 1"/>
    <limit effort="4" lower="0" upper="0.045" velocity="0.01"/>
  </joint>
  <link name="link_4_7">
    <visual>
      <geometry>
        <box size="0.016 0.016 0.055"/>
      </geometry>
      <origin rpy="0 0 0" xyz="0 0 -0.0275"/>
      <material name="blue">
        <color rgba="0 0 1 0.9"/>
      </material>
    </visual>
    <collision>
      <geometry>
        <box size="0.016 0.016 0.055"/>
      </geometry>
      <origin rpy="0 0 0" xyz="0 0 -0.0275"/>
    </collision>
    <inertial>
      <origin rpy="0 0 0" xyz="0 0 0"/>
      <mass value="0.5"/>
      <inertia ixx="1.0" ixy="0.0" ixz="0.0" iyy="1.0" iyz="0.0" izz="1.0"/>
    </inertial>
  </link>
  <joint name="joint_4_7" type="prismatic">
    <parent link="table_base"/>
    <child link="link_4_7"/>
    <origin ryp="0 0 0" xyz="0.08600000000000001 0.137 0"/>
    <axis xyz="0 0 1"/>
    <limit effort="4" lower="0" upper="0.045" velocity="0.01"/>
  </joint>
  <link name="link_4_6">
    <visual>
      <geometry>
        <box size="0.016 0.016 0.055"/>
      </geometry>
      <origin rpy="0 0 0" xyz="0 0 -0.0275"/>
      <material name="blue">
        <color rgba="0 0 1 0.9"/>
      </material>
    </visual>
    <collision>
      <geometry>
        <box size="0.016 0.016 0.055"/>
      </geometry>
      <origin rpy="0 0 0" xyz="0 0 -0.0275"/>
    </collision>
    <inertial>
      <origin rpy="0 0 0" xyz="0 0 0"/>
      <mass value="0.5"/>
      <inertia ixx="1.0" ixy="0.0" ixz="0.0" iyy="1.0" iyz="0.0" izz="1.0"/>
    </inertial>
  </link>
  <joint name="joint_4_6" type="prismatic">
    <parent link="table_base"/>
    <child link="link_4_6"/>
    <origin ryp="0 0 0" xyz="0.08600000000000001 0.12000000000000001 0"/>
    <axis xyz="0 0 1"/>
    <limit effort="4" lower="0" upper="0.045" velocity="0.01"/>
  </joint>
  <link name="link_4_5">
    <visual>
      <geometry>
        <box size="0.016 0.016 0.055"/>
      </geometry>
      <origin rpy="0 0 0" xyz="0 0 -0.0275"/>
      <material name="blue">
        <color rgba="0 0 1 0.9"/>
      </material>
    </visual>
    <collision>
      <geometry>
        <box size="0.016 0.016 0.055"/>
      </geometry>
      <origin rpy="0 0 0" xyz="0 0 -0.0275"/>
    </collision>
    <inertial>
      <origin rpy="0 0 0" xyz="0 0 0"/>
      <mass value="0.5"/>
      <inertia ixx="1.0" ixy="0.0" ixz="0.0" iyy="1.0" iyz="0.0" izz="1.0"/>
    </inertial>
  </link>
  <joint name="joint_4_5" type="prismatic">
    <parent link="table_base"/>
    <child link="link_4_5"/>
    <origin ryp="0 0 0" xyz="0.08600000000000001 0.103 0"/>
    <axis xyz="0 0 1"/>
    <limit effort="4" lower="0" upper="0.045" velocity="0.01"/>
  </joint>
  <link name="link_4_4">
    <visual>
      <geometry>
        <box size="0.016 0.016 0.055"/>
      </geometry>
      <origin rpy="0 0 0" xyz="0 0 -0.0275"/>
      <material name="blue">
        <color rgba="0 0 1 0.9"/>
      </material>
    </visual>
    <collision>
      <geometry>
        <box size="0.016 0.016 0.055"/>
      </geometry>
      <origin rpy="0 0 0" xyz="0 0 -0.0275"/>
    </collision>
    <inertial>
      <origin rpy="0 0 0" xyz="0 0 0"/>
      <mass value="0.5"/>
      <inertia ixx="1.0" ixy="0.0" ixz="0.0" iyy="1.0" iyz="0.0" izz="1.0"/>
    </inertial>
  </link>
  <joint name="joint_4_4" type="prismatic">
    <parent link="table_base"/>
    <child link="link_4_4"/>
    <origin ryp="0 0 0" xyz="0.08600000000000001 0.08600000000000001 0"/>
    <axis xyz="0 0 1"/>
    <limit effort="4" lower="0" upper="0.045" velocity="0.01"/>
  </joint>
  <link name="link_4_3">
    <visual>
      <geometry>
        <box size="0.016 0.016 0.055"/>
      </geometry>
      <origin rpy="0 0 0" xyz="0 0 -0.0275"/>
      <material name="blue">
        <color rgba="0 0 1 0.9"/>
      </material>
    </visual>
    <collision>
      <geometry>
        <box size="0.016 0.016 0.055"/>
      </geometry>
      <origin rpy="0 0 0" xyz="0 0 -0.0275"/>
    </collision>
    <inertial>
      <origin rpy="0 0 0" xyz="0 0 0"/>
      <mass value="0.5"/>
      <inertia ixx="1.0" ixy="0.0" ixz="0.0" iyy="1.0" iyz="0.0" izz="1.0"/>
    </inertial>
  </link>
  <joint name="joint_4_3" type="prismatic">
    <parent link="table_base"/>
    <child link="link_4_3"/>
    <origin ryp="0 0 0" xyz="0.08600000000000001 0.069 0"/>
    <axis xyz="0 0 1"/>
    <limit effort="4" lower="0" upper="0.045" velocity="0.01"/>
  </joint>
  <link name="link_4_2">
    <visual>
      <geometry>
        <box size="0.016 0.016 0.055"/>
      </geometry>
      <origin rpy="0 0 0" xyz="0 0 -0.0275"/>
      <material name="blue">
        <color rgba="0 0 1 0.9"/>
      </material>
    </visual>
    <collision>
      <geometry>
        <box size="0.016 0.016 0.055"/>
      </geometry>
      <origin rpy="0 0 0" xyz="0 0 -0.0275"/>
    </collision>
    <inertial>
      <origin rpy="0 0 0" xyz="0 0 0"/>
      <mass value="0.5"/>
      <inertia ixx="1.0" ixy="0.0" ixz="0.0" iyy="1.0" iyz="0.0" izz="1.0"/>
    </inertial>
  </link>
  <joint name="joint_4_2" type="prismatic">
    <parent link="table_base"/>
    <child link="link_4_2"/>
    <origin ryp="0 0 0" xyz="0.08600000000000001 0.052000000000000005 0"/>
    <axis xyz="0 0 1"/>
    <limit effort="4" lower="0" upper="0.045" velocity="0.01"/>
  </joint>
  <link name="link_4_1">
    <visual>
      <geometry>
        <box size="0.016 0.016 0.055"/>
      </geometry>
      <origin rpy="0 0 0" xyz="0 0 -0.0275"/>
      <material name="blue">
        <color rgba="0 0 1 0.9"/>
      </material>
    </visual>
    <collision>
      <geometry>
        <box size="0.016 0.016 0.055"/>
      </geometry>
      <origin rpy="0 0 0" xyz="0 0 -0.0275"/>
    </collision>
    <inertial>
      <origin rpy="0 0 0" xyz="0 0 0"/>
      <mass value="0.5"/>
      <inertia ixx="1.0" ixy="0.0" ixz="0.0" iyy="1.0" iyz="0.0" izz="1.0"/>
    </inertial>
  </link>
  <joint name="joint_4_1" type="prismatic">
    <parent link="table_base"/>
    <child link="link_4_1"/>
    <origin ryp="0 0 0" xyz="0.08600000000000001 0.035 0"/>
    <axis xyz="0 0 1"/>
    <limit effort="4" lower="0" upper="0.045" velocity="0.01"/>
  </joint>
  <link name="link_4_0">
    <visual>
      <geometry>
        <box size="0.016 0.016 0.055"/>
      </geometry>
      <origin rpy="0 0 0" xyz="0 0 -0.0275"/>
      <material name="blue">
        <color rgba="0 0 1 0.9"/>
      </material>
    </visual>
    <collision>
      <geometry>
        <box size="0.016 0.016 0.055"/>
      </geometry>
      <origin rpy="0 0 0" xyz="0 0 -0.0275"/>
    </collision>
    <inertial>
      <origin rpy="0 0 0" xyz="0 0 0"/>
      <mass value="0.5"/>
      <inertia ixx="1.0" ixy="0.0" ixz="0.0" iyy="1.0" iyz="0.0" izz="1.0"/>
    </inertial>
  </link>
  <joint name="joint_4_0" type="prismatic">
    <parent link="table_base"/>
    <child link="link_4_0"/>
    <origin ryp="0 0 0" xyz="0.08600000000000001 0.018000000000000002 0"/>
    <axis xyz="0 0 1"/>
    <limit effort="4" lower="0" upper="0.045" velocity="0.01"/>
  </joint>
  <link name="link_3_7">
    <visual>
      <geometry>
        <box size="0.016 0.016 0.055"/>
      </geometry>
      <origin rpy="0 0 0" xyz="0 0 -0.0275"/>
      <material name="blue">
        <color rgba="0 0 1 0.9"/>
      </material>
    </visual>
    <collision>
      <geometry>
        <box size="0.016 0.016 0.055"/>
      </geometry>
      <origin rpy="0 0 0" xyz="0 0 -0.0275"/>
    </collision>
    <inertial>
      <origin rpy="0 0 0" xyz="0 0 0"/>
      <mass value="0.5"/>
      <inertia ixx="1.0" ixy="0.0" ixz="0.0" iyy="1.0" iyz="0.0" izz="1.0"/>
    </inertial>
  </link>
  <joint name="joint_3_7" type="prismatic">
    <parent link="table_base"/>
    <child link="link_3_7"/>
    <origin ryp="0 0 0" xyz="0.069 0.137 0"/>
    <axis xyz="0 0 1"/>
    <limit effort="4" lower="0" upper="0.045" velocity="0.01"/>
  </joint>
  <link name="link_3_6">
    <visual>
      <geometry>
        <box size="0.016 0.016 0.055"/>
      </geometry>
      <origin rpy="0 0 0" xyz="0 0 -0.0275"/>
      <material name="blue">
        <color rgba="0 0 1 0.9"/>
      </material>
    </visual>
    <collision>
      <geometry>
        <box size="0.016 0.016 0.055"/>
      </geometry>
      <origin rpy="0 0 0" xyz="0 0 -0.0275"/>
    </collision>
    <inertial>
      <origin rpy="0 0 0" xyz="0 0 0"/>
      <mass value="0.5"/>
      <inertia ixx="1.0" ixy="0.0" ixz="0.0" iyy="1.0" iyz="0.0" izz="1.0"/>
    </inertial>
  </link>
  <joint name="joint_3_6" type="prismatic">
    <parent link="table_base"/>
    <child link="link_3_6"/>
    <origin ryp="0 0 0" xyz="0.069 0.12000000000000001 0"/>
    <axis xyz="0 0 1"/>
    <limit effort="4" lower="0" upper="0.045" velocity="0.01"/>
  </joint>
  <link name="link_3_5">
    <visual>
      <geometry>
        <box size="0.016 0.016 0.055"/>
      </geometry>
      <origin rpy="0 0 0" xyz="0 0 -0.0275"/>
      <material name="blue">
        <color rgba="0 0 1 0.9"/>
      </material>
    </visual>
    <collision>
      <geometry>
        <box size="0.016 0.016 0.055"/>
      </geometry>
      <origin rpy="0 0 0" xyz="0 0 -0.0275"/>
    </collision>
    <inertial>
      <origin rpy="0 0 0" xyz="0 0 0"/>
      <mass value="0.5"/>
      <inertia ixx="1.0" ixy="0.0" ixz="0.0" iyy="1.0" iyz="0.0" izz="1.0"/>
    </inertial>
  </link>
  <joint name="joint_3_5" type="prismatic">
    <parent link="table_base"/>
    <child link="link_3_5"/>
    <origin ryp="0 0 0" xyz="0.069 0.103 0"/>
    <axis xyz="0 0 1"/>
    <limit effort="4" lower="0" upper="0.045" velocity="0.01"/>
  </joint>
  <link name="link_3_4">
    <visual>
      <geometry>
        <box size="0.016 0.016 0.055"/>
      </geometry>
      <origin rpy="0 0 0" xyz="0 0 -0.0275"/>
      <material name="blue">
        <color rgba="0 0 1 0.9"/>
      </material>
    </visual>
    <collision>
      <geometry>
        <box size="0.016 0.016 0.055"/>
      </geometry>
      <origin rpy="0 0 0" xyz="0 0 -0.0275"/>
    </collision>
    <inertial>
      <origin rpy="0 0 0" xyz="0 0 0"/>
      <mass value="0.5"/>
      <inertia ixx="1.0" ixy="0.0" ixz="0.0" iyy="1.0" iyz="0.0" izz="1.0"/>
    </inertial>
  </link>
  <joint name="joint_3_4" type="prismatic">
    <parent link="table_base"/>
    <child link="link_3_4"/>
    <origin ryp="0 0 0" xyz="0.069 0.08600000000000001 0"/>
    <axis xyz="0 0 1"/>
    <limit effort="4" lower="0" upper="0.045" velocity="0.01"/>
  </joint>
  <link name="link_3_3">
    <visual>
      <geometry>
        <box size="0.016 0.016 0.055"/>
      </geometry>
      <origin rpy="0 0 0" xyz="0 0 -0.0275"/>
      <material name="blue">
        <color rgba="0 0 1 0.9"/>
      </material>
    </visual>
    <collision>
      <geometry>
        <box size="0.016 0.016 0.055"/>
      </geometry>
      <origin rpy="0 0 0" xyz="0 0 -0.0275"/>
    </collision>
    <inertial>
      <origin rpy="0 0 0" xyz="0 0 0"/>
      <mass value="0.5"/>
      <inertia ixx="1.0" ixy="0.0" ixz="0.0" iyy="1.0" iyz="0.0" izz="1.0"/>
    </inertial>
  </link>
  <joint name="joint_3_3" type="prismatic">
    <parent link="table_base"/>
    <child link="link_3_3"/>
    <origin ryp="0 0 0" xyz="0.069 0.069 0"/>
    <axis xyz="0 0 1"/>
    <limit effort="4" lower="0" upper="0.045" velocity="0.01"/>
  </joint>
  <link name="link_3_2">
    <visual>
      <geometry>
        <box size="0.016 0.016 0.055"/>
      </geometry>
      <origin rpy="0 0 0" xyz="0 0 -0.0275"/>
      <material name="blue">
        <color rgba="0 0 1 0.9"/>
      </material>
    </visual>
    <collision>
      <geometry>
        <box size="0.016 0.016 0.055"/>
      </geometry>
      <origin rpy="0 0 0" xyz="0 0 -0.0275"/>
    </collision>
    <inertial>
      <origin rpy="0 0 0" xyz="0 0 0"/>
      <mass value="0.5"/>
      <inertia ixx="1.0" ixy="0.0" ixz="0.0" iyy="1.0" iyz="0.0" izz="1.0"/>
    </inertial>
  </link>
  <joint name="joint_3_2" type="prismatic">
    <parent link="table_base"/>
    <child link="link_3_2"/>
    <origin ryp="0 0 0" xyz="0.069 0.052000000000000005 0"/>
    <axis xyz="0 0 1"/>
    <limit effort="4" lower="0" upper="0.045" velocity="0.01"/>
  </joint>
  <link name="link_3_1">
    <visual>
      <geometry>
        <box size="0.016 0.016 0.055"/>
      </geometry>
      <origin rpy="0 0 0" xyz="0 0 -0.0275"/>
      <material name="blue">
        <color rgba="0 0 1 0.9"/>
      </material>
    </visual>
    <collision>
      <geometry>
        <box size="0.016 0.016 0.055"/>
      </geometry>
      <origin rpy="0 0 0" xyz="0 0 -0.0275"/>
    </collision>
    <inertial>
      <origin rpy="0 0 0" xyz="0 0 0"/>
      <mass value="0.5"/>
      <inertia ixx="1.0" ixy="0.0" ixz="0.0" iyy="1.0" iyz="0.0" izz="1.0"/>
    </inertial>
  </link>
  <joint name="joint_3_1" type="prismatic">
    <parent link="table_base"/>
    <child link="link_3_1"/>
    <origin ryp="0 0 0" xyz="0.069 0.035 0"/>
    <axis xyz="0 0 1"/>
    <limit effort="4" lower="0" upper="0.045" velocity="0.01"/>
  </joint>
  <link name="link_3_0">
    <visual>
      <geometry>
        <box size="0.016 0.016 0.055"/>
      </geometry>
      <origin rpy="0 0 0" xyz="0 0 -0.0275"/>
      <material name="blue">
        <color rgba="0 0 1 0.9"/>
      </material>
    </visual>
    <collision>
      <geometry>
        <box size="0.016 0.016 0.055"/>
      </geometry>
      <origin rpy="0 0 0" xyz="0 0 -0.0275"/>
    </collision>
    <inertial>
      <origin rpy="0 0 0" xyz="0 0 0"/>
      <mass value="0.5"/>
      <inertia ixx="1.0" ixy="0.0" ixz="0.0" iyy="1.0" iyz="0.0" izz="1.0"/>
    </inertial>
  </link>
  <joint name="joint_3_0" type="prismatic">
    <parent link="table_base"/>
    <child link="link_3_0"/>
    <origin ryp="0 0 0" xyz="0.069 0.018000000000000002 0"/>
    <axis xyz="0 0 1"/>
    <limit effort="4" lower="0" upper="0.045" velocity="0.01"/>
  </joint>
  <link name="link_2_7">
    <visual>
      <geometry>
        <box size="0.016 0.016 0.055"/>
      </geometry>
      <origin rpy="0 0 0" xyz="0 0 -0.0275"/>
      <material name="blue">
        <color rgba="0 0 1 0.9"/>
      </material>
    </visual>
    <collision>
      <geometry>
        <box size="0.016 0.016 0.055"/>
      </geometry>
      <origin rpy="0 0 0" xyz="0 0 -0.0275"/>
    </collision>
    <inertial>
      <origin rpy="0 0 0" xyz="0 0 0"/>
      <mass value="0.5"/>
      <inertia ixx="1.0" ixy="0.0" ixz="0.0" iyy="1.0" iyz="0.0" izz="1.0"/>
    </inertial>
  </link>
  <joint name="joint_2_7" type="prismatic">
    <parent link="table_base"/>
    <child link="link_2_7"/>
    <origin ryp="0 0 0" xyz="0.052000000000000005 0.137 0"/>
    <axis xyz="0 0 1"/>
    <limit effort="4" lower="0" upper="0.045" velocity="0.01"/>
  </joint>
  <link name="link_2_6">
    <visual>
      <geometry>
        <box size="0.016 0.016 0.055"/>
      </geometry>
      <origin rpy="0 0 0" xyz="0 0 -0.0275"/>
      <material name="blue">
        <color rgba="0 0 1 0.9"/>
      </material>
    </visual>
    <collision>
      <geometry>
        <box size="0.016 0.016 0.055"/>
      </geometry>
      <origin rpy="0 0 0" xyz="0 0 -0.0275"/>
    </collision>
    <inertial>
      <origin rpy="0 0 0" xyz="0 0 0"/>
      <mass value="0.5"/>
      <inertia ixx="1.0" ixy="0.0" ixz="0.0" iyy="1.0" iyz="0.0" izz="1.0"/>
    </inertial>
  </link>
  <joint name="joint_2_6" type="prismatic">
    <parent link="table_base"/>
    <child link="link_2_6"/>
    <origin ryp="0 0 0" xyz="0.052000000000000005 0.12000000000000001 0"/>
    <axis xyz="0 0 1"/>
    <limit effort="4" lower="0" upper="0.045" velocity="0.01"/>
  </joint>
  <link name="link_2_5">
    <visual>
      <geometry>
        <box size="0.016 0.016 0.055"/>
      </geometry>
      <origin rpy="0 0 0" xyz="0 0 -0.0275"/>
      <material name="blue">
        <color rgba="0 0 1 0.9"/>
      </material>
    </visual>
    <collision>
      <geometry>
        <box size="0.016 0.016 0.055"/>
      </geometry>
      <origin rpy="0 0 0" xyz="0 0 -0.0275"/>
    </collision>
    <inertial>
      <origin rpy="0 0 0" xyz="0 0 0"/>
      <mass value="0.5"/>
      <inertia ixx="1.0" ixy="0.0" ixz="0.0" iyy="1.0" iyz="0.0" izz="1.0"/>
    </inertial>
  </link>
  <joint name="joint_2_5" type="prismatic">
    <parent link="table_base"/>
    <child link="link_2_5"/>
    <origin ryp="0 0 0" xyz="0.052000000000000005 0.103 0"/>
    <axis xyz="0 0 1"/>
    <limit effort="4" lower="0" upper="0.045" velocity="0.01"/>
  </joint>
  <link name="link_2_4">
    <visual>
      <geometry>
        <box size="0.016 0.016 0.055"/>
      </geometry>
      <origin rpy="0 0 0" xyz="0 0 -0.0275"/>
      <material name="blue">
        <color rgba="0 0 1 0.9"/>
      </material>
    </visual>
    <collision>
      <geometry>
        <box size="0.016 0.016 0.055"/>
      </geometry>
      <origin rpy="0 0 0" xyz="0 0 -0.0275"/>
    </collision>
    <inertial>
      <origin rpy="0 0 0" xyz="0 0 0"/>
      <mass value="0.5"/>
      <inertia ixx="1.0" ixy="0.0" ixz="0.0" iyy="1.0" iyz="0.0" izz="1.0"/>
    </inertial>
  </link>
  <joint name="joint_2_4" type="prismatic">
    <parent link="table_base"/>
    <child link="link_2_4"/>
    <origin ryp="0 0 0" xyz="0.052000000000000005 0.08600000000000001 0"/>
    <axis xyz="0 0 1"/>
    <limit effort="4" lower="0" upper="0.045" velocity="0.01"/>
  </joint>
  <link name="link_2_3">
    <visual>
      <geometry>
        <box size="0.016 0.016 0.055"/>
      </geometry>
      <origin rpy="0 0 0" xyz="0 0 -0.0275"/>
      <material name="blue">
        <color rgba="0 0 1 0.9"/>
      </material>
    </visual>
    <collision>
      <geometry>
        <box size="0.016 0.016 0.055"/>
      </geometry>
      <origin rpy="0 0 0" xyz="0 0 -0.0275"/>
    </collision>
    <inertial>
      <origin rpy="0 0 0" xyz="0 0 0"/>
      <mass value="0.5"/>
      <inertia ixx="1.0" ixy="0.0" ixz="0.0" iyy="1.0" iyz="0.0" izz="1.0"/>
    </inertial>
  </link>
  <joint name="joint_2_3" type="prismatic">
    <parent link="table_base"/>
    <child link="link_2_3"/>
    <origin ryp="0 0 0" xyz="0.052000000000000005 0.069 0"/>
    <axis xyz="0 0 1"/>
    <limit effort="4" lower="0" upper="0.045" velocity="0.01"/>
  </joint>
  <link name="link_2_2">
    <visual>
      <geometry>
        <box size="0.016 0.016 0.055"/>
      </geometry>
      <origin rpy="0 0 0" xyz="0 0 -0.0275"/>
      <material name="blue">
        <color rgba="0 0 1 0.9"/>
      </material>
    </visual>
    <collision>
      <geometry>
        <box size="0.016 0.016 0.055"/>
      </geometry>
      <origin rpy="0 0 0" xyz="0 0 -0.0275"/>
    </collision>
    <inertial>
      <origin rpy="0 0 0" xyz="0 0 0"/>
      <mass value="0.5"/>
      <inertia ixx="1.0" ixy="0.0" ixz="0.0" iyy="1.0" iyz="0.0" izz="1.0"/>
    </inertial>
  </link>
  <joint name="joint_2_2" type="prismatic">
    <parent link="table_base"/>
    <child link="link_2_2"/>
    <origin ryp="0 0 0" xyz="0.052000000000000005 0.052000000000000005 0"/>
    <axis xyz="0 0 1"/>
    <limit effort="4" lower="0" upper="0.045" velocity="0.01"/>
  </joint>
  <link name="link_2_1">
    <visual>
      <geometry>
        <box size="0.016 0.016 0.055"/>
      </geometry>
      <origin rpy="0 0 0" xyz="0 0 -0.0275"/>
      <material name="blue">
        <color rgba="0 0 1 0.9"/>
      </material>
    </visual>
    <collision>
      <geometry>
        <box size="0.016 0.016 0.055"/>
      </geometry>
      <origin rpy="0 0 0" xyz="0 0 -0.0275"/>
    </collision>
    <inertial>
      <origin rpy="0 0 0" xyz="0 0 0"/>
      <mass value="0.5"/>
      <inertia ixx="1.0" ixy="0.0" ixz="0.0" iyy="1.0" iyz="0.0" izz="1.0"/>
    </inertial>
  </link>
  <joint name="joint_2_1" type="prismatic">
    <parent link="table_base"/>
    <child link="link_2_1"/>
    <origin ryp="0 0 0" xyz="0.052000000000000005 0.035 0"/>
    <axis xyz="0 0 1"/>
    <limit effort="4" lower="0" upper="0.045" velocity="0.01"/>
  </joint>
  <link name="link_2_0">
    <visual>
      <geometry>
        <box size="0.016 0.016 0.055"/>
      </geometry>
      <origin rpy="0 0 0" xyz="0 0 -0.0275"/>
      <material name="blue">
        <color rgba="0 0 1 0.9"/>
      </material>
    </visual>
    <collision>
      <geometry>
        <box size="0.016 0.016 0.055"/>
      </geometry>
      <origin rpy="0 0 0" xyz="0 0 -0.0275"/>
    </collision>
    <inertial>
      <origin rpy="0 0 0" xyz="0 0 0"/>
      <mass value="0.5"/>
      <inertia ixx="1.0" ixy="0.0" ixz="0.0" iyy="1.0" iyz="0.0" izz="1.0"/>
    </inertial>
  </link>
  <joint name="joint_2_0" type="prismatic">
    <parent link="table_base"/>
    <child link="link_2_0"/>
    <origin ryp="0 0 0" xyz="0.052000000000000005 0.018000000000000002 0"/>
    <axis xyz="0 0 1"/>
    <limit effort="4" lower="0" upper="0.045" velocity="0.01"/>
  </joint>
  <link name="link_1_7">
    <visual>
      <geometry>
        <box size="0.016 0.016 0.055"/>
      </geometry>
      <origin rpy="0 0 0" xyz="0 0 -0.0275"/>
      <material name="blue">
        <color rgba="0 0 1 0.9"/>
      </material>
    </visual>
    <collision>
      <geometry>
        <box size="0.016 0.016 0.055"/>
      </geometry>
      <origin rpy="0 0 0" xyz="0 0 -0.0275"/>
    </collision>
    <inertial>
      <origin rpy="0 0 0" xyz="0 0 0"/>
      <mass value="0.5"/>
      <inertia ixx="1.0" ixy="0.0" ixz="0.0" iyy="1.0" iyz="0.0" izz="1.0"/>
    </inertial>
  </link>
  <joint name="joint_1_7" type="prismatic">
    <parent link="table_base"/>
    <child link="link_1_7"/>
    <origin ryp="0 0 0" xyz="0.035 0.137 0"/>
    <axis xyz="0 0 1"/>
    <limit effort="4" lower="0" upper="0.045" velocity="0.01"/>
  </joint>
  <link name="link_1_6">
    <visual>
      <geometry>
        <box size="0.016 0.016 0.055"/>
      </geometry>
      <origin rpy="0 0 0" xyz="0 0 -0.0275"/>
      <material name="blue">
        <color rgba="0 0 1 0.9"/>
      </material>
    </visual>
    <collision>
      <geometry>
        <box size="0.016 0.016 0.055"/>
      </geometry>
      <origin rpy="0 0 0" xyz="0 0 -0.0275"/>
    </collision>
    <inertial>
      <origin rpy="0 0 0" xyz="0 0 0"/>
      <mass value="0.5"/>
      <inertia ixx="1.0" ixy="0.0" ixz="0.0" iyy="1.0" iyz="0.0" izz="1.0"/>
    </inertial>
  </link>
  <joint name="joint_1_6" type="prismatic">
    <parent link="table_base"/>
    <child link="link_1_6"/>
    <origin ryp="0 0 0" xyz="0.035 0.12000000000000001 0"/>
    <axis xyz="0 0 1"/>
    <limit effort="4" lower="0" upper="0.045" velocity="0.01"/>
  </joint>
  <link name="link_1_5">
    <visual>
      <geometry>
        <box size="0.016 0.016 0.055"/>
      </geometry>
      <origin rpy="0 0 0" xyz="0 0 -0.0275"/>
      <material name="blue">
        <color rgba="0 0 1 0.9"/>
      </material>
    </visual>
    <collision>
      <geometry>
        <box size="0.016 0.016 0.055"/>
      </geometry>
      <origin rpy="0 0 0" xyz="0 0 -0.0275"/>
    </collision>
    <inertial>
      <origin rpy="0 0 0" xyz="0 0 0"/>
      <mass value="0.5"/>
      <inertia ixx="1.0" ixy="0.0" ixz="0.0" iyy="1.0" iyz="0.0" izz="1.0"/>
    </inertial>
  </link>
  <joint name="joint_1_5" type="prismatic">
    <parent link="table_base"/>
    <child link="link_1_5"/>
    <origin ryp="0 0 0" xyz="0.035 0.103 0"/>
    <axis xyz="0 0 1"/>
    <limit effort="4" lower="0" upper="0.045" velocity="0.01"/>
  </joint>
  <link name="link_1_4">
    <visual>
      <geometry>
        <box size="0.016 0.016 0.055"/>
      </geometry>
      <origin rpy="0 0 0" xyz="0 0 -0.0275"/>
      <material name="blue">
        <color rgba="0 0 1 0.9"/>
      </material>
    </visual>
    <collision>
      <geometry>
        <box size="0.016 0.016 0.055"/>
      </geometry>
      <origin rpy="0 0 0" xyz="0 0 -0.0275"/>
    </collision>
    <inertial>
      <origin rpy="0 0 0" xyz="0 0 0"/>
      <mass value="0.5"/>
      <inertia ixx="1.0" ixy="0.0" ixz="0.0" iyy="1.0" iyz="0.0" izz="1.0"/>
    </inertial>
  </link>
  <joint name="joint_1_4" type="prismatic">
    <parent link="table_base"/>
    <child link="link_1_4"/>
    <origin ryp="0 0 0" xyz="0.035 0.08600000000000001 0"/>
    <axis xyz="0 0 1"/>
    <limit effort="4" lower="0" upper="0.045" velocity="0.01"/>
  </joint>
  <link name="link_1_3">
    <visual>
      <geometry>
        <box size="0.016 0.016 0.055"/>
      </geometry>
      <origin rpy="0 0 0" xyz="0 0 -0.0275"/>
      <material name="blue">
        <color rgba="0 0 1 0.9"/>
      </material>
    </visual>
    <collision>
      <geometry>
        <box size="0.016 0.016 0.055"/>
      </geometry>
      <origin rpy="0 0 0" xyz="0 0 -0.0275"/>
    </collision>
    <inertial>
      <origin rpy="0 0 0" xyz="0 0 0"/>
      <mass value="0.5"/>
      <inertia ixx="1.0" ixy="0.0" ixz="0.0" iyy="1.0" iyz="0.0" izz="1.0"/>
    </inertial>
  </link>
  <joint name="joint_1_3" type="prismatic">
    <parent link="table_base"/>
    <child link="link_1_3"/>
    <origin ryp="0 0 0" xyz="0.035 0.069 0"/>
    <axis xyz="0 0 1"/>
    <limit effort="4" lower="0" upper="0.045" velocity="0.01"/>
  </joint>
  <link name="link_1_2">
    <visual>
      <geometry>
        <box size="0.016 0.016 0.055"/>
      </geometry>
      <origin rpy="0 0 0" xyz="0 0 -0.0275"/>
      <material name="blue">
        <color rgba="0 0 1 0.9"/>
      </material>
    </visual>
    <collision>
      <geometry>
        <box size="0.016 0.016 0.055"/>
      </geometry>
      <origin rpy="0 0 0" xyz="0 0 -0.0275"/>
    </collision>
    <inertial>
      <origin rpy="0 0 0" xyz="0 0 0"/>
      <mass value="0.5"/>
      <inertia ixx="1.0" ixy="0.0" ixz="0.0" iyy="1.0" iyz="0.0" izz="1.0"/>
    </inertial>
  </link>
  <joint name="joint_1_2" type="prismatic">
    <parent link="table_base"/>
    <child link="link_1_2"/>
    <origin ryp="0 0 0" xyz="0.035 0.052000000000000005 0"/>
    <axis xyz="0 0 1"/>
    <limit effort="4" lower="0" upper="0.045" velocity="0.01"/>
  </joint>
  <link name="link_1_1">
    <visual>
      <geometry>
        <box size="0.016 0.016 0.055"/>
      </geometry>
      <origin rpy="0 0 0" xyz="0 0 -0.0275"/>
      <material name="blue">
        <color rgba="0 0 1 0.9"/>
      </material>
    </visual>
    <collision>
      <geometry>
        <box size="0.016 0.016 0.055"/>
      </geometry>
      <origin rpy="0 0 0" xyz="0 0 -0.0275"/>
    </collision>
    <inertial>
      <origin rpy="0 0 0" xyz="0 0 0"/>
      <mass value="0.5"/>
      <inertia ixx="1.0" ixy="0.0" ixz="0.0" iyy="1.0" iyz="0.0" izz="1.0"/>
    </inertial>
  </link>
  <joint name="joint_1_1" type="prismatic">
    <parent link="table_base"/>
    <child link="link_1_1"/>
    <origin ryp="0 0 0" xyz="0.035 0.035 0"/>
    <axis xyz="0 0 1"/>
    <limit effort="4" lower="0" upper="0.045" velocity="0.01"/>
  </joint>
  <link name="link_1_0">
    <visual>
      <geometry>
        <box size="0.016 0.016 0.055"/>
      </geometry>
      <origin rpy="0 0 0" xyz="0 0 -0.0275"/>
      <material name="blue">
        <color rgba="0 0 1 0.9"/>
      </material>
    </visual>
    <collision>
      <geometry>
        <box size="0.016 0.016 0.055"/>
      </geometry>
      <origin rpy="0 0 0" xyz="0 0 -0.0275"/>
    </collision>
    <inertial>
      <origin rpy="0 0 0" xyz="0 0 0"/>
      <mass value="0.5"/>
      <inertia ixx="1.0" ixy="0.0" ixz="0.0" iyy="1.0" iyz="0.0" izz="1.0"/>
    </inertial>
  </link>
  <joint name="joint_1_0" type="prismatic">
    <parent link="table_base"/>
    <child link="link_1_0"/>
    <origin ryp="0 0 0" xyz="0.035 0.018000000000000002 0"/>
    <axis xyz="0 0 1"/>
    <limit effort="4" lower="0" upper="0.045" velocity="0.01"/>
  </joint>
  <link name="link_0_7">
    <visual>
      <geometry>
        <box size="0.016 0.016 0.055"/>
      </geometry>
      <origin rpy="0 0 0" xyz="0 0 -0.0275"/>
      <material name="blue">
        <color rgba="0 0 1 0.9"/>
      </material>
    </visual>
    <collision>
      <geometry>
        <box size="0.016 0.016 0.055"/>
      </geometry>
      <origin rpy="0 0 0" xyz="0 0 -0.0275"/>
    </collision>
    <inertial>
      <origin rpy="0 0 0" xyz="0 0 0"/>
      <mass value="0.5"/>
      <inertia ixx="1.0" ixy="0.0" ixz="0.0" iyy="1.0" iyz="0.0" izz="1.0"/>
    </inertial>
  </link>
  <joint name="joint_0_7" type="prismatic">
    <parent link="table_base"/>
    <child link="link_0_7"/>
    <origin ryp="0 0 0" xyz="0.018000000000000002 0.137 0"/>
    <axis xyz="0 0 1"/>
    <limit effort="4" lower="0" upper="0.045" velocity="0.01"/>
  </joint>
  <link name="link_0_6">
    <visual>
      <geometry>
        <box size="0.016 0.016 0.055"/>
      </geometry>
      <origin rpy="0 0 0" xyz="0 0 -0.0275"/>
      <material name="blue">
        <color rgba="0 0 1 0.9"/>
      </material>
    </visual>
    <collision>
      <geometry>
        <box size="0.016 0.016 0.055"/>
      </geometry>
      <origin rpy="0 0 0" xyz="0 0 -0.0275"/>
    </collision>
    <inertial>
      <origin rpy="0 0 0" xyz="0 0 0"/>
      <mass value="0.5"/>
      <inertia ixx="1.0" ixy="0.0" ixz="0.0" iyy="1.0" iyz="0.0" izz="1.0"/>
    </inertial>
  </link>
  <joint name="joint_0_6" type="prismatic">
    <parent link="table_base"/>
    <child link="link_0_6"/>
    <origin ryp="0 0 0" xyz="0.018000000000000002 0.12000000000000001 0"/>
    <axis xyz="0 0 1"/>
    <limit effort="4" lower="0" upper="0.045" velocity="0.01"/>
  </joint>
  <link name="link_0_5">
    <visual>
      <geometry>
        <box size="0.016 0.016 0.055"/>
      </geometry>
      <origin rpy="0 0 0" xyz="0 0 -0.0275"/>
      <material name="blue">
        <color rgba="0 0 1 0.9"/>
      </material>
    </visual>
    <collision>
      <geometry>
        <box size="0.016 0.016 0.055"/>
      </geometry>
      <origin rpy="0 0 0" xyz="0 0 -0.0275"/>
    </collision>
    <inertial>
      <origin rpy="0 0 0" xyz="0 0 0"/>
      <mass value="0.5"/>
      <inertia ixx="1.0" ixy="0.0" ixz="0.0" iyy="1.0" iyz="0.0" izz="1.0"/>
    </inertial>
  </link>
  <joint name="joint_0_5" type="prismatic">
    <parent link="table_base"/>
    <child link="link_0_5"/>
    <origin ryp="0 0 0" xyz="0.018000000000000002 0.103 0"/>
    <axis xyz="0 0 1"/>
    <limit effort="4" lower="0" upper="0.045" velocity="0.01"/>
  </joint>
  <link name="link_0_4">
    <visual>
      <geometry>
        <box size="0.016 0.016 0.055"/>
      </geometry>
      <origin rpy="0 0 0" xyz="0 0 -0.0275"/>
      <material name="blue">
        <color rgba="0 0 1 0.9"/>
      </material>
    </visual>
    <collision>
      <geometry>
        <box size="0.016 0.016 0.055"/>
      </geometry>
      <origin rpy="0 0 0" xyz="0 0 -0.0275"/>
    </collision>
    <inertial>
      <origin rpy="0 0 0" xyz="0 0 0"/>
      <mass value="0.5"/>
      <inertia ixx="1.0" ixy="0.0" ixz="0.0" iyy="1.0" iyz="0.0" izz="1.0"/>
    </inertial>
  </link>
  <joint name="joint_0_4" type="prismatic">
    <parent link="table_base"/>
    <child link="link_0_4"/>
    <origin ryp="0 0 0" xyz="0.018000000000000002 0.08600000000000001 0"/>
    <axis xyz="0 0 1"/>
    <limit effort="4" lower="0" upper="0.045" velocity="0.01"/>
  </joint>
  <link name="link_0_3">
    <visual>
      <geometry>
        <box size="0.016 0.016 0.055"/>
      </geometry>
      <origin rpy="0 0 0" xyz="0 0 -0.0275"/>
      <material name="blue">
        <color rgba="0 0 1 0.9"/>
      </material>
    </visual>
    <collision>
      <geometry>
        <box size="0.016 0.016 0.055"/>
      </geometry>
      <origin rpy="0 0 0" xyz="0 0 -0.0275"/>
    </collision>
    <inertial>
      <origin rpy="0 0 0" xyz="0 0 0"/>
      <mass value="0.5"/>
      <inertia ixx="1.0" ixy="0.0" ixz="0.0" iyy="1.0" iyz="0.0" izz="1.0"/>
    </inertial>
  </link>
  <joint name="joint_0_3" type="prismatic">
    <parent link="table_base"/>
    <child link="link_0_3"/>
    <origin ryp="0 0 0" xyz="0.018000000000000002 0.069 0"/>
    <axis xyz="0 0 1"/>
    <limit effort="4" lower="0" upper="0.045" velocity="0.01"/>
  </joint>
  <link name="link_0_2">
    <visual>
      <geometry>
        <box size="0.016 0.016 0.055"/>
      </geometry>
      <origin rpy="0 0 0" xyz="0 0 -0.0275"/>
      <material name="blue">
        <color rgba="0 0 1 0.9"/>
      </material>
    </visual>
    <collision>
      <geometry>
        <box size="0.016 0.016 0.055"/>
      </geometry>
      <origin rpy="0 0 0" xyz="0 0 -0.0275"/>
    </collision>
    <inertial>
      <origin rpy="0 0 0" xyz="0 0 0"/>
      <mass value="0.5"/>
      <inertia ixx="1.0" ixy="0.0" ixz="0.0" iyy="1.0" iyz="0.0" izz="1.0"/>
    </inertial>
  </link>
  <joint name="joint_0_2" type="prismatic">
    <parent link="table_base"/>
    <child link="link_0_2"/>
    <origin ryp="0 0 0" xyz="0.018000000000000002 0.052000000000000005 0"/>
    <axis xyz="0 0 1"/>
    <limit effort="4" lower="0" upper="0.045" velocity="0.01"/>
  </joint>
  <link name="link_0_1">
    <visual>
      <geometry>
        <box size="0.016 0.016 0.055"/>
      </geometry>
      <origin rpy="0 0 0" xyz="0 0 -0.0275"/>
      <material name="blue">
        <color rgba="0 0 1 0.9"/>
      </material>
    </visual>
    <collision>
      <geometry>
        <box size="0.016 0.016 0.055"/>
      </geometry>
      <origin rpy="0 0 0" xyz="0 0 -0.0275"/>
    </collision>
    <inertial>
      <origin rpy="0 0 0" xyz="0 0 0"/>
      <mass value="0.5"/>
      <inertia ixx="1.0" ixy="0.0" ixz="0.0" iyy="1.0" iyz="0.0" izz="1.0"/>
    </inertial>
  </link>
  <joint name="joint_0_1" type="prismatic">
    <parent link="table_base"/>
    <child link="link_0_1"/>
    <origin ryp="0 0 0" xyz="0.018000000000000002 0.035 0"/>
    <axis xyz="0 0 1"/>
    <limit effort="4" lower="0" upper="0.045" velocity="0.01"/>
  </joint>
  <link name="link_0_0">
    <visual>
      <geometry>
        <box size="0.016 0.016 0.055"/>
      </geometry>
      <origin rpy="0 0 0" xyz="0 0 -0.0275"/>
      <material name="blue">
        <color rgba="0 0 1 0.9"/>
      </material>
    </visual>
    <collision>
      <geometry>
        <box size="0.016 0.016 0.055"/>
      </geometry>
      <origin rpy="0 0 0" xyz="0 0 -0.0275"/>
    </collision>
    <inertial>
      <origin rpy="0 0 0" xyz="0 0 0"/>
      <mass value="0.5"/>
      <inertia ixx="1.0" ixy="0.0" ixz="0.0" iyy="1.0" iyz="0.0" izz="1.0"/>
    </inertial>
  </link>
  <joint name="joint_0_0" type="prismatic">
    <parent link="table_base"/>
    <child link="link_0_0"/>
    <origin ryp="0 0 0" xyz="0.018000000000000002 0.018000000000000002 0"/>
    <axis xyz="0 0 1"/>
    <limit effort="4" lower="0" upper="0.045" velocity="0.01"/>
  </joint>
</robot>

